Workbook

Sheet 収支予測
H1: =+#REF! -> #REF! | I1: =IF(H2=12,H1+1,H1) -> #REF! | J1: =IF(I2=12,I1+1,I1) -> #REF! | K1: 30 | L1: =IF(K2=12,K1+1,K1) -> 30 | M1: =IF(L2=12,L1+1,L1) -> 30 | N1: =IF(M2=12,M1+1,M1) -> 31 | O1: =IF(N2=12,N1+1,N1) -> 31 | P1: 31 | Q1: 31 | R1: 31 | S1: 31 | T1: 31 | U1: 31 | V1: 31 | W1: =IF(V2=12,V1+1,V1) -> 31 | X1: 31 | Y1: 31 | Z1: =IF(Y2=12,Y1+1,Y1) -> 32 | AA1: =IF(Z2=12,Z1+1,Z1) -> 32 | AB1: =IF(AA2=12,AA1+1,AA1) -> 32 | AC1: =IF(AB2=12,AB1+1,AB1) -> 32 | AD1: =IF(AC2=12,AC1+1,AC1) -> 32 | AE1: =IF(AD2=12,AD1+1,AD1) -> 32 | AF1: =IF(AE2=12,AE1+1,AE1) -> 32 | AG1: =IF(AF2=12,AF1+1,AF1) -> 32 | ... BO1: =IF(BN2=12,BN1+1,BN1) -> 35
H2: =+#REF! -> #REF! | I2: =IF(H2=12,1,H2+1) -> #REF! | J2: =IF(I2=12,1,I2+1) -> #REF! | K2: 10 | L2: =IF(K2=12,1,K2+1) -> 11 | M2: =IF(L2=12,1,L2+1) -> 12 | N2: =IF(M2=12,1,M2+1) -> 1 | O2: 2 | P2: 3 | Q2: 4 | R2: 5 | S2: 6 | T2: 7 | U2: 8 | V2: 9 | W2: =IF(V2=12,1,V2+1) -> 10 | X2: 11 | Y2: 12 | Z2: =IF(Y2=12,1,Y2+1) -> 1 | AA2: =IF(Z2=12,1,Z2+1) -> 2 | AB2: =IF(AA2=12,1,AA2+1) -> 3 | AC2: =IF(AB2=12,1,AB2+1) -> 4 | AD2: =IF(AC2=12,1,AC2+1) -> 5 | AE2: =IF(AD2=12,1,AD2+1) -> 6 | AF2: =IF(AE2=12,1,AE2+1) -> 7 | AG2: =IF(AF2=12,1,AF2+1) -> 8 | ... BO2: =IF(BN2=12,1,BN2+1) -> 6
H3: =+#REF! -> #REF! | I3: =+#REF! -> #REF! | J3: =+#REF! -> #REF! | K3: 4 | L3: =+#REF! -> #REF! | M3: =+#REF! -> #REF! | N3: =+#REF! -> #REF! | O3: 8 | P3: 9 | Q3: 10 | R3: 11 | S3: 12 | T3: 1 | U3: 2 | V3: 3 | W3: =+V3+1 -> 4 | X3: 5 | Y3: 6 | Z3: =+Y3+1 -> 7 | AA3: =+Z3+1 -> 8 | AB3: =+AA3+1 -> 9 | AC3: =+AB3+1 -> 10 | AD3: =+AC3+1 -> 11 | AE3: =+AD3+1 -> 12 | AF3: =+AE3+1 -> 13 | AG3: =+AF3+1 -> 14 | ... BO3: =+BN3+1 -> 48
T4: 1 | U4: 2 | V4: 3 | W4: 4 | X4: 5 | Y4: 6 | Z4: 7 | AA4: 8 | AB4: 9 | AC4: 10 | AD4: 11 | AE4: 12 | AF4: 13 | AG4: 14 | AH4: 15 | AI4: 15 | AJ4: 15 | AK4: 15 | AL4: 15 | AM4: 15 | AN4: 15 | AO4: 15 | AP4: 15 | AQ4: 15 | AR4: 15 | AS4: 15 | AT4: 15 | AU4: 15 | AV4: 15 | AW4: 15 | AX4: 15 | AY4: 15 | AZ4: 15 | BA4: 15 | BB4: 15 | BC4: 15 | BD4: 15 | BE4: 15 | BF4: 15 | BG4: 15 | BH4: 15 | BI4: 15 | BJ4: 15 | BK4: 15 | BL4: 15 | BM4: 15 | BN4: 15 | BO4: 15
F5: 収支予測表
F9: 勘定科目 | H9: =IF(H3>$F$4,H3-$F$4,"実績") -> #REF! | I9: =IF(I3>$F$4,I3-$F$4,"実績") -> #REF! | J9: 実績 | K9: 実績 | L9: 実績 | M9: 実績 | N9: =IF(N3>$F$4,N3-$F$4,"実績") -> #REF! | O9: =IF(O3>$F$4,O3-$F$4,"実績") -> 8 | P9: 実績 | Q9: 実績 | R9: 実績 | S9: 実績 | T9: 実績 | U9: 実績 | V9: 実績 | W9: 実績 | X9: 実績 | Y9: 実績 | Z9: 実績 | AA9: 実績 | AB9: 予算 | AC9: 予算 | AD9: 予算 | AE9: 予算 | AF9: 手入力 | AG9: 手入力 | AH9: 手入力 | AI9: 手入力 | AJ9: 手入力 | AK9: 手入力 | AL9: 手入力 | AM9: 手入力 | AN9: 手入力 | AO9: 手入力 | AP9: 手入力 | AQ9: 手入力 | AR9: 手入力 | AS9: 手入力 | AT9: 手入力 | AU9: 手入力 | AV9: 手入力 | AW9: 手入力 | AX9: 手入力 | AY9: 手入力 | AZ9: 手入力 | BA9: 手入力 | BB9: 手入力 | BC9: 手入力 | BD9: 手入力 | BE9: 手入力 | BF9: 手入力 | BG9: 手入力 | BH9: 手入力 | BI9: 手入力 | BJ9: 手入力 | BK9: 手入力 | BL9: 手入力 | BM9: 手入力 | BN9: 手入力 | BO9: 手入力
H10: =+H1+H2/100 -> #REF! | I10: =+I1+I2/100 -> #REF! | J10: 30.09 | K10: 30.1 | L10: 30.11 | M10: 30.12 | N10: =+N1+N2/100 -> 31.01 | O10: 31.02 | P10: 31.03 | Q10: 31.04 | R10: 31.05 | S10: 31.06 | T10: 31.07 | U10: 31.08 | V10: 31.09 | W10: 31.1 | X10: 31.11 | Y10: 31.12 | Z10: 32.01 | AA10: =+AA1+AA2/100 -> 32.02 | AB10: =+AB1+AB2/100 -> 32.03 | AC10: =+AC1+AC2/100 -> 32.04 | AD10: =+AD1+AD2/100 -> 32.05 | AE10: =+AE1+AE2/100 -> 32.06 | AF10: =+AF1+AF2/100 -> 32.07 | AG10: =+AG1+AG2/100 -> 32.08 | AH10: =+AH1+AH2/100 -> 32.09 | ... BO10: =+BO1+BO2/100 -> 35.06 | BP10: 2024.07 | BQ10: 2024.08 | BR10: 2024.09 | BS10: 2024.10. | BT10: 2024.11. | BU10: 2024.12. | BV10: 2025.01 | BW10: 2025.02 | BX10: 2025.03 | BY10: 2025.04 | BZ10: 2025.05 | CA10: 2025.06 | CB10: 2025.04 | CC10: 2025.05 | CD10: 2025.06 | CE10: 2025.07 | CF10: 2025.08 | CG10: 2025.09 | CH10: 2025.10. | CI10: 2025.11 | CJ10: 2025.12 | CK10: 2026.01 | CL10: 2026.02 | CM10: 2026.03 | CN10: 2026.04 | CO10: 2026.05
F11: 売上高 | G11: 国保連Ａ型 | H11: =IF($F$4>=H$3,AO11,BA11) -> #REF! | I11: =IF($F$4>=I$3,AP11,BB11) -> #REF! | J11: 11649 | K11: 13405 | L11: 13307 | M11: 19201 | N11: =IF($F$4>=N$3,AU11,BG11) -> #REF! | O11: 13355 | P11: 18202 | Q11: 13100 | R11: 12490 | S11: 13027 | T11: 12481 | U11: 14091 | V11: 13080 | W11: 11883 | X11: 12402 | AB11: 1227385 | AC11: ='予測PL'!L3 -> 780153 | AD11: ='予測PL'!M3 -> 514206 | AE11: ='予測PL'!N3 -> 334355 | AF11: ='予測PL'!C3 -> 955367 | AG11: ='予測PL'!D3 -> 818306 | AH11: ='予測PL'!E3 -> 760538 | AI11: ='予測PL'!F3 -> 903177 | AJ11: ='予測PL'!G3 -> 921683 | AK11: ='予測PL'!H3 -> 806522 | AL11: ='予測PL'!I3 -> 822486 | AM11: ='予測PL'!J3 -> 793307 | ... AQ11: ='予測PL'!N3 -> 334355 | AR11: ='予測PL (2021)'!C3 | AS11: ='予測PL (2021)'!D3 -> 82000 | AT11: ='予測PL (2021)'!E3 -> 119363 | AU11: ='予測PL (2021)'!F3 -> 388107 | AV11: ='予測PL (2021)'!G3 -> 297878 | AW11: ='予測PL (2021)'!H3 -> 321334 | AX11: ='予測PL (2021)'!I3 -> 326856 | AY11: ='予測PL (2021)'!J3 -> 310213 | ... BC11: ='予測PL (2021)'!N3 -> 316667 | BD11: ='予測PL (2023)'!C3 -> 507273 | BE11: ='予測PL (2023)'!D3 -> 367202 | BF11: ='予測PL (2023)'!E3 -> 355174 | BG11: ='予測PL (2023)'!F3 -> 343678 | BH11: ='予測PL (2023)'!G3 -> 310741 | BI11: ='予測PL (2023)'!H3 -> 305926 | BJ11: ='予測PL (2023)'!I3 -> 198380 | BK11: ='予測PL (2023)'!J3 | ... BO11: ='予測PL (2023)'!N3 | BP11: ='予測PL (2024)'!C4 -> 2522779 | BQ11: ='予測PL (2024)'!D4 -> 2548892 | BR11: ='予測PL (2024)'!E4 -> 1925694 | BS11: ='予測PL (2024)'!F4 -> 2380420 | BT11: ='予測PL (2024)'!G4 -> 1810499 | BU11: ='予測PL (2024)'!H4 -> 1671189 | BV11: ='予測PL (2024)'!I4 -> 1672457 | BW11: ='予測PL (2024)'!J4 -> 1488521 | ... CA11: ='予測PL (2024)'!N4 | CB11: ='予測PL (2025.04-)'!C4 -> 2216026 | CC11: ='予測PL (2025.04-)'!D4 -> 2153396 | CD11: ='予測PL (2025.04-)'!E4 -> 2068535 | CE11: ='予測PL (2025.04-)'!F4 -> 1924273 | CF11: ='予測PL (2025.04-)'!G4 -> 1821950 | CG11: ='予測PL (2025.04-)'!H4 -> 1892545 | CH11: ='予測PL (2025.04-)'!I4 -> 1754854 | CI11: ='予測PL (2025.04-)'!J4 -> 1586450 | ... CM11: ='予測PL (2025.04-)'!N4 -> 1952454
G12: 国保連Ｂ型 | H12: =IF($F$4>=H$3,AO12,BA12) -> #REF! | I12: =IF($F$4>=I$3,AP12,BB12) -> #REF! | J12: 6404 | K12: 8041 | L12: 8680 | M12: 11304 | N12: =IF($F$4>=N$3,AU12,BG12) -> #REF! | O12: 7404 | P12: 9786 | Q12: 7695 | R12: 7859 | S12: 7390 | T12: 7106 | U12: 8314 | V12: 7975 | W12: 8048 | X12: 7746 | BP12: ='予測PL (2024)'!C5 -> 0 | BQ12: ='予測PL (2024)'!D5 -> 0 | BR12: ='予測PL (2024)'!E5 -> 0 | BS12: ='予測PL (2024)'!F5 -> 0 | BT12: ='予測PL (2024)'!G5 -> 98373 | BU12: ='予測PL (2024)'!H5 -> 136927 | BV12: ='予測PL (2024)'!I5 -> 120493 | BW12: ='予測PL (2024)'!J5 -> 184887 | ... CA12: ='予測PL (2024)'!N5 | CB12: ='予測PL (2025.04-)'!C5 -> 363290 | CC12: ='予測PL (2025.04-)'!D5 -> 352012 | CD12: ='予測PL (2025.04-)'!E5 -> 411068 | CE12: ='予測PL (2025.04-)'!F5 -> 689889 | CF12: ='予測PL (2025.04-)'!G5 -> 478943 | CG12: ='予測PL (2025.04-)'!H5 -> 465733 | CH12: ='予測PL (2025.04-)'!I5 -> 603545 | CI12: ='予測PL (2025.04-)'!J5 -> 517528 | ... CM12: ='予測PL (2025.04-)'!N5 -> 1036612
G13: 処遇改善手当 | H13: =IF($F$4>=H$3,AO13,BA13) -> #REF! | I13: =IF($F$4>=I$3,AP13,BB13) -> #REF! | J13: 0 | K13: 0 | L13: 0 | M13: 0 | N13: =IF($F$4>=N$3,AU13,BG13) -> #REF! | O13: 0 | P13: 0 | Q13: 0 | R13: 0 | S13: 0 | T13: 0 | U13: 0 | V13: 0 | W13: 0 | X13: 0 | BP13: ='予測PL (2024)'!C6 | BQ13: ='予測PL (2024)'!D6 | BR13: ='予測PL (2024)'!E6 | BS13: ='予測PL (2024)'!F6 | BT13: ='予測PL (2024)'!G6 | BU13: ='予測PL (2024)'!H6 | BV13: ='予測PL (2024)'!I6 | BW13: ='予測PL (2024)'!J6 | ... CA13: ='予測PL (2024)'!N6 | CB13: ='予測PL (2025.04-)'!C6 -> 0 | CC13: ='予測PL (2025.04-)'!D6 -> 0 | CD13: ='予測PL (2025.04-)'!E6 -> 0 | CE13: ='予測PL (2025.04-)'!F6 -> 0 | CF13: ='予測PL (2025.04-)'!G6 -> 0 | CG13: ='予測PL (2025.04-)'!H6 -> 0 | CH13: ='予測PL (2025.04-)'!I6 -> 0 | CI13: ='予測PL (2025.04-)'!J6 -> 0 | ... CM13: ='予測PL (2025.04-)'!N6 -> 0
G14: 特開金 | BP14: ='予測PL (2024)'!C7 -> 0 | BQ14: ='予測PL (2024)'!D7 -> 0 | BR14: ='予測PL (2024)'!E7 -> 0 | BS14: ='予測PL (2024)'!F7 -> 0 | BT14: ='予測PL (2024)'!G7 | BU14: ='予測PL (2024)'!H7 -> 0 | BV14: ='予測PL (2024)'!I7 -> 0 | BW14: ='予測PL (2024)'!J7 -> 0 | ... CA14: ='予測PL (2024)'!N7 | CB14: ='予測PL (2025.04-)'!C7 -> 0 | CC14: ='予測PL (2025.04-)'!D7 -> 2333333 | CD14: ='予測PL (2025.04-)'!E7 -> 0 | CE14: ='予測PL (2025.04-)'!F7 -> 0 | CF14: ='予測PL (2025.04-)'!G7 -> 533333 | CG14: ='予測PL (2025.04-)'!H7 -> 0 | CH14: ='予測PL (2025.04-)'!I7 -> 200000 | CI14: ='予測PL (2025.04-)'!J7 -> 1300000 | ... CM14: ='予測PL (2025.04-)'!N7 -> 200000
C15: 月末売掛残高割合 | D15: 現金割合 | G15: 生産活動 | H15: =IF($F$4>=H$3,AO15,BA15) -> #REF! | I15: =IF($F$4>=I$3,AP15,BB15) -> #REF! | J15: 3531 | K15: 3025 | L15: 3591 | M15: 5315 | N15: =IF($F$4>=N$3,AU15,BG15) -> #REF! | O15: 3168 | P15: 4804 | Q15: 3967 | R15: 3565 | S15: 4107 | T15: 0 | U15: 0 | V15: 0 | W15: 0 | X15: 0 | BP15: ='予測PL (2024)'!C8 -> 644818 | BQ15: ='予測PL (2024)'!D8 -> 876136 | BR15: ='予測PL (2024)'!E8 -> 984805 | BS15: ='予測PL (2024)'!F8 -> 1237218 | BT15: ='予測PL (2024)'!G8 -> 965402 | BU15: ='予測PL (2024)'!H8 -> 792768 | BV15: ='予測PL (2024)'!I8 -> 742111 | BW15: ='予測PL (2024)'!J8 -> 870500 | ... CA15: ='予測PL (2024)'!N8 | CB15: ='予測PL (2025.04-)'!C8 -> 984127 | CC15: ='予測PL (2025.04-)'!D8 -> 1106034 | CD15: ='予測PL (2025.04-)'!E8 -> 1096306 | CE15: ='予測PL (2025.04-)'!F8 -> 1024244 | CF15: ='予測PL (2025.04-)'!G8 -> 1050190 | CG15: ='予測PL (2025.04-)'!H8 -> 1224773 | CH15: ='予測PL (2025.04-)'!I8 -> 1157279 | CI15: ='予測PL (2025.04-)'!J8+1 -> 1138273 | CJ15: ='予測PL (2025.04-)'!K8 -> 1238651 | CK15: ='予測PL (2025.04-)'!L8 -> 2667279 | CL15: ='予測PL (2025.04-)'!M8 -> 1021820 | CM15: ='予測PL (2025.04-)'!N8 -> 1038464
A16: 原価率 | C16: 1 | D16: =1-C16 -> 0 | G16: 合計 | H16: =SUM(H11:H15) -> #REF! | I16: =SUM(I11:I15) -> #REF! | J16: 21584 | K16: 24471 | L16: 25578 | M16: 35820 | N16: =SUM(N11:N15) -> #REF! | O16: 23927 | P16: 32792 | Q16: 24762 | R16: 23914 | S16: 24524 | T16: 19587 | U16: 22405 | V16: 21055 | W16: 19931 | X16: 20148 | AA16: =SUM(AA11:AA15) -> 0 | AB16: =SUM(AB11:AB15) -> 1227385 | AC16: =SUM(AC11:AC15) -> 780153 | AD16: =SUM(AD11:AD15) -> 514206 | AE16: =SUM(AE11:AE15) -> 334355 | AF16: =SUM(AF11:AF15) -> 955367 | AG16: =SUM(AG11:AG15) -> 818306 | AH16: =SUM(AH11:AH15) -> 760538 | ... CO16: =SUM(CO11:CO15) -> 0
A17: 0.3 | F17: 売上原価 | H17: =IF($F$4>=H$3,AO17,BA17) -> #REF! | I17: =IF($F$4>=I$3,AP17,BB17) -> #REF! | J17: 4020 | K17: 4666 | L17: 4472 | M17: 6232 | N17: =IF($F$4>=N$3,AU17,BG17) -> #REF! | O17: 4632 | P17: 6210 | Q17: 4766 | R17: 4484 | S17: 4508 | T17: 4688 | U17: 4399 | V17: 4287 | W17: 3521 | X17: 3939 | AS17: ='予測PL (2021)'!D4 -> 47991 | AT17: ='予測PL (2021)'!E4 -> 100227 | AU17: ='予測PL (2021)'!F4 -> 68268 | AV17: ='予測PL (2021)'!G4 -> 44669 | AW17: ='予測PL (2021)'!H4 -> 53656 | AX17: ='予測PL (2021)'!I4 -> -25789 | AY17: ='予測PL (2021)'!J4 -> 68015 | AZ17: ='予測PL (2021)'!K4 -> 9742 | ... BC17: ='予測PL (2021)'!N4 -> 9368 | BD17: ='予測PL (2023)'!C4 -> 47776 | BE17: ='予測PL (2023)'!D4 -> 20813 | BF17: ='予測PL (2023)'!E4 -> 7576 | BG17: ='予測PL (2023)'!F4 -> 21859 | BH17: ='予測PL (2023)'!G4 -> 14718 | BI17: ='予測PL (2023)'!H4 -> 31386 | BJ17: ='予測PL (2023)'!I4 -> 198380 | BK17: ='予測PL (2023)'!J4 | ... BO17: ='予測PL (2023)'!N4 | BP17: ='予測PL (2024)'!C9 | BQ17: ='予測PL (2024)'!D9 -> 2500 | BR17: ='予測PL (2024)'!E9 -> 55700 | BS17: ='予測PL (2024)'!F9 -> 100695 | BT17: ='予測PL (2024)'!G9 -> 5538 | BU17: ='予測PL (2024)'!H9 -> 15412 | BV17: ='予測PL (2024)'!I9 -> 25044 | BW17: ='予測PL (2024)'!J9 -> 17848 | ... CA17: ='予測PL (2024)'!N9 | CB17: ='予測PL (2025.04-)'!C9 -> 20830 | CC17: ='予測PL (2025.04-)'!D9 -> 119803 | CD17: ='予測PL (2025.04-)'!E9 -> 40602 | CE17: ='予測PL (2025.04-)'!F9 -> 34150 | CF17: ='予測PL (2025.04-)'!G9 -> 20247 | CG17: ='予測PL (2025.04-)'!H9 -> 44500 | CH17: ='予測PL (2025.04-)'!I9 -> 79387 | CI17: ='予測PL (2025.04-)'!J9 -> 6177 | ... CM17: ='予測PL (2025.04-)'!N9 -> 50466
A18: 0.34 | H18: =IF($F$4>=H$3,AO18,BA18) -> #REF! | I18: =IF($F$4>=I$3,AP18,BB18) -> #REF! | J18: 2173 | K18: 2613 | L18: 2735 | M18: 3642 | N18: =IF($F$4>=N$3,AU18,BG18) -> #REF! | O18: 2681 | P18: 3169 | Q18: 2537 | R18: 2684 | S18: 2415 | T18: 2395 | U18: 2566 | V18: 2408 | W18: 2459 | X18: 2423
A19: 0.32 | H19: =IF($F$4>=H$3,AO19,BA19) -> #REF! | I19: =IF($F$4>=I$3,AP19,BB19) -> #REF! | J19: 0 | K19: 0 | L19: 0 | M19: 0 | N19: =IF($F$4>=N$3,AU19,BG19) -> #REF! | O19: 0 | P19: 0 | Q19: 0 | R19: 0 | S19: 0 | T19: 0 | U19: 0 | V19: 0 | W19: 0 | X19: 0
A20: 0.34 | C20: 掛割合 | D20: 現金割合 | H20: =IF($F$4>=H$3,AO20,BA20) -> #REF! | I20: =IF($F$4>=I$3,AP20,BB20) -> #REF! | J20: 627 | K20: 622 | L20: 728 | M20: 1100 | N20: =IF($F$4>=N$3,AU20,BG20) -> #REF! | O20: 680 | P20: 801 | Q20: 769 | R20: 616 | S20: 734 | T20: 0 | U20: 0 | V20: 0 | W20: 0 | X20: 0
C21: 0.995 | D21: =1-C21 -> 0.005 | G21: 合計 | H21: =SUM(H17:H20) -> #REF! | I21: =SUM(I17:I20) -> #REF! | J21: 6820 | K21: 7901 | L21: 7935 | M21: 10974 | N21: =SUM(N17:N20) -> #REF! | O21: 7993 | P21: 10180 | Q21: 8072 | R21: 7784 | S21: 7657 | T21: 7083 | U21: 6965 | V21: 6695 | W21: 5980 | X21: 6362 | AA21: =SUM(AA17:AA20) -> 0 | AB21: =SUM(AB17:AB20) -> 0 | AC21: =SUM(AC17:AC20) -> 0 | AD21: =SUM(AD17:AD20) -> 0 | AE21: =SUM(AE17:AE20) -> 0 | AF21: =SUM(AF17:AF20) -> 0 | AG21: =SUM(AG17:AG20) -> 0 | AH21: =SUM(AH17:AH20) -> 0 | ... CO21: =SUM(CO17:CO20) -> 0
F22: 粗利益 | H22: =+H16-H21 -> #REF! | I22: =+I16-I21 -> #REF! | J22: 14764 | K22: 16570 | L22: 17643 | M22: 24846 | N22: =+N16-N21 -> #REF! | O22: 15934 | P22: 22612 | Q22: 16690 | R22: 16130 | S22: 16867 | T22: 12504 | U22: 15440 | V22: 14360 | W22: 13951 | X22: 13786 | AA22: =+AA16-AA21 -> 0 | AB22: =+AB16-AB21 -> 1227385 | AC22: =+AC16-AC21 -> 780153 | AD22: =+AD16-AD21 -> 514206 | AE22: =+AE16-AE21 -> 334355 | AF22: =+AF16-AF21 -> 955367 | AG22: =+AG16-AG21 -> 818306 | AH22: =+AH16-AH21 -> 760538 | ... CO22: =+CO16-CO21 -> 0
A23: 予測値 | H23: =+H22/H16 -> #REF! | I23: =+I22/I16 -> #REF! | J23: 0.6840252 | K23: 0.67712803 | L23: 0.68977246 | M23: 0.69363484 | N23: =+N22/N16 -> #REF! | O23: 0.66594224 | P23: 0.68955843 | Q23: 0.67401664 | R23: 0.67450029 | S23: 0.68777524 | T23: 0.6383826 | U23: 0.68913189 | V23: 0.68202327 | W23: 0.69996488 | X23: 0.68423665 | AA23: =+AA22/AA16 -> #DIV/0! | AB23: =+AB22/AB16 -> 1 | AC23: =+AC22/AC16 -> 1 | AD23: =+AD22/AD16 -> 1 | AE23: =+AE22/AE16 -> 1 | AF23: =+AF22/AF16 -> 1 | AG23: =+AG22/AG16 -> 1 | AH23: =+AH22/AH16 -> 1 | ... CO23: =+CO22/CO16 -> #DIV/0!
A24: 590 | B24: ＊＊＊＊ | F24: 人件費 | G24: 役員 | H24: =IF($F$4>=H$3,AO24,BA24) -> #REF! | I24: =IF($F$4>=I$3,AP24,BB24) -> #REF! | J24: 950 | K24: 950 | L24: 950 | M24: 950 | N24: =IF($F$4>=N$3,AU24,BG24) -> #REF! | O24: 950 | P24: 950 | Q24: 950 | R24: 950 | S24: 950 | T24: 1400 | U24: 1400 | V24: 1400 | W24: 1400 | X24: 1400 | AB24: 50000 | AC24: ='予測PL'!L7 | AD24: ='予測PL'!M7 | AE24: ='予測PL'!N7 | BP24: ='予測PL (2024)'!C12 -> 100000 | BQ24: ='予測PL (2024)'!D12 -> 100000 | BR24: ='予測PL (2024)'!E12 -> 100000 | BS24: ='予測PL (2024)'!F12 -> 100000 | BT24: ='予測PL (2024)'!G12 -> 100000 | BU24: ='予測PL (2024)'!H12 -> 100000 | BV24: ='予測PL (2024)'!I12 -> 100000 | BW24: ='予測PL (2024)'!J12 -> 100000 | ... CA24: ='予測PL (2024)'!N12 | CB24: ='予測PL (2025.04-)'!C12 -> 100000 | CC24: ='予測PL (2025.04-)'!D12 -> 100000 | CD24: ='予測PL (2025.04-)'!E12 -> 100000 | CE24: ='予測PL (2025.04-)'!F12 -> 100000 | CF24: ='予測PL (2025.04-)'!G12 -> 100000 | CG24: ='予測PL (2025.04-)'!H12 -> 100000 | CH24: ='予測PL (2025.04-)'!I12 -> 100000 | CI24: ='予測PL (2025.04-)'!J12 -> 100000 | ... CM24: ='予測PL (2025.04-)'!N12 -> 100000
B25: ＊＊＊＊ | G25: 給与手当（社員） | H25: =IF($F$4>=H$3,AO25,BA25) -> #REF! | I25: =IF($F$4>=I$3,AP25,BB25) -> #REF! | J25: 1669 | K25: 1729 | L25: 1686 | M25: 1699 | N25: =IF($F$4>=N$3,AU25,BG25) -> #REF! | O25: 1898 | P25: 1919 | Q25: 1914 | R25: 1889 | S25: 1904 | T25: 993 | U25: 1000 | V25: 1024 | W25: 999 | X25: 1006 | AR25: ='予測PL (2021)'!C34 -> 50000 | AS25: ='予測PL (2021)'!D34 -> 30000 | AT25: ='予測PL (2021)'!E34 -> 130000 | AU25: ='予測PL (2021)'!F34 -> 30000 | AV25: ='予測PL (2021)'!G34 -> 30000 | AW25: ='予測PL (2021)'!H34 -> 30000 | AX25: ='予測PL (2021)'!I34 -> 30000 | AY25: ='予測PL (2021)'!J34 -> 30000 | ... BC25: ='予測PL (2021)'!N34 -> 30000 | BD25: ='予測PL (2023)'!C34 -> 30000 | BE25: ='予測PL (2023)'!D34 -> 30000 | BF25: ='予測PL (2023)'!E34 -> 130000 | BG25: ='予測PL (2023)'!F34 -> 30000 | BH25: ='予測PL (2023)'!G34 -> 30000 | BI25: ='予測PL (2023)'!H34 -> 30000 | BJ25: ='予測PL (2023)'!I34 -> 30000 | BK25: ='予測PL (2023)'!J34 -> 30000 | ... BN25: ='予測PL (2023)'!M34 -> 30000 | BP25: ='予測PL (2024)'!C13 -> 990985 | BQ25: ='予測PL (2024)'!D13 -> 1012718 | BR25: ='予測PL (2024)'!E13 -> 1329766 | BS25: ='予測PL (2024)'!F13 -> 1546185 | BT25: ='予測PL (2024)'!G13 -> 1327564 | BU25: ='予測PL (2024)'!H13 -> 1340000 | BV25: ='予測PL (2024)'!I13 -> 1406600 | BW25: ='予測PL (2024)'!J13 -> 1355000 | ... CA25: ='予測PL (2024)'!N13 | CB25: ='予測PL (2025.04-)'!C13 -> 1618732 | CC25: ='予測PL (2025.04-)'!D13 -> 1671913 | CD25: ='予測PL (2025.04-)'!E13 -> 1681563 | CE25: 1855056 | CF25: 1840706 | CG25: 1949143 | CH25: 1854122 | CI25: 1556600 | CJ25: 1477525 | CK25: 1501650 | CL25: 1480172 | CM25: =1229900+885000 -> 2114900
A26: ＊＊＊＊ | B26: 0.11 | G26: 雑給（利用者） | H26: =IF($F$4>=H$3,AO26,BA26) -> #REF! | I26: =IF($F$4>=I$3,AP26,BB26) -> #REF! | J26: 173 | K26: 174 | L26: 204 | M26: 212 | N26: =IF($F$4>=N$3,AU26,BG26) -> #REF! | O26: 0 | P26: 0 | Q26: 0 | R26: 301 | S26: 348 | T26: 553 | U26: 600 | V26: 557 | W26: 759 | X26: 755 | AB26: 1223604 | AC26: ='予測PL'!L9 -> 599194 | AD26: ='予測PL'!M9 -> 328097 | AE26: ='予測PL'!N9 -> 315516 | AF26: ='予測PL'!C9 -> 929867 | AG26: ='予測PL'!D9 -> 791706 | AH26: ='予測PL'!E9 -> 735138 | AI26: ='予測PL'!F9 -> 874778 | AJ26: ='予測PL'!G9 -> 709883 | AK26: ='予測PL'!H9 -> 598522 | AL26: ='予測PL'!I9 -> 640544 | AM26: ='予測PL'!J9 -> 583508 | ... AQ26: ='予測PL'!N9 -> 315516 | AR26: ='予測PL (2021)'!C9 | AS26: ='予測PL (2021)'!D9 | AT26: ='予測PL (2021)'!E9 | AU26: ='予測PL (2021)'!F9 | AV26: ='予測PL (2021)'!G9 | AW26: ='予測PL (2021)'!H9 | AX26: ='予測PL (2021)'!I9 | AY26: ='予測PL (2021)'!J9 | ... BC26: ='予測PL (2021)'!N9 | BP26: ='予測PL (2024)'!C14 -> 1668580 | BQ26: ='予測PL (2024)'!D14 -> 1770640 | BR26: ='予測PL (2024)'!E14 -> 1302720 | BS26: ='予測PL (2024)'!F14 -> 1714646 | BT26: ='予測PL (2024)'!G14 -> 1620679 | BU26: ='予測PL (2024)'!H14 -> 1435431 | BV26: ='予測PL (2024)'!I14 -> 1324109 | BW26: ='予測PL (2024)'!J14 -> 1241742 | ... CA26: ='予測PL (2024)'!N14 | CB26: ='予測PL (2025.04-)'!C14 -> 1369774 | CC26: ='予測PL (2025.04-)'!D14 -> 1323908 | CD26: ='予測PL (2025.04-)'!E14 -> 1441193 | CE26: ='予測PL (2025.04-)'!F14 -> 1160059 | CF26: ='予測PL (2025.04-)'!G14 -> 1091031 | CG26: ='予測PL (2025.04-)'!H14 -> 1107705 | CH26: ='予測PL (2025.04-)'!I14 -> 1005377 | CI26: ='予測PL (2025.04-)'!J14 -> 1113862 | CJ26: 1153096 | CK26: ='予測PL (2025.04-)'!L14 -> 1117223 | CL26: 1023990 | CM26: ='予測PL (2025.04-)'!N14 -> 1240553
A27: ＊＊＊＊ | B27: 0.005 | G27: 法定福利費 | H27: =IF($F$4>=H$3,AO27,BA27) -> #REF! | I27: =IF($F$4>=I$3,AP27,BB27) -> #REF! | J27: 484 | K27: 408 | L27: 392 | M27: 411 | N27: =IF($F$4>=N$3,AU27,BG27) -> #REF! | O27: 360 | P27: 437 | Q27: 408 | R27: 406 | S27: 604 | T27: 490 | U27: 493 | V27: 481 | W27: 583 | X27: 597 | AB27: -640 | AC27: ='予測PL'!L10 -> -1120 | AD27: ='予測PL'!M10 -> -936 | AE27: ='予測PL'!N10 -> -725 | AF27: ='予測PL'!C10 -> -797 | AG27: ='予測PL'!D10 -> 31466 | AH27: ='予測PL'!E10 -> -552 | AI27: ='予測PL'!F10 -> -838 | AJ27: ='予測PL'!G10 -> -1465 | AK27: ='予測PL'!H10 -> -1400 | AL27: ='予測PL'!I10 -> -1353 | AM27: ='予測PL'!J10 -> -1344 | ... AQ27: ='予測PL'!N10 -> -725 | AR27: ='予測PL (2021)'!C10 -> 54574 | AS27: ='予測PL (2021)'!D10 | AT27: ='予測PL (2021)'!E10 | AU27: ='予測PL (2021)'!F10 | AV27: ='予測PL (2021)'!G10 | AW27: ='予測PL (2021)'!H10 | AX27: ='予測PL (2021)'!I10 | AY27: ='予測PL (2021)'!J10 | ... BC27: ='予測PL (2021)'!N10 | BP27: ='予測PL (2024)'!C15 -> 238453 | BQ27: ='予測PL (2024)'!D15 -> 173534 | BR27: ='予測PL (2024)'!E15 -> 197529 | BS27: ='予測PL (2024)'!F15 -> 192435 | BT27: ='予測PL (2024)'!G15 -> 246407 | BU27: ='予測PL (2024)'!H15 -> 247527 | BV27: ='予測PL (2024)'!I15 -> -288512 | BW27: ='予測PL (2024)'!J15 -> 180964 | ... CA27: ='予測PL (2024)'!N15 | CB27: ='予測PL (2025.04-)'!C15 -> 299728 | CC27: ='予測PL (2025.04-)'!D15 -> 111670 | CD27: ='予測PL (2025.04-)'!E15 -> 103259 | CE27: ='予測PL (2025.04-)'!F15 -> 1230856 | CF27: ='予測PL (2025.04-)'!G15 -> 454352 | CG27: ='予測PL (2025.04-)'!H15 -> 216106 | CH27: 357403 | CI27: ='予測PL (2025.04-)'!J15 -> 190986 | CJ27: 190987 | CK27: ='予測PL (2025.04-)'!L15 -> 361748 | CL27: 236847 | CM27: ='予測PL (2025.04-)'!N15 -> 101433
A28: 3780 | B28: ＊＊＊＊ | G28: 福利厚生費 | H28: =IF($F$4>=H$3,AO28,BA28) -> #REF! | I28: =IF($F$4>=I$3,AP28,BB28) -> #REF! | J28: 4719 | K28: 4578 | L28: 4696 | M28: 6936 | N28: =IF($F$4>=N$3,AU28,BG28) -> #REF! | O28: 4078 | P28: 6324 | Q28: 5375 | R28: 4747 | S28: 5173 | T28: 3004 | U28: 3305 | V28: 3130 | W28: 2981 | X28: 3014 | AB28: 55000 | AC28: ='予測PL'!L34*1.1 -> 55000 | AD28: ='予測PL'!M34*1.1 -> 55000 | AE28: ='予測PL'!N34*1.1 -> 55000 | AF28: ='予測PL'!C34 -> 50000 | AG28: ='予測PL'!D34 -> 50000 | AH28: ='予測PL'!E34 -> 150000 | AI28: ='予測PL'!F34 -> 57273 | AJ28: ='予測PL'!G34 -> 50000 | AK28: ='予測PL'!H34 -> 50000 | AL28: ='予測PL'!I34 -> 50000 | AM28: ='予測PL'!J34 -> 50000 | ... AQ28: ='予測PL'!N34 -> 50000 | AR28: ='予測PL (2021)'!C12 -> 181818 | AS28: ='予測PL (2021)'!D12 -> 181818 | AT28: ='予測PL (2021)'!E12 -> 181818 | AU28: ='予測PL (2021)'!F12 -> 227273 | AV28: ='予測PL (2021)'!G12 -> 227273 | AW28: ='予測PL (2021)'!H12 -> 227273 | AX28: ='予測PL (2021)'!I12 -> 272727 | AY28: ='予測PL (2021)'!J12 -> 272727 | ... BC28: ='予測PL (2021)'!N12 -> 272727 | BD28: ='予測PL (2022)'!C12 -> 227273 | BE28: ='予測PL (2022)'!D12 -> 227273 | BF28: ='予測PL (2022)'!E12 -> 227273 | BG28: ='予測PL (2022)'!F12 -> 227273 | BH28: ='予測PL (2022)'!G12 -> 227273 | BI28: ='予測PL (2022)'!H12 -> 227273 | BJ28: ='予測PL (2022)'!I12 -> 272727 | BK28: ='予測PL (2022)'!J12 -> 272727 | BL28: ='予測PL (2022)'!K12 -> 272727 | BP28: ='予測PL (2024)'!C16 -> 201852 | BQ28: ='予測PL (2024)'!D16 -> 253855 | BR28: ='予測PL (2024)'!E16 -> 184259 | BS28: ='予測PL (2024)'!F16 -> 214815 | BT28: ='予測PL (2024)'!G16 -> 205741 | BU28: ='予測PL (2024)'!H16 -> 194028 | BV28: ='予測PL (2024)'!I16 -> 186306 | BW28: ='予測PL (2024)'!J16 -> 154000 | ... CA28: ='予測PL (2024)'!N16 | CB28: ='予測PL (2025.04-)'!C16 -> 194593 | CC28: ='予測PL (2025.04-)'!D16 -> 129626 | CD28: ='予測PL (2025.04-)'!E16 -> 133704 | CE28: ='予測PL (2025.04-)'!F16 -> 176944 | CF28: ='予測PL (2025.04-)'!G16 -> 103241 | CG28: ='予測PL (2025.04-)'!H16 -> 143055 | CH28: ='予測PL (2025.04-)'!I16 -> 200139 | CI28: ='予測PL (2025.04-)'!J16 -> 129352 | ... CK28: ='予測PL (2025.04-)'!L16 -> 158750 | CL28: 298704 | CM28: ='予測PL (2025.04-)'!N16 -> 156297
A29: 予測値 | G29: 合計 | H29: =SUM(H24:H28) -> #REF! | I29: =SUM(I24:I28) -> #REF! | J29: 7995 | K29: 7839 | L29: 7928 | M29: 10208 | N29: =SUM(N24:N28) -> #REF! | O29: 7286 | P29: 9630 | Q29: 8647 | R29: 8293 | S29: 8979 | T29: 6440 | U29: 6798 | V29: 6592 | W29: 6722 | X29: 6772 | AA29: =SUM(AA24:AA28) -> 0 | AB29: =SUM(AB24:AB28) -> 1327964 | AC29: =SUM(AC24:AC28) -> 653074 | AD29: =SUM(AD24:AD28) -> 382161 | AE29: =SUM(AE24:AE28) -> 369791 | AF29: =SUM(AF24:AF28) -> 979070 | AG29: =SUM(AG24:AG28) -> 873172 | AH29: =SUM(AH24:AH28) -> 884586 | ... CO29: =SUM(CO24:CO28) -> 0
A30: 661 | B30: ＊＊＊＊ | F30: 販売費管理費 | G30: 地代家賃 | H30: =IF($F$4>=H$3,AO30,BA30) -> #REF! | I30: =IF($F$4>=I$3,AP30,BB30) -> #REF! | J30: 548 | K30: 548 | L30: 548 | M30: 548 | N30: =IF($F$4>=N$3,AU30,BG30) -> #REF! | O30: 548 | P30: 548 | Q30: 548 | R30: 548 | S30: 548 | T30: 464 | U30: 464 | V30: 464 | W30: 464 | X30: 464 | BP30: ='予測PL (2024)'!C27 -> 217000 | BQ30: ='予測PL (2024)'!D27 -> 217000 | BR30: ='予測PL (2024)'!E27 -> 217000 | BS30: ='予測PL (2024)'!F27 -> 217000 | BT30: ='予測PL (2024)'!G27 -> 367000 | BU30: ='予測PL (2024)'!H27 -> 367000 | BV30: ='予測PL (2024)'!I27 -> 367000 | BW30: ='予測PL (2024)'!J27 -> 367000 | ... CA30: ='予測PL (2024)'!N27 | CB30: ='予測PL (2025.04-)'!C27 -> 367000 | CC30: ='予測PL (2025.04-)'!D27 -> 367000 | CD30: ='予測PL (2025.04-)'!E27 -> 367000 | CE30: ='予測PL (2025.04-)'!F27 -> 367000 | CF30: ='予測PL (2025.04-)'!G27 -> 367000 | CG30: ='予測PL (2025.04-)'!H27 -> 367000 | CH30: ='予測PL (2025.04-)'!I27 -> 367000 | CI30: ='予測PL (2025.04-)'!J27 -> 367000 | ... CM30: ='予測PL (2025.04-)'!N27 -> 350000
A31: ＊＊＊＊ | B31: 0.06 | G31: 消耗品費 | H31: =IF($F$4>=H$3,AO31,BA31) -> #REF! | I31: =IF($F$4>=I$3,AP31,BB31) -> #REF! | J31: 1172 | K31: 860 | L31: 1309 | M31: 1313 | N31: =IF($F$4>=N$3,AU31,BG31) -> #REF! | O31: 1375 | P31: 1391 | Q31: 1106 | R31: 1061 | S31: 877 | T31: 928 | U31: 971 | V31: 1001 | W31: 716 | X31: 1100 | BP31: ='予測PL (2024)'!C32 -> 27530 | BQ31: ='予測PL (2024)'!D32 -> 29515 | BR31: ='予測PL (2024)'!E32 -> 11798 | BS31: ='予測PL (2024)'!F32 -> 11204 | BT31: ='予測PL (2024)'!G32 -> 12816 | BU31: ='予測PL (2024)'!H32 -> 12173 | BV31: ='予測PL (2024)'!I32 -> 2340 | BW31: ='予測PL (2024)'!J32 -> 100 | ... CA31: ='予測PL (2024)'!N32 | CB31: ='予測PL (2025.04-)'!C32 -> 6168 | CC31: ='予測PL (2025.04-)'!D32 -> 6484 | CD31: ='予測PL (2025.04-)'!E32 -> 28378 | CE31: ='予測PL (2025.04-)'!F32 -> 26228 | CF31: ='予測PL (2025.04-)'!G32 -> 7400 | CG31: ='予測PL (2025.04-)'!H32 -> 2600 | CH31: ='予測PL (2025.04-)'!I32 -> 16226 | CI31: ='予測PL (2025.04-)'!J32 -> 10723 | ... CM31: ='予測PL (2025.04-)'!N32 -> 9300
A32: ＊＊＊＊ | B32: 0.02 | G32: 保険料 | H32: =IF($F$4>=H$3,AO32,BA32) -> #REF! | I32: =IF($F$4>=I$3,AP32,BB32) -> #REF! | J32: 425 | K32: 631 | L32: 756 | M32: 877 | N32: =IF($F$4>=N$3,AU32,BG32) -> #REF! | O32: 740 | P32: 579 | Q32: 686 | R32: 418 | S32: 524 | T32: 504 | U32: 782 | V32: 356 | W32: 502 | X32: 463 | AB32: 30000 | AC32: ='予測PL'!L27*1.1 -> 0 | AD32: ='予測PL'!M27*1.1 -> 0 | AE32: ='予測PL'!N27*1.1 -> 0 | AF32: ='予測PL'!C27 | AG32: ='予測PL'!D27 | AH32: ='予測PL'!E27 | AI32: ='予測PL'!F27 | AJ32: ='予測PL'!G27 | AK32: ='予測PL'!H27 | AL32: ='予測PL'!I27 | AM32: ='予測PL'!J27 | ... AQ32: ='予測PL'!N27 | AS32: ='予測PL'!P27 -> 0 | AT32: ='予測PL'!Q27 | AU32: ='予測PL'!R27 | AV32: ='予測PL'!S27 | AW32: ='予測PL'!T27 | AX32: ='予測PL'!U27 | AY32: ='予測PL'!V27 | AZ32: ='予測PL'!W27 | ... BC32: ='予測PL'!Z27 | BP32: ='予測PL (2024)'!C30 -> 10270 | BQ32: ='予測PL (2024)'!D30 -> 10270 | BR32: ='予測PL (2024)'!E30 -> 10270 | BS32: ='予測PL (2024)'!F30 -> 10270 | BT32: ='予測PL (2024)'!G30 -> 10270 | BU32: ='予測PL (2024)'!H30 -> 10270 | BV32: ='予測PL (2024)'!I30 -> 10270 | BW32: ='予測PL (2024)'!J30 -> 10270 | ... CA32: ='予測PL (2024)'!N30 | CB32: ='予測PL (2025.04-)'!C30 -> 9360 | CC32: ='予測PL (2025.04-)'!D30 -> 8840 | CD32: ='予測PL (2025.04-)'!E30 -> 8840 | CE32: ='予測PL (2025.04-)'!F30 -> 8840 | CF32: ='予測PL (2025.04-)'!G30 -> 8840 | CG32: ='予測PL (2025.04-)'!H30 -> 8840 | CH32: ='予測PL (2025.04-)'!I30 -> 8840 | CI32: ='予測PL (2025.04-)'!J30 -> 8840 | ... CM32: ='予測PL (2025.04-)'!N30 -> 8840
A33: 1750 | B33: ＊＊＊＊ | C33: 0.07 | G33: 支払手数料 | H33: =IF($F$4>=H$3,AO33,BA33) -> #REF! | I33: =IF($F$4>=I$3,AP33,BB33) -> #REF! | J33: 0 | K33: 189 | L33: 1 | M33: 3 | N33: =IF($F$4>=N$3,AU33,BG33) -> #REF! | O33: 4 | P33: 3 | Q33: 1 | R33: 147 | S33: 3 | T33: 152 | U33: 0 | V33: 148 | W33: 2 | X33: 32 | AB33: 17589 | AC33: ='予測PL'!L15*1.1 -> 0 | AD33: ='予測PL'!M15*1.1 -> 0 | AE33: ='予測PL'!N15*1.1 -> 0 | AF33: ='予測PL'!C15 -> 20275 | AG33: ='予測PL'!D15 | AH33: ='予測PL'!E15 -> 23091 | AI33: ='予測PL'!F15 -> 473 | AJ33: ='予測PL'!G15 | AK33: ='予測PL'!H15 | AL33: ='予測PL'!I15 | AM33: ='予測PL'!J15 | ... AQ33: ='予測PL'!N15 | AS33: ='予測PL'!P15 -> 0.0047084466 | AT33: ='予測PL'!Q15 | AU33: ='予測PL'!R15 | AV33: ='予測PL'!S15 | AW33: ='予測PL'!T15 | AX33: ='予測PL'!U15 | AY33: ='予測PL'!V15 | AZ33: ='予測PL'!W15 | ... BC33: ='予測PL'!Z15 | BD33: ='予測PL (2023)'!C27 -> 8737 | BE33: ='予測PL (2023)'!D27 | BF33: ='予測PL (2023)'!E27 -> 5940 | BG33: ='予測PL (2023)'!F27 -> 45780 | BH33: ='予測PL (2023)'!G27 | BI33: ='予測PL (2023)'!H27 | BJ33: ='予測PL (2023)'!I27 | BK33: ='予測PL (2023)'!J27 | ... BM33: ='予測PL (2023)'!L27 | BN33: 13480 | BP33: ='予測PL (2024)'!C35 -> 5700 | BQ33: ='予測PL (2024)'!D35 -> 7550 | BR33: ='予測PL (2024)'!E35 -> 8000 | BS33: ='予測PL (2024)'!F35 -> 7850 | BT33: ='予測PL (2024)'!G35 -> 6850 | BU33: ='予測PL (2024)'!H35 -> 7250 | BV33: ='予測PL (2024)'!I35 -> 34150 | BW33: ='予測PL (2024)'!J35 -> 38930 | ... CA33: ='予測PL (2024)'!N35 | CB33: ='予測PL (2025.04-)'!C35 -> 38078 | CC33: ='予測PL (2025.04-)'!D35 -> 75349 | CD33: ='予測PL (2025.04-)'!E35 -> 74842 | CE33: ='予測PL (2025.04-)'!F35 -> 76493 | CF33: ='予測PL (2025.04-)'!G35 -> 49538 | CG33: ='予測PL (2025.04-)'!H35 -> 57097 | CH33: ='予測PL (2025.04-)'!I35 -> 48259 | CI33: ='予測PL (2025.04-)'!J35 -> 49243 | ... CM33: ='予測PL (2025.04-)'!N35 -> 125621
A34: 2758 | B34: ＊＊＊＊ | G34: 管理諸費 | H34: =IF($F$4>=H$3,AO34,BA34) -> #REF! | I34: =IF($F$4>=I$3,AP34,BB34) -> #REF! | J34: 2783 | K34: 2783 | L34: 2783 | M34: 2783 | N34: =IF($F$4>=N$3,AU34,BG34) -> #REF! | O34: 2783 | P34: 2783 | Q34: 2783 | R34: 2783 | S34: 2783 | T34: 2363 | U34: 2363 | V34: 2363 | W34: 2363 | X34: 2363 | AB34: 71758 | AC34: ='予測PL'!L17*1.1 -> 0 | AD34: ='予測PL'!M17*1.1 -> 0 | AE34: ='予測PL'!N17*1.1 -> 0 | AR34: ='予測PL (2021)'!C14 | AS34: ='予測PL (2021)'!D14 | AT34: ='予測PL (2021)'!E14 | AU34: ='予測PL (2021)'!F14 | AV34: ='予測PL (2021)'!G14 | AW34: ='予測PL (2021)'!H14 | AX34: ='予測PL (2021)'!I14 | AY34: ='予測PL (2021)'!J14 | ... BC34: ='予測PL (2021)'!N14 | BP34: ='予測PL (2024)'!C39 -> 30000 | BQ34: ='予測PL (2024)'!D39 -> 30000 | BR34: ='予測PL (2024)'!E39 -> 150000 | BS34: ='予測PL (2024)'!F39 -> 50000 | BT34: ='予測PL (2024)'!G39 -> 50000 | BU34: ='予測PL (2024)'!H39 -> 50000 | BV34: ='予測PL (2024)'!I39 -> 50000 | BW34: ='予測PL (2024)'!J39 -> 69000 | ... CA34: ='予測PL (2024)'!N39 | CB34: ='予測PL (2025.04-)'!C38 -> 418897 | CC34: ='予測PL (2025.04-)'!D38 -> 533082 | CD34: ='予測PL (2025.04-)'!E38 -> 687721 | CE34: 565597 | CF34: ='予測PL (2025.04-)'!G38 -> 541642 | CG34: ='予測PL (2025.04-)'!H38 -> 553455 | CH34: ='予測PL (2025.04-)'!I38 -> 553479 | CI34: ='予測PL (2025.04-)'!J38 -> 414542 | CJ34: ='予測PL (2025.04-)'!K38 -> 549875 | CK34: ='予測PL (2025.04-)'!L38 -> 694845 | CL34: ='予測PL (2025.04-)'!M38 -> 481502 | CM34: ='予測PL (2025.04-)'!N38 -> 625266
A35: 265 | B35: ＊＊＊＊ | H35: =IF($F$4>=H$3,AO35,BA35) -> #REF! | I35: =IF($F$4>=I$3,AP35,BB35) -> #REF! | J35: 317 | K35: 307 | L35: 324 | M35: 324 | N35: =IF($F$4>=N$3,AU35,BG35) -> #REF! | O35: 273 | P35: 273 | Q35: 230 | R35: 336 | S35: 255 | T35: 334 | U35: 299 | V35: 295 | W35: 295 | X35: 308 | AB35: 7480 | AC35: ='予測PL'!L30*1.1 -> 6380 | AD35: ='予測PL'!M30*1.1 -> 8360 | AE35: ='予測PL'!N30*1.1 -> 6490 | AF35: ='予測PL'!C30 -> 5200 | AG35: ='予測PL'!D30 -> 5200 | AH35: ='予測PL'!E30 -> 5400 | AI35: ='予測PL'!F30 -> 5700 | AJ35: ='予測PL'!G30 -> 8100 | AK35: ='予測PL'!H30 -> 5200 | AL35: ='予測PL'!I30 -> 11127 | AM35: ='予測PL'!J30 -> 5900 | ... AQ35: ='予測PL'!N30 -> 5900 | AR35: ='予測PL (2021)'!C30 -> 5800 | AS35: ='予測PL (2021)'!D30 -> 5600 | AT35: ='予測PL (2021)'!E30 -> 5900 | AU35: ='予測PL (2021)'!F30 -> 3350 | AV35: ='予測PL (2021)'!G30 -> 2600 | AW35: ='予測PL (2021)'!H30 -> 2300 | AX35: ='予測PL (2021)'!I30 -> 2150 | AY35: ='予測PL (2021)'!J30 -> 2150 | ... BC35: ='予測PL (2021)'!N30 -> 2400 | BD35: ='予測PL (2023)'!C30 -> 32650 | BE35: ='予測PL (2023)'!D30 -> 32300 | BF35: ='予測PL (2023)'!E30 -> 31800 | BG35: ='予測PL (2023)'!F30 -> 2100 | BH35: ='予測PL (2023)'!G30 -> 2100 | BI35: ='予測PL (2023)'!H30 -> 92709 | BJ35: ='予測PL (2023)'!I30 -> 1400 | BK35: ='予測PL (2023)'!J30 -> 1400 | ... BN35: ='予測PL (2023)'!M30 -> 1400
A36: 332 | B36: ＊＊＊＊ | H36: =IF($F$4>=H$3,AO36,BA36) -> #REF! | I36: =IF($F$4>=I$3,AP36,BB36) -> #REF! | J36: 189 | K36: 189 | L36: 209 | M36: 189 | N36: =IF($F$4>=N$3,AU36,BG36) -> #REF! | O36: 189 | P36: 189 | Q36: 189 | R36: 189 | S36: 189 | T36: 169 | U36: 169 | V36: 169 | W36: 169 | X36: 169
A37: 1800 | B37: ＊＊＊＊ | G37: その他 | H37: =+H38-#REF! -> #REF! | I37: =+I38-#REF! -> #REF! | J37: 3073 | K37: 3358 | L37: 3576 | M37: 3668 | N37: =+N38-#REF! -> #REF! | O37: 3014 | P37: 3737 | Q37: 3244 | R37: 2082 | S37: 3349 | T37: 2535 | U37: 2918 | V37: 2550 | W37: 2375 | X37: 2460 | AB37: 79824 | AC37: ='予測PL'!L37-'収支予測'!AC29-'収支予測'!AC32-'収支予測'!AC33-'収支予測'!AC34-'収支予測'!AC35 -> 364602 | AD37: ='予測PL'!M37-'収支予測'!AD29-'収支予測'!AD32-'収支予測'!AD33-'収支予測'!AD34-'収支予測'!AD35 -> 360785 | AE37: ='予測PL'!N37-'収支予測'!AE29-'収支予測'!AE32-'収支予測'!AE33-'収支予測'!AE34-'収支予測'!AE35 -> 364264 | AF37: =AF39-AF29-AF32-AF33-AF35 -> 23091 | AG37: =AG39-AG29-AG32-AG33-AG35 -> 24182 | AH37: =AH39-AH29-AH32-AH33-AH35 -> 350 | AI37: =AI39-AI29-AI32-AI33-AI35 -> 36298 | AJ37: =AJ39-AJ29-AJ32-AJ33-AJ35 -> 215236 | AK37: =AK39-AK29-AK32-AK33-AK35 -> 206182 | AL37: =AL39-AL29-AL32-AL33-AL35 -> 240116 | AM37: =AM39-AM29-AM32-AM33-AM35 -> 569982 | ... AQ37: =AQ39-AQ29-AQ32-AQ33-AQ35 -> 369854 | AR37: ='予測PL (2021)'!C37-'収支予測'!AR29-'収支予測'!AR34-'収支予測'!AR35 -> 0 | AS37: ='予測PL (2021)'!D37-'収支予測'!AS29-'収支予測'!AS34-'収支予測'!AS35 -> 4000 | AT37: ='予測PL (2021)'!E37-'収支予測'!AT29-'収支予測'!AT34-'収支予測'!AT35 -> 0 | AU37: ='予測PL (2021)'!F37-'収支予測'!AU29-'収支予測'!AU34-'収支予測'!AU35 -> 1000 | AV37: ='予測PL (2021)'!G37-'収支予測'!AV29-'収支予測'!AV34-'収支予測'!AV35 -> 0 | AW37: ='予測PL (2021)'!H37-'収支予測'!AW29-'収支予測'!AW34-'収支予測'!AW35 -> 0 | AX37: ='予測PL (2021)'!I37-'収支予測'!AX29-'収支予測'!AX34-'収支予測'!AX35 -> 0 | AY37: ='予測PL (2021)'!J37-'収支予測'!AY29-'収支予測'!AY34-'収支予測'!AY35 -> 0 | ... BC37: ='予測PL (2021)'!N37-'収支予測'!BC29-'収支予測'!BC34-'収支予測'!BC35 -> 9232 | BD37: ='予測PL (2023)'!C37-'収支予測'!BD29-'収支予測'!BD33-'収支予測'!BD34-'収支予測'!BD35 -> 45454 | BE37: ='予測PL (2023)'!D37-'収支予測'!BE29-'収支予測'!BE33-'収支予測'!BE34-'収支予測'!BE35 -> 90994 | BF37: ='予測PL (2023)'!E37-'収支予測'!BF29-'収支予測'!BF33-'収支予測'!BF34-'収支予測'!BF35 -> 90909 | BG37: ='予測PL (2023)'!F37-'収支予測'!BG29-'収支予測'!BG33-'収支予測'!BG34-'収支予測'!BG35 -> 90909 | BH37: ='予測PL (2023)'!G37-'収支予測'!BH29-'収支予測'!BH33-'収支予測'!BH34-'収支予測'!BH35 -> 90909 | BI37: ='予測PL (2023)'!H37-'収支予測'!BI29-'収支予測'!BI33-'収支予測'!BI34-'収支予測'!BI35 -> 90909 | BJ37: ='予測PL (2023)'!I37-'収支予測'!BJ29-'収支予測'!BJ33-'収支予測'!BJ34-'収支予測'!BJ35 -> -272727 | BK37: ='予測PL (2023)'!J37-'収支予測'!BK29-'収支予測'!BK33-'収支予測'!BK34-'収支予測'!BK35 -> -272727 | ... BN37: ='予測PL (2023)'!M37-'収支予測'!BN29-'収支予測'!BN33-'収支予測'!BN34-'収支予測'!BN35 -> 24940 | BP37: ='予測PL (2024)'!C42-'収支予測'!BP29-SUM('収支予測'!BP30:BP36) -> 84199 | BQ37: ='予測PL (2024)'!D42-'収支予測'!BQ29-SUM('収支予測'!BQ30:BQ36) -> 62289 | BR37: ='予測PL (2024)'!E42-'収支予測'!BR29-SUM('収支予測'!BR30:BR36) -> 90014 | BS37: ='予測PL (2024)'!F42-'収支予測'!BS29-SUM('収支予測'!BS30:BS36) -> 132989 | BT37: ='予測PL (2024)'!G42-'収支予測'!BT29-SUM('収支予測'!BT30:BT36) -> 34691 | BU37: ='予測PL (2024)'!H42-'収支予測'!BU29-SUM('収支予測'!BU30:BU36) -> 32429 | BV37: ='予測PL (2024)'!I42-'収支予測'!BV29-SUM('収支予測'!BV30:BV36) -> 66194 | BW37: ='予測PL (2024)'!J42-'収支予測'!BW29-SUM('収支予測'!BW30:BW36) -> 87541 | ... CA37: ='予測PL (2024)'!N42-'収支予測'!CA29-SUM('収支予測'!CA30:CA36) -> 0 | CB37: ='予測PL (2025.04-)'!C42-'収支予測'!CB30-'収支予測'!CB31-'収支予測'!CB32-'収支予測'!CB33-'収支予測'!CB34-'収支予測'!CB35-'収支予測'!CB36-CB29 -> 71180 | CC37: ='予測PL (2025.04-)'!D42-'収支予測'!CC30-'収支予測'!CC31-'収支予測'!CC32-'収支予測'!CC33-'収支予測'!CC34-'収支予測'!CC35-'収支予測'!CC36-CC29 -> 86030 | CD37: ='予測PL (2025.04-)'!E42-'収支予測'!CD30-'収支予測'!CD31-'収支予測'!CD32-'収支予測'!CD33-'収支予測'!CD34-'収支予測'!CD35-'収支予測'!CD36-CD29 -> 396015 | CE37: =54000+'予測PL (2025.04-)'!F42-'収支予測'!CE30-'収支予測'!CE31-'収支予測'!CE32-'収支予測'!CE33-'収支予測'!CE34-'収支予測'!CE35-'収支予測'!CE36-CE29 -> 139887 | CF37: =158000+'予測PL (2025.04-)'!G42-'収支予測'!CF30-'収支予測'!CF31-'収支予測'!CF32-'収支予測'!CF33-'収支予測'!CF34-'収支予測'!CF35-'収支予測'!CF36-CF29 -> 87123 | CG37: =158000+'予測PL (2025.04-)'!H42-'収支予測'!CG30-'収支予測'!CG31-'収支予測'!CG32-'収支予測'!CG33-'収支予測'!CG34-'収支予測'!CG35-'収支予測'!CG36-CG29 -> 77821 | CH37: =10000+49491+6135 -> 65626 | CI37: 106774 | CJ37: 98369 | CK37: 95634 | CL37: 76535 | CM37: 79997
G38: 合計 | H38: =+H39-H29 -> #REF! | I38: =+I39-I29 -> #REF! | J38: 8507 | K38: 8865 | L38: 9506 | M38: 9705 | N38: =+N39-N29 -> #REF! | O38: 9129 | P38: 9503 | Q38: 8787 | R38: 8456 | S38: 8528 | T38: 7449 | U38: 7966 | V38: 7346 | W38: 6886 | X38: 7359 | AA38: =SUM(AA30:AA37) -> 0 | AB38: =SUM(AB30:AB37) -> 206651 | AC38: =SUM(AC30:AC37) -> 370982 | AD38: =SUM(AD30:AD37) -> 369145 | AE38: =SUM(AE30:AE37) -> 370754 | AF38: =SUM(AF30:AF37) -> 48566 | AG38: =SUM(AG30:AG37) -> 29382 | AH38: =SUM(AH30:AH37) -> 28841 | ... CO38: =SUM(CO30:CO37) -> 0
F39: 経費合計 | H39: =IF($F$4>=H$3,AO39,BA39) -> #REF! | I39: =IF($F$4>=I$3,AP39,BB39) -> #REF! | J39: 16502 | K39: 16704 | L39: 17434 | M39: 19913 | N39: =IF($F$4>=N$3,AU39,BG39) -> #REF! | O39: 16415 | P39: 19133 | Q39: 17434 | R39: 16749 | S39: 17507 | T39: 13889 | U39: 14764 | V39: 13938 | W39: 13608 | X39: 14131 | AA39: =AA29+AA38 -> 0 | AB39: =AB29+AB38 -> 1534615 | AC39: =AC29+AC38 -> 1024056 | AD39: =AD29+AD38 -> 751306 | AE39: =AE29+AE38 -> 740545 | AF39: ='予測PL'!C37 -> 1027636 | AG39: ='予測PL'!D37 -> 902554 | AH39: ='予測PL'!E37 -> 913427 | AI39: ='予測PL'!F37 -> 973684 | AJ39: ='予測PL'!G37 -> 981754 | AK39: ='予測PL'!H37 -> 858504 | AL39: ='予測PL'!I37 -> 940434 | AM39: ='予測PL'!J37 -> 1208046 | ... AQ39: ='予測PL'!N37 -> 740545 | AR39: =AR29+AR38 -> 292192 | AS39: =AS29+AS38 -> 221418 | AT39: =AT29+AT38 -> 317718 | AU39: =AU29+AU38 -> 261623 | AV39: =AV29+AV38 -> 259873 | AW39: =AW29+AW38 -> 259573 | AX39: =AX29+AX38 -> 304877 | AY39: =AY29+AY38 -> 304877 | ... CO39: =CO29+CO38 -> 0
A40: 予測値 | F40: 営業利益 | H40: =+H22-H39 -> #REF! | I40: =+I22-I39 -> #REF! | J40: -1738 | K40: -134 | L40: 209 | M40: 4933 | N40: =+N22-N39 -> #REF! | O40: -481 | P40: 3479 | Q40: -744 | R40: -619 | S40: -640 | T40: -1385 | U40: 676 | V40: 422 | W40: 343 | X40: -345 | AA40: =+AA22-AA39 -> 0 | AB40: =+AB22-AB39 -> -307230 | AC40: =+AC22-AC39 -> -243903 | AD40: =+AD22-AD39 -> -237100 | AE40: =+AE22-AE39 -> -406190 | AF40: =+AF22-AF39 -> -72269 | AG40: =+AG22-AG39 -> -84248 | AH40: =+AH22-AH39 -> -152889 | ... CO40: =+CO22-CO39 -> 0
B41: ＊＊＊＊ | F41: 営業外収益 | H41: =IF($F$4>=H$3,AO41,+$A41+H42+H43) -> #REF! | I41: =IF($F$4>=I$3,AP41,+$A41+I42+I43) -> #REF! | J41: 0 | K41: 102 | L41: 570 | M41: 196 | N41: =IF($F$4>=N$3,AU41,+$A41+N42+N43) -> #REF! | O41: 180 | P41: 0 | Q41: 93 | R41: 0 | S41: 0 | T41: 38 | U41: 0 | V41: 0 | W41: 0 | X41: 0 | AB41: ='予測PL'!K39 | AC41: ='予測PL'!L39 | AD41: ='予測PL'!M39 | AE41: ='予測PL'!N39 | AF41: ='予測PL'!C41 -> 2019000 | AG41: ='予測PL'!D41 -> 7339 | AH41: ='予測PL'!E41 -> 149788 | AI41: ='予測PL'!F41 -> 100000 | AJ41: ='予測PL'!G41 | AK41: ='予測PL'!H41 | AL41: ='予測PL'!I41 | AM41: ='予測PL'!J41 -> 30 | ... AQ41: ='予測PL'!N41 | AR41: ='予測PL (2021)'!C41 -> 200000 | AS41: ='予測PL (2021)'!D41 -> 200034 | AT41: ='予測PL (2021)'!E41 -> 200000 | AU41: ='予測PL (2021)'!F41 -> 400000 | AV41: ='予測PL (2021)'!G41 | AW41: ='予測PL (2021)'!H41 | AX41: ='予測PL (2021)'!I41 | AY41: ='予測PL (2021)'!J41 -> 30 | ... BC41: ='予測PL (2021)'!N41 | BD41: ='予測PL'!AA41 | BE41: ='予測PL'!AB41 | BF41: ='予測PL'!AC41 | BG41: ='予測PL'!AD41 | BH41: ='予測PL'!AE41 | BI41: ='予測PL'!AF41 | BJ41: ='予測PL'!AG41 | BK41: ='予測PL'!AH41 | ... BN41: ='予測PL'!AK41 | BO41: 54 | BP41: ='予測PL (2024)'!C46 -> 77636 | BQ41: ='予測PL (2024)'!D46 -> 78459 | BR41: ='予測PL (2024)'!E46 -> 67823 | BS41: ='予測PL (2024)'!F46 -> 75273 | BT41: ='予測PL (2024)'!G46 -> 67636 | BU41: ='予測PL (2024)'!H46 -> 63273 | BV41: ='予測PL (2024)'!I46 -> 59091 | BW41: ='予測PL (2024)'!J46 -> 51561 | ... CA41: ='予測PL (2024)'!N46 | CB41: ='予測PL (2025.04-)'!C46 -> 19444 | CC41: ='予測PL (2025.04-)'!D46 -> 179264 | CD41: ='予測PL (2025.04-)'!E46 -> 155 | CE41: ='予測PL (2025.04-)'!F46 -> 101047 | CF41: ='予測PL (2025.04-)'!G46 -> 2783 | CG41: ='予測PL (2025.04-)'!H46 -> 0 | CH41: ='予測PL (2025.04-)'!I46 -> 0 | CI41: ='予測PL (2025.04-)'!J46 -> 0 | ... CM41: ='予測PL (2025.04-)'!N46 -> 0
T42: 0 | U42: 0 | V42: 0 | W42: 0 | X42: 0 | AA42: 0
T43: 0 | U43: 0 | V43: 0 | W43: 0 | X43: 0 | AA43: 0
...

Sheet 単位計算
A1: 令和7年3月～ | C1: 単位 | G1: 単位 | M1: 処遇改善手当
A2: A型 | B2: 基本 | C2: 533 | E2: B型 | F2: 基本 | G2: 590
B3: 賃金向上 | C3: 70 | F3: 賃金向上 | G3: 0
B4: 食事提供 | C4: 30 | F4: 食事提供 | G4: 30
B5: 専門職員 | C5: 6 | F5: 専門職員 | G5: 6
B7: 合計 | C7: =SUM(C2:C5) -> 639 | F7: 合計 | G7: =SUM(G2:G5) -> 626
B8: 地域単価 | C8: 10.17 | F8: 地域単価 | G8: 10.17
B9: 一日一人あたり | C9: =C7*C8 -> 6498.63 | F9: 一日一人あたり | G9: =G7*G8 -> 6366.42
A14: 令和7年4月～ | C14: 単位 | G14: 単位
A15: A型 | B15: 基本 | C15: 533 | E15: B型 | F15: 基本 | G15: 590
B16: 賃金向上 | C16: 70 | F16: 賃金向上 | G16: 0
B17: 食事提供 | C17: 30 | F17: 食事提供 | G17: 30
B18: 専門職員 | C18: 6 | F18: 専門職員 | G18: 6
B19: 就労移行加算 | C19: 65 | F19: 就労移行加算 | G19: 0
B21: 合計 | C21: =SUM(C15:C19) -> 704 | F21: 合計 | G21: =SUM(G15:G19) -> 626
B22: 地域単価 | C22: 10.17 | F22: 地域単価 | G22: 10.17
B23: 一日一人あたり | C23: =C21*C22 -> 7159.68 | F23: 一日一人あたり | G23: =G21*G22 -> 6366.42
B25: 処遇改善手当 | C25: 0.096 | E25: 処遇改善手当 | G25: 0.093
A28: 令和8年4月～ | C28: 単位 | G28: 単位
A29: A型 | B29: 基本 | E29: B型 | F29: 基本
B30: 賃金向上 | C30: 70 | F30: 賃金向上 | G30: 0
B31: 食事提供 | C31: 30 | F31: 食事提供 | G31: 30
B32: 専門職員 | C32: 6 | F32: 専門職員 | G32: 6
B33: 就労移行加算 | C33: =65*3 -> 195 | D33: 3名 | F33: 就労移行加算 | M33: 就労移行加算
B35: 合計 | C35: =SUM(C29:C33) -> 301 | F35: 合計 | G35: =SUM(G29:G32) -> 36
B36: 地域単価 | C36: 10.17 | F36: 地域単価 | G36: 10.17
B37: 一日一人あたり | C37: =C35*C36 -> 3061.17 | F37: 一日一人あたり | G37: =G35*G36 -> 366.12
B39: 処遇改善手当 | C39: 0.096 | E39: 処遇改善手当 | G39: 0.093

Sheet 予測PL (2025.04-)
B1: 変動費率 | C1: 4月実績 | D1: 5月実績 | E1: 6月実績 | F1: 7月実績 | G1: 8月実績 | H1: 9月実績 | I1: 10月実績 | J1: 11月実績 | K1: 12月実績 | L1: 1月実績 | M1: 2月実績 | N1: 3月実績 | O1: 累計
O2: =SUM(C2:N2) -> 0
A3: 売上 | C3: =SUM(C4:C8) -> 3563443 | D3: =SUM(D4:D8) -> 5944775 | E3: =SUM(E4:E8) -> 3575909 | F3: =SUM(F4:F8) -> 3638406 | G3: =SUM(G4:G8) -> 3884416 | H3: =SUM(H4:H8) -> 3583051 | I3: =SUM(I4:I8) -> 3715678 | J3: =SUM(J4:J8) -> 4542250 | ... N3: =SUM(N4:N8) -> 4227530 | O3: =SUM(C3:N3) -> 50493228 | P3: =O3/$O$3 -> 1
A4: 国保連Ａ型 | C4: ='A型'!C4+'B型'!C4+'共通費'!C4 -> 2216026 | D4: ='A型'!D4+'B型'!D4+'共通費'!D4 -> 2153396 | E4: ='A型'!E4+'B型'!E4+'共通費'!E4 -> 2068535 | F4: ='A型'!F4+'B型'!F4+'共通費'!F4 -> 1924273 | G4: ='A型'!G4+'B型'!G4+'共通費'!G4 -> 1821950 | H4: ='A型'!H4+'B型'!H4+'共通費'!H4 -> 1892545 | I4: ='A型'!I4+'B型'!I4+'共通費'!I4 -> 1754854 | J4: ='A型'!J4+'B型'!J4+'共通費'!J4 -> 1586450 | ... N4: ='A型'!N4+'B型'!N4+'共通費'!N4 -> 1952454 | O4: =SUM(C4:N4) -> 22543362
A5: 国保連Ｂ型 | C5: ='A型'!C5+'B型'!C5+'共通費'!C5 -> 363290 | D5: ='A型'!D5+'B型'!D5+'共通費'!D5 -> 352012 | E5: ='A型'!E5+'B型'!E5+'共通費'!E5 -> 411068 | F5: ='A型'!F5+'B型'!F5+'共通費'!F5 -> 689889 | G5: ='A型'!G5+'B型'!G5+'共通費'!G5 -> 478943 | H5: ='A型'!H5+'B型'!H5+'共通費'!H5 -> 465733 | I5: ='A型'!I5+'B型'!I5+'共通費'!I5 -> 603545 | J5: ='A型'!J5+'B型'!J5+'共通費'!J5 -> 517528 | ... N5: ='A型'!N5+'B型'!N5+'共通費'!N5 -> 1036612 | O5: =SUM(C5:N5) -> 7235761
A6: 処遇改善手当 | C6: ='A型'!C6+'B型'!C6+'共通費'!C6 -> 0 | D6: ='A型'!D6+'B型'!D6+'共通費'!D6 -> 0 | E6: ='A型'!E6+'B型'!E6+'共通費'!E6 -> 0 | F6: ='A型'!F6+'B型'!F6+'共通費'!F6 -> 0 | G6: ='A型'!G6+'B型'!G6+'共通費'!G6 -> 0 | H6: ='A型'!H6+'B型'!H6+'共通費'!H6 -> 0 | I6: ='A型'!I6+'B型'!I6+'共通費'!I6 -> 0 | J6: ='A型'!J6+'B型'!J6+'共通費'!J6 -> 0 | ... N6: ='A型'!N6+'B型'!N6+'共通費'!N6 -> 0 | O6: =SUM(C6:N6) -> 0
A7: 特開金 | C7: ='A型'!C7+'B型'!C7+'共通費'!C7 -> 0 | D7: ='A型'!D7+'B型'!D7+'共通費'!D7 -> 2333333 | E7: ='A型'!E7+'B型'!E7+'共通費'!E7 -> 0 | F7: ='A型'!F7+'B型'!F7+'共通費'!F7 -> 0 | G7: ='A型'!G7+'B型'!G7+'共通費'!G7 -> 533333 | H7: ='A型'!H7+'B型'!H7+'共通費'!H7 -> 0 | I7: ='A型'!I7+'B型'!I7+'共通費'!I7 -> 200000 | J7: ='A型'!J7+'B型'!J7+'共通費'!J7 -> 1300000 | ... N7: ='A型'!N7+'B型'!N7+'共通費'!N7 -> 200000 | O7: =SUM(C7:N7) -> 5966666
A8: 生産活動 | C8: ='A型'!C8+'B型'!C8+'共通費'!C8 -> 984127 | D8: ='A型'!D8+'B型'!D8+'共通費'!D8 -> 1106034 | E8: ='A型'!E8+'B型'!E8+'共通費'!E8 -> 1096306 | F8: ='A型'!F8+'B型'!F8+'共通費'!F8 -> 1024244 | G8: ='A型'!G8+'B型'!G8+'共通費'!G8 -> 1050190 | H8: ='A型'!H8+'B型'!H8+'共通費'!H8 -> 1224773 | I8: ='A型'!I8+'B型'!I8+'共通費'!I8 -> 1157279 | J8: ='A型'!J8+'B型'!J8+'共通費'!J8 -> 1138272 | ... N8: ='A型'!N8+'B型'!N8+'共通費'!N8 -> 1038464 | O8: =SUM(C8:N8) -> 14747439
A9: 売上原価 | C9: ='A型'!C9+'B型'!C9+'共通費'!C9 -> 20830 | D9: ='A型'!D9+'B型'!D9+'共通費'!D9 -> 119803 | E9: ='A型'!E9+'B型'!E9+'共通費'!E9 -> 40602 | F9: ='A型'!F9+'B型'!F9+'共通費'!F9 -> 34150 | G9: ='A型'!G9+'B型'!G9+'共通費'!G9 -> 20247 | H9: ='A型'!H9+'B型'!H9+'共通費'!H9 -> 44500 | I9: ='A型'!I9+'B型'!I9+'共通費'!I9 -> 79387 | J9: ='A型'!J9+'B型'!J9+'共通費'!J9 -> 6177 | ... N9: ='A型'!N9+'B型'!N9+'共通費'!N9 -> 50466 | O9: =SUM(C9:N9) -> 511267 | P9: =O9/$O$3 -> 0.010125457
A10: 売上総利益 | C10: =C2+C3-C9 -> 3542613 | D10: =D2+D3-D9 -> 5824972 | E10: =E2+E3-E9 -> 3535307 | F10: =F2+F3-F9 -> 3604256 | G10: =G2+G3-G9 -> 3864169 | H10: =H2+H3-H9 -> 3538551 | I10: =I2+I3-I9 -> 3636291 | J10: =J2+J3-J9 -> 4536073 | ... N10: =N2+N3-N9 -> 4177064 | O10: =SUM(C10:N10) -> 49981961
A12: 役員報酬 | C12: ='A型'!C12+'B型'!C12+'共通費'!C12 -> 100000 | D12: ='A型'!D12+'B型'!D12+'共通費'!D12 -> 100000 | E12: ='A型'!E12+'B型'!E12+'共通費'!E12 -> 100000 | F12: ='A型'!F12+'B型'!F12+'共通費'!F12 -> 100000 | G12: ='A型'!G12+'B型'!G12+'共通費'!G12 -> 100000 | H12: ='A型'!H12+'B型'!H12+'共通費'!H12 -> 100000 | I12: ='A型'!I12+'B型'!I12+'共通費'!I12 -> 100000 | J12: ='A型'!J12+'B型'!J12+'共通費'!J12 -> 100000 | ... N12: ='A型'!N12+'B型'!N12+'共通費'!N12 -> 100000 | O12: =SUM(C12:N12) -> 1200000 | P12: =O12/$O$10 -> 0.024008662
A13: 給与手当 | C13: ='A型'!C13+'B型'!C13+'共通費'!C13 -> 1618732 | D13: ='A型'!D13+'B型'!D13+'共通費'!D13 -> 1671913 | E13: ='A型'!E13+'B型'!E13+'共通費'!E13 -> 1681563 | F13: ='A型'!F13+'B型'!F13+'共通費'!F13 -> 1801056 | G13: ='A型'!G13+'B型'!G13+'共通費'!G13 -> 1682706 | H13: ='A型'!H13+'B型'!H13+'共通費'!H13 -> 1791143 | I13: ='A型'!I13+'B型'!I13+'共通費'!I13 -> 1696122 | J13: ='A型'!J13+'B型'!J13+'共通費'!J13 -> 1398600 | ... N13: ='A型'!N13+'B型'!N13+'共通費'!N13 -> 2114900 | O13: =SUM(C13:N13) -> 19442082
A14: 雑給 | C14: ='A型'!C14+'B型'!C14+'共通費'!C14 -> 1369774 | D14: ='A型'!D14+'B型'!D14+'共通費'!D14 -> 1323908 | E14: ='A型'!E14+'B型'!E14+'共通費'!E14 -> 1441193 | F14: ='A型'!F14+'B型'!F14+'共通費'!F14 -> 1160059 | G14: ='A型'!G14+'B型'!G14+'共通費'!G14 -> 1091031 | H14: ='A型'!H14+'B型'!H14+'共通費'!H14 -> 1107705 | I14: ='A型'!I14+'B型'!I14+'共通費'!I14 -> 1005377 | J14: ='A型'!J14+'B型'!J14+'共通費'!J14 -> 1113862 | ... N14: ='A型'!N14+'B型'!N14+'共通費'!N14 -> 1240553 | O14: =SUM(C14:N14) -> 14137946 | P14: =O14/$O$10 -> 0.28286097
A15: 法定福利費 | B15: 0.15 | C15: ='A型'!C15+'B型'!C15+'共通費'!C15 -> 299728 | D15: ='A型'!D15+'B型'!D15+'共通費'!D15 -> 111670 | E15: ='A型'!E15+'B型'!E15+'共通費'!E15 -> 103259 | F15: ='A型'!F15+'B型'!F15+'共通費'!F15 -> 1230856 | G15: ='A型'!G15+'B型'!G15+'共通費'!G15 -> 454352 | H15: ='A型'!H15+'B型'!H15+'共通費'!H15 -> 216106 | I15: ='A型'!I15+'B型'!I15+'共通費'!I15 -> 474202 | J15: ='A型'!J15+'B型'!J15+'共通費'!J15 -> 190986 | ... N15: ='A型'!N15+'B型'!N15+'共通費'!N15 -> 101433 | O15: =SUM(C15:N15) -> 3972199
A16: 福利厚生費 | C16: ='A型'!C16+'B型'!C16+'共通費'!C16 -> 194593 | D16: ='A型'!D16+'B型'!D16+'共通費'!D16 -> 129626 | E16: ='A型'!E16+'B型'!E16+'共通費'!E16 -> 133704 | F16: ='A型'!F16+'B型'!F16+'共通費'!F16 -> 176944 | G16: ='A型'!G16+'B型'!G16+'共通費'!G16 -> 103241 | H16: ='A型'!H16+'B型'!H16+'共通費'!H16 -> 143055 | I16: ='A型'!I16+'B型'!I16+'共通費'!I16 -> 200139 | J16: ='A型'!J16+'B型'!J16+'共通費'!J16 -> 129352 | ... N16: ='A型'!N16+'B型'!N16+'共通費'!N16 -> 156297 | O16: =SUM(C16:N16) -> 1964817
A17: 業務委託費 | C17: ='A型'!C17+'B型'!C17+'共通費'!C17 -> 10000 | D17: ='A型'!D17+'B型'!D17+'共通費'!D17 -> 10000 | E17: ='A型'!E17+'B型'!E17+'共通費'!E17 -> 10000 | F17: ='A型'!F17+'B型'!F17+'共通費'!F17 -> 10000 | G17: ='A型'!G17+'B型'!G17+'共通費'!G17 -> 10000 | H17: ='A型'!H17+'B型'!H17+'共通費'!H17 -> 10000 | I17: ='A型'!I17+'B型'!I17+'共通費'!I17 -> 10000 | J17: ='A型'!J17+'B型'!J17+'共通費'!J17 -> 10000 | ... N17: ='A型'!N17+'B型'!N17+'共通費'!N17 -> 10000 | O17: =SUM(C17:N17) -> 120000
A18: 労務委託費 | C18: ='A型'!C18+'B型'!C18+'共通費'!C18 -> 0 | D18: ='A型'!D18+'B型'!D18+'共通費'!D18 -> 0 | E18: ='A型'!E18+'B型'!E18+'共通費'!E18 -> 0 | F18: ='A型'!F18+'B型'!F18+'共通費'!F18 -> 0 | G18: ='A型'!G18+'B型'!G18+'共通費'!G18 -> 0 | H18: ='A型'!H18+'B型'!H18+'共通費'!H18 -> 0 | I18: ='A型'!I18+'B型'!I18+'共通費'!I18 -> 0 | J18: ='A型'!J18+'B型'!J18+'共通費'!J18 -> 0 | ... N18: ='A型'!N18+'B型'!N18+'共通費'!N18 -> 0 | O18: =SUM(C18:N18) -> 0
A19: 旅費交通費 | C19: ='A型'!C19+'B型'!C19+'共通費'!C19 -> 55573 | D19: ='A型'!D19+'B型'!D19+'共通費'!D19 -> 54809 | E19: ='A型'!E19+'B型'!E19+'共通費'!E19 -> 66055 | F19: ='A型'!F19+'B型'!F19+'共通費'!F19 -> 69082 | G19: ='A型'!G19+'B型'!G19+'共通費'!G19 -> 61855 | H19: ='A型'!H19+'B型'!H19+'共通費'!H19 -> 66209 | I19: ='A型'!I19+'B型'!I19+'共通費'!I19 -> 49491 | J19: ='A型'!J19+'B型'!J19+'共通費'!J19 -> 43618 | ... N19: ='A型'!N19+'B型'!N19+'共通費'!N19 -> 60309 | O19: =SUM(C19:N19) -> 704783
A20: 通信費 | C20: ='A型'!C20+'B型'!C20+'共通費'!C20 -> 1607 | D20: ='A型'!D20+'B型'!D20+'共通費'!D20 -> 1821 | E20: ='A型'!E20+'B型'!E20+'共通費'!E20 -> 1178 | F20: ='A型'!F20+'B型'!F20+'共通費'!F20 -> 9905 | G20: ='A型'!G20+'B型'!G20+'共通費'!G20 -> 13432 | H20: ='A型'!H20+'B型'!H20+'共通費'!H20 -> 1612 | I20: ='A型'!I20+'B型'!I20+'共通費'!I20 -> 6135 | J20: ='A型'!J20+'B型'!J20+'共通費'!J20 -> 3356 | ... N20: ='A型'!N20+'B型'!N20+'共通費'!N20 -> 2235 | O20: =SUM(C20:N20) -> 103686 | P20: =O20/$O$10 -> 0.0020744684
A21: 研修採用費 | C21: ='A型'!C21+'B型'!C21+'共通費'!C21 -> 0 | D21: ='A型'!D21+'B型'!D21+'共通費'!D21 -> 0 | E21: ='A型'!E21+'B型'!E21+'共通費'!E21 -> 18182 | F21: ='A型'!F21+'B型'!F21+'共通費'!F21 -> 0 | G21: ='A型'!G21+'B型'!G21+'共通費'!G21 -> 0 | H21: ='A型'!H21+'B型'!H21+'共通費'!H21 -> 0 | I21: 0 | J21: ='A型'!J21+'B型'!J21+'共通費'!J21 -> 0 | K21: ='A型'!K21+'B型'!K22+'共通費'!K21 -> 0 | L21: ='A型'!L21+'B型'!L21+'共通費'!L21 -> 0 | M21: ='A型'!M21+'B型'!M21+'共通費'!M21 -> 0 | N21: ='A型'!N21+'B型'!N21+'共通費'!N21 -> 7273 | O21: =SUM(C21:N21) -> 25455
A22: 交際費 | C22: ='A型'!C22+'B型'!C22+'共通費'!C22 -> 0 | D22: ='A型'!D22+'B型'!D22+'共通費'!D22 -> 0 | E22: ='A型'!E22+'B型'!E22+'共通費'!E22 -> 0 | F22: ='A型'!F22+'B型'!F22+'共通費'!F22 -> 0 | G22: ='A型'!G22+'B型'!G22+'共通費'!G22 -> 0 | H22: ='A型'!H22+'B型'!H22+'共通費'!H22 -> 0 | I22: ='A型'!I22+'B型'!I22+'共通費'!I22 -> 0 | J22: ='A型'!J22+'B型'!J22+'共通費'!J22 -> 0 | ... N22: ='A型'!N22+'B型'!N22+'共通費'!N22 -> 0 | O22: =SUM(C22:N22) -> 0 | P22: =O22/$O$10 -> 0
A23: 会議費 | C23: ='A型'!C23+'B型'!C23+'共通費'!C23 -> 0 | D23: ='A型'!D23+'B型'!D23+'共通費'!D23 -> 0 | E23: ='A型'!E23+'B型'!E23+'共通費'!E23 -> 0 | F23: ='A型'!F23+'B型'!F23+'共通費'!F23 -> 0 | G23: ='A型'!G23+'B型'!G23+'共通費'!G23 -> 0 | H23: ='A型'!H23+'B型'!H23+'共通費'!H23 -> 0 | I23: ='A型'!I23+'B型'!I23+'共通費'!I23 -> 0 | J23: ='A型'!J23+'B型'!J23+'共通費'!J23 -> 0 | ... N23: ='A型'!N23+'B型'!N23+'共通費'!N23 -> 0 | O23: =SUM(C23:N23) -> 0
A24: 戦略費 | C24: ='A型'!C24+'B型'!C24+'共通費'!C24 -> 0 | D24: ='A型'!D24+'B型'!D24+'共通費'!D24 -> 0 | E24: ='A型'!E24+'B型'!E24+'共通費'!E24 -> 0 | F24: ='A型'!F24+'B型'!F24+'共通費'!F24 -> 0 | G24: ='A型'!G24+'B型'!G24+'共通費'!G24 -> 0 | H24: ='A型'!H24+'B型'!H24+'共通費'!H24 -> 0 | I24: ='A型'!I24+'B型'!I24+'共通費'!I24 -> 0 | J24: ='A型'!J24+'B型'!J24+'共通費'!J24 -> 0 | ... N24: ='A型'!N24+'B型'!N24+'共通費'!N24 -> 0 | O24: =SUM(C24:N24) -> 0 | P24: =O24/$O$10 -> 0
A25: 減価償却費 | C25: ='A型'!C25+'B型'!C25+'共通費'!C25 -> 0 | D25: ='A型'!D25+'B型'!D25+'共通費'!D25 -> 0 | E25: ='A型'!E25+'B型'!E25+'共通費'!E25 -> 0 | F25: ='A型'!F25+'B型'!F25+'共通費'!F25 -> 0 | G25: ='A型'!G25+'B型'!G25+'共通費'!G25 -> 0 | H25: ='A型'!H25+'B型'!H25+'共通費'!H25 -> 0 | I25: ='A型'!I25+'B型'!I25+'共通費'!I25 -> 0 | J25: ='A型'!J25+'B型'!J25+'共通費'!J25 -> 0 | ... N25: ='A型'!N25+'B型'!N25+'共通費'!N25 -> 0 | O25: =SUM(C25:N25) -> 0
A26: 賃借料 | C26: ='A型'!C26+'B型'!C26+'共通費'!C26 -> 0 | D26: ='A型'!D26+'B型'!D26+'共通費'!D26 -> 0 | E26: ='A型'!E26+'B型'!E26+'共通費'!E26 -> 0 | F26: ='A型'!F26+'B型'!F26+'共通費'!F26 -> 0 | G26: ='A型'!G26+'B型'!G26+'共通費'!G26 -> 0 | H26: ='A型'!H26+'B型'!H26+'共通費'!H26 -> 0 | I26: ='A型'!I26+'B型'!I26+'共通費'!I26 -> 0 | J26: ='A型'!J26+'B型'!J26+'共通費'!J26 -> 0 | ... N26: ='A型'!N26+'B型'!N26+'共通費'!N26 -> 0 | O26: =SUM(C26:N26) -> 0
A27: 地代家賃 | C27: ='A型'!C27+'B型'!C27+'共通費'!C27 -> 367000 | D27: ='A型'!D27+'B型'!D27+'共通費'!D27 -> 367000 | E27: ='A型'!E27+'B型'!E27+'共通費'!E27 -> 367000 | F27: ='A型'!F27+'B型'!F27+'共通費'!F27 -> 367000 | G27: ='A型'!G27+'B型'!G27+'共通費'!G27 -> 367000 | H27: ='A型'!H27+'B型'!H27+'共通費'!H27 -> 367000 | I27: ='A型'!I27+'B型'!I27+'共通費'!I27 -> 367000 | J27: ='A型'!J27+'B型'!J27+'共通費'!J27 -> 367000 | ... N27: ='A型'!N27+'B型'!N27+'共通費'!N27 -> 350000 | O27: =SUM(C27:N27) -> 4340600
A28: リース料 | C28: ='A型'!C28+'B型'!C28+'共通費'!C28 -> 0 | D28: ='A型'!D28+'B型'!D28+'共通費'!D28 -> 0 | E28: ='A型'!E28+'B型'!E28+'共通費'!E28 -> 0 | F28: ='A型'!F28+'B型'!F28+'共通費'!F28 -> 0 | G28: ='A型'!G28+'B型'!G28+'共通費'!G28 -> 0 | H28: ='A型'!H28+'B型'!H28+'共通費'!H28 -> 0 | I28: ='A型'!I28+'B型'!I28+'共通費'!I28 -> 0 | J28: ='A型'!J28+'B型'!J28+'共通費'!J28 -> 0 | ... N28: ='A型'!N28+'B型'!N28+'共通費'!N28 -> 0 | O28: =SUM(C28:N28) -> 0
A29: 修繕費 | C29: ='A型'!C29+'B型'!C29+'共通費'!C29 -> 0 | D29: ='A型'!D29+'B型'!D29+'共通費'!D29 -> 0 | E29: ='A型'!E29+'B型'!E29+'共通費'!E29 -> 0 | F29: ='A型'!F29+'B型'!F29+'共通費'!F29 -> 0 | G29: ='A型'!G29+'B型'!G29+'共通費'!G29 -> 0 | H29: ='A型'!H29+'B型'!H29+'共通費'!H29 -> 0 | I29: ='A型'!I29+'B型'!I29+'共通費'!I29 -> 0 | J29: ='A型'!J29+'B型'!J29+'共通費'!J29 -> 0 | ... N29: ='A型'!N29+'B型'!N29+'共通費'!N29 -> 0 | O29: =SUM(C29:N29) -> 0
A30: 保険料 | C30: ='A型'!C30+'B型'!C30+'共通費'!C30 -> 9360 | D30: ='A型'!D30+'B型'!D30+'共通費'!D30 -> 8840 | E30: ='A型'!E30+'B型'!E30+'共通費'!E30 -> 8840 | F30: ='A型'!F30+'B型'!F30+'共通費'!F30 -> 8840 | G30: ='A型'!G30+'B型'!G30+'共通費'!G30 -> 8840 | H30: ='A型'!H30+'B型'!H30+'共通費'!H30 -> 8840 | I30: ='A型'!I30+'B型'!I30+'共通費'!I30 -> 8840 | J30: ='A型'!J30+'B型'!J30+'共通費'!J30 -> 8840 | ... N30: ='A型'!N30+'B型'!N30+'共通費'!N30 -> 8840 | O30: =SUM(C30:N30) -> 106599
A31: 水道光熱費 | B31: 0 | C31: ='A型'!C31+'B型'!C31+'共通費'!C31 -> 0 | D31: ='A型'!D31+'B型'!D31+'共通費'!D31 -> 0 | E31: ='A型'!E31+'B型'!E31+'共通費'!E31 -> 0 | F31: ='A型'!F31+'B型'!F31+'共通費'!F31 -> 0 | G31: ='A型'!G31+'B型'!G31+'共通費'!G31 -> 0 | H31: ='A型'!H31+'B型'!H31+'共通費'!H31 -> 0 | I31: ='A型'!I31+'B型'!I31+'共通費'!I31 -> 0 | J31: ='A型'!J31+'B型'!J31+'共通費'!J31 -> 0 | ... N31: ='A型'!N31+'B型'!N31+'共通費'!N31 -> 0 | O31: =SUM(C31:N31) -> 0
A32: 消耗品費 | B32: 0 | C32: ='A型'!C32+'B型'!C32+'共通費'!C32 -> 6168 | D32: ='A型'!D32+'B型'!D32+'共通費'!D32 -> 6484 | E32: ='A型'!E32+'B型'!E32+'共通費'!E32 -> 28378 | F32: ='A型'!F32+'B型'!F32+'共通費'!F32 -> 26228 | G32: ='A型'!G32+'B型'!G32+'共通費'!G32 -> 7400 | H32: ='A型'!H32+'B型'!H32+'共通費'!H32 -> 2600 | I32: ='A型'!I32+'B型'!I32+'共通費'!I32 -> 16226 | J32: ='A型'!J32+'B型'!J32+'共通費'!J32 -> 10723 | ... N32: ='A型'!N32+'B型'!N32+'共通費'!N32 -> 9300 | O32: =SUM(C32:N32) -> 138413 | P32: =O32/$O$10 -> 0.0027692591
A33: 租税公課 | C33: ='A型'!C33+'B型'!C33+'共通費'!C33 -> 0 | D33: ='A型'!D33+'B型'!D33+'共通費'!D33 -> 14300 | E33: ='A型'!E33+'B型'!E33+'共通費'!E33 -> 600 | F33: ='A型'!F33+'B型'!F33+'共通費'!F33 -> 1100 | G33: ='A型'!G33+'B型'!G33+'共通費'!G33 -> 0 | H33: ='A型'!H33+'B型'!H33+'共通費'!H33 -> 0 | I33: ='A型'!I33+'B型'!I33+'共通費'!I33 -> 0 | J33: ='A型'!J33+'B型'!J33+'共通費'!J33 -> 0 | ... N33: ='A型'!N33+'B型'!N33+'共通費'!N33 -> 180 | O33: =SUM(C33:N33) -> 16180
A34: 広告宣伝費 | C34: ='A型'!C34+'B型'!C34+'共通費'!C34 -> 0 | D34: ='A型'!D34+'B型'!D34+'共通費'!D34 -> 5100 | E34: ='A型'!E34+'B型'!E34+'共通費'!E34 -> 0 | F34: ='A型'!F34+'B型'!F34+'共通費'!F34 -> 0 | G34: ='A型'!G34+'B型'!G34+'共通費'!G34 -> 0 | H34: ='A型'!H34+'B型'!H34+'共通費'!H34 -> 0 | I34: ='A型'!I34+'B型'!I34+'共通費'!I34 -> 0 | J34: ='A型'!J34+'B型'!J34+'共通費'!J34 -> 49800 | ... N34: ='A型'!N34+'B型'!N34+'共通費'!N34 -> 0 | O34: =SUM(C34:N34) -> 54900
A35: 支払手数料 | B35: 0 | C35: ='A型'!C35+'B型'!C35+'共通費'!C35 -> 38078 | D35: ='A型'!D35+'B型'!D35+'共通費'!D35 -> 75349 | E35: ='A型'!E35+'B型'!E35+'共通費'!E35 -> 74842 | F35: ='A型'!F35+'B型'!F35+'共通費'!F35 -> 76493 | G35: ='A型'!G35+'B型'!G35+'共通費'!G35 -> 49538 | H35: ='A型'!H35+'B型'!H35+'共通費'!H35 -> 57097 | I35: ='A型'!I35+'B型'!I35+'共通費'!I35 -> 48259 | J35: ='A型'!J35+'B型'!J35+'共通費'!J35 -> 49243 | ... N35: ='A型'!N35+'B型'!N35+'共通費'!N35 -> 125621 | O35: =SUM(C35:N35) -> 629296
A36: 教育費 | C36: ='A型'!C36+'B型'!C36+'共通費'!C36 -> 0 | D36: ='A型'!D36+'B型'!D36+'共通費'!D36 -> 0 | E36: ='A型'!E36+'B型'!E36+'共通費'!E36 -> 0 | F36: ='A型'!F36+'B型'!F36+'共通費'!F36 -> 0 | G36: ='A型'!G36+'B型'!G36+'共通費'!G36 -> 0 | H36: ='A型'!H36+'B型'!H36+'共通費'!H36 -> 0 | I36: ='A型'!I36+'B型'!I36+'共通費'!I36 -> 0 | J36: ='A型'!J36+'B型'!J36+'共通費'!J36 -> 0 | ... N36: ='A型'!N36+'B型'!N36+'共通費'!N36 -> 0 | O36: =SUM(C36:N36) -> 0
A37: 新聞図書費 | C37: ='A型'!C37+'B型'!C37+'共通費'!C37 -> 4000 | D37: ='A型'!D37+'B型'!D37+'共通費'!D37 -> 0 | E37: ='A型'!E37+'B型'!E37+'共通費'!E37 -> 0 | F37: ='A型'!F37+'B型'!F37+'共通費'!F37 -> 0 | G37: ='A型'!G37+'B型'!G37+'共通費'!G37 -> 1836 | H37: ='A型'!H37+'B型'!H37+'共通費'!H37 -> 0 | I37: ='A型'!I37+'B型'!I37+'共通費'!I37 -> 0 | J37: ='A型'!J37+'B型'!J37+'共通費'!J37 -> 0 | ... N37: ='A型'!N37+'B型'!N37+'共通費'!N37 -> 0 | O37: =SUM(C37:N37) -> 5836
A38: 管理諸費 | B38: 0.2 | C38: ='A型'!C38+'B型'!C38+'共通費'!C38 -> 418897 | D38: ='A型'!D38+'B型'!D38+'共通費'!D38 -> 533082 | E38: ='A型'!E38+'B型'!E38+'共通費'!E38 -> 687721 | F38: ='A型'!F38+'B型'!F38+'共通費'!F38 -> 615397 | G38: ='A型'!G38+'B型'!G38+'共通費'!G38 -> 541642 | H38: ='A型'!H38+'B型'!H38+'共通費'!H38 -> 553455 | I38: ='A型'!I38+'B型'!I38+'共通費'!I38 -> 553479 | J38: ='A型'!J38+'B型'!J38+'共通費'!J38 -> 414542 | ... N38: ='A型'!N38+'B型'!N38+'共通費'!N38 -> 625266 | O38: =SUM(C38:N38) -> 6669703
C39: ='A型'!C39+'B型'!C39+'共通費'!C39 -> 0 | D39: ='A型'!D39+'B型'!D39+'共通費'!D39 -> 0 | E39: ='A型'!E39+'B型'!E39+'共通費'!E39 -> 300000 | F39: ='A型'!F39+'B型'!F39+'共通費'!F39 -> 0 | G39: ='A型'!G39+'B型'!G39+'共通費'!G39 -> 0 | H39: ='A型'!H39+'B型'!H39+'共通費'!H39 -> 0 | I39: ='A型'!I39+'B型'!I39+'共通費'!I39 -> 0 | J39: ='A型'!J39+'B型'!J39+'共通費'!J39 -> 0 | ... N39: ='A型'!N39+'B型'!N39+'共通費'!N39 -> 0 | O39: =SUM(C39:N39) -> 300000 | P39: =O39/$O$10 -> 0.0060021655
C40: ='A型'!C40+'B型'!C40+'共通費'!C40 -> 0 | D40: ='A型'!D40+'B型'!D40+'共通費'!D40 -> 0 | E40: ='A型'!E40+'B型'!E40+'共通費'!E40 -> 0 | F40: ='A型'!F40+'B型'!F40+'共通費'!F40 -> 0 | G40: ='A型'!G40+'B型'!G40+'共通費'!G40 -> 0 | H40: ='A型'!H40+'B型'!H40+'共通費'!H40 -> 0 | I40: ='A型'!I40+'B型'!I40+'共通費'!I40 -> 0 | J40: ='A型'!J40+'B型'!J40+'共通費'!J40 -> 0 | ... N40: ='A型'!N40+'B型'!N40+'共通費'!N40 -> 0 | O40: =SUM(C40:N40) -> 0
C41: ='A型'!C41+'B型'!C41+'共通費'!C41 -> 0 | D41: ='A型'!D41+'B型'!D41+'共通費'!D41 -> 0 | E41: ='A型'!E41+'B型'!E41+'共通費'!E41 -> 0 | F41: ='A型'!F41+'B型'!F41+'共通費'!F41 -> 0 | G41: ='A型'!G41+'B型'!G41+'共通費'!G41 -> 0 | H41: ='A型'!H41+'B型'!H41+'共通費'!H41 -> 0 | I41: ='A型'!I41+'B型'!I41+'共通費'!I41 -> 0 | J41: ='A型'!J41+'B型'!J41+'共通費'!J41 -> 0 | ... N41: ='A型'!N41+'B型'!N41+'共通費'!N41 -> 0 | O41: =SUM(C41:N41) -> 0
...

Sheet A型
B1: 変動費率 | C1: 4月実績 | D1: 5月実績 | E1: 6月実績 | F1: 7月実績 | G1: 8月実績 | H1: 9月実績 | I1: 10月実績 | J1: 11月実績 | K1: 12月実績 | L1: 1月実績 | M1: 2月実績 | N1: 3月 | O1: 累計
O2: =SUM(C2:N2) -> 0
A3: 売上 | C3: =SUM(C4:C8) -> 3101741 | D3: =SUM(D4:D8) -> 5482159 | E3: =SUM(E4:E8) -> 3055210 | F3: =SUM(F4:F8) -> 2846093 | G3: =SUM(G4:G8) -> 3300454 | H3: =SUM(H4:H8) -> 2994841 | I3: =SUM(I4:I8) -> 2996404 | J3: =SUM(J4:J8) -> 3910896 | ... N3: =SUM(N4:N8) -> 3118225 | O3: =SUM(C3:N3) -> 41813877 | P3: =O3/$O$3 -> 1
A4: 国保連Ａ型 | C4: 2216026 | D4: 2153396 | E4: 2068535 | F4: 1924273 | G4: 1821950 | H4: 1892545 | I4: 1754854 | J4: 1586450 | K4: 2029779 | L4: 1574937 | M4: 1568163 | N4: 1952454 | O4: =SUM(C4:N4) -> 22543362
A5: 国保連Ｂ型 | C5: =C58 -> 0 | D5: =D58 -> 0 | E5: =E58 -> 0 | F5: =F58 -> 0 | G5: =G58 -> 0 | H5: =H58 -> 0 | I5: =I58 -> 0 | J5: =J58 -> 0 | ... N5: =N58 -> 0 | O5: =SUM(C5:N5) -> 0
A6: 処遇改善手当 | C6: 0 | D6: 0 | E6: 0 | F6: 0 | G6: 0 | H6: 0 | I6: 0 | J6: 0 | K6: 0 | L6: 0 | M6: 0 | N6: 0 | O6: =SUM(C6:N6) -> 0
A7: 特開金 | C7: =C56*200000 -> 0 | D7: 2333333 | E7: =E56*200000 -> 0 | F7: 0 | G7: 533333 | H7: =H56*200000 -> 0 | I7: 200000 | J7: =J56*200000 -> 1300000 | K7: 900000 | L7: 500000 | M7: 0 | N7: 200000 | O7: =SUM(C7:N7) -> 5966666
A8: 生産活動 | C8: 885715 | D8: 995430 | E8: 986675 | F8: 921820 | G8: =663225+281946 -> 945171 | H8: =883882+218414 -> 1102296 | I8: =805710+235840 -> 1041550 | J8: =803414+221032 -> 1024446 | K8: =879379+235407 -> 1114786 | L8: =2213105+187446 -> 2400551 | M8: =755011+164627 -> 919638 | N8: =813590+152181 -> 965771 | O8: =SUM(C8:N8) -> 13303849
A9: 売上原価 | C9: 18747 | D9: 107823 | E9: 36542 | F9: 30735 | G9: 18222 | H9: 40050 | I9: 71448 | J9: 5560 | K9: 0 | L9: 46256 | M9: 39338 | N9: 46933 | O9: =SUM(C9:N9) -> 461654 | P9: =O9/$O$3 -> 0.011040689
A10: 売上総利益 | C10: =C2+C3-C9 -> 3082994 | D10: =D2+D3-D9 -> 5374336 | E10: =E2+E3-E9 -> 3018668 | F10: =F2+F3-F9 -> 2815358 | G10: =G2+G3-G9 -> 3282232 | H10: =H2+H3-H9 -> 2954791 | I10: =I2+I3-I9 -> 2924956 | J10: =J2+J3-J9 -> 3905336 | ... N10: =N2+N3-N9 -> 3071292 | O10: =SUM(C10:N10) -> 41352223
A11: 処遇改善手当 | C11: =C6 -> 0 | D11: =D6 -> 0 | E11: =E6 -> 0 | F11: =F6 -> 0 | G11: =G6 -> 0 | H11: =H6 -> 0 | I11: =I6 -> 0 | J11: =J6 -> 0 | K11: 0 | L11: 0 | O11: =SUM(C11:N11) -> 0
A12: 役員報酬 | C12: 0 | D12: 0 | E12: 0 | F12: 0 | G12: 0 | H12: 0 | I12: 0 | J12: 0 | K12: 0 | L12: 0 | O12: =SUM(C12:N12) -> 0 | P12: =O12/$O$10 -> 0
A13: 給与手当 | C13: 1456859 | D13: 1504722 | E13: 1513407 | F13: 1620950 | G13: 1514435 | H13: 1612029 | I13: 1526510 | J13: 1258740 | K13: 1187573 | L13: 1209285 | M13: 1189955 | N13: =1143807+823050 -> 1966857 | O13: =SUM(C13:N13) -> 17561322
