Workbook

Sheet 月次BS
B1: 勘定科目 | C1: 期首残 | D1: 7 | E1: =IF(D1=12,1,D1+1) -> 8 | F1: =IF(E1=12,1,E1+1) -> 9 | G1: =IF(F1=12,1,F1+1) -> 10 | H1: =IF(G1=12,1,G1+1) -> 11 | I1: =IF(H1=12,1,H1+1) -> 12 | J1: =IF(I1=12,1,I1+1) -> 1 | K1: =IF(J1=12,1,J1+1) -> 2 | L1: =IF(K1=12,1,K1+1) -> 3 | ... O1: =IF(N1=12,1,N1+1) -> 6
A2: 資産の部
A3: 流動資産
A4: 現金及び預金
B5: 現金
B6: 普通預金
A7: 現金及び預金合計 | C7: 2348989 | D7: 2725169 | E7: 1998006 | F7: 2031109 | G7: 1400195 | H7: 1532912 | I7: 1488143 | J7: 1217238 | K7: 2273568 | L7: 5469239 | M7: 5065984 | N7: 4720980 | O7: 4131529
A8: 売上債権
B9: 売掛金 | C9: 2838186 | D9: 3314302 | E9: 3820128 | F9: 4338949 | G9: 4857796 | H9: 5278592 | I9: 5913222 | J9: 6433571 | K9: 6896344 | L9: 6377513 | M9: 7291191 | N9: 7999295 | O9: 8976617
A10: 売上債権合計 | C10: 2838186 | D10: 3314302 | E10: 3820128 | F10: 4338949 | G10: 4857796 | H10: 5278592 | I10: 5913222 | J10: 6433571 | K10: 6896344 | L10: 6377513 | M10: 7291191 | N10: 7999295 | O10: 8976617
A11: 有価証券
A12: 有価証券合計
A13: 棚卸資産
B14: 商品
B15: 貯蔵品
A16: 棚卸資産合計
A17: その他流動資産
B18: 前払費用
B19: 立替金 | C19: 39666 | D19: 39666 | E19: 39666 | F19: 39666 | G19: 39666 | H19: 39666 | I19: 39666 | J19: 39666 | K19: 39666 | L19: 0 | M19: 0 | N19: 0 | O19: 0
B20: 短期貸付金 | C20: 7300000 | D20: 6277710 | E20: 6277710 | F20: 5771884 | G20: 5771884 | H20: 5196768 | I20: 4710947 | J20: 4159100 | K20: 2638882 | L20: 0 | M20: 0 | N20: 0 | O20: 0
B21: 仮払金 | C21: 0 | D21: 0 | E21: 0 | F21: 0 | G21: 0 | H21: 0 | I21: 0 | J21: 0 | K21: 0 | L21: 0 | M21: 0 | N21: 0 | O21: 4504
B22: 仮払消費税 | C22: 0 | D22: 75177 | E22: 109421 | F22: 151629 | G22: 200980 | H22: 230515 | I22: 277017 | J22: 320754 | K22: 360471 | L22: 402132 | M22: 438440 | N22: 483285 | O22: 526662
A23: その他流動資産合計 | C23: 7339666 | D23: 6392553 | E23: 6426797 | F23: 5963179 | G23: 6012530 | H23: 5466949 | I23: 5027630 | J23: 4519520 | K23: 3039019 | L23: 402132 | M23: 438440 | N23: 483285 | O23: 531166
A24: 流動資産合計 | C24: 12526841 | D24: 12432024 | E24: 12244931 | F24: 12333237 | G24: 12270521 | H24: 12278453 | I24: 12428995 | J24: 12170329 | K24: 12208931 | L24: 12248884 | M24: 12795615 | N24: 13203560 | O24: 13639312
A25: 固定資産
A26: 有形固定資産
B27: 建物
B28: 車両運搬具
B29: 工具器具備品
B30: 一括償却資産
B31: 減価償却累計額
A32: 有形固定資産合計
A33: 無形固定資産
B34: ソフトウェア | C34: 795000 | D34: 768500 | E34: 742000 | F34: 715500 | G34: 689000 | H34: 662500 | I34: 636000 | J34: 609500 | K34: 583000 | L34: 556500 | M34: 530000 | N34: 503500 | O34: 477000
A35: 無形固定資産合計 | C35: 795000 | D35: 768500 | E35: 742000 | F35: 715500 | G35: 689000 | H35: 662500 | I35: 636000 | J35: 609500 | K35: 583000 | L35: 556500 | M35: 530000 | N35: 503500 | O35: 477000
A36: 投資その他の資産
B37: 出資金 | C37: 6600000 | D37: 6600000 | E37: 6600000 | F37: 6600000 | G37: 6600000 | H37: 6600000 | I37: 6600000 | J37: 6600000 | K37: 6600000 | L37: 6600000 | M37: 6600000 | N37: 6600000 | O37: 6600000
B38: 長期前払費用 | C38: 114983 | D38: 114983 | E38: 114983 | F38: 114983 | G38: 114983 | H38: 114983 | I38: 114983 | J38: 114983 | K38: 114983 | L38: 114983 | M38: 114983 | N38: 114983 | O38: 114983
B39: 敷金
B40: 預託金
...

Sheet BS千円
B1: 勘定科目 | C1: 期首残 | D1: 7月 | E1: 8月 | F1: =+月次BS!F1 -> 9 | G1: =+月次BS!G1 -> 10 | H1: =+月次BS!H1 -> 11 | I1: =+月次BS!I1 -> 12 | J1: =+月次BS!J1 -> 1 | K1: =+月次BS!K1 -> 2 | L1: =+月次BS!L1 -> 3 | M1: =+月次BS!M1 -> 4 | ... O1: =+月次BS!O1 -> 6
A2: =+月次BS!A2 -> 資産の部
A3: =+月次BS!A3 -> 流動資産
A4: =+月次BS!A4 -> 現金及び預金
A5: =+月次BS!A5 -> 0 | B5: =+月次BS!B5 -> 現金 | C5: =+月次BS!C5/1000 -> 0 | D5: =+月次BS!D5/1000 -> 0 | E5: =+月次BS!E5/1000 -> 0 | F5: =+月次BS!F5/1000 -> 0 | G5: =+月次BS!G5/1000 -> 0 | H5: =+月次BS!H5/1000 -> 0 | I5: =+月次BS!I5/1000 -> 0 | J5: =+月次BS!J5/1000 -> 0 | ... O5: =+月次BS!O5/1000 -> 0
A6: =+月次BS!A6 -> 0 | B6: =+月次BS!B6 -> 普通預金 | C6: =+月次BS!C6/1000 -> 0 | D6: =+月次BS!D6/1000 -> 0 | E6: =+月次BS!E6/1000 -> 0 | F6: =+月次BS!F6/1000 -> 0 | G6: =+月次BS!G6/1000 -> 0 | H6: =+月次BS!H6/1000 -> 0 | I6: =+月次BS!I6/1000 -> 0 | J6: =+月次BS!J6/1000 -> 0 | ... O6: =+月次BS!O6/1000 -> 0
A7: =+月次BS!A7 -> 現金及び預金合計 | B7: =+月次BS!B7 -> 0 | C7: =+月次BS!C7/1000 -> 2348.989 | D7: =+月次BS!D7/1000 -> 2725.169 | E7: =+月次BS!E7/1000 -> 1998.006 | F7: =+月次BS!F7/1000 -> 2031.109 | G7: =+月次BS!G7/1000 -> 1400.195 | H7: =+月次BS!H7/1000 -> 1532.912 | I7: =+月次BS!I7/1000 -> 1488.143 | J7: =+月次BS!J7/1000 -> 1217.238 | ... O7: =+月次BS!O7/1000 -> 4131.529
A8: =+月次BS!A8 -> 売上債権 | B8: =+月次BS!B8 -> 0 | C8: =+月次BS!C8/1000 -> 0 | D8: =+月次BS!D8/1000 -> 0 | E8: =+月次BS!E8/1000 -> 0 | F8: =+月次BS!F8/1000 -> 0 | G8: =+月次BS!G8/1000 -> 0 | H8: =+月次BS!H8/1000 -> 0 | I8: =+月次BS!I8/1000 -> 0 | J8: =+月次BS!J8/1000 -> 0 | ... O8: =+月次BS!O8/1000 -> 0
A9: =+月次BS!A9 -> 0 | B9: =+月次BS!B9 -> 売掛金 | C9: =+月次BS!C9/1000 -> 2838.186 | D9: =+月次BS!D9/1000 -> 3314.302 | E9: =+月次BS!E9/1000 -> 3820.128 | F9: =+月次BS!F9/1000 -> 4338.949 | G9: =+月次BS!G9/1000 -> 4857.796 | H9: =+月次BS!H9/1000 -> 5278.592 | I9: =+月次BS!I9/1000 -> 5913.222 | J9: =+月次BS!J9/1000 -> 6433.571 | ... O9: =+月次BS!O9/1000 -> 8976.617
A10: =+月次BS!A10 -> 売上債権合計 | B10: =+月次BS!B10 -> 0 | C10: =+月次BS!C10/1000 -> 2838.186 | D10: =+月次BS!D10/1000 -> 3314.302 | E10: =+月次BS!E10/1000 -> 3820.128 | F10: =+月次BS!F10/1000 -> 4338.949 | G10: =+月次BS!G10/1000 -> 4857.796 | H10: =+月次BS!H10/1000 -> 5278.592 | I10: =+月次BS!I10/1000 -> 5913.222 | J10: =+月次BS!J10/1000 -> 6433.571 | ... O10: =+月次BS!O10/1000 -> 8976.617
A11: =+月次BS!A11 -> 有価証券 | B11: =+月次BS!B11 -> 0 | C11: =+月次BS!C11/1000 -> 0 | D11: =+月次BS!D11/1000 -> 0 | E11: =+月次BS!E11/1000 -> 0 | F11: =+月次BS!F11/1000 -> 0 | G11: =+月次BS!G11/1000 -> 0 | H11: =+月次BS!H11/1000 -> 0 | I11: =+月次BS!I11/1000 -> 0 | J11: =+月次BS!J11/1000 -> 0 | ... O11: =+月次BS!O11/1000 -> 0
A12: =+月次BS!A12 -> 有価証券合計 | B12: =+月次BS!B12 -> 0 | C12: =+月次BS!C12/1000 -> 0 | D12: =+月次BS!D12/1000 -> 0 | E12: =+月次BS!E12/1000 -> 0 | F12: =+月次BS!F12/1000 -> 0 | G12: =+月次BS!G12/1000 -> 0 | H12: =+月次BS!H12/1000 -> 0 | I12: =+月次BS!I12/1000 -> 0 | J12: =+月次BS!J12/1000 -> 0 | ... O12: =+月次BS!O12/1000 -> 0
A13: =+月次BS!A13 -> 棚卸資産 | B13: =+月次BS!B13 -> 0 | C13: =+月次BS!C13/1000 -> 0 | D13: =+月次BS!D13/1000 -> 0 | E13: =+月次BS!E13/1000 -> 0 | F13: =+月次BS!F13/1000 -> 0 | G13: =+月次BS!G13/1000 -> 0 | H13: =+月次BS!H13/1000 -> 0 | I13: =+月次BS!I13/1000 -> 0 | J13: =+月次BS!J13/1000 -> 0 | ... O13: =+月次BS!O13/1000 -> 0
A14: =+月次BS!A14 -> 0 | B14: =+月次BS!B14 -> 商品 | C14: =+月次BS!C14/1000 -> 0 | D14: =+月次BS!D14/1000 -> 0 | E14: =+月次BS!E14/1000 -> 0 | F14: =+月次BS!F14/1000 -> 0 | G14: =+月次BS!G14/1000 -> 0 | H14: =+月次BS!H14/1000 -> 0 | I14: =+月次BS!I14/1000 -> 0 | J14: =+月次BS!J14/1000 -> 0 | ... O14: =+月次BS!O14/1000 -> 0
A15: =+月次BS!A15 -> 0 | B15: =+月次BS!B15 -> 貯蔵品 | C15: =+月次BS!C15/1000 -> 0 | D15: =+月次BS!D15/1000 -> 0 | E15: =+月次BS!E15/1000 -> 0 | F15: =+月次BS!F15/1000 -> 0 | G15: =+月次BS!G15/1000 -> 0 | H15: =+月次BS!H15/1000 -> 0 | I15: =+月次BS!I15/1000 -> 0 | J15: =+月次BS!J15/1000 -> 0 | ... O15: =+月次BS!O15/1000 -> 0
A16: =+月次BS!A16 -> 棚卸資産合計 | B16: =+月次BS!B16 -> 0 | C16: =+月次BS!C16/1000 -> 0 | D16: =+月次BS!D16/1000 -> 0 | E16: =+月次BS!E16/1000 -> 0 | F16: =+月次BS!F16/1000 -> 0 | G16: =+月次BS!G16/1000 -> 0 | H16: =+月次BS!H16/1000 -> 0 | I16: =+月次BS!I16/1000 -> 0 | J16: =+月次BS!J16/1000 -> 0 | ... O16: =+月次BS!O16/1000 -> 0
... A53: =+月次BS!A53 -> その他流動負債 | B53: =+月次BS!B53 -> 0 | C53: =+月次BS!C53/1000 -> 0 | D53: =+月次BS!D53/1000 -> 0 | E53: =+月次BS!E53/1000 -> 0 | F53: =+月次BS!F53/1000 -> 0 | G53: =+月次BS!G53/1000 -> 0 | H53: =+月次BS!H53/1000 -> 0 | I53: =+月次BS!I53/1000 -> 0 | J53: =+月次BS!J53/1000 -> 0 | ... O53: =+月次BS!O53/1000 -> 0
B54: =+月次BS!B54 -> 短期借入金 | C54: =+月次BS!C54/1000 -> 0 | D54: =+月次BS!D54/1000 -> 0 | E54: =+月次BS!E54/1000 -> 0 | F54: =+月次BS!F54/1000 -> 0 | G54: =+月次BS!G54/1000 -> 0 | H54: =+月次BS!H54/1000 -> 0 | I54: =+月次BS!I54/1000 -> 0 | J54: =+月次BS!J54/1000 -> 0 | ... O54: =+月次BS!O54/1000 -> 0
A55: =+月次BS!A55 -> 0 | B55: =+月次BS!B55 -> 未払金 | C55: =+月次BS!C55/1000 -> 250 | D55: =+月次BS!D55/1000 -> 250 | E55: =+月次BS!E55/1000 -> 349.28 | F55: =+月次BS!F55/1000 -> 349.28 | G55: =+月次BS!G55/1000 -> 349.28 | H55: =+月次BS!H55/1000 -> 349.28 | I55: =+月次BS!I55/1000 -> 301.677 | J55: =+月次BS!J55/1000 -> 301.677 | ... O55: =+月次BS!O55/1000 -> 271.677
A56: =+月次BS!A56 -> 0 | B56: =+月次BS!B56 -> 未払費用 | C56: =+月次BS!C56/1000 -> 154.397 | D56: =+月次BS!D56/1000 -> 277.182 | E56: =+月次BS!E56/1000 -> 174.937 | F56: =+月次BS!F56/1000 -> 256.413 | G56: =+月次BS!G56/1000 -> 233.345 | H56: =+月次BS!H56/1000 -> 201.349 | I56: =+月次BS!I56/1000 -> 346.833 | J56: =+月次BS!J56/1000 -> 214.413 | ... O56: =+月次BS!O56/1000 -> 299.367
A57: =+月次BS!A57 -> 0 | B57: =+月次BS!B57 -> 預り金 | C57: =+月次BS!C57/1000 -> 0 | D57: =+月次BS!D57/1000 -> 0 | E57: =+月次BS!E57/1000 -> 0.72 | F57: =+月次BS!F57/1000 -> 1.44 | G57: =+月次BS!G57/1000 -> 14.412 | H57: =+月次BS!H57/1000 -> 15.132 | I57: =+月次BS!I57/1000 -> 18.195 | J57: =+月次BS!J57/1000 -> 6.126 | ... O57: =+月次BS!O57/1000 -> 21.441
A58: =+月次BS!A58 -> 0 | B58: =+月次BS!B58 -> 仮受金 | C58: =+月次BS!C58/1000 -> 21.421 | D58: =+月次BS!D58/1000 -> -1.101 | E58: =+月次BS!E58/1000 -> -48.041 | F58: =+月次BS!F58/1000 -> -35.82 | G58: =+月次BS!G58/1000 -> -10.303 | H58: =+月次BS!H58/1000 -> 5.031 | I58: =+月次BS!I58/1000 -> 106.718 | J58: =+月次BS!J58/1000 -> 18.3 | ... O58: =+月次BS!O58/1000 -> 11.08
A59: =+月次BS!A59 -> 0 | B59: =+月次BS!B59 -> 未払消費税 | C59: =+月次BS!C59/1000 -> 135.6 | D59: =+月次BS!D59/1000 -> 135.6 | E59: =+月次BS!E59/1000 -> 0 | F59: =+月次BS!F59/1000 -> 0 | G59: =+月次BS!G59/1000 -> 0 | H59: =+月次BS!H59/1000 -> 0 | I59: =+月次BS!I59/1000 -> 0 | J59: =+月次BS!J59/1000 -> 0 | ... O59: =+月次BS!O59/1000 -> 0
A60: =+月次BS!A60 -> 0 | B60: =+月次BS!B60 -> 未払法人税等 | C60: =+月次BS!C60/1000 -> 70 | D60: =+月次BS!D60/1000 -> 70 | E60: =+月次BS!E60/1000 -> 0 | F60: =+月次BS!F60/1000 -> 0 | G60: =+月次BS!G60/1000 -> 0 | H60: =+月次BS!H60/1000 -> 0 | I60: =+月次BS!I60/1000 -> 0 | J60: =+月次BS!J60/1000 -> 0 | ... O60: =+月次BS!O60/1000 -> 0
A61: =+月次BS!A61 -> 0 | B61: =+月次BS!B61 -> 仮受消費税 | C61: =+月次BS!C61/1000 -> 0 | D61: =+月次BS!D61/1000 -> 62.283 | E61: =+月次BS!E61/1000 -> 118.267 | F61: =+月次BS!F61/1000 -> 175.432 | G61: =+月次BS!G61/1000 -> 232.599 | H61: =+月次BS!H61/1000 -> 280.853 | I61: =+月次BS!I61/1000 -> 337.66 | J61: =+月次BS!J61/1000 -> 394.964 | ... O61: =+月次BS!O61/1000 -> 806.873
A62: =+月次BS!A62 -> 0 | B62: =+月次BS!B62 -> 助成引当 | C62: =+月次BS!C62/1000 -> 0 | D62: =+月次BS!D62/1000 -> 0 | E62: =+月次BS!E62/1000 -> 0 | F62: =+月次BS!F62/1000 -> 0 | G62: =+月次BS!G62/1000 -> 0 | H62: =+月次BS!H62/1000 -> 0 | I62: =+月次BS!I62/1000 -> 0 | J62: =+月次BS!J62/1000 -> 0 | ... O62: =+月次BS!O62/1000 -> 0
A63: =+月次BS!A63 -> 0 | B63: =+月次BS!B63 -> 一年以内返済長期借入金 | C63: =+月次BS!C63/1000 -> 1200 | D63: =+月次BS!D63/1000 -> 1200 | E63: =+月次BS!E63/1000 -> 1200 | F63: =+月次BS!F63/1000 -> 1200 | G63: =+月次BS!G63/1000 -> 1200 | H63: =+月次BS!H63/1000 -> 1200 | I63: =+月次BS!I63/1000 -> 1200 | J63: =+月次BS!J63/1000 -> 1200 | ... O63: =+月次BS!O63/1000 -> 0
A64: =+月次BS!A64 -> その他流動負債合計 | B64: =+月次BS!B64 -> 0 | C64: =+月次BS!C64/1000 -> 1831.418 | D64: =+月次BS!D64/1000 -> 1993.964 | E64: =+月次BS!E64/1000 -> 1795.163 | F64: =+月次BS!F64/1000 -> 1946.745 | G64: =+月次BS!G64/1000 -> 2019.333 | H64: =+月次BS!H64/1000 -> 2051.645 | I64: =+月次BS!I64/1000 -> 2311.083 | J64: =+月次BS!J64/1000 -> 2135.48 | ... O64: =+月次BS!O64/1000 -> 1410.438
A65: =+月次BS!A65 -> 流動負債合計 | B65: =+月次BS!B65 -> 0 | C65: =+月次BS!C65/1000 -> 1831.418 | D65: =+月次BS!D65/1000 -> 1993.964 | E65: =+月次BS!E65/1000 -> 1795.163 | F65: =+月次BS!F65/1000 -> 1946.745 | G65: =+月次BS!G65/1000 -> 2019.333 | H65: =+月次BS!H65/1000 -> 2051.645 | I65: =+月次BS!I65/1000 -> 2311.083 | J65: =+月次BS!J65/1000 -> 2135.48 | ... O65: =+月次BS!O65/1000 -> 1410.438
A66: =+月次BS!A66 -> 固定負債 | B66: =+月次BS!B66 -> 0 | C66: =+月次BS!C66/1000 -> 0 | D66: =+月次BS!D66/1000 -> 0 | E66: =+月次BS!E66/1000 -> 0 | F66: =+月次BS!F66/1000 -> 0 | G66: =+月次BS!G66/1000 -> 0 | H66: =+月次BS!H66/1000 -> 0 | I66: =+月次BS!I66/1000 -> 0 | J66: =+月次BS!J66/1000 -> 0 | ... O66: =+月次BS!O66/1000 -> 0
... A93: =+月次BS!A93 -> 負債・純資産の部合計 | B93: =+月次BS!B93 -> 0 | C93: =+月次BS!C93/1000 -> 20036.824 | D93: =+月次BS!D93/1000 -> 19915.507 | E93: =+月次BS!E93/1000 -> 19701.914 | F93: =+月次BS!F93/1000 -> 19763.72 | G93: =+月次BS!G93/1000 -> 19674.504 | H93: =+月次BS!H93/1000 -> 19655.936 | I93: =+月次BS!I93/1000 -> 19779.978 | J93: =+月次BS!J93/1000 -> 19494.812 | ... O93: =+月次BS!O93/1000 -> 20831.295
A94: =+月次BS!A95 -> 0 | B94: =+月次BS!B95 -> 0 | C94: =+月次BS!C95/1000 -> 0 | D94: =+月次BS!D95/1000 -> 0 | E94: =+月次BS!E95/1000 -> 0 | F94: =+月次BS!F95/1000 -> 0 | G94: =+月次BS!G95/1000 -> 0 | H94: =+月次BS!H95/1000 -> 0 | I94: =+月次BS!I95/1000 -> 0 | J94: =+月次BS!J95/1000 -> 0 | ... O94: =+月次BS!O95/1000 -> 0
A95: =+月次BS!A96 -> 0 | B95: 買掛未払債務 | C95: =+C51+C55+C56 -> 404.397 | D95: =+D51+D55+D56 -> 527.182 | E95: =+E51+E55+E56 -> 524.217 | F95: =+F51+F55+F56 -> 605.693 | G95: =+G51+G55+G56 -> 582.625 | H95: =+H51+H55+H56 -> 550.629 | I95: =+I51+I55+I56 -> 648.51 | J95: =+J51+J55+J56 -> 516.09 | ... O95: =+O51+O55+O56 -> 571.044
A96: =+月次BS!A97 -> 0 | B96: その他流動負債 | C96: =+C57+C58+C62+C61 -> 21.421 | D96: =+D57+D58+D62+D61 -> 61.182 | E96: =+E57+E58+E62+E61 -> 70.946 | F96: =+F57+F58+F62+F61 -> 141.052 | G96: =+G57+G58+G62+G61 -> 236.708 | H96: =+H57+H58+H62+H61 -> 301.016 | I96: =+I57+I58+I62+I61 -> 462.573 | J96: =+J57+J58+J62+J61 -> 419.39 | ... O96: =+O57+O58+O62+O61 -> 839.394
A97: =+月次BS!A98 -> 0 | B97: 有形・無形固定資産 | C97: =+C32+C35 -> 795 | D97: =+D32+D35 -> 768.5 | E97: =+E32+E35 -> 742 | F97: =+F32+F35 -> 715.5 | G97: =+G32+G35 -> 689 | H97: =+H32+H35 -> 662.5 | I97: =+I32+I35 -> 636 | J97: =+J32+J35 -> 609.5 | ... O97: =+O32+O35 -> 477
A98: =+月次BS!A99 -> 0 | B98: 長期借入金 | C98: =+C63+C67 -> 10000 | D98: =+D63+D67 -> 10000 | E98: =+E63+E67 -> 10000 | F98: =+F63+F67 -> 10000 | G98: =+G63+G67 -> 10000 | H98: =+H63+H67 -> 10000 | I98: =+I63+I67 -> 10000 | J98: =+J63+J67 -> 10000 | ... O98: =+O63+O67 -> 10000
A99: =+月次BS!A100 -> 0 | B99: =+B54 -> 短期借入金 | C99: =+C54 -> 0 | D99: =+D54 -> 0 | E99: =+E54 -> 0 | F99: =+F54 -> 0 | G99: =+G54 -> 0 | H99: =+H54 -> 0 | I99: =+I54 -> 0 | ... O99: =+O54 -> 0
A100: =+月次BS!A101 -> 0 | B100: 貸付金 | C100: =+月次BS!C101/1000 -> 0 | D100: =+月次BS!D101/1000 -> 0 | E100: =+月次BS!E101/1000 -> 0 | F100: =+月次BS!F101/1000 -> 0 | G100: =+月次BS!G101/1000 -> 0 | H100: =+月次BS!H101/1000 -> 0 | I100: =+月次BS!I101/1000 -> 0 | J100: =+月次BS!J101/1000 -> 0 | ... O100: =+月次BS!O101/1000 -> 0
A101: =+月次BS!A102 -> 0 | B101: =+月次BS!B102 -> 0 | C101: =+月次BS!C102/1000 -> 0 | D101: =+月次BS!D102/1000 -> 0 | E101: =+月次BS!E102/1000 -> 0 | F101: =+月次BS!F102/1000 -> 0 | G101: =+月次BS!G102/1000 -> 0 | H101: =+月次BS!H102/1000 -> 0 | I101: =+月次BS!I102/1000 -> 0 | J101: =+月次BS!J102/1000 -> 0 | ... O101: =+月次BS!O102/1000 -> 0
A102: =+月次BS!A103 -> 0 | B102: =+月次BS!B103 -> 0 | C102: =+月次BS!C103/1000 -> 0 | D102: =+月次BS!D103/1000 -> 0 | E102: =+月次BS!E103/1000 -> 0 | F102: =+月次BS!F103/1000 -> 0 | G102: =+月次BS!G103/1000 -> 0 | H102: =+月次BS!H103/1000 -> 0 | I102: =+月次BS!I103/1000 -> 0 | J102: =+月次BS!J103/1000 -> 0 | ... O102: =+月次BS!O103/1000 -> 0
...

Sheet 月次PL
B1: 勘定科目 | C1: =+月次BS!D1 -> 7 | D1: =+月次BS!E1 -> 8 | E1: =+月次BS!F1 -> 9 | F1: =+月次BS!G1 -> 10 | G1: =+月次BS!H1 -> 11 | H1: =+月次BS!I1 -> 12 | I1: =+月次BS!J1 -> 1 | J1: =+月次BS!K1 -> 2 | ... N1: =+月次BS!O1 -> 6 | O1: 累計
A2: 売上高
B3: 売上高 | C3: 622833 | D3: 559842 | E3: 571656 | F3: 571680 | G3: 482542 | H3: 568075 | I3: 573045 | J3: 566158 | K3: 643467 | L3: 1030617 | M3: 890404 | N3: 988475 | O3: =SUM(C3:N3) -> 8068794
O4: =SUM(C4:N4) -> 0
O5: =SUM(C5:N5) -> 0
O6: =SUM(C6:N6) -> 0
O7: =SUM(C7:N7) -> 0
A8: 売上高合計 | C8: =+SUM(C3:C7) -> 622833 | D8: =+SUM(D3:D7) -> 559842 | E8: =+SUM(E3:E7) -> 571656 | F8: =+SUM(F3:F7) -> 571680 | G8: =+SUM(G3:G7) -> 482542 | H8: =+SUM(H3:H7) -> 568075 | I8: =+SUM(I3:I7) -> 573045 | J8: =+SUM(J3:J7) -> 566158 | ... N8: =+SUM(N3:N7) -> 988475 | O8: =SUM(C8:N8) -> 8068794
A9: 売上原価 | O9: =SUM(C9:N9) -> 0
O10: =SUM(C10:N10) -> 0
O11: =SUM(C11:N11) -> 0
O12: =SUM(C12:N12) -> 0
O13: =SUM(C13:N13) -> 0
O14: =SUM(C14:N14) -> 0
A15: 売上原価 | C15: =+C10+C11+C12-C13-C14 -> 0 | D15: =+D10+D11+D12-D13-D14 -> 0 | E15: =+E10+E11+E12-E13-E14 -> 0 | F15: =+F10+F11+F12-F13-F14 -> 0 | G15: =+G10+G11+G12-G13-G14 -> 0 | H15: =+H10+H11+H12-H13-H14 -> 0 | I15: =+I10+I11+I12-I13-I14 -> 0 | J15: =+J10+J11+J12-J13-J14 -> 0 | ... N15: =+N10+N11+N12-N13-N14 -> 0 | O15: =SUM(C15:N15) -> 0
A16: 売上総利益 | C16: =+C8-C15 -> 622833 | D16: =+D8-D15 -> 559842 | E16: =+E8-E15 -> 571656 | F16: =+F8-F15 -> 571680 | G16: =+G8-G15 -> 482542 | H16: =+H8-H15 -> 568075 | I16: =+I8-I15 -> 573045 | J16: =+J8-J15 -> 566158 | ... N16: =+N8-N15 -> 988475 | O16: =SUM(C16:N16) -> 8068794
A17: 販売費及び一般管理費 | O17: =SUM(C17:N17) -> 0
B18: 役員報酬 | C18: 0 | D18: 100000 | E18: 100000 | F18: 100000 | G18: 100000 | H18: 100000 | I18: 100000 | J18: 100000 | K18: 100000 | L18: 100000 | M18: 100000 | N18: 100000 | O18: =SUM(C18:N18) -> 1100000
B19: 給料賃金 | O19: =SUM(C19:N19) -> 0
B20: 賞与 | O20: =SUM(C20:N20) -> 0
B21: 雑給 | O21: =SUM(C21:N21) -> 0
B22: 法定福利費 | O22: =SUM(C22:N22) -> 0
B23: 福利厚生費 | O23: =SUM(C23:N23) -> 0
B24: 研修採用費
B25: 業務委託費 | C25: 535456 | D25: 231819 | E25: 231819 | F25: 231819 | G25: 231819 | H25: 231819 | I25: 231819 | J25: 231819 | K25: 231819 | L25: 231819 | M25: 231819 | N25: 231819 | O25: =SUM(C25:N25) -> 3085465
B26: 広告宣伝費 | O26: =SUM(C26:N26) -> 0
B27: 接待交際費 | C27: 13438 | D27: 50137 | E27: 103900 | F27: 12119 | G27: 30000 | H27: 158371 | I27: 87515 | J27: 113663 | K27: 172618 | L27: 89768 | M27: 95002 | N27: 111724 | O27: =SUM(C27:N27) -> 1038255
B28: 旅費交通費 | C28: 9720 | D28: 5371 | E28: 8966 | F28: 74104 | G28: 6693 | H28: 1928 | I28: 101043 | J28: 5547 | K28: 1091 | L28: 0 | M28: 57464 | N28: 24862 | O28: =SUM(C28:N28) -> 296789
B29: 通信費 | C29: 1200 | D29: 55560 | E29: 54960 | F29: 1200 | G29: 1200 | H29: 78960 | I29: 3837 | J29: 57597 | K29: 18513 | L29: 27326 | M29: 71599 | N29: 62331 | O29: =SUM(C29:N29) -> 434283
B30: 水道光熱費 | O30: =SUM(C30:N30) -> 0
B31: 修繕費 | O31: =SUM(C31:N31) -> 0
B32: 消耗品費 | C32: 4797 | D32: 0 | E32: 0 | F32: 0 | G32: 0 | H32: 0 | I32: 0 | J32: 0 | K32: 0 | L32: 39584 | M32: 10200 | N32: 0 | O32: =SUM(C32:N32) -> 54581
B33: リース料 | O33: =SUM(C33:N33) -> 0
B34: 地代家賃 | C34: 44500 | D34: 44500 | E34: 44500 | F34: 44500 | G34: 44500 | H34: 44500 | I34: 44500 | J34: 44500 | K34: 44500 | L34: 44500 | M34: 44500 | N34: 44500 | O34: =SUM(C34:N34) -> 534000
B35: 賃借料 | O35: =SUM(C35:N35) -> 0
B36: 保険料 | C36: 5000 | D36: 5000 | E36: 5000 | F36: 5000 | G36: 5000 | H36: 5000 | I36: 5000 | J36: 5000 | K36: 5000 | L36: 5000 | M36: 5000 | N36: 5000 | O36: =SUM(C36:N36) -> 60000
B37: 租税公課 | C37: 0 | D37: 0 | E37: 0 | F37: 0 | G37: 1200 | H37: 0 | I37: 600 | J37: 0 | K37: 0 | L37: 0 | M37: 0 | N37: 0 | O37: =SUM(C37:N37) -> 1800
B38: 支払手数料 | C38: 12455 | D38: 1955 | E38: 2105 | F38: 2255 | G38: 7469 | H38: 4353 | I38: 4694 | J38: 2155 | K38: 2255 | L38: 2105 | M38: 2105 | N38: 2105 | O38: =SUM(C38:N38) -> 46011
B39: 会議費 | C39: 84497 | D39: 10447 | E39: 11637 | F39: 67568 | G39: 49291 | H39: 22016 | I39: 45376 | J39: 13067 | K39: 27771 | L39: 13158 | M39: 10469 | N39: 27614 | O39: =SUM(C39:N39) -> 382911
B40: 新聞図書費 | C40: 0 | D40: 1990 | E40: 1990 | F40: 891 | G40: 891 | H40: 891 | I40: 891 | J40: 3919 | K40: 891 | L40: 891 | M40: 891 | N40: 0 | O40: =SUM(C40:N40) -> 14136
...

Sheet 決算予測
A1: ■決算着地予測
B2: 勘定科目 | C2: =+月次BS!D1 -> 7 | D2: =+月次BS!E1 -> 8 | E2: =+月次BS!F1 -> 9 | F2: =+月次BS!G1 -> 10 | G2: =+月次BS!H1 -> 11 | H2: =+月次BS!I1 -> 12 | I2: =+月次BS!J1 -> 1 | J2: =+月次BS!K1 -> 2 | ... N2: =+月次BS!O1 -> 6 | O2: 累計
A3: 売上高
B4: 売上高 | C4: =+月次PL!C3 -> 622833 | D4: =+月次PL!D3 -> 559842 | E4: =+月次PL!E3 -> 571656 | F4: =+月次PL!F3 -> 571680 | G4: =+月次PL!G3 -> 482542 | H4: =+月次PL!H3 -> 568075 | I4: =+月次PL!I3 -> 573045 | J4: =+月次PL!J3 -> 566158 | ... M4: =+月次PL!M3 -> 890404 | N4: =932914+100000 -> 1032914 | O4: =SUM(C4:N4) -> 8113233 | P4: ライフワーク計画値
O5: =SUM(C5:N5) -> 0
O6: =SUM(C6:N6) -> 0
O7: =SUM(C7:N7) -> 0
O8: =SUM(C8:N8) -> 0
A9: 売上高合計 | C9: =+SUM(C4:C8) -> 622833 | D9: =+SUM(D4:D8) -> 559842 | E9: =+SUM(E4:E8) -> 571656 | F9: =+SUM(F4:F8) -> 571680 | G9: =+SUM(G4:G8) -> 482542 | H9: =+SUM(H4:H8) -> 568075 | I9: =+SUM(I4:I8) -> 573045 | J9: =+SUM(J4:J8) -> 566158 | ... N9: =+SUM(N4:N8) -> 1032914 | O9: =SUM(C9:N9) -> 8113233
A10: 売上原価 | O10: =SUM(C10:N10) -> 0
O11: =SUM(C11:N11) -> 0
O12: =SUM(C12:N12) -> 0
O13: =SUM(C13:N13) -> 0
O14: =SUM(C14:N14) -> 0
O15: =SUM(C15:N15) -> 0
A16: 売上原価 | C16: =+C11+C12+C13-C14-C15 -> 0 | D16: =+D11+D12+D13-D14-D15 -> 0 | E16: =+E11+E12+E13-E14-E15 -> 0 | F16: =+F11+F12+F13-F14-F15 -> 0 | G16: =+G11+G12+G13-G14-G15 -> 0 | H16: =+H11+H12+H13-H14-H15 -> 0 | I16: =+I11+I12+I13-I14-I15 -> 0 | J16: =+J11+J12+J13-J14-J15 -> 0 | ... N16: =+N11+N12+N13-N14-N15 -> 0 | O16: =SUM(C16:N16) -> 0
A17: 売上総利益 | C17: =+C9-C16 -> 622833 | D17: =+D9-D16 -> 559842 | E17: =+E9-E16 -> 571656 | F17: =+F9-F16 -> 571680 | G17: =+G9-G16 -> 482542 | H17: =+H9-H16 -> 568075 | I17: =+I9-I16 -> 573045 | J17: =+J9-J16 -> 566158 | ... N17: =+N9-N16 -> 1032914 | O17: =SUM(C17:N17) -> 8113233
A18: 販売費及び一般管理費 | O18: =SUM(C18:N18) -> 0
B19: 役員報酬 | C19: =+月次PL!C18 -> 0 | D19: =+月次PL!D18 -> 100000 | E19: =+月次PL!E18 -> 100000 | F19: =+月次PL!F18 -> 100000 | G19: =+月次PL!G18 -> 100000 | H19: =+月次PL!H18 -> 100000 | I19: =+月次PL!I18 -> 100000 | J19: =+月次PL!J18 -> 100000 | ... M19: =+月次PL!M18 -> 100000 | N19: =+M19 -> 100000 | O19: =SUM(C19:N19) -> 1100000 | P19: 前月実績値
B20: 給料賃金 | O20: =SUM(C20:N20) -> 0
B21: 賞与 | O21: =SUM(C21:N21) -> 0
B22: 雑給 | O22: =SUM(C22:N22) -> 0
B23: 法定福利費 | O23: =SUM(C23:N23) -> 0
B24: 福利厚生費 | O24: =SUM(C24:N24) -> 0
B25: 研修採用費
B26: 業務委託費 | C26: =+月次PL!C25 -> 535456 | D26: =+月次PL!D25 -> 231819 | E26: =+月次PL!E25 -> 231819 | F26: =+月次PL!F25 -> 231819 | G26: =+月次PL!G25 -> 231819 | H26: =+月次PL!H25 -> 231819 | I26: =+月次PL!I25 -> 231819 | J26: =+月次PL!J25 -> 231819 | ... M26: =+月次PL!M25 -> 231819 | N26: =+M26 -> 231819 | O26: =SUM(C26:N26) -> 3085465 | P26: 前月実績値
B27: 広告宣伝費 | O27: =SUM(C27:N27) -> 0 | P27: 今期実績平均
B28: 接待交際費 | C28: =+月次PL!C27 -> 13438 | D28: =+月次PL!D27 -> 50137 | E28: =+月次PL!E27 -> 103900 | F28: =+月次PL!F27 -> 12119 | G28: =+月次PL!G27 -> 30000 | H28: =+月次PL!H27 -> 158371 | I28: =+月次PL!I27 -> 87515 | J28: =+月次PL!J27 -> 113663 | ... M28: =+月次PL!M27 -> 95002 | N28: =+P28 -> 84230.091 | O28: =SUM(C28:N28) -> 1010761.1 | P28: =SUM(C28:M28)/11 -> 84230.091
B29: 旅費交通費 | C29: =+月次PL!C28 -> 9720 | D29: =+月次PL!D28 -> 5371 | E29: =+月次PL!E28 -> 8966 | F29: =+月次PL!F28 -> 74104 | G29: =+月次PL!G28 -> 6693 | H29: =+月次PL!H28 -> 1928 | I29: =+月次PL!I28 -> 101043 | J29: =+月次PL!J28 -> 5547 | ... M29: =+月次PL!M28 -> 57464 | N29: =+P29 -> 24720.636 | O29: =SUM(C29:N29) -> 296647.64 | P29: =SUM(C29:M29)/11 -> 24720.636
B30: 通信費 | C30: =+月次PL!C29 -> 1200 | D30: =+月次PL!D29 -> 55560 | E30: =+月次PL!E29 -> 54960 | F30: =+月次PL!F29 -> 1200 | G30: =+月次PL!G29 -> 1200 | H30: =+月次PL!H29 -> 78960 | I30: =+月次PL!I29 -> 3837 | J30: =+月次PL!J29 -> 57597 | ... M30: =+月次PL!M29 -> 71599 | N30: =+P30 -> 33813.818 | O30: =SUM(C30:N30) -> 405765.82 | P30: =SUM(C30:M30)/11 -> 33813.818
B31: 水道光熱費 | C31: =+月次PL!C30 -> 0 | D31: =+月次PL!D30 -> 0 | E31: =+月次PL!E30 -> 0 | F31: =+月次PL!F30 -> 0 | G31: =+月次PL!G30 -> 0 | H31: =+月次PL!H30 -> 0 | I31: =+月次PL!I30 -> 0 | J31: =+月次PL!J30 -> 0 | ... M31: =+月次PL!M30 -> 0 | N31: =+P31 -> 0 | O31: =SUM(C31:N31) -> 0 | P31: =SUM(C31:M31)/11 -> 0
B32: 修繕費 | C32: =+月次PL!C31 -> 0 | D32: =+月次PL!D31 -> 0 | E32: =+月次PL!E31 -> 0 | F32: =+月次PL!F31 -> 0 | G32: =+月次PL!G31 -> 0 | H32: =+月次PL!H31 -> 0 | I32: =+月次PL!I31 -> 0 | J32: =+月次PL!J31 -> 0 | ... M32: =+月次PL!M31 -> 0 | N32: =+P32 -> 0 | O32: =SUM(C32:N32) -> 0 | P32: =SUM(C32:M32)/11 -> 0
B33: 消耗品費 | C33: =+月次PL!C32 -> 4797 | D33: =+月次PL!D32 -> 0 | E33: =+月次PL!E32 -> 0 | F33: =+月次PL!F32 -> 0 | G33: =+月次PL!G32 -> 0 | H33: =+月次PL!H32 -> 0 | I33: =+月次PL!I32 -> 0 | J33: =+月次PL!J32 -> 0 | ... M33: =+月次PL!M32 -> 10200 | N33: =+P33 -> 4961.9091 | O33: =SUM(C33:N33) -> 59542.909 | P33: =SUM(C33:M33)/11 -> 4961.9091
B34: リース料 | C34: =+月次PL!C33 -> 0 | D34: =+月次PL!D33 -> 0 | E34: =+月次PL!E33 -> 0 | F34: =+月次PL!F33 -> 0 | G34: =+月次PL!G33 -> 0 | H34: =+月次PL!H33 -> 0 | I34: =+月次PL!I33 -> 0 | J34: =+月次PL!J33 -> 0 | ... M34: =+月次PL!M33 -> 0 | N34: =+P34 -> 0 | O34: =SUM(C34:N34) -> 0 | P34: =SUM(C34:M34)/11 -> 0
B35: 地代家賃 | C35: =+月次PL!C34 -> 44500 | D35: =+月次PL!D34 -> 44500 | E35: =+月次PL!E34 -> 44500 | F35: =+月次PL!F34 -> 44500 | G35: =+月次PL!G34 -> 44500 | H35: =+月次PL!H34 -> 44500 | I35: =+月次PL!I34 -> 44500 | J35: =+月次PL!J34 -> 44500 | ... M35: =+月次PL!M34 -> 44500 | N35: =+P35 -> 44500 | O35: =SUM(C35:N35) -> 534000 | P35: =SUM(C35:M35)/11 -> 44500
B36: 賃借料 | C36: =+月次PL!C35 -> 0 | D36: =+月次PL!D35 -> 0 | E36: =+月次PL!E35 -> 0 | F36: =+月次PL!F35 -> 0 | G36: =+月次PL!G35 -> 0 | H36: =+月次PL!H35 -> 0 | I36: =+月次PL!I35 -> 0 | J36: =+月次PL!J35 -> 0 | ... M36: =+月次PL!M35 -> 0 | N36: =+P36 -> 0 | O36: =SUM(C36:N36) -> 0 | P36: =SUM(C36:M36)/11 -> 0
B37: 保険料 | C37: =+月次PL!C36 -> 5000 | D37: =+月次PL!D36 -> 5000 | E37: =+月次PL!E36 -> 5000 | F37: =+月次PL!F36 -> 5000 | G37: =+月次PL!G36 -> 5000 | H37: =+月次PL!H36 -> 5000 | I37: =+月次PL!I36 -> 5000 | J37: =+月次PL!J36 -> 5000 | ... M37: =+月次PL!M36 -> 5000 | N37: =+P37 -> 5000 | O37: =SUM(C37:N37) -> 60000 | P37: =SUM(C37:M37)/11 -> 5000
B38: 租税公課 | C38: =+月次PL!C37 -> 0 | D38: =+月次PL!D37 -> 0 | E38: =+月次PL!E37 -> 0 | F38: =+月次PL!F37 -> 0 | G38: =+月次PL!G37 -> 1200 | H38: =+月次PL!H37 -> 0 | I38: =+月次PL!I37 -> 600 | J38: =+月次PL!J37 -> 0 | ... M38: =+月次PL!M37 -> 0 | N38: =+P38 -> 163.63636 | O38: =SUM(C38:N38) -> 1963.6364 | P38: =SUM(C38:M38)/11 -> 163.63636
B39: 支払手数料 | C39: =+月次PL!C38 -> 12455 | D39: =+月次PL!D38 -> 1955 | E39: =+月次PL!E38 -> 2105 | F39: =+月次PL!F38 -> 2255 | G39: =+月次PL!G38 -> 7469 | H39: =+月次PL!H38 -> 4353 | I39: =+月次PL!I38 -> 4694 | J39: =+月次PL!J38 -> 2155 | ... M39: =+月次PL!M38 -> 2105 | N39: =+P39 -> 3991.4545 | O39: =SUM(C39:N39) -> 47897.455 | P39: =SUM(C39:M39)/11 -> 3991.4545
... B45: 市場調査費 | C45: =+月次PL!C44 -> 140000 | D45: =+月次PL!D44 -> 14004 | E45: =+月次PL!E44 -> 42383 | F45: =+月次PL!F44 -> 0 | G45: =+月次PL!G44 -> 0 | H45: =+月次PL!H44 -> 0 | I45: =+月次PL!I44 -> 0 | J45: =+月次PL!J44 -> 0 | ... M45: =+月次PL!M44 -> 0 | N45: =+P45 -> 17853.364 | O45: =SUM(C45:N45) -> 214240.36 | P45: =SUM(C45:M45)/11 -> 17853.364
...

Sheet PL推移
B2: CK | C2: 売上高 | D2: =IF(D10<>0,IF(D10=月次PL!C8/1000,"OK",PL推移!D10-月次PL!C8/1000),"nd") -> OK | F2: =IF(F10<>0,IF(月次PL!D8/1000=PL推移!F10,"OK",PL推移!F10-月次PL!D8/1000),"nd") -> OK | H2: =IF(H10<>0,IF(月次PL!E8/1000=PL推移!H10,"OK",PL推移!H10-月次PL!E8/1000),"nd") -> OK | J2: =IF(J10<>0,IF(月次PL!F8/1000=PL推移!J10,"OK",PL推移!J10-月次PL!F8/1000),"nd") -> OK | L2: =IF(L10<>0,IF(月次PL!G8/1000=PL推移!L10,"OK",PL推移!L10-月次PL!G8/1000),"nd") -> OK | N2: =IF(N10<>0,IF(月次PL!H8/1000=PL推移!N10,"OK",PL推移!N10-月次PL!H8/1000),"nd") -> OK | P2: =IF(P10<>0,IF(月次PL!I8/1000=PL推移!P10,"OK",PL推移!P10-月次PL!I8/1000),"nd") -> OK | R2: =IF(R10<>0,IF(月次PL!J8/1000=PL推移!R10,"OK",PL推移!R10-月次PL!J8/1000),"nd") -> OK | T2: =IF(T10<>0,IF(月次PL!K8/1000=PL推移!T10,"OK",PL推移!T10-月次PL!K8/1000),"nd") -> OK | V2: =IF(V10<>0,IF(月次PL!L8/1000=PL推移!V10,"OK",PL推移!V10-月次PL!L8/1000),"nd") -> OK | X2: =IF(X10<>0,IF(月次PL!M8/1000=PL推移!X10,"OK",PL推移!X10-月次PL!M8/1000),"nd") -> OK | Z2: =IF(Z10<>0,IF(月次PL!N8/1000=PL推移!Z10,"OK",PL推移!Z10-月次PL!N8/1000),"nd") -> OK
C3: 粗利益 | D3: =IF(D22<>0,IF(D22=月次PL!C16/1000,"OK",PL推移!D22-月次PL!C16/1000),"nd") -> OK | F3: =IF(F22<>0,IF(F22=月次PL!D16/1000,"OK",PL推移!F22-月次PL!D16/1000),"nd") -> OK | H3: =IF(H22<>0,IF(H22=月次PL!E16/1000,"OK",PL推移!H22-月次PL!E16/1000),"nd") -> OK | J3: =IF(J22<>0,IF(J22=月次PL!F16/1000,"OK",PL推移!J22-月次PL!F16/1000),"nd") -> OK | L3: =IF(L22<>0,IF(L22=月次PL!G16/1000,"OK",PL推移!L22-月次PL!G16/1000),"nd") -> OK | N3: =IF(N22<>0,IF(N22=月次PL!H16/1000,"OK",PL推移!N22-月次PL!H16/1000),"nd") -> OK | P3: =IF(P22<>0,IF(P22=月次PL!I16/1000,"OK",PL推移!P22-月次PL!I16/1000),"nd") -> OK | R3: =IF(R22<>0,IF(R22=月次PL!J16/1000,"OK",PL推移!R22-月次PL!J16/1000),"nd") -> OK | T3: =IF(T22<>0,IF(T22=月次PL!K16/1000,"OK",PL推移!T22-月次PL!K16/1000),"nd") -> OK | V3: =IF(V22<>0,IF(V22=月次PL!L16/1000,"OK",PL推移!V22-月次PL!L16/1000),"nd") -> OK | X3: =IF(X22<>0,IF(X22=月次PL!M16/1000,"OK",PL推移!X22-月次PL!M16/1000),"nd") -> OK | Z3: =IF(Z22<>0,IF(Z22=月次PL!N16/1000,"OK",PL推移!Z22-月次PL!N16/1000),"nd") -> OK
C4: 販管費 | D4: =IF(D28<>0,IF(D28=月次PL!C45/1000,"OK",PL推移!D28-月次PL!C45/1000),"nd") -> OK | F4: =IF(F28<>0,IF(F28=月次PL!D45/1000,"OK",PL推移!F28-月次PL!D45/1000),"nd") -> OK | H4: =IF(H28<>0,IF(H28=月次PL!E45/1000,"OK",PL推移!H28-月次PL!E45/1000),"nd") -> OK | J4: =IF(J28<>0,IF(J28=月次PL!F45/1000,"OK",PL推移!J28-月次PL!F45/1000),"nd") -> OK | L4: =IF(L28<>0,IF(L28=月次PL!G45/1000,"OK",PL推移!L28-月次PL!G45/1000),"nd") -> OK | N4: =IF(N28<>0,IF(N28=月次PL!H45/1000,"OK",PL推移!N28-月次PL!H45/1000),"nd") -> OK | P4: =IF(P28<>0,IF(P28=月次PL!I45/1000,"OK",PL推移!P28-月次PL!I45/1000),"nd") -> OK | R4: =IF(R28<>0,IF(R28=月次PL!J45/1000,"OK",PL推移!R28-月次PL!J45/1000),"nd") -> OK | T4: =IF(T28<>0,IF(T28=月次PL!K45/1000,"OK",PL推移!T28-月次PL!K45/1000),"nd") -> OK | V4: =IF(V28<>0,IF(V28=月次PL!L45/1000,"OK",PL推移!V28-月次PL!L45/1000),"nd") -> OK | X4: =IF(X28<>0,IF(X28=月次PL!M45/1000,"OK",PL推移!X28-月次PL!M45/1000),"nd") -> OK | Z4: =IF(Z28<>0,IF(Z28=月次PL!N45/1000,"OK",PL推移!Z28-月次PL!N45/1000),"nd") -> OK
C5: 営業利益 | D5: =IF(D50<>0,IF(D50=月次PL!C46/1000,"OK",PL推移!D50-月次PL!C46/1000),"nd") -> OK | F5: =IF(F50<>0,IF(F50=月次PL!D46/1000,"OK",PL推移!F50-月次PL!D46/1000),"nd") -> -1.7763568e-14 | H5: =IF(H50<>0,IF(H50=月次PL!E46/1000,"OK",PL推移!H50-月次PL!E46/1000),"nd") -> OK | J5: =IF(J50<>0,IF(J50=月次PL!F46/1000,"OK",PL推移!J50-月次PL!F46/1000),"nd") -> OK | L5: =IF(L50<>0,IF(L50=月次PL!G46/1000,"OK",PL推移!L50-月次PL!G46/1000),"nd") -> OK | N5: =IF(N50<>0,IF(N50=月次PL!H46/1000,"OK",PL推移!N50-月次PL!H46/1000),"nd") -> OK | P5: =IF(P50<>0,IF(P50=月次PL!I46/1000,"OK",PL推移!P50-月次PL!I46/1000),"nd") -> OK | R5: =IF(R50<>0,IF(R50=月次PL!J46/1000,"OK",PL推移!R50-月次PL!J46/1000),"nd") -> 9.2370556e-14 | T5: =IF(T50<>0,IF(T50=月次PL!K46/1000,"OK",PL推移!T50-月次PL!K46/1000),"nd") -> 1.4210855e-13 | V5: =IF(V50<>0,IF(V50=月次PL!L46/1000,"OK",PL推移!V50-月次PL!L46/1000),"nd") -> OK | X5: =IF(X50<>0,IF(X50=月次PL!M46/1000,"OK",PL推移!X50-月次PL!M46/1000),"nd") -> OK | Z5: =IF(Z50<>0,IF(Z50=月次PL!N46/1000,"OK",PL推移!Z50-月次PL!N46/1000),"nd") -> OK
C6: 経常利益 | D6: =IF(D54<>0,IF(D54=月次PL!C57/1000,"OK",PL推移!D54-月次PL!C57/1000),"nd") -> OK | F6: =IF(F54<>0,IF(F54=月次PL!D57/1000,"OK",PL推移!F54-月次PL!D57/1000),"nd") -> OK | H6: =IF(H54<>0,IF(H54=月次PL!E57/1000,"OK",PL推移!H54-月次PL!E57/1000),"nd") -> OK | J6: =IF(J54<>0,IF(J54=月次PL!F57/1000,"OK",PL推移!J54-月次PL!F57/1000),"nd") -> OK | L6: =IF(L54<>0,IF(L54=月次PL!G57/1000,"OK",PL推移!L54-月次PL!G57/1000),"nd") -> OK | N6: =IF(N54<>0,IF(N54=月次PL!H57/1000,"OK",PL推移!N54-月次PL!H57/1000),"nd") -> OK | P6: =IF(P54<>0,IF(P54=月次PL!I57/1000,"OK",PL推移!P54-月次PL!I57/1000),"nd") -> OK | R6: =IF(R54<>0,IF(R54=月次PL!J57/1000,"OK",PL推移!R54-月次PL!J57/1000),"nd") -> 8.5265128e-14 | T6: =IF(T54<>0,IF(T54=月次PL!K57/1000,"OK",PL推移!T54-月次PL!K57/1000),"nd") -> 1.4210855e-13 | V6: =IF(V54<>0,IF(V54=月次PL!L57/1000,"OK",PL推移!V54-月次PL!L57/1000),"nd") -> OK | X6: =IF(X54<>0,IF(X54=月次PL!M57/1000,"OK",PL推移!X54-月次PL!M57/1000),"nd") -> OK | Z6: =IF(Z54<>0,IF(Z54=月次PL!N57/1000,"OK",PL推移!Z54-月次PL!N57/1000),"nd") -> OK
B7: ■月次報告PL | D7: ㈱Ｓクリエイト | AH7: 注意事項 | AI7: 概算値 | AJ7: 異常値 | AK7: 特記事項 | AL7: 予算検討
B8: 2025 | C8: 年度 | D8: 単位：千円 | F8: 注意事項 | G8: 概算値 | H8: 異常値 | I8: 処理検討 | J8: 予算検討
B9: 項目 | D9: =+月次PL!C1 -> 7 | F9: =+月次PL!D1 -> 8 | H9: =+月次PL!E1 -> 9 | J9: =+月次PL!F1 -> 10 | L9: =+月次PL!G1 -> 11 | N9: =+月次PL!H1 -> 12 | P9: =+月次PL!I1 -> 1 | R9: =+月次PL!J1 -> 2 | T9: =+月次PL!K1 -> 3 | V9: =+月次PL!L1 -> 4 | X9: =+月次PL!M1 -> 5 | Z9: =+月次PL!N1 -> 6
B10: 売上高 | D10: =+月次PL!C8/1000 -> 622.833 | E10: =IF(D$10<>0,D10/D$10,0) -> 1 | F10: =+月次PL!D8/1000 -> 559.842 | G10: =IF(F$10<>0,F10/F$10,0) -> 1 | H10: =+月次PL!E8/1000 -> 571.656 | I10: =IF(H$10<>0,H10/H$10,0) -> 1 | J10: =+月次PL!F8/1000 -> 571.68 | K10: =IF(J$10<>0,J10/J$10,0) -> 1 | L10: =SUM(L11:L15) -> 482.542 | M10: =IF(L$10<>0,L10/L$10,0) -> 1 | N10: =SUM(N11:N15) -> 568.075 | O10: =IF(N$10<>0,N10/N$10,0) -> 1 | P10: =+月次PL!I8/1000 -> 573.045 | Q10: =IF(P$10<>0,P10/P$10,0) -> 1 | R10: =+月次PL!J8/1000 -> 566.158 | S10: =IF(R$10<>0,R10/R$10,0) -> 1 | T10: =+月次PL!K8/1000 -> 643.467 | U10: =IF(T$10<>0,T10/T$10,0) -> 1 | V10: =+月次PL!L3/1000 -> 1030.617 | W10: =IF(V$10<>0,V10/V$10,0) -> 1 | X10: =SUM(X11:X15) -> 890.404 | Y10: =IF(X$10<>0,X10/X$10,0) -> 1 | Z10: =+月次PL!N8/1000 -> 988.475 | AA10: =IF(Z$10<>0,Z10/Z$10,0) -> 1
C11: =+月次PL!B3 -> 売上高 | D11: =+月次PL!C3/1000 -> 622.833 | E11: =IF(D$10<>0,D11/D$10,0) -> 1 | F11: =+月次PL!D3/1000 -> 559.842 | G11: =IF(F$10<>0,F11/F$10,0) -> 1 | H11: =+月次PL!E3/1000 -> 571.656 | I11: =IF(H$10<>0,H11/H$10,0) -> 1 | J11: =+月次PL!F3/1000 -> 571.68 | K11: =IF(J$10<>0,J11/J$10,0) -> 1 | L11: =+月次PL!G3/1000 -> 482.542 | M11: =IF(L$10<>0,L11/L$10,0) -> 1 | N11: =+月次PL!H3/1000 -> 568.075 | O11: =IF(N$10<>0,N11/N$10,0) -> 1 | P11: =+月次PL!I3/1000 -> 573.045 | Q11: =IF(P$10<>0,P11/P$10,0) -> 1 | R11: =+月次PL!J3/1000 -> 566.158 | S11: =IF(R$10<>0,R11/R$10,0) -> 1 | T11: =+月次PL!K3/1000 -> 643.467 | U11: =IF(T$10<>0,T11/T$10,0) -> 1 | V11: =+月次PL!L8/1000 -> 1030.617 | W11: =IF(V$10<>0,V11/V$10,0) -> 1 | X11: =+月次PL!M3/1000 -> 890.404 | Y11: =IF(X$10<>0,X11/X$10,0) -> 1 | AA11: =IF(Z$10<>0,Z11/Z$10,0) -> 0
C12: =+月次PL!B4 -> 0 | D12: =+月次PL!C4/1000 -> 0 | E12: =IF(D$10<>0,D12/D$10,0) -> 0 | F12: =+月次PL!D4/1000 -> 0 | G12: =IF(F$10<>0,F12/F$10,0) -> 0 | H12: =+月次PL!E4/1000 -> 0 | I12: =IF(H$10<>0,H12/H$10,0) -> 0 | J12: =+月次PL!F4/1000 -> 0 | K12: =IF(J$10<>0,J12/J$10,0) -> 0 | L12: =+月次PL!G4/1000 -> 0 | M12: =IF(L$10<>0,L12/L$10,0) -> 0 | O12: =IF(N$10<>0,N12/N$10,0) -> 0 | Q12: =IF(P$10<>0,P12/P$10,0) -> 0 | S12: =IF(R$10<>0,R12/R$10,0) -> 0 | U12: =IF(T$10<>0,T12/T$10,0) -> 0 | W12: =IF(V$10<>0,V12/V$10,0) -> 0 | Y12: =IF(X$10<>0,X12/X$10,0) -> 0 | AA12: =IF(Z$10<>0,Z12/Z$10,0) -> 0
C13: =+月次PL!B5 -> 0 | D13: =+月次PL!C5/1000 -> 0 | E13: =IF(D$10<>0,D13/D$10,0) -> 0 | F13: =+月次PL!D5/1000 -> 0 | G13: =IF(F$10<>0,F13/F$10,0) -> 0 | H13: =+月次PL!E5/1000 -> 0 | I13: =IF(H$10<>0,H13/H$10,0) -> 0 | J13: =+月次PL!F5/1000 -> 0 | K13: =IF(J$10<>0,J13/J$10,0) -> 0 | L13: =+月次PL!G5/1000 -> 0 | M13: =IF(L$10<>0,L13/L$10,0) -> 0 | O13: =IF(N$10<>0,N13/N$10,0) -> 0 | Q13: =IF(P$10<>0,P13/P$10,0) -> 0 | S13: =IF(R$10<>0,R13/R$10,0) -> 0 | U13: =IF(T$10<>0,T13/T$10,0) -> 0 | W13: =IF(V$10<>0,V13/V$10,0) -> 0 | Y13: =IF(X$10<>0,X13/X$10,0) -> 0 | AA13: =IF(Z$10<>0,Z13/Z$10,0) -> 0
C14: =+月次PL!B6 -> 0 | D14: =+月次PL!C6/1000 -> 0 | E14: =IF(D$10<>0,D14/D$10,0) -> 0 | F14: =+月次PL!D6/1000 -> 0 | G14: =IF(F$10<>0,F14/F$10,0) -> 0 | H14: =+月次PL!E6/1000 -> 0 | I14: =IF(H$10<>0,H14/H$10,0) -> 0 | J14: =+月次PL!F6/1000 -> 0 | K14: =IF(J$10<>0,J14/J$10,0) -> 0 | L14: =+月次PL!G6/1000 -> 0 | M14: =IF(L$10<>0,L14/L$10,0) -> 0 | O14: =IF(N$10<>0,N14/N$10,0) -> 0 | Q14: =IF(P$10<>0,P14/P$10,0) -> 0 | S14: =IF(R$10<>0,R14/R$10,0) -> 0 | U14: =IF(T$10<>0,T14/T$10,0) -> 0 | W14: =IF(V$10<>0,V14/V$10,0) -> 0 | Y14: =IF(X$10<>0,X14/X$10,0) -> 0 | AA14: =IF(Z$10<>0,Z14/Z$10,0) -> 0
C15: =+月次PL!B7 -> 0 | D15: =+月次PL!C7/1000 -> 0 | E15: =IF(D$10<>0,D15/D$10,0) -> 0 | F15: =+月次PL!D7/1000 -> 0 | G15: =IF(F$10<>0,F15/F$10,0) -> 0 | H15: =+月次PL!E7/1000 -> 0 | I15: =IF(H$10<>0,H15/H$10,0) -> 0 | J15: =+月次PL!F7/1000 -> 0 | K15: =IF(J$10<>0,J15/J$10,0) -> 0 | L15: =+月次PL!G7/1000 -> 0 | M15: =IF(L$10<>0,L15/L$10,0) -> 0 | O15: =IF(N$10<>0,N15/N$10,0) -> 0 | Q15: =IF(P$10<>0,P15/P$10,0) -> 0 | S15: =IF(R$10<>0,R15/R$10,0) -> 0 | U15: =IF(T$10<>0,T15/T$10,0) -> 0 | W15: =IF(V$10<>0,V15/V$10,0) -> 0 | Y15: =IF(X$10<>0,X15/X$10,0) -> 0 | AA15: =IF(Z$10<>0,Z15/Z$10,0) -> 0
B16: 売上原価 | D16: =+月次PL!C15/1000 -> 0 | E16: =IF(D$10<>0,D16/D$10,0) -> 0 | F16: =+月次PL!D15/1000 -> 0 | G16: =IF(F$10<>0,F16/F$10,0) -> 0 | H16: =+月次PL!E15/1000 -> 0 | I16: =IF(H$10<>0,H16/H$10,0) -> 0 | J16: =+月次PL!F15/1000 -> 0 | K16: =IF(J$10<>0,J16/J$10,0) -> 0 | L16: =+月次PL!G15/1000 -> 0 | M16: =IF(L$10<>0,L16/L$10,0) -> 0 | N16: =+月次PL!H15/1000 -> 0 | O16: =IF(N$10<>0,N16/N$10,0) -> 0 | P16: =+月次PL!I15/1000 -> 0 | Q16: =IF(P$10<>0,P16/P$10,0) -> 0 | R16: =+月次PL!J15/1000 -> 0 | S16: =IF(R$10<>0,R16/R$10,0) -> 0 | T16: =+月次PL!K15/1000 -> 0 | U16: =IF(T$10<>0,T16/T$10,0) -> 0 | V16: =+月次PL!L15/1000 -> 0 | W16: =IF(V$10<>0,V16/V$10,0) -> 0 | X16: =+月次PL!M15/1000 -> 0 | Y16: =IF(X$10<>0,X16/X$10,0) -> 0 | Z16: =+月次PL!N15/1000 -> 0 | AA16: =IF(Z$10<>0,Z16/Z$10,0) -> 0
C17: =+月次PL!B10 -> 0 | D17: =+月次PL!C10/1000 -> 0 | E17: =IF(D11<>0,D17/D11,0) -> 0 | F17: =+月次PL!D10/1000 -> 0 | G17: =IF(F11<>0,F17/F11,0) -> 0 | H17: =+月次PL!E10/1000 -> 0 | I17: =IF(H11<>0,H17/H11,0) -> 0 | J17: =+月次PL!F10/1000 -> 0 | K17: =IF(J11<>0,J17/J11,0) -> 0 | L17: =+月次PL!G10/1000 -> 0 | M17: =IF(L11<>0,L17/L11,0) -> 0 | O17: =IF(N11<>0,N17/N11,0) -> 0 | Q17: =IF(P11<>0,P17/P11,0) -> 0 | S17: =IF(R11<>0,R17/R11,0) -> 0 | U17: =IF(T11<>0,T17/T11,0) -> 0 | W17: =IF(V11<>0,V17/V11,0) -> 0 | Y17: =IF(X11<>0,X17/X11,0) -> 0 | AA17: =IF(Z11<>0,Z17/Z11,0) -> 0
E18: =IF(D12<>0,D18/D12,0) -> 0 | G18: =IF(F12<>0,F18/F12,0) -> 0 | I18: =IF(H12<>0,H18/H12,0) -> 0 | K18: =IF(J12<>0,J18/J12,0) -> 0 | M18: =IF(L12<>0,L18/L12,0) -> 0 | O18: =IF(N12<>0,N18/N12,0) -> 0 | Q18: =IF(P12<>0,P18/P12,0) -> 0 | S18: =IF(R12<>0,R18/R12,0) -> 0 | U18: =IF(T12<>0,T18/T12,0) -> 0 | W18: =IF(V12<>0,V18/V12,0) -> 0 | Y18: =IF(X12<>0,X18/X12,0) -> 0 | AA18: =IF(Z12<>0,Z18/Z12,0) -> 0
E19: =IF(D13<>0,D19/D13,0) -> 0 | G19: =IF(F13<>0,F19/F13,0) -> 0 | I19: =IF(H13<>0,H19/H13,0) -> 0 | K19: =IF(J13<>0,J19/J13,0) -> 0 | M19: =IF(L13<>0,L19/L13,0) -> 0 | O19: =IF(N13<>0,N19/N13,0) -> 0 | Q19: =IF(P13<>0,P19/P13,0) -> 0 | S19: =IF(R13<>0,R19/R13,0) -> 0 | U19: =IF(T13<>0,T19/T13,0) -> 0 | W19: =IF(V13<>0,V19/V13,0) -> 0 | Y19: =IF(X13<>0,X19/X13,0) -> 0 | AA19: =IF(Z13<>0,Z19/Z13,0) -> 0
E20: =IF(D14<>0,D20/D14,0) -> 0 | G20: =IF(F14<>0,F20/F14,0) -> 0 | I20: =IF(H14<>0,H20/H14,0) -> 0 | K20: =IF(J14<>0,J20/J14,0) -> 0 | M20: =IF(L14<>0,L20/L14,0) -> 0 | O20: =IF(N14<>0,N20/N14,0) -> 0 | Q20: =IF(P14<>0,P20/P14,0) -> 0 | S20: =IF(R14<>0,R20/R14,0) -> 0 | U20: =IF(T14<>0,T20/T14,0) -> 0 | W20: =IF(V14<>0,V20/V14,0) -> 0 | Y20: =IF(X14<>0,X20/X14,0) -> 0 | AA20: =IF(Z14<>0,Z20/Z14,0) -> 0
E21: =IF(D15<>0,D21/D15,0) -> 0 | G21: =IF(F15<>0,F21/F15,0) -> 0 | I21: =IF(H15<>0,H21/H15,0) -> 0 | K21: =IF(J15<>0,J21/J15,0) -> 0 | M21: =IF(L15<>0,L21/L15,0) -> 0 | O21: =IF(N15<>0,N21/N15,0) -> 0 | Q21: =IF(P15<>0,P21/P15,0) -> 0 | S21: =IF(R15<>0,R21/R15,0) -> 0 | U21: =IF(T15<>0,T21/T15,0) -> 0 | W21: =IF(V15<>0,V21/V15,0) -> 0 | Y21: =IF(X15<>0,X21/X15,0) -> 0 | AA21: =IF(Z15<>0,Z21/Z15,0) -> 0
B22: 粗利益 | D22: =+D10-D16 -> 622.833 | E22: =IF(D$10<>0,D22/D$10,0) -> 1 | F22: =+F10-F16 -> 559.842 | G22: =IF(F$10<>0,F22/F$10,0) -> 1 | H22: =+H10-H16 -> 571.656 | I22: =IF(H$10<>0,H22/H$10,0) -> 1 | J22: =+J10-J16 -> 571.68 | K22: =IF(J$10<>0,J22/J$10,0) -> 1 | L22: =+L10-L16 -> 482.542 | M22: =IF(L$10<>0,L22/L$10,0) -> 1 | N22: =+N10-N16 -> 568.075 | O22: =IF(N$10<>0,N22/N$10,0) -> 1 | P22: =+P10-P16 -> 573.045 | Q22: =IF(P$10<>0,P22/P$10,0) -> 1 | R22: =+R10-R16 -> 566.158 | S22: =IF(R$10<>0,R22/R$10,0) -> 1 | T22: =+T10-T16 -> 643.467 | U22: =IF(T$10<>0,T22/T$10,0) -> 1 | V22: =+V10-V16 -> 1030.617 | W22: =IF(V$10<>0,V22/V$10,0) -> 1 | X22: =+X10-X16 -> 890.404 | Y22: =IF(X$10<>0,X22/X$10,0) -> 1 | Z22: =+Z10-Z16 -> 988.475 | AA22: =IF(Z$10<>0,Z22/Z$10,0) -> 1
E23: =IF(D11<>0,D23/D11,0) -> 0 | F23: =+F11-F17 -> 559.842 | G23: =IF(F11<>0,F23/F11,0) -> 1 | H23: =+H11-H17 -> 571.656 | I23: =IF(H11<>0,H23/H11,0) -> 1 | J23: =+J11-J17 -> 571.68 | K23: =IF(J11<>0,J23/J11,0) -> 1 | L23: =+L11-L17 -> 482.542 | M23: =IF(L11<>0,L23/L11,0) -> 1 | N23: =+N11-N17 -> 568.075 | O23: =IF(N11<>0,N23/N11,0) -> 1 | P23: =+P11-P17 -> 573.045 | Q23: =IF(P11<>0,P23/P11,0) -> 1 | R23: =+R11-R17 -> 566.158 | S23: =IF(R11<>0,R23/R11,0) -> 1 | T23: =+T11-T17 -> 643.467 | U23: =IF(T11<>0,T23/T11,0) -> 1 | V23: =+V11-V17 -> 1030.617 | W23: =IF(V11<>0,V23/V11,0) -> 1 | X23: =+X11-X17 -> 890.404 | Y23: =IF(X11<>0,X23/X11,0) -> 1 | Z23: =+Z11-Z17 -> 0 | AA23: =IF(Z11<>0,Z23/Z11,0) -> 0
E24: =IF(D12<>0,D24/D12,0) -> 0 | F24: =+F12-F18 -> 0 | G24: =IF(F12<>0,F24/F12,0) -> 0 | H24: =+H12-H18 -> 0 | I24: =IF(H12<>0,H24/H12,0) -> 0 | J24: =+J12-J18 -> 0 | K24: =IF(J12<>0,J24/J12,0) -> 0 | L24: =+L12-L18 -> 0 | M24: =IF(L12<>0,L24/L12,0) -> 0 | N24: =+N12-N18 -> 0 | O24: =IF(N12<>0,N24/N12,0) -> 0 | P24: =+P12-P18 -> 0 | Q24: =IF(P12<>0,P24/P12,0) -> 0 | R24: =+R12-R18 -> 0 | S24: =IF(R12<>0,R24/R12,0) -> 0 | T24: =+T12-T18 -> 0 | U24: =IF(T12<>0,T24/T12,0) -> 0 | V24: =+V12-V18 -> 0 | W24: =IF(V12<>0,V24/V12,0) -> 0 | X24: =+X12-X18 -> 0 | Y24: =IF(X12<>0,X24/X12,0) -> 0 | Z24: =+Z12-Z18 -> 0 | AA24: =IF(Z12<>0,Z24/Z12,0) -> 0
E25: =IF(D13<>0,D25/D13,0) -> 0 | F25: =+F13-F19 -> 0 | G25: =IF(F13<>0,F25/F13,0) -> 0 | H25: =+H13-H19 -> 0 | I25: =IF(H13<>0,H25/H13,0) -> 0 | J25: =+J13-J19 -> 0 | K25: =IF(J13<>0,J25/J13,0) -> 0 | L25: =+L13-L19 -> 0 | M25: =IF(L13<>0,L25/L13,0) -> 0 | N25: =+N13-N19 -> 0 | O25: =IF(N13<>0,N25/N13,0) -> 0 | P25: =+P13-P19 -> 0 | Q25: =IF(P13<>0,P25/P13,0) -> 0 | R25: =+R13-R19 -> 0 | S25: =IF(R13<>0,R25/R13,0) -> 0 | T25: =+T13-T19 -> 0 | U25: =IF(T13<>0,T25/T13,0) -> 0 | V25: =+V13-V19 -> 0 | W25: =IF(V13<>0,V25/V13,0) -> 0 | X25: =+X13-X19 -> 0 | Y25: =IF(X13<>0,X25/X13,0) -> 0 | Z25: =+Z13-Z19 -> 0 | AA25: =IF(Z13<>0,Z25/Z13,0) -> 0
E26: =IF(D14<>0,D26/D14,0) -> 0 | F26: =+F14-F20 -> 0 | G26: =IF(F14<>0,F26/F14,0) -> 0 | H26: =+H14-H20 -> 0 | I26: =IF(H14<>0,H26/H14,0) -> 0 | J26: =+J14-J20 -> 0 | K26: =IF(J14<>0,J26/J14,0) -> 0 | L26: =+L14-L20 -> 0 | M26: =IF(L14<>0,L26/L14,0) -> 0 | N26: =+N14-N20 -> 0 | O26: =IF(N14<>0,N26/N14,0) -> 0 | P26: =+P14-P20 -> 0 | Q26: =IF(P14<>0,P26/P14,0) -> 0 | R26: =+R14-R20 -> 0 | S26: =IF(R14<>0,R26/R14,0) -> 0 | T26: =+T14-T20 -> 0 | U26: =IF(T14<>0,T26/T14,0) -> 0 | V26: =+V14-V20 -> 0 | W26: =IF(V14<>0,V26/V14,0) -> 0 | X26: =+X14-X20 -> 0 | Y26: =IF(X14<>0,X26/X14,0) -> 0 | Z26: =+Z14-Z20 -> 0 | AA26: =IF(Z14<>0,Z26/Z14,0) -> 0
E27: =IF(D15<>0,D27/D15,0) -> 0 | F27: =+F15-F21 -> 0 | G27: =IF(F15<>0,F27/F15,0) -> 0 | H27: =+H15-H21 -> 0 | I27: =IF(H15<>0,H27/H15,0) -> 0 | J27: =+J15-J21 -> 0 | K27: =IF(J15<>0,J27/J15,0) -> 0 | L27: =+L15-L21 -> 0 | M27: =IF(L15<>0,L27/L15,0) -> 0 | N27: =+N15-N21 -> 0 | O27: =IF(N15<>0,N27/N15,0) -> 0 | P27: =+P15-P21 -> 0 | Q27: =IF(P15<>0,P27/P15,0) -> 0 | R27: =+R15-R21 -> 0 | S27: =IF(R15<>0,R27/R15,0) -> 0 | T27: =+T15-T21 -> 0 | U27: =IF(T15<>0,T27/T15,0) -> 0 | V27: =+V15-V21 -> 0 | W27: =IF(V15<>0,V27/V15,0) -> 0 | X27: =+X15-X21 -> 0 | Y27: =IF(X15<>0,X27/X15,0) -> 0 | Z27: =+Z15-Z21 -> 0 | AA27: =IF(Z15<>0,Z27/Z15,0) -> 0
B28: 販売管理費 | D28: =SUM(D29:D49) -> 898.203 | E28: =IF(D$10<>0,D28/D$10,0) -> 1.4421249 | F28: =SUM(F29:F49) -> 567.923 | G28: =IF(F$10<>0,F28/F$10,0) -> 1.0144344 | H28: =SUM(H29:H49) -> 654.4 | I28: =IF(H$10<>0,H28/H$10,0) -> 1.1447444 | J28: =SUM(J29:J49) -> 724.991 | K28: =IF(J$10<>0,J28/J$10,0) -> 1.2681763 | L28: =SUM(L29:L49) -> 525.203 | M28: =IF(L$10<>0,L28/L$10,0) -> 1.0884089 | N28: =SUM(N29:N49) -> 694.978 | O28: =IF(N$10<>0,N28/N$10,0) -> 1.2233913 | P28: =SUM(P29:P49) -> 674.115 | Q28: =IF(P$10<>0,P28/P$10,0) -> 1.1763736 | R28: =SUM(R29:R49) -> 624.407 | S28: =IF(R$10<>0,R28/R$10,0) -> 1.1028847 | T28: =SUM(T29:T49) -> 654.598 | U28: =IF(T$10<>0,T28/T$10,0) -> 1.0172985 | V28: =SUM(V29:V49) -> 601.291 | W28: =IF(V$10<>0,V28/V$10,0) -> 0.58342818 | X28: =SUM(X29:X49) -> 676.189 | Y28: =IF(X$10<>0,X28/X$10,0) -> 0.7594182 | Z28: =SUM(Z29:Z49) -> 661.641 | AA28: =IF(Z$10<>0,Z28/Z$10,0) -> 0.66935532
C29: 人件費 | D29: =SUM(月次PL!C18:C25)/1000 -> 535.456 | E29: =IF(D$10<>0,D29/D$10,0) -> 0.85971039 | F29: =SUM(月次PL!D18:D25)/1000 -> 331.819 | G29: =IF(F$10<>0,F29/F$10,0) -> 0.59270115 | H29: =SUM(月次PL!E18:E25)/1000 -> 331.819 | I29: =IF(H$10<>0,H29/H$10,0) -> 0.58045223 | J29: =SUM(月次PL!F18:F25)/1000 -> 331.819 | K29: =IF(J$10<>0,J29/J$10,0) -> 0.58042786 | L29: =SUM(月次PL!G18:G25)/1000 -> 331.819 | M29: =IF(L$10<>0,L29/L$10,0) -> 0.68764791 | N29: =SUM(月次PL!H18:H25)/1000 -> 331.819 | O29: =IF(N$10<>0,N29/N$10,0) -> 0.58411125 | P29: =SUM(月次PL!I18:I25)/1000 -> 331.819 | Q29: =IF(P$10<>0,P29/P$10,0) -> 0.57904528 | R29: =SUM(月次PL!J18:J25)/1000 -> 331.819 | S29: =IF(R$10<>0,R29/R$10,0) -> 0.58608904 | T29: =SUM(月次PL!K18:K25)/1000 -> 331.819 | U29: =IF(T$10<>0,T29/T$10,0) -> 0.51567369 | V29: =SUM(月次PL!L18:L25)/1000 -> 331.819 | W29: =IF(V$10<>0,V29/V$10,0) -> 0.3219615 | X29: =SUM(月次PL!M18:M25)/1000 -> 331.819 | Y29: =IF(X$10<>0,X29/X$10,0) -> 0.37266117 | Z29: =SUM(月次PL!N18:N25)/1000 -> 331.819 | AA29: =IF(Z$10<>0,Z29/Z$10,0) -> 0.3356878
C30: 旅費交通費 | D30: =+月次PL!C28/1000 -> 9.72 | E30: =IF(D$10<>0,D30/D$10,0) -> 0.01560611 | F30: =+月次PL!D28/1000 -> 5.371 | G30: =IF(F$10<>0,F30/F$10,0) -> 0.0095937782 | H30: =+月次PL!E28/1000 -> 8.966 | I30: =IF(H$10<>0,H30/H$10,0) -> 0.015684258 | J30: =+月次PL!F28/1000 -> 74.104 | K30: =IF(J$10<>0,J30/J$10,0) -> 0.12962497 | L30: =+月次PL!G28/1000 -> 6.693 | M30: =IF(L$10<>0,L30/L$10,0) -> 0.013870295 | N30: =+月次PL!H28/1000 -> 1.928 | O30: =IF(N$10<>0,N30/N$10,0) -> 0.0033939181 | P30: =+月次PL!I28/1000 -> 101.043 | Q30: =IF(P$10<>0,P30/P$10,0) -> 0.17632647 | R30: =+月次PL!J28/1000 -> 5.547 | S30: =IF(R$10<>0,R30/R$10,0) -> 0.0097976183 | T30: =+月次PL!K28/1000 -> 1.091 | U30: =IF(T$10<>0,T30/T$10,0) -> 0.0016955026 | V30: =+月次PL!L28/1000 -> 0 | W30: =IF(V$10<>0,V30/V$10,0) -> 0 | X30: =+月次PL!M28/1000 -> 57.464 | Y30: =IF(X$10<>0,X30/X$10,0) -> 0.064536997 | Z30: =+月次PL!N28/1000 -> 24.862 | AA30: =IF(Z$10<>0,Z30/Z$10,0) -> 0.025151875
C31: 通信費 | D31: =+月次PL!C29/1000 -> 1.2 | E31: =IF(D$10<>0,D31/D$10,0) -> 0.0019266802 | F31: =+月次PL!D29/1000 -> 55.56 | G31: =IF(F$10<>0,F31/F$10,0) -> 0.099242286 | H31: =+月次PL!E29/1000 -> 54.96 | I31: =IF(H$10<>0,H31/H$10,0) -> 0.096141736 | J31: =+月次PL!F29/1000 -> 1.2 | K31: =IF(J$10<>0,J31/J$10,0) -> 0.0020990764 | L31: =+月次PL!G29/1000 -> 1.2 | M31: =IF(L$10<>0,L31/L$10,0) -> 0.0024868302 | N31: =+月次PL!H29/1000 -> 78.96 | O31: =IF(N$10<>0,N31/N$10,0) -> 0.13899573 | P31: =+月次PL!I29/1000 -> 3.837 | Q31: =IF(P$10<>0,P31/P$10,0) -> 0.0066958092 | R31: =+月次PL!J29/1000 -> 57.597 | S31: =IF(R$10<>0,R31/R$10,0) -> 0.10173309 | T31: =+月次PL!K29/1000 -> 18.513 | U31: =IF(T$10<>0,T31/T$10,0) -> 0.028770706 | V31: =+月次PL!L29/1000 -> 27.326 | W31: =IF(V$10<>0,V31/V$10,0) -> 0.026514214 | X31: =+月次PL!M29/1000 -> 71.599 | Y31: =IF(X$10<>0,X31/X$10,0) -> 0.080411813 | Z31: =+月次PL!N29/1000 -> 62.331 | AA31: =IF(Z$10<>0,Z31/Z$10,0) -> 0.06305774
C32: 市場調査費 | D32: =+月次PL!C44/1000 -> 140 | E32: =IF(D$10<>0,D32/D$10,0) -> 0.22477935 | F32: =+月次PL!D44/1000 -> 14.004 | G32: =IF(F$10<>0,F32/F$10,0) -> 0.0250142 | H32: =+月次PL!E44/1000 -> 42.383 | I32: =IF(H$10<>0,H32/H$10,0) -> 0.074140742 | J32: =+月次PL!F44/1000 -> 0 | K32: =IF(J$10<>0,J32/J$10,0) -> 0 | L32: =+月次PL!G44/1000 -> 0 | M32: =IF(L$10<>0,L32/L$10,0) -> 0 | N32: =+月次PL!H44/1000 -> 0 | O32: =IF(N$10<>0,N32/N$10,0) -> 0 | P32: =+月次PL!I44/1000 -> 0 | Q32: =IF(P$10<>0,P32/P$10,0) -> 0 | R32: =+月次PL!J44/1000 -> 0 | S32: =IF(R$10<>0,R32/R$10,0) -> 0 | T32: =+月次PL!K44/1000 -> 0 | U32: =IF(T$10<>0,T32/T$10,0) -> 0 | V32: =+月次PL!L44/1000 -> 0 | W32: =IF(V$10<>0,V32/V$10,0) -> 0 | X32: =+月次PL!M44/1000 -> 0 | Y32: =IF(X$10<>0,X32/X$10,0) -> 0 | Z32: =+月次PL!N44/1000 -> 0 | AA32: =IF(Z$10<>0,Z32/Z$10,0) -> 0
C33: 交際費 | D33: =+月次PL!C27/1000 -> 13.438 | E33: =IF(D$10<>0,D33/D$10,0) -> 0.021575607 | F33: =+月次PL!D27/1000 -> 50.137 | G33: =IF(F$10<>0,F33/F$10,0) -> 0.089555625 | H33: =+月次PL!E27/1000 -> 103.9 | I33: =IF(H$10<>0,H33/H$10,0) -> 0.18175266 | J33: =+月次PL!F27/1000 -> 12.119 | K33: =IF(J$10<>0,J33/J$10,0) -> 0.021198922 | L33: =+月次PL!G27/1000 -> 30 | M33: =IF(L$10<>0,L33/L$10,0) -> 0.062170754 | N33: =+月次PL!H27/1000 -> 158.371 | O33: =IF(N$10<>0,N33/N$10,0) -> 0.27878537 | P33: =+月次PL!I27/1000 -> 87.515 | Q33: =IF(P$10<>0,P33/P$10,0) -> 0.15271925 | R33: =+月次PL!J27/1000 -> 113.663 | S33: =IF(R$10<>0,R33/R$10,0) -> 0.20076198 | T33: =+月次PL!K27/1000 -> 172.618 | U33: =IF(T$10<>0,T33/T$10,0) -> 0.2682624 | V33: =+月次PL!L27/1000 -> 89.768 | W33: =IF(V$10<>0,V33/V$10,0) -> 0.087101222 | X33: =+月次PL!M27/1000 -> 95.002 | Y33: =IF(X$10<>0,X33/X$10,0) -> 0.10669539 | Z33: =+月次PL!N27/1000 -> 111.724 | AA33: =IF(Z$10<>0,Z33/Z$10,0) -> 0.11302663
C34: 会議費 | D34: =+月次PL!C39/1000 -> 84.497 | E34: =IF(D$10<>0,D34/D$10,0) -> 0.13566558 | F34: =+月次PL!D39/1000 -> 10.447 | G34: =IF(F$10<>0,F34/F$10,0) -> 0.018660622 | H34: =+月次PL!E39/1000 -> 11.637 | I34: =IF(H$10<>0,H34/H$10,0) -> 0.020356648 | J34: =+月次PL!F39/1000 -> 67.568 | K34: =IF(J$10<>0,J34/J$10,0) -> 0.118192 | L34: =+月次PL!G39/1000 -> 49.291 | M34: =IF(L$10<>0,L34/L$10,0) -> 0.10214862 | N34: =+月次PL!H39/1000 -> 22.016 | O34: =IF(N$10<>0,N34/N$10,0) -> 0.038755446 | P34: =+月次PL!I39/1000 -> 45.376 | Q34: =IF(P$10<>0,P34/P$10,0) -> 0.079184008 | R34: =+月次PL!J39/1000 -> 13.067 | S34: =IF(R$10<>0,R34/R$10,0) -> 0.02308013 | T34: =+月次PL!K39/1000 -> 27.771 | U34: =IF(T$10<>0,T34/T$10,0) -> 0.04315839 | V34: =+月次PL!L39/1000 -> 13.158 | W34: =IF(V$10<>0,V34/V$10,0) -> 0.012767109 | X34: =+月次PL!M39/1000 -> 10.469 | Y34: =IF(X$10<>0,X34/X$10,0) -> 0.011757584 | Z34: =+月次PL!N39/1000 -> 27.614 | AA34: =IF(Z$10<>0,Z34/Z$10,0) -> 0.027935962
C35: 減価償却費 | D35: =+月次PL!C41/1000 -> 26.5 | E35: =IF(D$10<>0,D35/D$10,0) -> 0.042547521 | F35: =+月次PL!D41/1000 -> 26.5 | G35: =IF(F$10<>0,F35/F$10,0) -> 0.047334784 | H35: =+月次PL!E41/1000 -> 26.5 | I35: =IF(H$10<>0,H35/H$10,0) -> 0.04635655 | J35: =+月次PL!F41/1000 -> 26.5 | K35: =IF(J$10<>0,J35/J$10,0) -> 0.046354604 | L35: =+月次PL!G41/1000 -> 26.5 | M35: =IF(L$10<>0,L35/L$10,0) -> 0.054917499 | N35: =+月次PL!H41/1000 -> 26.5 | O35: =IF(N$10<>0,N35/N$10,0) -> 0.04664877 | P35: =+月次PL!I41/1000 -> 26.5 | Q35: =IF(P$10<>0,P35/P$10,0) -> 0.046244187 | R35: =+月次PL!J41/1000 -> 26.5 | S35: =IF(R$10<>0,R35/R$10,0) -> 0.046806722 | T35: =+月次PL!K41/1000 -> 26.5 | U35: =IF(T$10<>0,T35/T$10,0) -> 0.041183153 | V35: =+月次PL!L41/1000 -> 26.5 | W35: =IF(V$10<>0,V35/V$10,0) -> 0.025712753 | X35: =+月次PL!M41/1000 -> 26.5 | Y35: =IF(X$10<>0,X35/X$10,0) -> 0.029761771 | Z35: =+月次PL!N41/1000 -> 26.5 | AA35: =IF(Z$10<>0,Z35/Z$10,0) -> 0.026808973
C36: 賃借料 | D36: =+月次PL!C35/1000 -> 0 | E36: =IF(D$10<>0,D36/D$10,0) -> 0 | F36: =+月次PL!D35/1000 -> 0 | G36: =IF(F$10<>0,F36/F$10,0) -> 0 | H36: =+月次PL!E35/1000 -> 0 | I36: =IF(H$10<>0,H36/H$10,0) -> 0 | J36: =+月次PL!F35/1000 -> 0 | K36: =IF(J$10<>0,J36/J$10,0) -> 0 | L36: =+月次PL!G35/1000 -> 0 | M36: =IF(L$10<>0,L36/L$10,0) -> 0 | N36: =+月次PL!H35/1000 -> 0 | O36: =IF(N$10<>0,N36/N$10,0) -> 0 | P36: =+月次PL!I35/1000 -> 0 | Q36: =IF(P$10<>0,P36/P$10,0) -> 0 | R36: =+月次PL!J35/1000 -> 0 | S36: =IF(R$10<>0,R36/R$10,0) -> 0 | T36: =+月次PL!K35/1000 -> 0 | U36: =IF(T$10<>0,T36/T$10,0) -> 0 | V36: =+月次PL!L35/1000 -> 0 | W36: =IF(V$10<>0,V36/V$10,0) -> 0 | X36: =+月次PL!M35/1000 -> 0 | Y36: =IF(X$10<>0,X36/X$10,0) -> 0 | Z36: =+月次PL!N35/1000 -> 0 | AA36: =IF(Z$10<>0,Z36/Z$10,0) -> 0
C37: 地代家賃 | D37: =+月次PL!C34/1000 -> 44.5 | E37: =IF(D$10<>0,D37/D$10,0) -> 0.071447724 | F37: =+月次PL!D34/1000 -> 44.5 | G37: =IF(F$10<>0,F37/F$10,0) -> 0.079486712 | H37: =+月次PL!E34/1000 -> 44.5 | I37: =IF(H$10<>0,H37/H$10,0) -> 0.077844018 | J37: =+月次PL!F34/1000 -> 44.5 | K37: =IF(J$10<>0,J37/J$10,0) -> 0.07784075 | L37: =+月次PL!G34/1000 -> 44.5 | M37: =IF(L$10<>0,L37/L$10,0) -> 0.092219952 | N37: =+月次PL!H34/1000 -> 44.5 | O37: =IF(N$10<>0,N37/N$10,0) -> 0.078334727 | P37: =+月次PL!I34/1000 -> 44.5 | Q37: =IF(P$10<>0,P37/P$10,0) -> 0.077655332 | R37: =+月次PL!J34/1000 -> 44.5 | S37: =IF(R$10<>0,R37/R$10,0) -> 0.078599967 | T37: =+月次PL!K34/1000 -> 44.5 | U37: =IF(T$10<>0,T37/T$10,0) -> 0.069156616 | V37: =+月次PL!L34/1000 -> 44.5 | W37: =IF(V$10<>0,V37/V$10,0) -> 0.043178019 | X37: =+月次PL!M34/1000 -> 44.5 | Y37: =IF(X$10<>0,X37/X$10,0) -> 0.049977314 | Z37: =+月次PL!N34/1000 -> 44.5 | AA37: =IF(Z$10<>0,Z37/Z$10,0) -> 0.045018842
C38: リース料 | D38: =+月次PL!C33/1000 -> 0 | E38: =IF(D$10<>0,D38/D$10,0) -> 0 | F38: =+月次PL!D33/1000 -> 0 | G38: =IF(F$10<>0,F38/F$10,0) -> 0 | H38: =+月次PL!E33/1000 -> 0 | I38: =IF(H$10<>0,H38/H$10,0) -> 0 | J38: =+月次PL!F33/1000 -> 0 | K38: =IF(J$10<>0,J38/J$10,0) -> 0 | L38: =+月次PL!G33/1000 -> 0 | M38: =IF(L$10<>0,L38/L$10,0) -> 0 | N38: =+月次PL!H33/1000 -> 0 | O38: =IF(N$10<>0,N38/N$10,0) -> 0 | P38: =+月次PL!I33/1000 -> 0 | Q38: =IF(P$10<>0,P38/P$10,0) -> 0 | R38: =+月次PL!J33/1000 -> 0 | S38: =IF(R$10<>0,R38/R$10,0) -> 0 | T38: =+月次PL!K33/1000 -> 0 | U38: =IF(T$10<>0,T38/T$10,0) -> 0 | V38: =+月次PL!L33/1000 -> 0 | W38: =IF(V$10<>0,V38/V$10,0) -> 0 | X38: =+月次PL!M33/1000 -> 0 | Y38: =IF(X$10<>0,X38/X$10,0) -> 0 | Z38: =+月次PL!N33/1000 -> 0 | AA38: =IF(Z$10<>0,Z38/Z$10,0) -> 0
C39: 修繕費 | D39: =+月次PL!C31/1000 -> 0 | E39: =IF(D$10<>0,D39/D$10,0) -> 0 | F39: =+月次PL!D31/1000 -> 0 | G39: =IF(F$10<>0,F39/F$10,0) -> 0 | H39: =+月次PL!E31/1000 -> 0 | I39: =IF(H$10<>0,H39/H$10,0) -> 0 | J39: =+月次PL!F31/1000 -> 0 | K39: =IF(J$10<>0,J39/J$10,0) -> 0 | L39: =+月次PL!G31/1000 -> 0 | M39: =IF(L$10<>0,L39/L$10,0) -> 0 | N39: =+月次PL!H31/1000 -> 0 | O39: =IF(N$10<>0,N39/N$10,0) -> 0 | P39: =+月次PL!I31/1000 -> 0 | Q39: =IF(P$10<>0,P39/P$10,0) -> 0 | R39: =+月次PL!J31/1000 -> 0 | S39: =IF(R$10<>0,R39/R$10,0) -> 0 | T39: =+月次PL!K31/1000 -> 0 | U39: =IF(T$10<>0,T39/T$10,0) -> 0 | V39: =+月次PL!L31/1000 -> 0 | W39: =IF(V$10<>0,V39/V$10,0) -> 0 | X39: =+月次PL!M31/1000 -> 0 | Y39: =IF(X$10<>0,X39/X$10,0) -> 0 | Z39: =+月次PL!N31/1000 -> 0 | AA39: =IF(Z$10<>0,Z39/Z$10,0) -> 0
C40: 保険料 | D40: =+月次PL!C36/1000 -> 5 | E40: =IF(D$10<>0,D40/D$10,0) -> 0.0080278341 | F40: =+月次PL!D36/1000 -> 5 | G40: =IF(F$10<>0,F40/F$10,0) -> 0.0089310913 | H40: =+月次PL!E36/1000 -> 5 | I40: =IF(H$10<>0,H40/H$10,0) -> 0.0087465189 | J40: =+月次PL!F36/1000 -> 5 | K40: =IF(J$10<>0,J40/J$10,0) -> 0.0087461517 | L40: =+月次PL!G36/1000 -> 5 | M40: =IF(L$10<>0,L40/L$10,0) -> 0.010361792 | N40: =+月次PL!H36/1000 -> 5 | O40: =IF(N$10<>0,N40/N$10,0) -> 0.0088016547 | P40: =+月次PL!I36/1000 -> 5 | Q40: =IF(P$10<>0,P40/P$10,0) -> 0.0087253183 | R40: =+月次PL!J36/1000 -> 5 | S40: =IF(R$10<>0,R40/R$10,0) -> 0.0088314569 | T40: =+月次PL!K36/1000 -> 5 | U40: =IF(T$10<>0,T40/T$10,0) -> 0.0077704063 | V40: =+月次PL!L36/1000 -> 5 | W40: =IF(V$10<>0,V40/V$10,0) -> 0.0048514628 | X40: =+月次PL!M36/1000 -> 5 | Y40: =IF(X$10<>0,X40/X$10,0) -> 0.0056154285 | Z40: =+月次PL!N36/1000 -> 5 | AA40: =IF(Z$10<>0,Z40/Z$10,0) -> 0.0050582969
C41: 水道光熱費 | D41: =+月次PL!C30/1000 -> 0 | E41: =IF(D$10<>0,D41/D$10,0) -> 0 | F41: =+月次PL!D30/1000 -> 0 | G41: =IF(F$10<>0,F41/F$10,0) -> 0 | H41: =+月次PL!E30/1000 -> 0 | I41: =IF(H$10<>0,H41/H$10,0) -> 0 | J41: =+月次PL!F30/1000 -> 0 | K41: =IF(J$10<>0,J41/J$10,0) -> 0 | L41: =+月次PL!G30/1000 -> 0 | M41: =IF(L$10<>0,L41/L$10,0) -> 0 | N41: =+月次PL!H30/1000 -> 0 | O41: =IF(N$10<>0,N41/N$10,0) -> 0 | P41: =+月次PL!I30/1000 -> 0 | Q41: =IF(P$10<>0,P41/P$10,0) -> 0 | R41: =+月次PL!J30/1000 -> 0 | S41: =IF(R$10<>0,R41/R$10,0) -> 0 | T41: =+月次PL!K30/1000 -> 0 | U41: =IF(T$10<>0,T41/T$10,0) -> 0 | V41: =+月次PL!L30/1000 -> 0 | W41: =IF(V$10<>0,V41/V$10,0) -> 0 | X41: =+月次PL!M30/1000 -> 0 | Y41: =IF(X$10<>0,X41/X$10,0) -> 0 | Z41: =+月次PL!N30/1000 -> 0 | AA41: =IF(Z$10<>0,Z41/Z$10,0) -> 0
...

Sheet PL予実対比
A7: ■月次PL予実対比 | BB7: =+PL推移!D7 -> ㈱Ｓクリエイト
A8: =+PL推移!B8 -> 2025 | B8: 年度 | BB8: 単位：千円
A9: 項目 | C9: =+PL推移!D9 -> 7 | G9: =+PL推移!F9 -> 8 | K9: =+PL推移!H9 -> 9 | O9: =+PL推移!J9 -> 10 | S9: =+PL推移!L9 -> 11 | W9: =+PL推移!N9 -> 12 | AA9: =+PL推移!P9 -> 1 | AE9: =+PL推移!R9 -> 2 | AI9: =+PL推移!T9 -> 3 | AM9: =+PL推移!V9 -> 4 | AQ9: =+PL推移!X9 -> 5 | AU9: =+PL推移!Z9 -> 6 | AY9: 累計
C10: 計画 | D10: 実績 | E10: 差異 | F10: 計画比 | G10: 計画 | H10: 実績 | I10: 差異 | J10: 計画比 | K10: 計画 | L10: 実績 | M10: 差異 | N10: 計画比 | O10: 計画 | P10: 実績 | Q10: 差異 | R10: 計画比 | S10: 計画 | T10: 実績 | U10: 差異 | V10: 計画比 | W10: 計画 | X10: 実績 | Y10: 差異 | Z10: 計画比 | AA10: 計画 | AB10: 実績 | AC10: 差異 | AD10: 計画比 | AE10: 計画 | AF10: 実績 | AG10: 差異 | AH10: 計画比 | AI10: 計画 | AJ10: 実績 | AK10: 差異 | AL10: 計画比 | AM10: 計画 | AN10: 実績 | AO10: 差異 | AP10: 計画比 | AQ10: 計画 | AR10: 実績 | AS10: 差異 | AT10: 計画比 | AU10: 計画 | AV10: 実績 | AW10: 差異 | AX10: 計画比 | AY10: 計画 | AZ10: 実績 | BA10: 差異 | BB10: 計画比
A11: 売上高 | C11: =+収支計画!G17/1000 -> 622.833 | D11: =+PL推移!D10 -> 622.833 | E11: =SUM(E12:E16) -> 0 | F11: =IF(C11<>0,D11/C11,"-") -> 1 | G11: =+収支計画!H17/1000 -> 559.842 | H11: =SUM(H12:H16) -> 559.842 | I11: =SUM(I12:I16) -> 0 | J11: =IF(G11<>0,H11/G11,"-") -> 1 | K11: =SUM(K12:K16) -> 621.88128 | L11: =+PL推移!H10 -> 571.656 | M11: =SUM(M12:M16) -> -50.225279 | N11: =IF(K11<>0,L11/K11,"-") -> 0.91923655 | O11: =SUM(O12:O16) -> 576.5003 | P11: =+PL推移!J10 -> 571.68 | Q11: =SUM(Q12:Q16) -> -4.8202984 | R11: =IF(O11<>0,P11/O11,"-") -> 0.99163869 | S11: =SUM(S12:S16) -> 553.80981 | T11: =+PL推移!L10 -> 482.542 | U11: =SUM(U12:U16) -> -71.267808 | V11: =IF(S11<>0,T11/S11,"-") -> 0.87131357 | W11: =+収支計画!L17/1000 -> 576.5003 | X11: =+PL推移!N10 -> 568.075 | Y11: =SUM(Y12:Y16) -> -8.4252984 | Z11: =IF(W11<>0,X11/W11,"-") -> 0.98538544 | AA11: =+収支計画!M17/1000 -> 599.19079 | AB11: =+PL推移!P10 -> 573.045 | AC11: =SUM(AC12:AC16) -> -26.145789 | AD11: =IF(AA11<>0,AB11/AA11,"-") -> 0.95636484 | AE11: =+収支計画!N17/1000 -> 599.19079 | AF11: =+PL推移!R10 -> 566.158 | AG11: =SUM(AG12:AG16) -> -33.032789 | AH11: =IF(AE11<>0,AF11/AE11,"-") -> 0.944871 | AI11: =+収支計画!O17/1000 -> 599.19079 | AJ11: =+PL推移!T10 -> 643.467 | AK11: =SUM(AK12:AK16) -> 44.276211 | AL11: =IF(AI11<>0,AJ11/AI11,"-") -> 1.0738933 | AM11: =+収支計画!P17/1000 -> 793.196 | AN11: =+PL推移!V10 -> 1030.617 | AO11: =+AN11-AM11 -> 237.421 | AP11: =IF(AM11<>0,AN11/AM11,"-") -> 1.299322 | AQ11: =+収支計画!Q17/1000 -> 761.687 | AR11: =+PL推移!X10 -> 890.404 | AS11: =+AR11-AQ11 -> 128.717 | AT11: =IF(AQ11<>0,AR11/AQ11,"-") -> 1.1689894 | AU11: =+収支計画!R17/1000 -> 793.196 | AV11: =+PL推移!Z10 -> 988.475 | AW11: =+AV11-AU11 -> 195.279 | AX11: =IF(AU11<>0,AV11/AU11,"-") -> 1.2461926 | AY11: =+C11+G11+K11+O11+S11+W11+AA11+AE11+AI11+AM11+AQ11+AU11 -> 7657.0181 | AZ11: =+D11+H11+L11+P11+T11+X11+AB11+AF11+AJ11+AN11+AR11+AV11 -> 8068.794 | BA11: =+AZ11-AY11 -> 411.77595 | BB11: =IF(AY11<>0,AZ11/AY11,"-") -> 1.0537776
B12: =+PL推移!C11 -> 売上高 | C12: =+収支計画!G11/1000 -> 622.833 | D12: =+PL推移!D11 -> 622.833 | E12: =+D12-C12 -> 0 | F12: =IF(C12<>0,D12/C12,"-") -> 1 | G12: =+収支計画!H11/1000 -> 559.842 | H12: =+PL推移!F11 -> 559.842 | I12: =+H12-G12 -> 0 | J12: =IF(G12<>0,H12/G12,"-") -> 1 | K12: =+収支計画!I11/1000 -> 621.88128 | L12: =+PL推移!H11 -> 571.656 | M12: =+L12-K12 -> -50.225279 | N12: =IF(K12<>0,L12/K12,"-") -> 0.91923655 | O12: =+収支計画!J11/1000 -> 576.5003 | P12: =+PL推移!J11 -> 571.68 | Q12: =+P12-O12 -> -4.8202984 | R12: =IF(O12<>0,P12/O12,"-") -> 0.99163869 | S12: =+収支計画!K11/1000 -> 553.80981 | T12: =+PL推移!L11 -> 482.542 | U12: =+T12-S12 -> -71.267808 | V12: =IF(S12<>0,T12/S12,"-") -> 0.87131357 | W12: =+収支計画!L11/1000 -> 576.5003 | X12: =+PL推移!N11 -> 568.075 | Y12: =+X12-W12 -> -8.4252984 | Z12: =IF(W12<>0,X12/W12,"-") -> 0.98538544 | AA12: =+収支計画!M11/1000 -> 599.19079 | AB12: =+PL推移!P11 -> 573.045 | AC12: =+AB12-AA12 -> -26.145789 | AD12: =IF(AA12<>0,AB12/AA12,"-") -> 0.95636484 | AE12: =+収支計画!O17/1000 -> 599.19079 | AF12: =+PL推移!R11 -> 566.158 | AG12: =+AF12-AE12 -> -33.032789 | AH12: =IF(AE12<>0,AF12/AE12,"-") -> 0.944871 | AI12: =+収支計画!O11/1000 -> 599.19079 | AJ12: =+PL推移!T11 -> 643.467 | AK12: =+AJ12-AI12 -> 44.276211 | AL12: =IF(AI12<>0,AJ12/AI12,"-") -> 1.0738933 | AM12: =+収支計画!P11/1000 -> 793.196 | AN12: =+PL推移!V11 -> 1030.617 | AO12: =+AN12-AM12 -> 237.421 | AP12: =IF(AM12<>0,AN12/AM12,"-") -> 1.299322 | AQ12: =+収支計画!Q11/1000 -> 761.687 | AR12: =+PL推移!X11 -> 890.404 | AS12: =+AR12-AQ12 -> 128.717 | AT12: =IF(AQ12<>0,AR12/AQ12,"-") -> 1.1689894 | AU12: =+収支計画!R11/1000 -> 793.196 | AV12: =+PL推移!Z11 -> 0 | AW12: =+AV12-AU12 -> -793.196 | AX12: =IF(AU12<>0,AV12/AU12,"-") -> 0 | AY12: =+C12+G12+K12+O12+S12+W12+AA12+AE12+AI12+AM12+AQ12+AU12 -> 7657.0181 | AZ12: =+D12+H12+L12+P12+T12+X12+AB12+AF12+AJ12+AN12+AR12+AV12 -> 7080.319 | BA12: =+AZ12-AY12 -> -576.69905 | BB12: =IF(AY12<>0,AZ12/AY12,"-") -> 0.9246836
