Workbook

Sheet 月次BS
B1: 勘定科目 | C1: 期首残 | D1: 7月 | E1: 8月 | F1: 9月 | G1: 10月 | H1: 11月 | I1: 12月 | J1: 1月 | K1: 2月 | L1: 3 | M1: 4 | N1: 5月 | O1: 6月
A2: 資産の部
A3: 流動資産
A4: 現金及び預金
B5: 現金 | C5: 2866900 | D5: 1880600
B6: 普通預金 | C6: 31678389 | D6: 33834099
B7: 小口現金 | C7: 356376 | D7: 340879
A8: 現金及び預金合計 | C8: 34901665 | D8: 36055578
A9: 売上債権
B10: 売掛金 | C10: 9122840 | D10: 8860846
A11: 売上債権合計 | C11: =+C10 -> 9122840 | D11: 8860846
A12: 有価証券
A13: 有価証券合計 | C13: 0 | D13: 0
A14: 棚卸資産
B15: 商品 | C15: 1354257 | D15: 1354396
B16: 貯蔵品 | C16: 99474 | D16: 99474
A17: 棚卸資産合計 | C17: 1453731 | D17: 1453870
A18: その他流動資産
B19: 前払費用 | C19: 1742739 | D19: 1742739
B20: 立替金 | C20: 877070 | D20: 874843
B21: 未収入金 | C21: 0 | D21: 0
B22: 仮払金 | C22: 0 | D22: 3946
B23: 仮払消費税 | C23: 0 | D23: 477821
A24: その他流動資産合計 | C24: 2619809 | D24: 3099349
A25: 流動資産合計 | C25: 48098045 | D25: 49469643
A26: 固定資産
A27: 有形固定資産
B28: 建物 | C28: 14805643 | D28: 14805643
B29: 附属設備 | C29: 26376787 | D29: 26376787
B30: 工具器具備品 | C30: 4922553 | D30: 4922553
B31: 一括償却資産 | C31: 263159 | D31: 263159
B32: 減価償却累計額 | C32: 0 | D32: 601448
A33: 有形固定資産合計 | C33: 46368142 | D33: 46969590
A34: 無形固定資産
B35: ソフトウェア | C35: 2553731 | D35: 1205374
A36: 無形固定資産合計 | C36: 2553731 | D36: 1205374
A37: 投資その他の資産
B38: 出資金 | C38: 8825960 | D38: 8825960
B39: 長期前払費用 | C39: 897030 | D39: 897030
B40: 敷金 | C40: 2126486 | D40: 2126486
...

Sheet BS千円
B1: 勘定科目 | C1: 期首残 | D1: 7月 | E1: 8月 | F1: =+月次BS!F1 -> 9月 | G1: =+月次BS!G1 -> 10月 | H1: =+月次BS!H1 -> 11月 | I1: =+月次BS!I1 -> 12月 | J1: =+月次BS!J1 -> 1月 | K1: =+月次BS!K1 -> 2月 | L1: =+月次BS!L1 -> 3 | M1: =+月次BS!M1 -> 4 | ... O1: =+月次BS!O1 -> 6月
A2: =+月次BS!A2 -> 資産の部
A3: =+月次BS!A3 -> 流動資産
A4: =+月次BS!A4 -> 現金及び預金
A5: =+月次BS!A5 -> 0 | B5: =+月次BS!B5 -> 現金 | C5: =+月次BS!C5/1000 -> 2866.9 | D5: =+月次BS!D5/1000 -> 1880.6 | E5: =+月次BS!E5/1000 -> 0 | F5: =+月次BS!F5/1000 -> 0 | G5: =+月次BS!G5/1000 -> 0 | H5: =+月次BS!H5/1000 -> 0 | I5: =+月次BS!I5/1000 -> 0 | J5: =+月次BS!J5/1000 -> 0 | ... O5: =+月次BS!O5/1000 -> 0
A6: =+月次BS!A6 -> 0 | B6: =+月次BS!B6 -> 普通預金 | C6: =+月次BS!C6/1000 -> 31678.389 | D6: =+月次BS!D6/1000 -> 33834.099 | E6: =+月次BS!E6/1000 -> 0 | F6: =+月次BS!F6/1000 -> 0 | G6: =+月次BS!G6/1000 -> 0 | H6: =+月次BS!H6/1000 -> 0 | I6: =+月次BS!I6/1000 -> 0 | J6: =+月次BS!J6/1000 -> 0 | ... O6: =+月次BS!O6/1000 -> 0
A7: =+月次BS!A7 -> 0 | B7: =+月次BS!B7 -> 小口現金 | C7: =+月次BS!C7/1000 -> 356.376 | D7: =+月次BS!D7/1000 -> 340.879 | E7: =+月次BS!E7/1000 -> 0 | F7: =+月次BS!F7/1000 -> 0 | G7: =+月次BS!G7/1000 -> 0 | H7: =+月次BS!H7/1000 -> 0 | I7: =+月次BS!I7/1000 -> 0 | J7: =+月次BS!J7/1000 -> 0 | ... O7: =+月次BS!O7/1000 -> 0
A8: =+月次BS!A8 -> 現金及び預金合計 | B8: =+月次BS!B8 -> 0 | C8: =+月次BS!C8/1000 -> 34901.665 | D8: =+月次BS!D8/1000 -> 36055.578 | E8: =+月次BS!E8/1000 -> 0 | F8: =+月次BS!F8/1000 -> 0 | G8: =+月次BS!G8/1000 -> 0 | H8: =+月次BS!H8/1000 -> 0 | I8: =+月次BS!I8/1000 -> 0 | J8: =+月次BS!J8/1000 -> 0 | ... O8: =+月次BS!O8/1000 -> 0
A9: =+月次BS!A9 -> 売上債権 | B9: =+月次BS!B9 -> 0 | C9: =+月次BS!C9/1000 -> 0 | D9: =+月次BS!D9/1000 -> 0 | E9: =+月次BS!E9/1000 -> 0 | F9: =+月次BS!F9/1000 -> 0 | G9: =+月次BS!G9/1000 -> 0 | H9: =+月次BS!H9/1000 -> 0 | I9: =+月次BS!I9/1000 -> 0 | J9: =+月次BS!J9/1000 -> 0 | ... O9: =+月次BS!O9/1000 -> 0
A10: =+月次BS!A10 -> 0 | B10: =+月次BS!B10 -> 売掛金 | C10: =+月次BS!C10/1000 -> 9122.84 | D10: =+月次BS!D10/1000 -> 8860.846 | E10: =+月次BS!E10/1000 -> 0 | F10: =+月次BS!F10/1000 -> 0 | G10: =+月次BS!G10/1000 -> 0 | H10: =+月次BS!H10/1000 -> 0 | I10: =+月次BS!I10/1000 -> 0 | J10: =+月次BS!J10/1000 -> 0 | ... O10: =+月次BS!O10/1000 -> 0
A11: =+月次BS!A11 -> 売上債権合計 | B11: =+月次BS!B11 -> 0 | C11: =+月次BS!C11/1000 -> 9122.84 | D11: =+月次BS!D11/1000 -> 8860.846 | E11: =+月次BS!E11/1000 -> 0 | F11: =+月次BS!F11/1000 -> 0 | G11: =+月次BS!G11/1000 -> 0 | H11: =+月次BS!H11/1000 -> 0 | I11: =+月次BS!I11/1000 -> 0 | J11: =+月次BS!J11/1000 -> 0 | ... O11: =+月次BS!O11/1000 -> 0
A12: =+月次BS!A12 -> 有価証券 | B12: =+月次BS!B12 -> 0 | C12: =+月次BS!C12/1000 -> 0 | D12: =+月次BS!D12/1000 -> 0 | E12: =+月次BS!E12/1000 -> 0 | F12: =+月次BS!F12/1000 -> 0 | G12: =+月次BS!G12/1000 -> 0 | H12: =+月次BS!H12/1000 -> 0 | I12: =+月次BS!I12/1000 -> 0 | J12: =+月次BS!J12/1000 -> 0 | ... O12: =+月次BS!O12/1000 -> 0
A13: =+月次BS!A13 -> 有価証券合計 | B13: =+月次BS!B13 -> 0 | C13: =+月次BS!C13/1000 -> 0 | D13: =+月次BS!D13/1000 -> 0 | E13: =+月次BS!E13/1000 -> 0 | F13: =+月次BS!F13/1000 -> 0 | G13: =+月次BS!G13/1000 -> 0 | H13: =+月次BS!H13/1000 -> 0 | I13: =+月次BS!I13/1000 -> 0 | J13: =+月次BS!J13/1000 -> 0 | ... O13: =+月次BS!O13/1000 -> 0
A14: =+月次BS!A14 -> 棚卸資産 | B14: =+月次BS!B14 -> 0 | C14: =+月次BS!C14/1000 -> 0 | D14: =+月次BS!D14/1000 -> 0 | E14: =+月次BS!E14/1000 -> 0 | F14: =+月次BS!F14/1000 -> 0 | G14: =+月次BS!G14/1000 -> 0 | H14: =+月次BS!H14/1000 -> 0 | I14: =+月次BS!I14/1000 -> 0 | J14: =+月次BS!J14/1000 -> 0 | ... O14: =+月次BS!O14/1000 -> 0
A15: =+月次BS!A15 -> 0 | B15: =+月次BS!B15 -> 商品 | C15: =+月次BS!C15/1000 -> 1354.257 | D15: =+月次BS!D15/1000 -> 1354.396 | E15: =+月次BS!E15/1000 -> 0 | F15: =+月次BS!F15/1000 -> 0 | G15: =+月次BS!G15/1000 -> 0 | H15: =+月次BS!H15/1000 -> 0 | I15: =+月次BS!I15/1000 -> 0 | J15: =+月次BS!J15/1000 -> 0 | ... O15: =+月次BS!O15/1000 -> 0
A16: =+月次BS!A16 -> 0 | B16: =+月次BS!B16 -> 貯蔵品 | C16: =+月次BS!C16/1000 -> 99.474 | D16: =+月次BS!D16/1000 -> 99.474 | E16: =+月次BS!E16/1000 -> 0 | F16: =+月次BS!F16/1000 -> 0 | G16: =+月次BS!G16/1000 -> 0 | H16: =+月次BS!H16/1000 -> 0 | I16: =+月次BS!I16/1000 -> 0 | J16: =+月次BS!J16/1000 -> 0 | ... O16: =+月次BS!O16/1000 -> 0
... A93: =+月次BS!A93 -> 負債・純資産の部合計 | B93: =+月次BS!B93 -> 0 | C93: =+月次BS!C93/1000 -> 122236.57 | D93: =+月次BS!D93/1000 -> 122864.31 | E93: =+月次BS!E93/1000 -> 0 | F93: =+月次BS!F93/1000 -> 0 | G93: =+月次BS!G93/1000 -> 0 | H93: =+月次BS!H93/1000 -> 0 | I93: =+月次BS!I93/1000 -> 0 | J93: =+月次BS!J93/1000 -> 0 | ... O93: =+月次BS!O93/1000 -> 0
A94: =+月次BS!A95 -> 0 | B94: =+月次BS!B95 -> 0 | C94: =+月次BS!C95/1000 -> 0 | D94: =+月次BS!D95/1000 -> 0 | E94: =+月次BS!E95/1000 -> 0 | F94: =+月次BS!F95/1000 -> 0 | G94: =+月次BS!G95/1000 -> 0 | H94: =+月次BS!H95/1000 -> 0 | I94: =+月次BS!I95/1000 -> 0 | J94: =+月次BS!J95/1000 -> 0 | ... O94: =+月次BS!O95/1000 -> 0
A95: =+月次BS!A96 -> 0 | B95: 買掛未払債務 | C95: =+C52+C55+C56 -> 4487.889 | D95: =+D52+D55+D56 -> 4729.474 | E95: =+E52+E55+E56 -> 0 | F95: =+F52+F55+F56 -> 0 | G95: =+G52+G55+G56 -> 0 | H95: =+H52+H55+H56 -> 0 | I95: =+I52+I55+I56 -> 0 | J95: =+J52+J55+J56 -> 0 | ... O95: =+O52+O55+O56 -> 0
A96: =+月次BS!A97 -> 0 | B96: その他流動負債 | C96: =+C57+C58+C59+C62 -> 574.341 | D96: =+D57+D58+D59+D62 -> 1172.838 | E96: =+E57+E58+E59+E62 -> 0 | F96: =+F57+F58+F59+F62 -> 0 | G96: =+G57+G58+G59+G62 -> 0 | H96: =+H57+H58+H59+H62 -> 0 | I96: =+I57+I58+I59+I62 -> 0 | J96: =+J57+J58+J59+J62 -> 0 | ... O96: =+O57+O58+O59+O62 -> 0
A97: =+月次BS!A98 -> 0 | B97: 有形・無形固定資産 | C97: =+C33+C36 -> 48921.873 | D97: =+D33+D36 -> 48174.964 | E97: =+E33+E36 -> 0 | F97: =+F33+F36 -> 0 | G97: =+G33+G36 -> 0 | H97: =+H33+H36 -> 0 | I97: =+I33+I36 -> 0 | J97: =+J33+J36 -> 0 | ... O97: =+O33+O36 -> 0
A98: =+月次BS!A99 -> 0 | B98: 長期借入金 | C98: =+C63+C67 -> 135225 | D98: =+D63+D67 -> 134745 | E98: =+E63+E67 -> 0 | F98: =+F63+F67 -> 0 | G98: =+G63+G67 -> 0 | H98: =+H63+H67 -> 0 | I98: =+I63+I67 -> 0 | J98: =+J63+J67 -> 0 | ... O98: =+O63+O67 -> 0
A99: =+月次BS!A100 -> 0 | B99: =+月次BS!B100 -> 0 | C99: =+月次BS!C100/1000 -> 0 | D99: =+月次BS!D100/1000 -> 0 | E99: =+月次BS!E100/1000 -> 0 | F99: =+月次BS!F100/1000 -> 0 | G99: =+月次BS!G100/1000 -> 0 | H99: =+月次BS!H100/1000 -> 0 | I99: =+月次BS!I100/1000 -> 0 | J99: =+月次BS!J100/1000 -> 0 | ... O99: =+月次BS!O100/1000 -> 0
A100: =+月次BS!A101 -> 0 | B100: =+月次BS!B101 -> 0 | C100: =+月次BS!C101/1000 -> 0 | D100: =+月次BS!D101/1000 -> 0 | E100: =+月次BS!E101/1000 -> 0 | F100: =+月次BS!F101/1000 -> 0 | G100: =+月次BS!G101/1000 -> 0 | H100: =+月次BS!H101/1000 -> 0 | I100: =+月次BS!I101/1000 -> 0 | J100: =+月次BS!J101/1000 -> 0 | ... O100: =+月次BS!O101/1000 -> 0
A101: =+月次BS!A102 -> 0 | B101: =+月次BS!B102 -> 0 | C101: =+月次BS!C102/1000 -> 0 | D101: =+月次BS!D102/1000 -> 0 | E101: =+月次BS!E102/1000 -> 0 | F101: =+月次BS!F102/1000 -> 0 | G101: =+月次BS!G102/1000 -> 0 | H101: =+月次BS!H102/1000 -> 0 | I101: =+月次BS!I102/1000 -> 0 | J101: =+月次BS!J102/1000 -> 0 | ... O101: =+月次BS!O102/1000 -> 0
A102: =+月次BS!A103 -> 0 | B102: =+月次BS!B103 -> 0 | C102: =+月次BS!C103/1000 -> 0 | D102: =+月次BS!D103/1000 -> 0 | E102: =+月次BS!E103/1000 -> 0 | F102: =+月次BS!F103/1000 -> 0 | G102: =+月次BS!G103/1000 -> 0 | H102: =+月次BS!H103/1000 -> 0 | I102: =+月次BS!I103/1000 -> 0 | J102: =+月次BS!J103/1000 -> 0 | ... O102: =+月次BS!O103/1000 -> 0
A103: =+月次BS!A104 -> 0 | B103: =+月次BS!B104 -> 0 | C103: =+月次BS!C104/1000 -> 0 | D103: =+月次BS!D104/1000 -> 0 | E103: =+月次BS!E104/1000 -> 0 | F103: =+月次BS!F104/1000 -> 0 | G103: =+月次BS!G104/1000 -> 0 | H103: =+月次BS!H104/1000 -> 0 | I103: =+月次BS!I104/1000 -> 0 | J103: =+月次BS!J104/1000 -> 0 | ... O103: =+月次BS!O104/1000 -> 0

Sheet 月次PL
B1: 勘定科目 | C1: =+月次BS!D1 -> 7月 | D1: =+月次BS!E1 -> 8月 | E1: =+月次BS!F1 -> 9月 | F1: =+月次BS!G1 -> 10月 | G1: =+月次BS!H1 -> 11月 | H1: =+月次BS!I1 -> 12月 | I1: =+月次BS!J1 -> 1月 | J1: =+月次BS!K1 -> 2月 | ... N1: =+月次BS!O1 -> 6月 | O1: 累計
A2: 売上高
B3: レストラン売上 | C3: 7101672 | O3: =SUM(C3:N3) -> 7101672
B4: デリバリー売上 | O4: =SUM(C4:N4) -> 0
B5: 売上高 | C5: 883931 | O5: =SUM(C5:N5) -> 883931
B6: 村売上 | C6: 645682 | O6: =SUM(C6:N6) -> 645682
B7: その他売上 | O7: =SUM(C7:N7) -> 0
A8: 売上高合計 | C8: =+SUM(C3:C7) -> 8631285 | D8: =+SUM(D3:D7) -> 0 | E8: =+SUM(E3:E7) -> 0 | F8: =+SUM(F3:F7) -> 0 | G8: =+SUM(G3:G7) -> 0 | H8: =+SUM(H3:H7) -> 0 | I8: =+SUM(I3:I7) -> 0 | J8: =+SUM(J3:J7) -> 0 | ... N8: =+SUM(N3:N7) -> 0 | O8: =SUM(C8:N8) -> 8631285
A9: 売上原価 | O9: =SUM(C9:N9) -> 0
B10: 期首商品棚卸高 | C10: 1323276 | O10: =SUM(C10:N10) -> 1323276
B11: 飲料仕入 | C11: 1027204 | O11: =SUM(C11:N11) -> 1027204
B12: 食材仕入 | C12: 994211 | O12: =SUM(C12:N12) -> 994211
B13: 仕入値引 | O13: =SUM(C13:N13) -> 0
B14: 期末商品棚卸高 | C14: 1323415 | O14: =SUM(C14:N14) -> 1323415
A15: 売上原価 | C15: =+C10+C11+C12-C13-C14 -> 2021276 | D15: =+D10+D11+D12-D13-D14 -> 0 | E15: =+E10+E11+E12-E13-E14 -> 0 | F15: =+F10+F11+F12-F13-F14 -> 0 | G15: =+G10+G11+G12-G13-G14 -> 0 | H15: =+H10+H11+H12-H13-H14 -> 0 | I15: =+I10+I11+I12-I13-I14 -> 0 | J15: =+J10+J11+J12-J13-J14 -> 0 | ... N15: =+N10+N11+N12-N13-N14 -> 0 | O15: =SUM(C15:N15) -> 2021276
A16: 売上総利益 | C16: =+C8-C15 -> 6610009 | D16: =+D8-D15 -> 0 | E16: =+E8-E15 -> 0 | F16: =+F8-F15 -> 0 | G16: =+G8-G15 -> 0 | H16: =+H8-H15 -> 0 | I16: =+I8-I15 -> 0 | J16: =+J8-J15 -> 0 | ... N16: =+N8-N15 -> 0 | O16: =SUM(C16:N16) -> 6610009
A17: 販売費及び一般管理費 | O17: =SUM(C17:N17) -> 0
B18: 役員報酬 | C18: 500000 | O18: =SUM(C18:N18) -> 500000
B19: 給料賃金 | C19: 350000 | O19: =SUM(C19:N19) -> 350000
B20: 賞与 | O20: =SUM(C20:N20) -> 0
B21: 雑給 | C21: 1055055 | O21: =SUM(C21:N21) -> 1055055
B22: 法定福利費 | C22: 219083 | O22: =SUM(C22:N22) -> 219083
B23: 福利厚生費 | O23: =SUM(C23:N23) -> 0
B24: 業務委託費 | C24: 338738 | O24: =SUM(C24:N24) -> 338738
B25: 広告宣伝費 | C25: 124456 | O25: =SUM(C25:N25) -> 124456
B26: 接待交際費 | O26: =SUM(C26:N26) -> 0
B27: 旅費交通費 | C27: 41261 | O27: =SUM(C27:N27) -> 41261
B28: 通信費 | C28: 62422 | O28: =SUM(C28:N28) -> 62422
B29: 水道光熱費 | C29: 659468 | O29: =SUM(C29:N29) -> 659468
B30: 修繕費 | O30: =SUM(C30:N30) -> 0
B31: 消耗品費 | C31: 207018 | O31: =SUM(C31:N31) -> 207018
B32: リース料 | C32: 49700 | O32: =SUM(C32:N32) -> 49700
B33: 地代家賃 | C33: 1295661 | O33: =SUM(C33:N33) -> 1295661
B34: 賃借料 | C34: 30000 | O34: =SUM(C34:N34) -> 30000
B35: 保険料 | C35: 28375 | O35: =SUM(C35:N35) -> 28375
B36: 租税公課 | C36: 124000 | O36: =SUM(C36:N36) -> 124000
B37: 支払手数料 | C37: 208468 | O37: =SUM(C37:N37) -> 208468
B38: 会議費 | C38: 7273 | O38: =SUM(C38:N38) -> 7273
B39: 新聞図書費 | O39: =SUM(C39:N39) -> 0
B40: 減価償却費 | C40: 749954 | O40: =SUM(C40:N40) -> 749954
...

Sheet PL推移
B2: CK | C2: 売上高 | D2: =IF(D10<>0,IF(D10=月次PL!C8/1000,"OK",PL推移!D10-月次PL!C8/1000),"nd") -> OK | F2: =IF(F10<>0,IF(月次PL!D8/1000=PL推移!F10,"OK",PL推移!F10-月次PL!D8/1000),"nd") -> nd | H2: =IF(H10<>0,IF(月次PL!E8/1000=PL推移!H10,"OK",PL推移!H10-月次PL!E8/1000),"nd") -> nd | J2: =IF(J10<>0,IF(月次PL!F8/1000=PL推移!J10,"OK",PL推移!J10-月次PL!F8/1000),"nd") -> nd | L2: =IF(L10<>0,IF(月次PL!G8/1000=PL推移!L10,"OK",PL推移!L10-月次PL!G8/1000),"nd") -> nd | N2: =IF(N10<>0,IF(月次PL!H8/1000=PL推移!N10,"OK",PL推移!N10-月次PL!H8/1000),"nd") -> nd | P2: =IF(P10<>0,IF(月次PL!I8/1000=PL推移!P10,"OK",PL推移!P10-月次PL!I8/1000),"nd") -> nd | R2: =IF(R10<>0,IF(月次PL!J8/1000=PL推移!R10,"OK",PL推移!R10-月次PL!J8/1000),"nd") -> nd | T2: =IF(T10<>0,IF(月次PL!K8/1000=PL推移!T10,"OK",PL推移!T10-月次PL!K8/1000),"nd") -> 350 | V2: =IF(V10<>0,IF(月次PL!L8/1000=PL推移!V10,"OK",PL推移!V10-月次PL!L8/1000),"nd") -> 8454 | X2: =IF(X10<>0,IF(月次PL!M8/1000=PL推移!X10,"OK",PL推移!X10-月次PL!M8/1000),"nd") -> 9017 | Z2: =IF(Z10<>0,IF(月次PL!N8/1000=PL推移!Z10,"OK",PL推移!Z10-月次PL!N8/1000),"nd") -> 8610
C3: 粗利益 | D3: =IF(D22<>0,IF(D22=月次PL!C16/1000,"OK",PL推移!D22-月次PL!C16/1000),"nd") -> OK | F3: =IF(F22<>0,IF(F22=月次PL!D16/1000,"OK",PL推移!F22-月次PL!D16/1000),"nd") -> nd | H3: =IF(H22<>0,IF(H22=月次PL!E16/1000,"OK",PL推移!H22-月次PL!E16/1000),"nd") -> nd | J3: =IF(J22<>0,IF(J22=月次PL!F16/1000,"OK",PL推移!J22-月次PL!F16/1000),"nd") -> nd | L3: =IF(L22<>0,IF(L22=月次PL!G16/1000,"OK",PL推移!L22-月次PL!G16/1000),"nd") -> nd | N3: =IF(N22<>0,IF(N22=月次PL!H16/1000,"OK",PL推移!N22-月次PL!H16/1000),"nd") -> nd | P3: =IF(P22<>0,IF(P22=月次PL!I16/1000,"OK",PL推移!P22-月次PL!I16/1000),"nd") -> nd | R3: =IF(R22<>0,IF(R22=月次PL!J16/1000,"OK",PL推移!R22-月次PL!J16/1000),"nd") -> nd | T3: =IF(T22<>0,IF(T22=月次PL!K16/1000,"OK",PL推移!T22-月次PL!K16/1000),"nd") -> 350 | V3: =IF(V22<>0,IF(V22=月次PL!L16/1000,"OK",PL推移!V22-月次PL!L16/1000),"nd") -> 8454 | X3: =IF(X22<>0,IF(X22=月次PL!M16/1000,"OK",PL推移!X22-月次PL!M16/1000),"nd") -> 9017 | Z3: =IF(Z22<>0,IF(Z22=月次PL!N16/1000,"OK",PL推移!Z22-月次PL!N16/1000),"nd") -> 8610
C4: 販管費 | D4: =IF(D28<>0,IF(D28=月次PL!C44/1000,"OK",PL推移!D28-月次PL!C44/1000),"nd") -> OK | F4: =IF(F28<>0,IF(F28=月次PL!D44/1000,"OK",PL推移!F28-月次PL!D44/1000),"nd") -> nd | H4: =IF(H28<>0,IF(H28=月次PL!E44/1000,"OK",PL推移!H28-月次PL!E44/1000),"nd") -> nd | J4: =IF(J28<>0,IF(J28=月次PL!F44/1000,"OK",PL推移!J28-月次PL!F44/1000),"nd") -> nd | L4: =IF(L28<>0,IF(L28=月次PL!G44/1000,"OK",PL推移!L28-月次PL!G44/1000),"nd") -> nd | N4: =IF(N28<>0,IF(N28=月次PL!H44/1000,"OK",PL推移!N28-月次PL!H44/1000),"nd") -> nd | P4: =IF(P28<>0,IF(P28=月次PL!I44/1000,"OK",PL推移!P28-月次PL!I44/1000),"nd") -> nd | R4: =IF(R28<>0,IF(R28=月次PL!J44/1000,"OK",PL推移!R28-月次PL!J44/1000),"nd") -> nd | T4: =IF(T28<>0,IF(T28=月次PL!K44/1000,"OK",PL推移!T28-月次PL!K44/1000),"nd") -> nd | V4: =IF(V28<>0,IF(V28=月次PL!L44/1000,"OK",PL推移!V28-月次PL!L44/1000),"nd") -> nd | X4: =IF(X28<>0,IF(X28=月次PL!M44/1000,"OK",PL推移!X28-月次PL!M44/1000),"nd") -> nd | Z4: =IF(Z28<>0,IF(Z28=月次PL!N44/1000,"OK",PL推移!Z28-月次PL!N44/1000),"nd") -> nd
C5: 営業利益 | D5: =IF(D50<>0,IF(D50=月次PL!C45/1000,"OK",PL推移!D50-月次PL!C45/1000),"nd") -> OK | F5: =IF(F50<>0,IF(F50=月次PL!D45/1000,"OK",PL推移!F50-月次PL!D45/1000),"nd") -> nd | H5: =IF(H50<>0,IF(H50=月次PL!E45/1000,"OK",PL推移!H50-月次PL!E45/1000),"nd") -> nd | J5: =IF(J50<>0,IF(J50=月次PL!F45/1000,"OK",PL推移!J50-月次PL!F45/1000),"nd") -> nd | L5: =IF(L50<>0,IF(L50=月次PL!G45/1000,"OK",PL推移!L50-月次PL!G45/1000),"nd") -> nd | N5: =IF(N50<>0,IF(N50=月次PL!H45/1000,"OK",PL推移!N50-月次PL!H45/1000),"nd") -> nd | P5: =IF(P50<>0,IF(P50=月次PL!I45/1000,"OK",PL推移!P50-月次PL!I45/1000),"nd") -> nd | R5: =IF(R50<>0,IF(R50=月次PL!J45/1000,"OK",PL推移!R50-月次PL!J45/1000),"nd") -> nd | T5: =IF(T50<>0,IF(T50=月次PL!K45/1000,"OK",PL推移!T50-月次PL!K45/1000),"nd") -> 350 | V5: =IF(V50<>0,IF(V50=月次PL!L45/1000,"OK",PL推移!V50-月次PL!L45/1000),"nd") -> 8454 | X5: =IF(X50<>0,IF(X50=月次PL!M45/1000,"OK",PL推移!X50-月次PL!M45/1000),"nd") -> 9017 | Z5: =IF(Z50<>0,IF(Z50=月次PL!N45/1000,"OK",PL推移!Z50-月次PL!N45/1000),"nd") -> 8610
C6: 経常利益 | D6: =IF(D54<>0,IF(D54=月次PL!C56/1000,"OK",PL推移!D54-月次PL!C56/1000),"nd") -> OK | F6: =IF(F54<>0,IF(F54=月次PL!D56/1000,"OK",PL推移!F54-月次PL!D56/1000),"nd") -> nd | H6: =IF(H54<>0,IF(H54=月次PL!E56/1000,"OK",PL推移!H54-月次PL!E56/1000),"nd") -> nd | J6: =IF(J54<>0,IF(J54=月次PL!F56/1000,"OK",PL推移!J54-月次PL!F56/1000),"nd") -> nd | L6: =IF(L54<>0,IF(L54=月次PL!G56/1000,"OK",PL推移!L54-月次PL!G56/1000),"nd") -> nd | N6: =IF(N54<>0,IF(N54=月次PL!H56/1000,"OK",PL推移!N54-月次PL!H56/1000),"nd") -> nd | P6: =IF(P54<>0,IF(P54=月次PL!I56/1000,"OK",PL推移!P54-月次PL!I56/1000),"nd") -> nd | R6: =IF(R54<>0,IF(R54=月次PL!J56/1000,"OK",PL推移!R54-月次PL!J56/1000),"nd") -> nd | T6: =IF(T54<>0,IF(T54=月次PL!K56/1000,"OK",PL推移!T54-月次PL!K56/1000),"nd") -> 350 | V6: =IF(V54<>0,IF(V54=月次PL!L56/1000,"OK",PL推移!V54-月次PL!L56/1000),"nd") -> 8454 | X6: =IF(X54<>0,IF(X54=月次PL!M56/1000,"OK",PL推移!X54-月次PL!M56/1000),"nd") -> 9017 | Z6: =IF(Z54<>0,IF(Z54=月次PL!N56/1000,"OK",PL推移!Z54-月次PL!N56/1000),"nd") -> 8610
B7: ■月次報告PL | D7: ㈱ｅｓエンターテイメント | AH7: 注意事項 | AI7: 概算値 | AJ7: 異常値 | AK7: 特記事項 | AL7: 予算検討
B8: 2026 | C8: 年度 | D8: 単位：千円 | F8: 注意事項 | G8: 概算値 | H8: 異常値 | I8: 特記事項 | J8: 予算検討
B9: 項目 | D9: =+月次PL!C1 -> 7月 | F9: =+月次PL!D1 -> 8月 | H9: =+月次PL!E1 -> 9月 | J9: =+月次PL!F1 -> 10月 | L9: =+月次PL!G1 -> 11月 | N9: =+月次PL!H1 -> 12月 | P9: =+月次PL!I1 -> 1月 | R9: =+月次PL!J1 -> 2月 | T9: =+月次PL!K1 -> 3 | V9: =+月次PL!L1 -> 4 | X9: =+月次PL!M1 -> 5月 | Z9: =+月次PL!N1 -> 6月
B10: 売上高 | D10: =+月次PL!C8/1000 -> 8631.285 | E10: =IF(D$10<>0,D10/D$10,0) -> 1 | F10: =+月次PL!D8/1000 -> 0 | G10: =IF(F$10<>0,F10/F$10,0) -> 0 | H10: =+月次PL!E8/1000 -> 0 | I10: =IF(H$10<>0,H10/H$10,0) -> 0 | J10: =+月次PL!F8/1000 -> 0 | K10: =IF(J$10<>0,J10/J$10,0) -> 0 | L10: =SUM(L11:L15) -> 0 | M10: =IF(L$10<>0,L10/L$10,0) -> 0 | N10: =SUM(N11:N15) -> 0 | O10: =IF(N$10<>0,N10/N$10,0) -> 0 | P10: =+月次PL!I8/1000 -> 0 | Q10: =IF(P$10<>0,P10/P$10,0) -> 0 | R10: =+月次PL!J8/1000 -> 0 | S10: =IF(R$10<>0,R10/R$10,0) -> 0 | T10: =SUM(T11:T15)+350 -> 350 | U10: =IF(T$10<>0,T10/T$10,0) -> 1 | V10: =SUM(V11:V15)+350 -> 8454 | W10: =IF(V$10<>0,V10/V$10,0) -> 1 | X10: =SUM(X11:X15)+350 -> 9017 | Y10: =IF(X$10<>0,X10/X$10,0) -> 1 | Z10: 8610 | AA10: =IF(Z$10<>0,Z10/Z$10,0) -> 1
C11: 恵愛 | D11: 6425 | E11: =IF(D$10<>0,D11/D$10,0) -> 0.74438511 | G11: =IF(F$10<>0,F11/F$10,0) -> 0 | I11: =IF(H$10<>0,H11/H$10,0) -> 0 | K11: =IF(J$10<>0,J11/J$10,0) -> 0 | M11: =IF(L$10<>0,L11/L$10,0) -> 0 | O11: =IF(N$10<>0,N11/N$10,0) -> 0 | Q11: =IF(P$10<>0,P11/P$10,0) -> 0 | S11: =IF(R$10<>0,R11/R$10,0) -> 0 | U11: =IF(T$10<>0,T11/T$10,0) -> 0 | V11: 6013 | W11: =IF(V$10<>0,V11/V$10,0) -> 0.71126094 | X11: 6855 | Y11: =IF(X$10<>0,X11/X$10,0) -> 0.76023068 | Z11: 6185 | AA11: =IF(Z$10<>0,Z11/Z$10,0) -> 0.71835075
C12: 村 | D12: 646 | E12: =IF(D$10<>0,D12/D$10,0) -> 0.074844012 | G12: =IF(F$10<>0,F12/F$10,0) -> 0 | I12: =IF(H$10<>0,H12/H$10,0) -> 0 | K12: =IF(J$10<>0,J12/J$10,0) -> 0 | M12: =IF(L$10<>0,L12/L$10,0) -> 0 | O12: =IF(N$10<>0,N12/N$10,0) -> 0 | Q12: =IF(P$10<>0,P12/P$10,0) -> 0 | S12: =IF(R$10<>0,R12/R$10,0) -> 0 | U12: =IF(T$10<>0,T12/T$10,0) -> 0 | V12: 791 | W12: =IF(V$10<>0,V12/V$10,0) -> 0.093565176 | X12: =+月次PL!M6/1000 -> 0 | Y12: =IF(X$10<>0,X12/X$10,0) -> 0 | Z12: =+月次PL!N6/1000 -> 0 | AA12: =IF(Z$10<>0,Z12/Z$10,0) -> 0
C13: 弁当 | D13: 525 | E13: =IF(D$10<>0,D13/D$10,0) -> 0.060825242 | G13: =IF(F$10<>0,F13/F$10,0) -> 0 | I13: =IF(H$10<>0,H13/H$10,0) -> 0 | K13: =IF(J$10<>0,J13/J$10,0) -> 0 | M13: =IF(L$10<>0,L13/L$10,0) -> 0 | O13: =IF(N$10<>0,N13/N$10,0) -> 0 | Q13: =IF(P$10<>0,P13/P$10,0) -> 0 | S13: =IF(R$10<>0,R13/R$10,0) -> 0 | U13: =IF(T$10<>0,T13/T$10,0) -> 0 | V13: 360 | W13: =IF(V$10<>0,V13/V$10,0) -> 0.042583392 | X13: 375 | Y13: =IF(X$10<>0,X13/X$10,0) -> 0.041588111 | Z13: 405 | AA13: =IF(Z$10<>0,Z13/Z$10,0) -> 0.047038328
C14: シェア | D14: 63 | E14: =IF(D$10<>0,D14/D$10,0) -> 0.0072990291 | G14: =IF(F$10<>0,F14/F$10,0) -> 0 | I14: =IF(H$10<>0,H14/H$10,0) -> 0 | K14: =IF(J$10<>0,J14/J$10,0) -> 0 | M14: =IF(L$10<>0,L14/L$10,0) -> 0 | O14: =IF(N$10<>0,N14/N$10,0) -> 0 | Q14: =IF(P$10<>0,P14/P$10,0) -> 0 | S14: =IF(R$10<>0,R14/R$10,0) -> 0 | U14: =IF(T$10<>0,T14/T$10,0) -> 0 | V14: 128 | W14: =IF(V$10<>0,V14/V$10,0) -> 0.015140762 | X14: 108 | Y14: =IF(X$10<>0,X14/X$10,0) -> 0.011977376 | Z14: 122 | AA14: =IF(Z$10<>0,Z14/Z$10,0) -> 0.01416957
C15: サウナ | D15: 973 | E15: =IF(D$10<>0,D15/D$10,0) -> 0.11272945 | G15: =IF(F$10<>0,F15/F$10,0) -> 0 | I15: =IF(H$10<>0,H15/H$10,0) -> 0 | K15: =IF(J$10<>0,J15/J$10,0) -> 0 | M15: =IF(L$10<>0,L15/L$10,0) -> 0 | O15: =IF(N$10<>0,N15/N$10,0) -> 0 | Q15: =IF(P$10<>0,P15/P$10,0) -> 0 | S15: =IF(R$10<>0,R15/R$10,0) -> 0 | U15: =IF(T$10<>0,T15/T$10,0) -> 0 | V15: 812 | W15: =IF(V$10<>0,V15/V$10,0) -> 0.096049207 | X15: 1329 | Y15: =IF(X$10<>0,X15/X$10,0) -> 0.14738827 | Z15: 892 | AA15: =IF(Z$10<>0,Z15/Z$10,0) -> 0.10360046
B16: 売上原価 | D16: =+月次PL!C15/1000 -> 2021.276 | E16: =IF(D$10<>0,D16/D$10,0) -> 0.23418019 | F16: =+月次PL!D15/1000 -> 0 | G16: =IF(F$10<>0,F16/F$10,0) -> 0 | H16: =+月次PL!E15/1000 -> 0 | I16: =IF(H$10<>0,H16/H$10,0) -> 0 | J16: =+月次PL!F15/1000 -> 0 | K16: =IF(J$10<>0,J16/J$10,0) -> 0 | L16: =+月次PL!G15/1000 -> 0 | M16: =IF(L$10<>0,L16/L$10,0) -> 0 | N16: =+月次PL!H15/1000 -> 0 | O16: =IF(N$10<>0,N16/N$10,0) -> 0 | P16: =+月次PL!I15/1000 -> 0 | Q16: =IF(P$10<>0,P16/P$10,0) -> 0 | R16: =+月次PL!J15/1000 -> 0 | S16: =IF(R$10<>0,R16/R$10,0) -> 0 | T16: =+月次PL!K15/1000 -> 0 | U16: =IF(T$10<>0,T16/T$10,0) -> 0 | V16: =+月次PL!L15/1000 -> 0 | W16: =IF(V$10<>0,V16/V$10,0) -> 0 | X16: =+月次PL!M15/1000 -> 0 | Y16: =IF(X$10<>0,X16/X$10,0) -> 0 | Z16: =+月次PL!N15/1000 -> 0 | AA16: =IF(Z$10<>0,Z16/Z$10,0) -> 0
C17: =+C11 -> 恵愛 | D17: 1728 | E17: =IF(D11<>0,D17/D11,0) -> 0.26894942 | G17: =IF(F11<>0,F17/F11,0) -> 0 | I17: =IF(H11<>0,H17/H11,0) -> 0 | K17: =IF(J11<>0,J17/J11,0) -> 0 | M17: =IF(L11<>0,L17/L11,0) -> 0 | O17: =IF(N11<>0,N17/N11,0) -> 0 | Q17: =IF(P11<>0,P17/P11,0) -> 0 | R17: 1634 | S17: =IF(R11<>0,R17/R11,0) -> 0 | T17: 1864 | U17: =IF(T11<>0,T17/T11,0) -> 0 | V17: 1607 | W17: =IF(V11<>0,V17/V11,0) -> 0.26725428 | X17: 1751 | Y17: =IF(X11<>0,X17/X11,0) -> 0.25543399 | Z17: 1643 | AA17: =IF(Z11<>0,Z17/Z11,0) -> 0.26564268
C18: =+C12 -> 村 | D18: 122 | E18: =IF(D12<>0,D18/D12,0) -> 0.18885449 | G18: =IF(F12<>0,F18/F12,0) -> 0 | I18: =IF(H12<>0,H18/H12,0) -> 0 | K18: =IF(J12<>0,J18/J12,0) -> 0 | M18: =IF(L12<>0,L18/L12,0) -> 0 | O18: =IF(N12<>0,N18/N12,0) -> 0 | Q18: =IF(P12<>0,P18/P12,0) -> 0 | R18: 92 | S18: =IF(R12<>0,R18/R12,0) -> 0 | T18: 143 | U18: =IF(T12<>0,T18/T12,0) -> 0 | V18: 82 | W18: =IF(V12<>0,V18/V12,0) -> 0.10366625 | X18: 115 | Y18: =IF(X12<>0,X18/X12,0) -> 0 | Z18: 120 | AA18: =IF(Z12<>0,Z18/Z12,0) -> 0
C19: =+C13 -> 弁当 | D19: 126 | E19: =IF(D13<>0,D19/D13,0) -> 0.24 | G19: =IF(F13<>0,F19/F13,0) -> 0 | I19: =IF(H13<>0,H19/H13,0) -> 0 | K19: =IF(J13<>0,J19/J13,0) -> 0 | M19: =IF(L13<>0,L19/L13,0) -> 0 | O19: =IF(N13<>0,N19/N13,0) -> 0 | Q19: =IF(P13<>0,P19/P13,0) -> 0 | R19: 87 | S19: =IF(R13<>0,R19/R13,0) -> 0 | T19: 154 | U19: =IF(T13<>0,T19/T13,0) -> 0 | V19: 151 | W19: =IF(V13<>0,V19/V13,0) -> 0.41944444 | X19: 167 | Y19: =IF(X13<>0,X19/X13,0) -> 0.44533333 | Z19: 184 | AA19: =IF(Z13<>0,Z19/Z13,0) -> 0.45432099
C20: =+C14 -> シェア | D20: 19 | E20: =IF(D14<>0,D20/D14,0) -> 0.3015873 | G20: =IF(F14<>0,F20/F14,0) -> 0 | I20: =IF(H14<>0,H20/H14,0) -> 0 | K20: =IF(J14<>0,J20/J14,0) -> 0 | M20: =IF(L14<>0,L20/L14,0) -> 0 | O20: =IF(N14<>0,N20/N14,0) -> 0 | Q20: =IF(P14<>0,P20/P14,0) -> 0 | R20: 25 | S20: =IF(R14<>0,R20/R14,0) -> 0 | T20: 73 | U20: =IF(T14<>0,T20/T14,0) -> 0 | V20: 38 | W20: =IF(V14<>0,V20/V14,0) -> 0.296875 | X20: 32 | Y20: =IF(X14<>0,X20/X14,0) -> 0.2962963 | Z20: 37 | AA20: =IF(Z14<>0,Z20/Z14,0) -> 0.30327869
C21: =+C15 -> サウナ | D21: 27 | E21: =IF(D15<>0,D21/D15,0) -> 0.027749229 | G21: =IF(F15<>0,F21/F15,0) -> 0 | I21: =IF(H15<>0,H21/H15,0) -> 0 | K21: =IF(J15<>0,J21/J15,0) -> 0 | M21: =IF(L15<>0,L21/L15,0) -> 0 | O21: =IF(N15<>0,N21/N15,0) -> 0 | Q21: =IF(P15<>0,P21/P15,0) -> 0 | R21: 62 | S21: =IF(R15<>0,R21/R15,0) -> 0 | T21: 32 | U21: =IF(T15<>0,T21/T15,0) -> 0 | V21: 33 | W21: =IF(V15<>0,V21/V15,0) -> 0.040640394 | X21: 52 | Y21: =IF(X15<>0,X21/X15,0) -> 0.039127163 | Z21: 23 | AA21: =IF(Z15<>0,Z21/Z15,0) -> 0.025784753
B22: 粗利益 | D22: =+D10-D16 -> 6610.009 | E22: =IF(D$10<>0,D22/D$10,0) -> 0.76581981 | F22: =+F10-F16 -> 0 | G22: =IF(F$10<>0,F22/F$10,0) -> 0 | H22: =+H10-H16 -> 0 | I22: =IF(H$10<>0,H22/H$10,0) -> 0 | J22: =+J10-J16 -> 0 | K22: =IF(J$10<>0,J22/J$10,0) -> 0 | L22: =+L10-L16 -> 0 | M22: =IF(L$10<>0,L22/L$10,0) -> 0 | N22: =+N10-N16 -> 0 | O22: =IF(N$10<>0,N22/N$10,0) -> 0 | P22: =+P10-P16 -> 0 | Q22: =IF(P$10<>0,P22/P$10,0) -> 0 | R22: =+R10-R16 -> 0 | S22: =IF(R$10<>0,R22/R$10,0) -> 0 | T22: =+T10-T16 -> 350 | U22: =IF(T$10<>0,T22/T$10,0) -> 1 | V22: =+V10-V16 -> 8454 | W22: =IF(V$10<>0,V22/V$10,0) -> 1 | X22: =+X10-X16 -> 9017 | Y22: =IF(X$10<>0,X22/X$10,0) -> 1 | Z22: =+Z10-Z16 -> 8610 | AA22: =IF(Z$10<>0,Z22/Z$10,0) -> 1
C23: =+C17 -> 恵愛 | D23: =+D11-D17 -> 4697 | E23: =IF(D11<>0,D23/D11,0) -> 0.73105058 | F23: =+F11-F17 -> 0 | G23: =IF(F11<>0,F23/F11,0) -> 0 | H23: =+H11-H17 -> 0 | I23: =IF(H11<>0,H23/H11,0) -> 0 | J23: =+J11-J17 -> 0 | K23: =IF(J11<>0,J23/J11,0) -> 0 | L23: =+L11-L17 -> 0 | M23: =IF(L11<>0,L23/L11,0) -> 0 | N23: =+N11-N17 -> 0 | O23: =IF(N11<>0,N23/N11,0) -> 0 | P23: =+P11-P17 -> 0 | Q23: =IF(P11<>0,P23/P11,0) -> 0 | R23: =+R11-R17 -> -1634 | S23: =IF(R11<>0,R23/R11,0) -> 0 | T23: =+T11-T17 -> -1864 | U23: =IF(T11<>0,T23/T11,0) -> 0 | V23: =+V11-V17 -> 4406 | W23: =IF(V11<>0,V23/V11,0) -> 0.73274572 | X23: =+X11-X17 -> 5104 | Y23: =IF(X11<>0,X23/X11,0) -> 0.74456601 | Z23: =+Z11-Z17 -> 4542 | AA23: =IF(Z11<>0,Z23/Z11,0) -> 0.73435732
C24: =+C18 -> 村 | D24: =+D12-D18 -> 524 | E24: =IF(D12<>0,D24/D12,0) -> 0.81114551 | F24: =+F12-F18 -> 0 | G24: =IF(F12<>0,F24/F12,0) -> 0 | H24: =+H12-H18 -> 0 | I24: =IF(H12<>0,H24/H12,0) -> 0 | J24: =+J12-J18 -> 0 | K24: =IF(J12<>0,J24/J12,0) -> 0 | L24: =+L12-L18 -> 0 | M24: =IF(L12<>0,L24/L12,0) -> 0 | N24: =+N12-N18 -> 0 | O24: =IF(N12<>0,N24/N12,0) -> 0 | P24: =+P12-P18 -> 0 | Q24: =IF(P12<>0,P24/P12,0) -> 0 | R24: =+R12-R18 -> -92 | S24: =IF(R12<>0,R24/R12,0) -> 0 | T24: =+T12-T18 -> -143 | U24: =IF(T12<>0,T24/T12,0) -> 0 | V24: =+V12-V18 -> 709 | W24: =IF(V12<>0,V24/V12,0) -> 0.89633375 | X24: =+X12-X18 -> -115 | Y24: =IF(X12<>0,X24/X12,0) -> 0 | Z24: =+Z12-Z18 -> -120 | AA24: =IF(Z12<>0,Z24/Z12,0) -> 0
C25: =+C19 -> 弁当 | D25: =+D13-D19 -> 399 | E25: =IF(D13<>0,D25/D13,0) -> 0.76 | F25: =+F13-F19 -> 0 | G25: =IF(F13<>0,F25/F13,0) -> 0 | H25: =+H13-H19 -> 0 | I25: =IF(H13<>0,H25/H13,0) -> 0 | J25: =+J13-J19 -> 0 | K25: =IF(J13<>0,J25/J13,0) -> 0 | L25: =+L13-L19 -> 0 | M25: =IF(L13<>0,L25/L13,0) -> 0 | N25: =+N13-N19 -> 0 | O25: =IF(N13<>0,N25/N13,0) -> 0 | P25: =+P13-P19 -> 0 | Q25: =IF(P13<>0,P25/P13,0) -> 0 | R25: =+R13-R19 -> -87 | S25: =IF(R13<>0,R25/R13,0) -> 0 | T25: =+T13-T19 -> -154 | U25: =IF(T13<>0,T25/T13,0) -> 0 | V25: =+V13-V19 -> 209 | W25: =IF(V13<>0,V25/V13,0) -> 0.58055556 | X25: =+X13-X19 -> 208 | Y25: =IF(X13<>0,X25/X13,0) -> 0.55466667 | Z25: =+Z13-Z19 -> 221 | AA25: =IF(Z13<>0,Z25/Z13,0) -> 0.54567901
C26: =+C20 -> シェア | D26: =+D14-D20 -> 44 | E26: =IF(D14<>0,D26/D14,0) -> 0.6984127 | F26: =+F14-F20 -> 0 | G26: =IF(F14<>0,F26/F14,0) -> 0 | H26: =+H14-H20 -> 0 | I26: =IF(H14<>0,H26/H14,0) -> 0 | J26: =+J14-J20 -> 0 | K26: =IF(J14<>0,J26/J14,0) -> 0 | L26: =+L14-L20 -> 0 | M26: =IF(L14<>0,L26/L14,0) -> 0 | N26: =+N14-N20 -> 0 | O26: =IF(N14<>0,N26/N14,0) -> 0 | P26: =+P14-P20 -> 0 | Q26: =IF(P14<>0,P26/P14,0) -> 0 | R26: =+R14-R20 -> -25 | S26: =IF(R14<>0,R26/R14,0) -> 0 | T26: =+T14-T20 -> -73 | U26: =IF(T14<>0,T26/T14,0) -> 0 | V26: =+V14-V20 -> 90 | W26: =IF(V14<>0,V26/V14,0) -> 0.703125 | X26: =+X14-X20 -> 76 | Y26: =IF(X14<>0,X26/X14,0) -> 0.7037037 | Z26: =+Z14-Z20 -> 85 | AA26: =IF(Z14<>0,Z26/Z14,0) -> 0.69672131
C27: =+C21 -> サウナ | D27: =+D15-D21 -> 946 | E27: =IF(D15<>0,D27/D15,0) -> 0.97225077 | F27: =+F15-F21 -> 0 | G27: =IF(F15<>0,F27/F15,0) -> 0 | H27: =+H15-H21 -> 0 | I27: =IF(H15<>0,H27/H15,0) -> 0 | J27: =+J15-J21 -> 0 | K27: =IF(J15<>0,J27/J15,0) -> 0 | L27: =+L15-L21 -> 0 | M27: =IF(L15<>0,L27/L15,0) -> 0 | N27: =+N15-N21 -> 0 | O27: =IF(N15<>0,N27/N15,0) -> 0 | P27: =+P15-P21 -> 0 | Q27: =IF(P15<>0,P27/P15,0) -> 0 | R27: =+R15-R21 -> -62 | S27: =IF(R15<>0,R27/R15,0) -> 0 | T27: =+T15-T21 -> -32 | U27: =IF(T15<>0,T27/T15,0) -> 0 | V27: =+V15-V21 -> 779 | W27: =IF(V15<>0,V27/V15,0) -> 0.95935961 | X27: =+X15-X21 -> 1277 | Y27: =IF(X15<>0,X27/X15,0) -> 0.96087284 | Z27: =+Z15-Z21 -> 869 | AA27: =IF(Z15<>0,Z27/Z15,0) -> 0.97421525
B28: 販売管理費 | D28: =SUM(D29:D49) -> 6195.861 | E28: =IF(D$10<>0,D28/D$10,0) -> 0.71783761 | F28: =SUM(F29:F49) -> 0 | G28: =IF(F$10<>0,F28/F$10,0) -> 0 | H28: =SUM(H29:H49) -> 0 | I28: =IF(H$10<>0,H28/H$10,0) -> 0 | J28: =SUM(J29:J49) -> 0 | K28: =IF(J$10<>0,J28/J$10,0) -> 0 | L28: =SUM(L29:L49) -> 0 | M28: =IF(L$10<>0,L28/L$10,0) -> 0 | N28: =SUM(N29:N49) -> 0 | O28: =IF(N$10<>0,N28/N$10,0) -> 0 | P28: =SUM(P29:P49) -> 0 | Q28: =IF(P$10<>0,P28/P$10,0) -> 0 | R28: =SUM(R29:R49) -> 0 | S28: =IF(R$10<>0,R28/R$10,0) -> 0 | T28: =SUM(T29:T49) -> 0 | U28: =IF(T$10<>0,T28/T$10,0) -> 0 | V28: =SUM(V29:V49) -> 0 | W28: =IF(V$10<>0,V28/V$10,0) -> 0 | X28: =SUM(X29:X49) -> 0 | Y28: =IF(X$10<>0,X28/X$10,0) -> 0 | Z28: =SUM(Z29:Z49) -> 0 | AA28: =IF(Z$10<>0,Z28/Z$10,0) -> 0
C29: 人件費 | D29: =SUM(月次PL!C18:C24)/1000 -> 2462.876 | E29: =IF(D$10<>0,D29/D$10,0) -> 0.28534291 | F29: =SUM(月次PL!D18:D24)/1000 -> 0 | G29: =IF(F$10<>0,F29/F$10,0) -> 0 | H29: =SUM(月次PL!E18:E24)/1000 -> 0 | I29: =IF(H$10<>0,H29/H$10,0) -> 0 | J29: =SUM(月次PL!F18:F24)/1000 -> 0 | K29: =IF(J$10<>0,J29/J$10,0) -> 0 | L29: =SUM(月次PL!G18:G24)/1000 -> 0 | M29: =IF(L$10<>0,L29/L$10,0) -> 0 | N29: =SUM(月次PL!H18:H24)/1000 -> 0 | O29: =IF(N$10<>0,N29/N$10,0) -> 0 | P29: =SUM(月次PL!I18:I24)/1000 -> 0 | Q29: =IF(P$10<>0,P29/P$10,0) -> 0 | R29: =SUM(月次PL!J18:J24)/1000 -> 0 | S29: =IF(R$10<>0,R29/R$10,0) -> 0 | T29: =SUM(月次PL!K18:K24)/1000 -> 0 | U29: =IF(T$10<>0,T29/T$10,0) -> 0 | V29: =SUM(月次PL!L18:L24)/1000 -> 0 | W29: =IF(V$10<>0,V29/V$10,0) -> 0 | X29: =SUM(月次PL!M18:M24)/1000 -> 0 | Y29: =IF(X$10<>0,X29/X$10,0) -> 0 | Z29: =SUM(月次PL!N18:N24)/1000 -> 0 | AA29: =IF(Z$10<>0,Z29/Z$10,0) -> 0
C30: 旅費交通費 | D30: =+月次PL!C27/1000 -> 41.261 | E30: =IF(D$10<>0,D30/D$10,0) -> 0.0047804006 | F30: =+月次PL!D27/1000 -> 0 | G30: =IF(F$10<>0,F30/F$10,0) -> 0 | H30: =+月次PL!E27/1000 -> 0 | I30: =IF(H$10<>0,H30/H$10,0) -> 0 | J30: =+月次PL!F27/1000 -> 0 | K30: =IF(J$10<>0,J30/J$10,0) -> 0 | L30: =+月次PL!G27/1000 -> 0 | M30: =IF(L$10<>0,L30/L$10,0) -> 0 | N30: =+月次PL!H27/1000 -> 0 | O30: =IF(N$10<>0,N30/N$10,0) -> 0 | P30: =+月次PL!I27/1000 -> 0 | Q30: =IF(P$10<>0,P30/P$10,0) -> 0 | R30: =+月次PL!J27/1000 -> 0 | S30: =IF(R$10<>0,R30/R$10,0) -> 0 | T30: =+月次PL!K27/1000 -> 0 | U30: =IF(T$10<>0,T30/T$10,0) -> 0 | V30: =+月次PL!L27/1000 -> 0 | W30: =IF(V$10<>0,V30/V$10,0) -> 0 | X30: =+月次PL!M27/1000 -> 0 | Y30: =IF(X$10<>0,X30/X$10,0) -> 0 | Z30: =+月次PL!N27/1000 -> 0 | AA30: =IF(Z$10<>0,Z30/Z$10,0) -> 0
C31: 通信費 | D31: =+月次PL!C28/1000 -> 62.422 | E31: =IF(D$10<>0,D31/D$10,0) -> 0.0072320634 | F31: =+月次PL!D28/1000 -> 0 | G31: =IF(F$10<>0,F31/F$10,0) -> 0 | H31: =+月次PL!E28/1000 -> 0 | I31: =IF(H$10<>0,H31/H$10,0) -> 0 | J31: =+月次PL!F28/1000 -> 0 | K31: =IF(J$10<>0,J31/J$10,0) -> 0 | L31: =+月次PL!G28/1000 -> 0 | M31: =IF(L$10<>0,L31/L$10,0) -> 0 | N31: =+月次PL!H28/1000 -> 0 | O31: =IF(N$10<>0,N31/N$10,0) -> 0 | P31: =+月次PL!I28/1000 -> 0 | Q31: =IF(P$10<>0,P31/P$10,0) -> 0 | R31: =+月次PL!J28/1000 -> 0 | S31: =IF(R$10<>0,R31/R$10,0) -> 0 | T31: =+月次PL!K28/1000 -> 0 | U31: =IF(T$10<>0,T31/T$10,0) -> 0 | V31: =+月次PL!L28/1000 -> 0 | W31: =IF(V$10<>0,V31/V$10,0) -> 0 | X31: =+月次PL!M28/1000 -> 0 | Y31: =IF(X$10<>0,X31/X$10,0) -> 0 | Z31: =+月次PL!N28/1000 -> 0 | AA31: =IF(Z$10<>0,Z31/Z$10,0) -> 0
C32: 開発費 | D32: =+月次PL!C43/1000 -> 0 | E32: =IF(D$10<>0,D32/D$10,0) -> 0 | F32: =+月次PL!D43/1000 -> 0 | G32: =IF(F$10<>0,F32/F$10,0) -> 0 | H32: =+月次PL!E43/1000 -> 0 | I32: =IF(H$10<>0,H32/H$10,0) -> 0 | J32: =+月次PL!F43/1000 -> 0 | K32: =IF(J$10<>0,J32/J$10,0) -> 0 | L32: =+月次PL!G43/1000 -> 0 | M32: =IF(L$10<>0,L32/L$10,0) -> 0 | N32: =+月次PL!H43/1000 -> 0 | O32: =IF(N$10<>0,N32/N$10,0) -> 0 | P32: =+月次PL!I43/1000 -> 0 | Q32: =IF(P$10<>0,P32/P$10,0) -> 0 | R32: =+月次PL!J43/1000 -> 0 | S32: =IF(R$10<>0,R32/R$10,0) -> 0 | T32: =+月次PL!K43/1000 -> 0 | U32: =IF(T$10<>0,T32/T$10,0) -> 0 | V32: =+月次PL!L43/1000 -> 0 | W32: =IF(V$10<>0,V32/V$10,0) -> 0 | X32: =+月次PL!M43/1000 -> 0 | Y32: =IF(X$10<>0,X32/X$10,0) -> 0 | Z32: =+月次PL!N43/1000 -> 0 | AA32: =IF(Z$10<>0,Z32/Z$10,0) -> 0
C33: 交際費 | D33: =+月次PL!C26/1000 -> 0 | E33: =IF(D$10<>0,D33/D$10,0) -> 0 | F33: =+月次PL!D26/1000 -> 0 | G33: =IF(F$10<>0,F33/F$10,0) -> 0 | H33: =+月次PL!E26/1000 -> 0 | I33: =IF(H$10<>0,H33/H$10,0) -> 0 | J33: =+月次PL!F26/1000 -> 0 | K33: =IF(J$10<>0,J33/J$10,0) -> 0 | L33: =+月次PL!G26/1000 -> 0 | M33: =IF(L$10<>0,L33/L$10,0) -> 0 | N33: =+月次PL!H26/1000 -> 0 | O33: =IF(N$10<>0,N33/N$10,0) -> 0 | P33: =+月次PL!I26/1000 -> 0 | Q33: =IF(P$10<>0,P33/P$10,0) -> 0 | R33: =+月次PL!J26/1000 -> 0 | S33: =IF(R$10<>0,R33/R$10,0) -> 0 | T33: =+月次PL!K26/1000 -> 0 | U33: =IF(T$10<>0,T33/T$10,0) -> 0 | V33: =+月次PL!L26/1000 -> 0 | W33: =IF(V$10<>0,V33/V$10,0) -> 0 | X33: =+月次PL!M26/1000 -> 0 | Y33: =IF(X$10<>0,X33/X$10,0) -> 0 | Z33: =+月次PL!N26/1000 -> 0 | AA33: =IF(Z$10<>0,Z33/Z$10,0) -> 0
C34: 会議費 | D34: =+月次PL!C38/1000 -> 7.273 | E34: =IF(D$10<>0,D34/D$10,0) -> 0.00084263235 | F34: =+月次PL!D38/1000 -> 0 | G34: =IF(F$10<>0,F34/F$10,0) -> 0 | H34: =+月次PL!E38/1000 -> 0 | I34: =IF(H$10<>0,H34/H$10,0) -> 0 | J34: =+月次PL!F38/1000 -> 0 | K34: =IF(J$10<>0,J34/J$10,0) -> 0 | L34: =+月次PL!G38/1000 -> 0 | M34: =IF(L$10<>0,L34/L$10,0) -> 0 | N34: =+月次PL!H38/1000 -> 0 | O34: =IF(N$10<>0,N34/N$10,0) -> 0 | P34: =+月次PL!I38/1000 -> 0 | Q34: =IF(P$10<>0,P34/P$10,0) -> 0 | R34: =+月次PL!J38/1000 -> 0 | S34: =IF(R$10<>0,R34/R$10,0) -> 0 | T34: =+月次PL!K38/1000 -> 0 | U34: =IF(T$10<>0,T34/T$10,0) -> 0 | V34: =+月次PL!L38/1000 -> 0 | W34: =IF(V$10<>0,V34/V$10,0) -> 0 | X34: =+月次PL!M38/1000 -> 0 | Y34: =IF(X$10<>0,X34/X$10,0) -> 0 | Z34: =+月次PL!N38/1000 -> 0 | AA34: =IF(Z$10<>0,Z34/Z$10,0) -> 0
C35: 減価償却費 | D35: =+月次PL!C40/1000 -> 749.954 | E35: =IF(D$10<>0,D35/D$10,0) -> 0.086887874 | F35: =+月次PL!D40/1000 -> 0 | G35: =IF(F$10<>0,F35/F$10,0) -> 0 | H35: =+月次PL!E40/1000 -> 0 | I35: =IF(H$10<>0,H35/H$10,0) -> 0 | J35: =+月次PL!F40/1000 -> 0 | K35: =IF(J$10<>0,J35/J$10,0) -> 0 | L35: =+月次PL!G40/1000 -> 0 | M35: =IF(L$10<>0,L35/L$10,0) -> 0 | N35: =+月次PL!H40/1000 -> 0 | O35: =IF(N$10<>0,N35/N$10,0) -> 0 | P35: =+月次PL!I40/1000 -> 0 | Q35: =IF(P$10<>0,P35/P$10,0) -> 0 | R35: =+月次PL!J40/1000 -> 0 | S35: =IF(R$10<>0,R35/R$10,0) -> 0 | T35: =+月次PL!K40/1000 -> 0 | U35: =IF(T$10<>0,T35/T$10,0) -> 0 | V35: =+月次PL!L40/1000 -> 0 | W35: =IF(V$10<>0,V35/V$10,0) -> 0 | X35: =+月次PL!M40/1000 -> 0 | Y35: =IF(X$10<>0,X35/X$10,0) -> 0 | Z35: =+月次PL!N40/1000 -> 0 | AA35: =IF(Z$10<>0,Z35/Z$10,0) -> 0
C36: 賃借料 | D36: =+月次PL!C34/1000 -> 30 | E36: =IF(D$10<>0,D36/D$10,0) -> 0.0034757281 | F36: =+月次PL!D34/1000 -> 0 | G36: =IF(F$10<>0,F36/F$10,0) -> 0 | H36: =+月次PL!E34/1000 -> 0 | I36: =IF(H$10<>0,H36/H$10,0) -> 0 | J36: =+月次PL!F34/1000 -> 0 | K36: =IF(J$10<>0,J36/J$10,0) -> 0 | L36: =+月次PL!G34/1000 -> 0 | M36: =IF(L$10<>0,L36/L$10,0) -> 0 | N36: =+月次PL!H34/1000 -> 0 | O36: =IF(N$10<>0,N36/N$10,0) -> 0 | P36: =+月次PL!I34/1000 -> 0 | Q36: =IF(P$10<>0,P36/P$10,0) -> 0 | R36: =+月次PL!J34/1000 -> 0 | S36: =IF(R$10<>0,R36/R$10,0) -> 0 | T36: =+月次PL!K34/1000 -> 0 | U36: =IF(T$10<>0,T36/T$10,0) -> 0 | V36: =+月次PL!L34/1000 -> 0 | W36: =IF(V$10<>0,V36/V$10,0) -> 0 | X36: =+月次PL!M34/1000 -> 0 | Y36: =IF(X$10<>0,X36/X$10,0) -> 0 | Z36: =+月次PL!N34/1000 -> 0 | AA36: =IF(Z$10<>0,Z36/Z$10,0) -> 0
C37: 地代家賃 | D37: =+月次PL!C33/1000 -> 1295.661 | E37: =IF(D$10<>0,D37/D$10,0) -> 0.15011218 | F37: =+月次PL!D33/1000 -> 0 | G37: =IF(F$10<>0,F37/F$10,0) -> 0 | H37: =+月次PL!E33/1000 -> 0 | I37: =IF(H$10<>0,H37/H$10,0) -> 0 | J37: =+月次PL!F33/1000 -> 0 | K37: =IF(J$10<>0,J37/J$10,0) -> 0 | L37: =+月次PL!G33/1000 -> 0 | M37: =IF(L$10<>0,L37/L$10,0) -> 0 | N37: =+月次PL!H33/1000 -> 0 | O37: =IF(N$10<>0,N37/N$10,0) -> 0 | P37: =+月次PL!I33/1000 -> 0 | Q37: =IF(P$10<>0,P37/P$10,0) -> 0 | R37: =+月次PL!J33/1000 -> 0 | S37: =IF(R$10<>0,R37/R$10,0) -> 0 | T37: =+月次PL!K33/1000 -> 0 | U37: =IF(T$10<>0,T37/T$10,0) -> 0 | V37: =+月次PL!L33/1000 -> 0 | W37: =IF(V$10<>0,V37/V$10,0) -> 0 | X37: =+月次PL!M33/1000 -> 0 | Y37: =IF(X$10<>0,X37/X$10,0) -> 0 | Z37: =+月次PL!N33/1000 -> 0 | AA37: =IF(Z$10<>0,Z37/Z$10,0) -> 0
C38: リース料 | D38: =+月次PL!C32/1000 -> 49.7 | E38: =IF(D$10<>0,D38/D$10,0) -> 0.0057581229 | F38: =+月次PL!D32/1000 -> 0 | G38: =IF(F$10<>0,F38/F$10,0) -> 0 | H38: =+月次PL!E32/1000 -> 0 | I38: =IF(H$10<>0,H38/H$10,0) -> 0 | J38: =+月次PL!F32/1000 -> 0 | K38: =IF(J$10<>0,J38/J$10,0) -> 0 | L38: =+月次PL!G32/1000 -> 0 | M38: =IF(L$10<>0,L38/L$10,0) -> 0 | N38: =+月次PL!H32/1000 -> 0 | O38: =IF(N$10<>0,N38/N$10,0) -> 0 | P38: =+月次PL!I32/1000 -> 0 | Q38: =IF(P$10<>0,P38/P$10,0) -> 0 | R38: =+月次PL!J32/1000 -> 0 | S38: =IF(R$10<>0,R38/R$10,0) -> 0 | T38: =+月次PL!K32/1000 -> 0 | U38: =IF(T$10<>0,T38/T$10,0) -> 0 | V38: =+月次PL!L32/1000 -> 0 | W38: =IF(V$10<>0,V38/V$10,0) -> 0 | X38: =+月次PL!M32/1000 -> 0 | Y38: =IF(X$10<>0,X38/X$10,0) -> 0 | Z38: =+月次PL!N32/1000 -> 0 | AA38: =IF(Z$10<>0,Z38/Z$10,0) -> 0
C39: 修繕費 | D39: =+月次PL!C30/1000 -> 0 | E39: =IF(D$10<>0,D39/D$10,0) -> 0 | F39: =+月次PL!D30/1000 -> 0 | G39: =IF(F$10<>0,F39/F$10,0) -> 0 | H39: =+月次PL!E30/1000 -> 0 | I39: =IF(H$10<>0,H39/H$10,0) -> 0 | J39: =+月次PL!F30/1000 -> 0 | K39: =IF(J$10<>0,J39/J$10,0) -> 0 | L39: =+月次PL!G30/1000 -> 0 | M39: =IF(L$10<>0,L39/L$10,0) -> 0 | N39: =+月次PL!H30/1000 -> 0 | O39: =IF(N$10<>0,N39/N$10,0) -> 0 | P39: =+月次PL!I30/1000 -> 0 | Q39: =IF(P$10<>0,P39/P$10,0) -> 0 | R39: =+月次PL!J30/1000 -> 0 | S39: =IF(R$10<>0,R39/R$10,0) -> 0 | T39: =+月次PL!K30/1000 -> 0 | U39: =IF(T$10<>0,T39/T$10,0) -> 0 | V39: =+月次PL!L30/1000 -> 0 | W39: =IF(V$10<>0,V39/V$10,0) -> 0 | X39: =+月次PL!M30/1000 -> 0 | Y39: =IF(X$10<>0,X39/X$10,0) -> 0 | Z39: =+月次PL!N30/1000 -> 0 | AA39: =IF(Z$10<>0,Z39/Z$10,0) -> 0
C40: 保険料 | D40: =+月次PL!C35/1000 -> 28.375 | E40: =IF(D$10<>0,D40/D$10,0) -> 0.0032874595 | F40: =+月次PL!D35/1000 -> 0 | G40: =IF(F$10<>0,F40/F$10,0) -> 0 | H40: =+月次PL!E35/1000 -> 0 | I40: =IF(H$10<>0,H40/H$10,0) -> 0 | J40: =+月次PL!F35/1000 -> 0 | K40: =IF(J$10<>0,J40/J$10,0) -> 0 | L40: =+月次PL!G35/1000 -> 0 | M40: =IF(L$10<>0,L40/L$10,0) -> 0 | N40: =+月次PL!H35/1000 -> 0 | O40: =IF(N$10<>0,N40/N$10,0) -> 0 | P40: =+月次PL!I35/1000 -> 0 | Q40: =IF(P$10<>0,P40/P$10,0) -> 0 | R40: =+月次PL!J35/1000 -> 0 | S40: =IF(R$10<>0,R40/R$10,0) -> 0 | T40: =+月次PL!K35/1000 -> 0 | U40: =IF(T$10<>0,T40/T$10,0) -> 0 | V40: =+月次PL!L35/1000 -> 0 | W40: =IF(V$10<>0,V40/V$10,0) -> 0 | X40: =+月次PL!M35/1000 -> 0 | Y40: =IF(X$10<>0,X40/X$10,0) -> 0 | Z40: =+月次PL!N35/1000 -> 0 | AA40: =IF(Z$10<>0,Z40/Z$10,0) -> 0
C41: 水道光熱費 | D41: =+月次PL!C29/1000 -> 659.468 | E41: =IF(D$10<>0,D41/D$10,0) -> 0.076404382 | F41: =+月次PL!D29/1000 -> 0 | G41: =IF(F$10<>0,F41/F$10,0) -> 0 | H41: =+月次PL!E29/1000 -> 0 | I41: =IF(H$10<>0,H41/H$10,0) -> 0 | J41: =+月次PL!F29/1000 -> 0 | K41: =IF(J$10<>0,J41/J$10,0) -> 0 | L41: =+月次PL!G29/1000 -> 0 | M41: =IF(L$10<>0,L41/L$10,0) -> 0 | N41: =+月次PL!H29/1000 -> 0 | O41: =IF(N$10<>0,N41/N$10,0) -> 0 | P41: =+月次PL!I29/1000 -> 0 | Q41: =IF(P$10<>0,P41/P$10,0) -> 0 | R41: =+月次PL!J29/1000 -> 0 | S41: =IF(R$10<>0,R41/R$10,0) -> 0 | T41: =+月次PL!K29/1000 -> 0 | U41: =IF(T$10<>0,T41/T$10,0) -> 0 | V41: =+月次PL!L29/1000 -> 0 | W41: =IF(V$10<>0,V41/V$10,0) -> 0 | X41: =+月次PL!M29/1000 -> 0 | Y41: =IF(X$10<>0,X41/X$10,0) -> 0 | Z41: =+月次PL!N29/1000 -> 0 | AA41: =IF(Z$10<>0,Z41/Z$10,0) -> 0
...

Sheet PL予実対比
A7: ■月次PL予実対比
A8: =+PL推移!B8 -> 2026 | B8: 年度 | C8: 注意事項 | D8: 概算値 | E8: 異常値 | F8: 特記事項 | G8: 予算検討 | BB8: 単位：千円
A9: 項目 | C9: =+PL推移!D9 -> 7月 | G9: =+PL推移!F9 -> 8月 | K9: =+PL推移!H9 -> 9月 | O9: =+PL推移!J9 -> 10月 | S9: =+PL推移!L9 -> 11月 | W9: =+PL推移!N9 -> 12月 | AA9: =+PL推移!P9 -> 1月 | AE9: =+PL推移!R9 -> 2月 | AI9: =+PL推移!T9 -> 3 | AM9: =+PL推移!V9 -> 4 | AQ9: =+PL推移!X9 -> 5月 | AU9: =+PL推移!Z9 -> 6月 | AY9: 累計 | BC9: =+PL推移!N9 -> 12月 | BE9: =+PL推移!P9 -> 1月 | BG9: =+PL推移!R9 -> 2月 | BI9: =+PL推移!T9 -> 3 | BK9: =+PL推移!V9 -> 4 | BM9: =+PL推移!X9 -> 5月 | BO9: =+PL推移!Z9 -> 6月
C10: 計画 | D10: 実績 | E10: 差異 | F10: 計画比 | G10: 計画 | H10: 実績 | I10: 差異 | J10: 計画比 | K10: 計画 | L10: 実績 | M10: 差異 | N10: 計画比 | O10: 計画 | P10: 実績 | Q10: 差異 | R10: 計画比 | S10: 計画 | T10: 実績 | U10: 差異 | V10: 計画比 | W10: 計画 | X10: 実績 | Y10: 差異 | Z10: 計画比 | AA10: 計画 | AB10: 実績 | AC10: 差異 | AD10: 計画比 | AE10: 計画 | AF10: 実績 | AG10: 差異 | AH10: 計画比 | AI10: 計画 | AJ10: 実績 | AK10: 差異 | AL10: 計画比 | AM10: 計画 | AN10: 実績 | AO10: 差異 | AP10: 計画比 | AQ10: 計画 | AR10: 実績 | AS10: 差異 | AT10: 計画比 | AU10: 計画 | AV10: 実績 | AW10: 差異 | AX10: 計画比 | AY10: 計画 | AZ10: 実績 | BA10: 差異 | BB10: 計画比
A11: 売上高 | C11: =+収支計画!G17/1000 -> 9250 | D11: =+PL推移!D10 -> 8631.285 | E11: =SUM(E12:E16) -> -618 | F11: =IF(C11<>0,D11/C11,"-") -> 0.93311189 | G11: =SUM(G12:G16) -> 9250 | H11: =SUM(H12:H16) -> 0 | I11: =SUM(I12:I16) -> -9250 | J11: =IF(G11<>0,H11/G11,"-") -> 0 | K11: =SUM(K12:K16) -> 10750 | L11: =+PL推移!H10 -> 0 | M11: =SUM(M12:M16) -> -10750 | N11: =IF(K11<>0,L11/K11,"-") -> 0 | O11: =SUM(O12:O16) -> 0 | P11: =+PL推移!J10 -> 0 | Q11: =SUM(Q12:Q16) -> 0 | R11: =IF(O11<>0,P11/O11,"-") -> - | S11: =SUM(S12:S16) -> 0 | T11: =+PL推移!L10 -> 0 | U11: =SUM(U12:U16) -> 0 | V11: =IF(S11<>0,T11/S11,"-") -> - | W11: =SUM(W12:W16) -> 0 | X11: =+PL推移!N10 -> 0 | Y11: =SUM(Y12:Y16) -> 0 | Z11: =IF(W11<>0,X11/W11,"-") -> - | AA11: =SUM(AA12:AA16) -> 0 | AB11: =+PL推移!P10 -> 0 | AC11: =SUM(AC12:AC16) -> 0 | AD11: =IF(AA11<>0,AB11/AA11,"-") -> - | AE11: =SUM(AE12:AE16) -> 0 | AF11: =+PL推移!R10 -> 0 | AG11: =SUM(AG12:AG16) -> 0 | AH11: =IF(AE11<>0,AF11/AE11,"-") -> - | AI11: =SUM(AI12:AI16) -> 0 | AJ11: =+PL推移!T10 -> 350 | AK11: =SUM(AK12:AK16) -> 0 | AL11: =IF(AI11<>0,AJ11/AI11,"-") -> - | AM11: =+収支計画!AE17/1000 -> 0 | AN11: =+PL推移!V10 -> 8454 | AO11: =+AN11-AM11 -> 8454 | AP11: =IF(AM11<>0,AN11/AM11,"-") -> - | AQ11: =+収支計画!AI17/1000 -> 0 | AR11: =+PL推移!X10 -> 9017 | AS11: =+AR11-AQ11 -> 9017 | AT11: =IF(AQ11<>0,AR11/AQ11,"-") -> - | AU11: =+収支計画!AI17/1000 -> 0 | AV11: =+PL推移!Z10 -> 8610 | AW11: =+AV11-AU11 -> 8610 | AX11: =IF(AU11<>0,AV11/AU11,"-") -> - | AY11: =+C11+G11+K11+O11+S11+W11+AA11+AE11+AI11+AM11+AQ11+AU11 -> 29250 | AZ11: =+D11+H11+L11+P11+T11+X11+AB11+AF11+AJ11+AN11+AR11+AV11 -> 35062.285 | BA11: =+AZ11-AY11 -> 5812.285 | BB11: =IF(AY11<>0,AZ11/AY11,"-") -> 1.1987106 | BC11: =+PL推移!N10-収支計画!W17/1000 -> 0 | BD11: =+BC11/(収支計画!W17/1000) -> #DIV/0! | BE11: =+PL推移!P10-収支計画!Y17/1000 -> 0 | BF11: =+BE11/(収支計画!Y17/1000) -> #DIV/0! | BG11: =+PL推移!R10-収支計画!AA17/1000 -> 0 | BH11: =+BG11/(収支計画!AA17/1000) -> #DIV/0! | BI11: =+PL推移!T10-収支計画!AC17/1000 -> 350 | BJ11: =+BI11/(収支計画!AC17/1000) -> #DIV/0! | BK11: =+PL推移!V10-収支計画!AE17/1000 -> 8454 | BL11: =+BK11/(収支計画!AE17/1000) -> #DIV/0! | BM11: =+PL推移!X10-収支計画!AG17/1000 -> 9017 | BN11: =+BM11/(収支計画!AG17/1000) -> #DIV/0! | BO11: =+PL推移!Z10-収支計画!AI17/1000 -> 8610 | BP11: =+BO11/(収支計画!AI17/1000) -> #DIV/0!
B12: 恵愛 | C12: =+収支計画!G11/1000 -> 7000 | D12: =+PL推移!D11 -> 6425 | E12: =+D12-C12 -> -575 | F12: =IF(C12<>0,D12/C12,"-") -> 0.91785714 | G12: =+収支計画!K11/1000 -> 7000 | H12: =+PL推移!F11 -> 0 | I12: =+H12-G12 -> -7000 | J12: =IF(G12<>0,H12/G12,"-") -> 0 | K12: =+収支計画!O11/1000 -> 8500 | L12: =+PL推移!H11 -> 0 | M12: =+L12-K12 -> -8500 | N12: =IF(K12<>0,L12/K12,"-") -> 0 | O12: =+収支計画!S11/1000 -> 0 | P12: =+PL推移!J11 -> 0 | Q12: =+P12-O12 -> 0 | R12: =IF(O12<>0,P12/O12,"-") -> - | S12: =+収支計画!U11/1000 -> 0 | T12: =+PL推移!L11 -> 0 | U12: =+T12-S12 -> 0 | V12: =IF(S12<>0,T12/S12,"-") -> - | W12: =+収支計画!W11/1000 -> 0 | X12: =+PL推移!N11 -> 0 | Y12: =+X12-W12 -> 0 | Z12: =IF(W12<>0,X12/W12,"-") -> - | AA12: =+収支計画!AA11/1000 -> 0 | AB12: =+PL推移!P11 -> 0 | AC12: =+AB12-AA12 -> 0 | AD12: =IF(AA12<>0,AB12/AA12,"-") -> - | AE12: =+収支計画!AA11/1000 -> 0 | AF12: =+PL推移!R11 -> 0 | AG12: =+AF12-AE12 -> 0 | AH12: =IF(AE12<>0,AF12/AE12,"-") -> - | AI12: =+収支計画!AC11/1000 -> 0 | AJ12: =+PL推移!T11 -> 0 | AK12: =+AJ12-AI12 -> 0 | AL12: =IF(AI12<>0,AJ12/AI12,"-") -> - | AM12: =+収支計画!AG11/1000 -> 0 | AN12: =+PL推移!V11 -> 6013 | AO12: =+AN12-AM12 -> 6013 | AP12: =IF(AM12<>0,AN12/AM12,"-") -> - | AQ12: =+収支計画!AG11/1000 -> 0 | AR12: =+PL推移!X11 -> 6855 | AS12: =+AR12-AQ12 -> 6855 | AT12: =IF(AQ12<>0,AR12/AQ12,"-") -> - | AU12: =+収支計画!AI11/1000 -> 0 | AV12: =+PL推移!Z11 -> 6185 | AW12: =+AV12-AU12 -> 6185 | AX12: =IF(AU12<>0,AV12/AU12,"-") -> - | AY12: =+C12+G12+K12+O12+S12+W12+AA12+AE12+AI12+AM12+AQ12+AU12 -> 22500 | AZ12: =+D12+H12+L12+P12+T12+X12+AB12+AF12+AJ12+AN12+AR12+AV12 -> 25478 | BA12: =+AZ12-AY12 -> 2978 | BB12: =IF(AY12<>0,AZ12/AY12,"-") -> 1.1323556 | BC12: =+PL推移!N11-収支計画!W11/1000 -> 0 | BD12: =+BC12/(収支計画!W11/1000) -> #DIV/0! | BE12: =+PL推移!P11-収支計画!Y11/1000 -> 0 | BF12: =+BE12/(収支計画!Y11/1000) -> #DIV/0! | BG12: =+PL推移!R11-収支計画!AA11/1000 -> 0 | BH12: =+BG12/(収支計画!AA11/1000) -> #DIV/0! | BI12: =+PL推移!T11-収支計画!AC11/1000 -> 0 | BJ12: =+BI12/(収支計画!AC11/1000) -> #DIV/0! | BK12: =+PL推移!V11-収支計画!AE11/1000 -> 6013 | BL12: =+BK12/(収支計画!AE11/1000) -> #DIV/0! | BM12: =+PL推移!X11-収支計画!AG11/1000 -> 6855 | BN12: =+BM12/(収支計画!AG11/1000) -> #DIV/0! | BO12: =+PL推移!Z11-収支計画!AI11/1000 -> 6185 | BP12: =+BO12/(収支計画!AI11/1000) -> #DIV/0!
B13: 村 | C13: =+収支計画!G12/1000 -> 750 | D13: =+PL推移!D12 -> 646 | E13: =+D13-C13 -> -104 | F13: =IF(C13<>0,D13/C13,"-") -> 0.86133333 | G13: =+収支計画!K12/1000 -> 750 | H13: =+PL推移!F12 -> 0 | I13: =+H13-G13 -> -750 | J13: =IF(G13<>0,H13/G13,"-") -> 0 | K13: =+収支計画!O12/1000 -> 750 | L13: =+PL推移!H12 -> 0 | M13: =+L13-K13 -> -750 | N13: =IF(K13<>0,L13/K13,"-") -> 0 | O13: =+収支計画!S12/1000 -> 0 | P13: =+PL推移!J12 -> 0 | Q13: =+P13-O13 -> 0 | R13: =IF(O13<>0,P13/O13,"-") -> - | S13: =+収支計画!U12/1000 -> 0 | T13: =+PL推移!L12 -> 0 | U13: =+T13-S13 -> 0 | V13: =IF(S13<>0,T13/S13,"-") -> - | W13: =+収支計画!W12/1000 -> 0 | X13: =+PL推移!N12 -> 0 | Y13: =+X13-W13 -> 0 | Z13: =IF(W13<>0,X13/W13,"-") -> - | AA13: =+収支計画!AA12/1000 -> 0 | AB13: =+PL推移!P12 -> 0 | AC13: =+AB13-AA13 -> 0 | AD13: =IF(AA13<>0,AB13/AA13,"-") -> - | AE13: =+収支計画!AA12/1000 -> 0 | AF13: =+PL推移!R12 -> 0 | AG13: =+AF13-AE13 -> 0 | AH13: =IF(AE13<>0,AF13/AE13,"-") -> - | AI13: =+収支計画!AC12/1000 -> 0 | AJ13: =+PL推移!T12 -> 0 | AK13: =+AJ13-AI13 -> 0 | AL13: =IF(AI13<>0,AJ13/AI13,"-") -> - | AM13: =+収支計画!AG12/1000 -> 0 | AN13: =+PL推移!V12 -> 791 | AO13: =+AN13-AM13 -> 791 | AP13: =IF(AM13<>0,AN13/AM13,"-") -> - | AQ13: =+収支計画!AG12/1000 -> 0 | AR13: =+PL推移!X12 -> 0 | AS13: =+AR13-AQ13 -> 0 | AT13: =IF(AQ13<>0,AR13/AQ13,"-") -> - | AU13: =+収支計画!AI12/1000 -> 0 | AV13: =+PL推移!Z12 -> 0 | AW13: =+AV13-AU13 -> 0 | AX13: =IF(AU13<>0,AV13/AU13,"-") -> - | AY13: =+C13+G13+K13+O13+S13+W13+AA13+AE13+AI13+AM13+AQ13+AU13 -> 2250 | AZ13: =+D13+H13+L13+P13+T13+X13+AB13+AF13+AJ13+AN13+AR13+AV13 -> 1437 | BA13: =+AZ13-AY13 -> -813 | BB13: =IF(AY13<>0,AZ13/AY13,"-") -> 0.63866667 | BC13: =+PL推移!N12-収支計画!W12/1000 -> 0 | BD13: =+BC13/(収支計画!W12/1000) -> #DIV/0! | BE13: =+PL推移!P12-収支計画!Y12/1000 -> 0 | BF13: =+BE13/(収支計画!Y12/1000) -> #DIV/0! | BG13: =+PL推移!R12-収支計画!AA12/1000 -> 0 | BH13: =+BG13/(収支計画!AA12/1000) -> #DIV/0! | BI13: =+PL推移!T12-収支計画!AC12/1000 -> 0 | BJ13: =+BI13/(収支計画!AC12/1000) -> #DIV/0! | BK13: =+PL推移!V12-収支計画!AE12/1000 -> 791 | BL13: =+BK13/(収支計画!AE12/1000) -> #DIV/0! | BM13: =+PL推移!X12-収支計画!AG12/1000 -> 0 | BN13: =+BM13/(収支計画!AG12/1000) -> #DIV/0! | BO13: =+PL推移!Z12-収支計画!AI12/1000 -> 0 | BP13: =+BO13/(収支計画!AI12/1000) -> #DIV/0!
B14: 弁当 | C14: =+収支計画!G13/1000 -> 350 | D14: =+PL推移!D13 -> 525 | E14: =+D14-C14 -> 175 | F14: =IF(C14<>0,D14/C14,"-") -> 1.5 | G14: =+収支計画!K13/1000 -> 350 | H14: =+PL推移!F13 -> 0 | I14: =+H14-G14 -> -350 | J14: =IF(G14<>0,H14/G14,"-") -> 0 | K14: =+収支計画!O13/1000 -> 350 | L14: =+PL推移!H13 -> 0 | M14: =+L14-K14 -> -350 | N14: =IF(K14<>0,L14/K14,"-") -> 0 | O14: =+収支計画!S13/1000 -> 0 | P14: =+PL推移!J13 -> 0 | Q14: =+P14-O14 -> 0 | R14: =IF(O14<>0,P14/O14,"-") -> - | S14: =+収支計画!U13/1000 -> 0 | T14: =+PL推移!L13 -> 0 | U14: =+T14-S14 -> 0 | V14: =IF(S14<>0,T14/S14,"-") -> - | W14: =+収支計画!W13/1000 -> 0 | X14: =+PL推移!N13 -> 0 | Y14: =+X14-W14 -> 0 | Z14: =IF(W14<>0,X14/W14,"-") -> - | AA14: =+収支計画!AA13/1000 -> 0 | AB14: =+PL推移!P13 -> 0 | AC14: =+AB14-AA14 -> 0 | AD14: =IF(AA14<>0,AB14/AA14,"-") -> - | AE14: =+収支計画!AA13/1000 -> 0 | AF14: =+PL推移!R13 -> 0 | AG14: =+AF14-AE14 -> 0 | AH14: =IF(AE14<>0,AF14/AE14,"-") -> - | AI14: =+収支計画!AC13/1000 -> 0 | AJ14: =+PL推移!T13 -> 0 | AK14: =+AJ14-AI14 -> 0 | AL14: =IF(AI14<>0,AJ14/AI14,"-") -> - | AM14: =+収支計画!AG13/1000 -> 0 | AN14: =+PL推移!V13 -> 360 | AO14: =+AN14-AM14 -> 360 | AP14: =IF(AM14<>0,AN14/AM14,"-") -> - | AQ14: =+収支計画!AG13/1000 -> 0 | AR14: =+PL推移!X13 -> 375 | AS14: =+AR14-AQ14 -> 375 | AT14: =IF(AQ14<>0,AR14/AQ14,"-") -> - | AU14: =+収支計画!AI13/1000 -> 0 | AV14: =+PL推移!Z13 -> 405 | AW14: =+AV14-AU14 -> 405 | AX14: =IF(AU14<>0,AV14/AU14,"-") -> - | AY14: =+C14+G14+K14+O14+S14+W14+AA14+AE14+AI14+AM14+AQ14+AU14 -> 1050 | AZ14: =+D14+H14+L14+P14+T14+X14+AB14+AF14+AJ14+AN14+AR14+AV14 -> 1665 | BA14: =+AZ14-AY14 -> 615 | BB14: =IF(AY14<>0,AZ14/AY14,"-") -> 1.5857143 | BC14: =+PL推移!N13-収支計画!W13/1000 -> 0 | BD14: =+BC14/(収支計画!W13/1000) -> #DIV/0! | BE14: =+PL推移!P13-収支計画!Y13/1000 -> 0 | BF14: =+BE14/(収支計画!Y13/1000) -> #DIV/0! | BG14: =+PL推移!R13-収支計画!AA13/1000 -> 0 | BH14: =+BG14/(収支計画!AA13/1000) -> #DIV/0! | BI14: =+PL推移!T13-収支計画!AC13/1000 -> 0 | BJ14: =+BI14/(収支計画!AC13/1000) -> #DIV/0! | BK14: =+PL推移!V13-収支計画!AE13/1000 -> 360 | BL14: =+BK14/(収支計画!AE13/1000) -> #DIV/0! | BM14: =+PL推移!X13-収支計画!AG13/1000 -> 375 | BN14: =+BM14/(収支計画!AG13/1000) -> #DIV/0! | BO14: =+PL推移!Z13-収支計画!AI13/1000 -> 405 | BP14: =+BO14/(収支計画!AI13/1000) -> #DIV/0!
B15: シェア | C15: =+収支計画!G14/1000 -> 150 | D15: =+PL推移!D14 -> 63 | E15: =+D15-C15 -> -87 | F15: =IF(C15<>0,D15/C15,"-") -> 0.42 | G15: =+収支計画!K14/1000 -> 150 | H15: =+PL推移!F14 -> 0 | I15: =+H15-G15 -> -150 | J15: =IF(G15<>0,H15/G15,"-") -> 0 | K15: =+収支計画!O14/1000 -> 150 | L15: =+PL推移!H14 -> 0 | M15: =+L15-K15 -> -150 | N15: =IF(K15<>0,L15/K15,"-") -> 0 | O15: =+収支計画!S14/1000 -> 0 | P15: =+PL推移!J14 -> 0 | Q15: =+P15-O15 -> 0 | R15: =IF(O15<>0,P15/O15,"-") -> - | S15: =+収支計画!U14/1000 -> 0 | T15: =+PL推移!L14 -> 0 | U15: =+T15-S15 -> 0 | V15: =IF(S15<>0,T15/S15,"-") -> - | W15: =+収支計画!W14/1000 -> 0 | X15: =+PL推移!N14 -> 0 | Y15: =+X15-W15 -> 0 | Z15: =IF(W15<>0,X15/W15,"-") -> - | AA15: =+収支計画!AA14/1000 -> 0 | AB15: =+PL推移!P14 -> 0 | AC15: =+AB15-AA15 -> 0 | AD15: =IF(AA15<>0,AB15/AA15,"-") -> - | AE15: =+収支計画!AA14/1000 -> 0 | AF15: =+PL推移!R14 -> 0 | AG15: =+AF15-AE15 -> 0 | AH15: =IF(AE15<>0,AF15/AE15,"-") -> - | AI15: =+収支計画!AC14/1000 -> 0 | AJ15: =+PL推移!T14 -> 0 | AK15: =+AJ15-AI15 -> 0 | AL15: =IF(AI15<>0,AJ15/AI15,"-") -> - | AM15: =+収支計画!AG14/1000 -> 0 | AN15: =+PL推移!V14 -> 128 | AO15: =+AN15-AM15 -> 128 | AP15: =IF(AM15<>0,AN15/AM15,"-") -> - | AQ15: =+収支計画!AG14/1000 -> 0 | AR15: =+PL推移!X14 -> 108 | AS15: =+AR15-AQ15 -> 108 | AT15: =IF(AQ15<>0,AR15/AQ15,"-") -> - | AU15: =+収支計画!AI14/1000 -> 0 | AV15: =+PL推移!Z14 -> 122 | AW15: =+AV15-AU15 -> 122 | AX15: =IF(AU15<>0,AV15/AU15,"-") -> - | AY15: =+C15+G15+K15+O15+S15+W15+AA15+AE15+AI15+AM15+AQ15+AU15 -> 450 | AZ15: =+D15+H15+L15+P15+T15+X15+AB15+AF15+AJ15+AN15+AR15+AV15 -> 421 | BA15: =+AZ15-AY15 -> -29 | BB15: =IF(AY15<>0,AZ15/AY15,"-") -> 0.93555556 | BC15: =+PL推移!N14-収支計画!W14/1000 -> 0 | BD15: =+BC15/(収支計画!W14/1000) -> #DIV/0! | BE15: =+PL推移!P14-収支計画!Y14/1000 -> 0 | BF15: =+BE15/(収支計画!Y14/1000) -> #DIV/0! | BG15: =+PL推移!R14-収支計画!AA14/1000 -> 0 | BH15: =+BG15/(収支計画!AA14/1000) -> #DIV/0! | BI15: =+PL推移!T14-収支計画!AC14/1000 -> 0 | BJ15: =+BI15/(収支計画!AC14/1000) -> #DIV/0! | BK15: =+PL推移!V14-収支計画!AE14/1000 -> 128 | BL15: =+BK15/(収支計画!AE14/1000) -> #DIV/0! | BM15: =+PL推移!X14-収支計画!AG14/1000 -> 108 | BN15: =+BM15/(収支計画!AG14/1000) -> #DIV/0! | BO15: =+PL推移!Z14-収支計画!AI14/1000 -> 122 | BP15: =+BO15/(収支計画!AI14/1000) -> #DIV/0!
B16: サウナ | C16: =+収支計画!G15/1000 -> 1000 | D16: =+PL推移!D15 -> 973 | E16: =+D16-C16 -> -27 | F16: =IF(C16<>0,D16/C16,"-") -> 0.973 | G16: =+収支計画!K15/1000 -> 1000 | H16: =+PL推移!F15 -> 0 | I16: =+H16-G16 -> -1000 | J16: =IF(G16<>0,H16/G16,"-") -> 0 | K16: =+収支計画!O15/1000 -> 1000 | L16: =+PL推移!H15 -> 0 | M16: =+L16-K16 -> -1000 | N16: =IF(K16<>0,L16/K16,"-") -> 0 | O16: =+収支計画!S15/1000 -> 0 | P16: =+PL推移!J15 -> 0 | Q16: =+P16-O16 -> 0 | R16: =IF(O16<>0,P16/O16,"-") -> - | S16: =+収支計画!U15/1000 -> 0 | T16: =+PL推移!L15 -> 0 | U16: =+T16-S16 -> 0 | V16: =IF(S16<>0,T16/S16,"-") -> - | W16: =+収支計画!W15/1000 -> 0 | X16: =+PL推移!N15 -> 0 | Y16: =+X16-W16 -> 0 | Z16: =IF(W16<>0,X16/W16,"-") -> - | AA16: =+収支計画!AA15/1000 -> 0 | AB16: =+PL推移!P15 -> 0 | AC16: =+AB16-AA16 -> 0 | AD16: =IF(AA16<>0,AB16/AA16,"-") -> - | AE16: =+収支計画!AA15/1000 -> 0 | AF16: =+PL推移!R15 -> 0 | AG16: =+AF16-AE16 -> 0 | AH16: =IF(AE16<>0,AF16/AE16,"-") -> - | AI16: =+収支計画!AC15/1000 -> 0 | AJ16: =+PL推移!T15 -> 0 | AK16: =+AJ16-AI16 -> 0 | AL16: =IF(AI16<>0,AJ16/AI16,"-") -> - | AM16: =+収支計画!AG15/1000 -> 0 | AN16: =+PL推移!V15 -> 812 | AO16: =+AN16-AM16 -> 812 | AP16: =IF(AM16<>0,AN16/AM16,"-") -> - | AQ16: =+収支計画!AG15/1000 -> 0 | AR16: =+PL推移!X15 -> 1329 | AS16: =+AR16-AQ16 -> 1329 | AT16: =IF(AQ16<>0,AR16/AQ16,"-") -> - | AU16: =+収支計画!AI15/1000 -> 0 | AV16: =+PL推移!Z15 -> 892 | AW16: =+AV16-AU16 -> 892 | AX16: =IF(AU16<>0,AV16/AU16,"-") -> - | AY16: =+C16+G16+K16+O16+S16+W16+AA16+AE16+AI16+AM16+AQ16+AU16 -> 3000 | AZ16: =+D16+H16+L16+P16+T16+X16+AB16+AF16+AJ16+AN16+AR16+AV16 -> 4006 | BA16: =+AZ16-AY16 -> 1006 | BB16: =IF(AY16<>0,AZ16/AY16,"-") -> 1.3353333 | BC16: =+PL推移!N15-収支計画!W15/1000 -> 0 | BD16: =+BC16/(収支計画!W15/1000) -> #DIV/0! | BE16: =+PL推移!P15-収支計画!Y15/1000 -> 0 | BF16: =+BE16/(収支計画!Y15/1000) -> #DIV/0! | BG16: =+PL推移!R15-収支計画!AA15/1000 -> 0 | BH16: =+BG16/(収支計画!AA15/1000) -> #DIV/0! | BI16: =+PL推移!T15-収支計画!AC15/1000 -> 0 | BJ16: =+BI16/(収支計画!AC15/1000) -> #DIV/0! | BK16: =+PL推移!V15-収支計画!AE15/1000 -> 812 | BL16: =+BK16/(収支計画!AE15/1000) -> #DIV/0! | BM16: =+PL推移!X15-収支計画!AG15/1000 -> 1329 | BN16: =+BM16/(収支計画!AG15/1000) -> #DIV/0! | BO16: =+PL推移!Z15-収支計画!AI15/1000 -> 892 | BP16: =+BO16/(収支計画!AI15/1000) -> #DIV/0!
A17: 売上原価 | C17: =SUM(C18:C22) -> 2200 | D17: =+PL推移!D16 -> 2021.276 | E17: =SUM(E18:E22) -> -178 | F17: =IF(C17<>0,D17/C17,"-") -> 0.91876182 | G17: =SUM(G18:G22) -> 2132.5 | H17: =+PL推移!F16 -> 0 | I17: =SUM(I18:I22) -> -2132.5 | J17: =IF(G17<>0,H17/G17,"-") -> 0 | K17: =SUM(K18:K22) -> 2507.5 | L17: =+PL推移!H16 -> 0 | M17: =SUM(M18:M22) -> -2507.5 | N17: =IF(K17<>0,L17/K17,"-") -> 0 | O17: =SUM(O18:O22) -> 0 | P17: =+PL推移!J16 -> 0 | Q17: =SUM(Q18:Q22) -> 0 | R17: =IF(O17<>0,P17/O17,"-") -> - | S17: =SUM(S18:S22) -> 0 | T17: =+PL推移!L16 -> 0 | U17: =SUM(U18:U22) -> 0 | V17: =IF(S17<>0,T17/S17,"-") -> - | W17: =SUM(W18:W22) -> 0 | X17: =+PL推移!N16 -> 0 | Y17: =SUM(Y18:Y22) -> 0 | Z17: =IF(W17<>0,X17/W17,"-") -> - | AA17: =SUM(AA18:AA22) -> 0 | AB17: =+PL推移!P16 -> 0 | AC17: =SUM(AC18:AC22) -> 0 | AD17: =IF(AA17<>0,AB17/AA17,"-") -> - | AE17: =SUM(AE18:AE22) -> 0 | AF17: =+PL推移!R16 -> 0 | AG17: =SUM(AG18:AG22) -> 1900 | AH17: =IF(AE17<>0,AF17/AE17,"-") -> - | AI17: =SUM(AI18:AI22) -> 0 | AJ17: =+PL推移!T16 -> 0 | AK17: =SUM(AK18:AK22) -> 2266 | AL17: =IF(AI17<>0,AJ17/AI17,"-") -> - | AM17: =SUM(AM18:AM22) -> 0 | AN17: =+PL推移!V16 -> 0 | AO17: =+AN17-AM17 -> 0 | AP17: =IF(AM17<>0,AN17/AM17,"-") -> - | AQ17: =SUM(AQ18:AQ22) -> 0 | AR17: =+PL推移!X16 -> 0 | AS17: =+AR17-AQ17 -> 0 | AT17: =IF(AQ17<>0,AR17/AQ17,"-") -> - | AU17: =+収支計画!AI24/1000 -> 0 | AV17: =+PL推移!Z16 -> 0 | AW17: =+AV17-AU17 -> 0 | AX17: =IF(AU17<>0,AV17/AU17,"-") -> - | AY17: =+C17+G17+K17+O17+S17+W17+AA17+AE17+AI17+AM17+AQ17+AU17 -> 6840 | AZ17: =+D17+H17+L17+P17+T17+X17+AB17+AF17+AJ17+AN17+AR17+AV17 -> 2021.276 | BA17: =+AZ17-AY17 -> -4818.724 | BB17: =IF(AY17<>0,AZ17/AY17,"-") -> 0.29550819 | BC17: =+PL推移!N16-収支計画!W24/1000 -> 0 | BD17: =+BC17/(収支計画!W24/1000) -> #DIV/0! | BE17: =+PL推移!P16-収支計画!Y24/1000 -> 0 | BF17: =+BE17/(収支計画!Y24/1000) -> #DIV/0! | BG17: =+PL推移!R16-収支計画!AA24/1000 -> 0 | BH17: =+BG17/(収支計画!AA24/1000) -> #DIV/0! | BI17: =+PL推移!T16-収支計画!AC24/1000 -> 0 | BJ17: =+BI17/(収支計画!AC24/1000) -> #DIV/0! | BK17: =+PL推移!V16-収支計画!AE24/1000 -> 0 | BL17: =+BK17/(収支計画!AE24/1000) -> #DIV/0! | BM17: =+PL推移!X16-収支計画!AG24/1000 -> 0 | BN17: =+BM17/(収支計画!AG24/1000) -> #DIV/0! | BO17: =+PL推移!Z16-収支計画!AI24/1000 -> 0 | BP17: =+BO17/(収支計画!AI24/1000) -> #DIV/0!
B18: =+B12 -> 恵愛 | C18: =+収支計画!G18/1000 -> 1785 | D18: =+PL推移!D17 -> 1728 | E18: =+D18-C18 -> -57 | F18: =IF(C18<>0,D18/C18,"-") -> 0.96806723 | G18: =+収支計画!K18/1000 -> 1785 | H18: =+PL推移!F17 -> 0 | I18: =+H18-G18 -> -1785 | J18: =IF(G18<>0,H18/G18,"-") -> 0 | K18: =+収支計画!O18/1000 -> 2167.5 | L18: =+PL推移!H17 -> 0 | M18: =+L18-K18 -> -2167.5 | N18: =IF(K18<>0,L18/K18,"-") -> 0 | O18: =+収支計画!S18/1000 -> 0 | P18: =+PL推移!J17 -> 0 | Q18: =+P18-O18 -> 0 | R18: =IF(O18<>0,P18/O18,"-") -> - | S18: =+収支計画!U18/1000 -> 0 | T18: =+PL推移!L17 -> 0 | U18: =+T18-S18 -> 0 | V18: =IF(S18<>0,T18/S18,"-") -> - | W18: =+収支計画!W18/1000 -> 0 | X18: =+PL推移!N17 -> 0 | Y18: =+X18-W18 -> 0 | Z18: =IF(W18<>0,X18/W18,"-") -> - | AA18: =+収支計画!Y18/1000 -> 0 | AB18: =+PL推移!P17 -> 0 | AC18: =+AB18-AA18 -> 0 | AD18: =IF(AA18<>0,AB18/AA18,"-") -> - | AE18: =+収支計画!AA18/1000 -> 0 | AF18: =+PL推移!R17 -> 1634 | AG18: =+AF18-AE18 -> 1634 | AH18: =IF(AE18<>0,AF18/AE18,"-") -> - | AI18: =+収支計画!AC18/1000 -> 0 | AJ18: =+PL推移!T17 -> 1864 | AK18: =+AJ18-AI18 -> 1864 | AL18: =IF(AI18<>0,AJ18/AI18,"-") -> - | AM18: =+収支計画!AG18/1000 -> 0 | AN18: =+PL推移!V17 -> 1607 | AO18: =+AN18-AM18 -> 1607 | AP18: =IF(AM18<>0,AN18/AM18,"-") -> - | AQ18: =+収支計画!AG18/1000 -> 0 | AR18: =+PL推移!X17 -> 1751 | AS18: =+AR18-AQ18 -> 1751 | AT18: =IF(AQ18<>0,AR18/AQ18,"-") -> - | AU18: =+収支計画!AI18/1000 -> 0 | AV18: =+PL推移!Z17 -> 1643 | AW18: =+AV18-AU18 -> 1643 | AX18: =IF(AU18<>0,AV18/AU18,"-") -> - | AY18: =+C18+G18+K18+O18+S18+W18+AA18+AE18+AI18+AM18+AQ18+AU18 -> 5737.5 | AZ18: =+D18+H18+L18+P18+T18+X18+AB18+AF18+AJ18+AN18+AR18+AV18 -> 10227 | BA18: =+AZ18-AY18 -> 4489.5 | BB18: =IF(AY18<>0,AZ18/AY18,"-") -> 1.7824837 | BC18: =+PL推移!N17-収支計画!W18/1000 -> 0 | BD18: =+BC18/(収支計画!W18/1000) -> #DIV/0! | BE18: =+PL推移!P17-収支計画!Y18/1000 -> 0 | BF18: =+BE18/(収支計画!Y18/1000) -> #DIV/0! | BG18: =+PL推移!R17-収支計画!AA18/1000 -> 1634 | BH18: =+BG18/(収支計画!AA18/1000) -> #DIV/0! | BI18: =+PL推移!T17-収支計画!AC18/1000 -> 1864 | BJ18: =+BI18/(収支計画!AC18/1000) -> #DIV/0! | BK18: =+PL推移!V17-収支計画!AE18/1000 -> 1607 | BL18: =+BK18/(収支計画!AE18/1000) -> #DIV/0! | BM18: =+PL推移!X17-収支計画!AG18/1000 -> 1751 | BN18: =+BM18/(収支計画!AG18/1000) -> #DIV/0! | BO18: =+PL推移!Z17-収支計画!AI18/1000 -> 1643 | BP18: =+BO18/(収支計画!AI18/1000) -> #DIV/0!
