Workbook

Sheet 月次BS
B1: 勘定科目 | C1: 期首残 | D1: 7月 | E1: 8月 | F1: 9月 | G1: 10月 | H1: 11月 | I1: 12月 | J1: 1月 | K1: 2月 | L1: 3 | M1: 4 | N1: 5月 | O1: 6月
A2: 資産の部
A3: 流動資産
A4: 現金及び預金
B5: 現金 | C5: 2646681 | D5: 2692031 | E5: 2697851 | F5: 2121031 | G5: 2255351 | H5: 2791061 | I5: 3237871 | J5: 2181771 | K5: 1832611 | L5: 2866171 | M5: 2205981 | N5: 2181191 | O5: 2906811
B6: 普通預金 | C6: 37905465 | D6: 37560836 | E6: 35756047 | F6: 35600198 | G6: 35188952 | H6: 35645955 | I6: 36227527 | J6: 35625770 | K6: 31193217 | L6: 29192910 | M6: 27892281 | N6: 27810336 | O6: 31678389
B7: 小口現金 | C7: 213497 | D7: 31415 | E7: -19488 | F7: 92694 | G7: 163098 | H7: 61084 | I7: 162213 | J7: 368643 | K7: 384155 | L7: 324462 | M7: 312171 | N7: 351796 | O7: 316465
A8: 現金及び預金合計 | C8: 40765643 | D8: 40284282 | E8: 38434410 | F8: 37813923 | G8: 37607401 | H8: 38498100 | I8: 39627611 | J8: 38176184 | K8: 33409983 | L8: 32383543 | M8: 30410433 | N8: 30343323 | O8: 34901665
A9: 売上債権
B10: 売掛金 | C10: 8953308 | D10: 9906965 | E10: 10752692 | F10: 10434641 | G10: 11510344 | H10: 11809720 | I10: 13589176 | J10: 13035142 | K10: 13691148 | L10: 14752238 | M10: 15273355 | N10: 16433660 | O10: 9716690
A11: 売上債権合計 | C11: 8953308 | D11: 9906965 | E11: 10752692 | F11: 10434641 | G11: 11510344 | H11: 11809720 | I11: 13589176 | J11: 13035142 | K11: 13691148 | L11: 14752238 | M11: 15273355 | N11: 16433660 | O11: 9716690
A12: 有価証券
A13: 有価証券合計 | C13: 0 | D13: 0 | E13: 0 | F13: 0 | G13: 0 | H13: 0 | I13: 0 | J13: 0 | K13: 0 | L13: 0 | M13: 0 | N13: 0 | O13: 0
A14: 棚卸資産
B15: 商品 | C15: 1324285 | D15: 1460296 | E15: 1288670 | F15: 1317901 | G15: 1280808 | H15: 1439855 | I15: 1677027 | J15: 1505883 | K15: 1584538 | L15: 1653458 | M15: 1664854 | N15: 1432987 | O15: 1319258
B16: 貯蔵品 | C16: 288654 | D16: 288654 | E16: 288654 | F16: 288654 | G16: 288654 | H16: 288654 | I16: 288654 | J16: 288654 | K16: 288654 | L16: 288654 | M16: 288654 | N16: 288654 | O16: 150450
A17: 棚卸資産合計 | C17: 1612939 | D17: 1748950 | E17: 1577324 | F17: 1606555 | G17: 1569462 | H17: 1728509 | I17: 1965681 | J17: 1794537 | K17: 1873192 | L17: 1942112 | M17: 1953508 | N17: 1721641 | O17: 1469708
A18: その他流動資産
B19: 前払費用 | C19: 1742739 | D19: 1728439 | E19: 1714139 | F19: 1699839 | G19: 1685539 | H19: 1828539 | I19: 1814239 | J19: 1799939 | K19: 1785639 | L19: 1771339 | M19: 1757039 | N19: 1742739 | O19: 1742739
B20: 立替金 | C20: 626802 | D20: 815496 | E20: 609227 | F20: 781038 | G20: 789246 | H20: 794149 | I20: 816594 | J20: 534339 | K20: 528396 | L20: 357837 | M20: 507497 | N20: 664615 | O20: 866085
B21: 未収入金 | C21: 26813 | D21: 0 | E21: 0 | F21: 0 | G21: 0 | H21: 0 | I21: 0 | J21: 0 | K21: 0 | L21: 0 | M21: 0 | N21: 0 | O21: 0
B22: 仮払金 | C22: 0 | D22: 0 | E22: 0 | F22: 12943 | G22: 0 | H22: 0 | I22: 0 | J22: 0 | K22: 0 | L22: 13150 | M22: 0 | N22: 0 | O22: 0
B23: 仮払消費税 | C23: 0 | D23: 602181 | E23: 1181263 | F23: 1723683 | G23: 2238998 | H23: 2785358 | I23: 3451329 | J23: 3971010 | K23: 4699700 | L23: 5271705 | M23: 5800805 | N23: 6308184 | O23: 6820350
A24: その他流動資産合計 | C24: 2396354 | D24: 3146116 | E24: 3504629 | F24: 4217503 | G24: 4713783 | H24: 5408046 | I24: 6082162 | J24: 6305288 | K24: 7013735 | L24: 7414031 | M24: 8065341 | N24: 8715538 | O24: 9429174
A25: 流動資産合計 | C25: 53728244 | D25: 55086313 | E25: 54269055 | F25: 54072622 | G25: 55400990 | H25: 57444375 | I25: 61264630 | J25: 59311151 | K25: 55988058 | L25: 56491924 | M25: 55702637 | N25: 57214162 | O25: 55517237
A26: 固定資産
A27: 有形固定資産
B28: 建物 | C28: 16345912 | D28: 16345912 | E28: 16345912 | F28: 16345912 | G28: 16345912 | H28: 16345912 | I28: 16345912 | J28: 16345912 | K28: 16345912 | L28: 16345912 | M28: 16345912 | N28: 16345912 | O28: 16345912
B29: 附属設備 | C29: 29167466 | D29: 29167466 | E29: 29167466 | F29: 29167466 | G29: 29167466 | H29: 29167466 | I29: 29167466 | J29: 29167466 | K29: 29167466 | L29: 29167466 | M29: 29167466 | N29: 29167466 | O29: 29167466
B30: 工具器具備品 | C30: 7249232 | D30: 7249232 | E30: 7249232 | F30: 7249232 | G30: 7249232 | H30: 7249232 | I30: 7404232 | J30: 7404232 | K30: 7404232 | L30: 7404232 | M30: 7404232 | N30: 7404232 | O30: 7404232
B31: 一括償却資産 | C31: 526316 | D31: 526316 | E31: 526316 | F31: 526316 | G31: 526316 | H31: 526316 | I31: 526316 | J31: 526316 | K31: 526316 | L31: 526316 | M31: 526316 | N31: 526316 | O31: 526316
B32: 減価償却累計額 | C32: 0 | D32: -586635 | E32: -1173270 | F32: -1759905 | G32: -2346540 | H32: -2933175 | I32: -3519810 | J32: -4106445 | K32: -4693080 | L32: -5279715 | M32: -5866350 | N32: -6452985 | O32: -7039620
A33: 有形固定資産合計 | C33: 53288926 | D33: 52702291 | E33: 52115656 | F33: 51529021 | G33: 50942386 | H33: 50355751 | I33: 49924116 | J33: 49337481 | K33: 48750846 | L33: 48164211 | M33: 47577576 | N33: 46990941 | O33: 46404306
A34: 無形固定資産
B35: ソフトウェア | C35: 3801185 | D35: 3697231 | E35: 3593277 | F35: 3489323 | G35: 3385369 | H35: 3281415 | I35: 3177461 | J35: 3073507 | K35: 2969553 | L35: 2865599 | M35: 2761645 | N35: 2657691 | O35: 2553737
A36: 無形固定資産合計 | C36: 3801185 | D36: 3697231 | E36: 3593277 | F36: 3489323 | G36: 3385369 | H36: 3281415 | I36: 3177461 | J36: 3073507 | K36: 2969553 | L36: 2865599 | M36: 2761645 | N36: 2657691 | O36: 2553737
A37: 投資その他の資産
B38: 出資金 | C38: 8825960 | D38: 8825960 | E38: 8825960 | F38: 8825960 | G38: 8825960 | H38: 8825960 | I38: 8825960 | J38: 8825960 | K38: 8825960 | L38: 8825960 | M38: 8825960 | N38: 8825960 | O38: 8825960
B39: 長期前払費用 | C39: 1092742 | D39: 1092742 | E39: 1092742 | F39: 1092742 | G39: 1092742 | H39: 1092742 | I39: 1092742 | J39: 1092742 | K39: 1092742 | L39: 1092742 | M39: 1092742 | N39: 1092742 | O39: 1092742
B40: 敷金 | C40: 2126486 | D40: 2126486 | E40: 2126486 | F40: 2126486 | G40: 2126486 | H40: 2126486 | I40: 2126486 | J40: 2126486 | K40: 2126486 | L40: 2126486 | M40: 2126486 | N40: 2126486 | O40: 2126486
...

Sheet BS千円
B1: 勘定科目 | C1: 期首残 | D1: 7月 | E1: 8月 | F1: =+月次BS!F1 -> 9月 | G1: =+月次BS!G1 -> 10月 | H1: =+月次BS!H1 -> 11月 | I1: =+月次BS!I1 -> 12月 | J1: =+月次BS!J1 -> 1月 | K1: =+月次BS!K1 -> 2月 | L1: =+月次BS!L1 -> 3 | M1: =+月次BS!M1 -> 4 | ... O1: =+月次BS!O1 -> 6月
A2: =+月次BS!A2 -> 資産の部
A3: =+月次BS!A3 -> 流動資産
A4: =+月次BS!A4 -> 現金及び預金
A5: =+月次BS!A5 -> 0 | B5: =+月次BS!B5 -> 現金 | C5: =+月次BS!C5/1000 -> 2646.681 | D5: =+月次BS!D5/1000 -> 2692.031 | E5: =+月次BS!E5/1000 -> 2697.851 | F5: =+月次BS!F5/1000 -> 2121.031 | G5: =+月次BS!G5/1000 -> 2255.351 | H5: =+月次BS!H5/1000 -> 2791.061 | I5: =+月次BS!I5/1000 -> 3237.871 | J5: =+月次BS!J5/1000 -> 2181.771 | ... O5: =+月次BS!O5/1000 -> 2906.811
A6: =+月次BS!A6 -> 0 | B6: =+月次BS!B6 -> 普通預金 | C6: =+月次BS!C6/1000 -> 37905.465 | D6: =+月次BS!D6/1000 -> 37560.836 | E6: =+月次BS!E6/1000 -> 35756.047 | F6: =+月次BS!F6/1000 -> 35600.198 | G6: =+月次BS!G6/1000 -> 35188.952 | H6: =+月次BS!H6/1000 -> 35645.955 | I6: =+月次BS!I6/1000 -> 36227.527 | J6: =+月次BS!J6/1000 -> 35625.77 | ... O6: =+月次BS!O6/1000 -> 31678.389
A7: =+月次BS!A7 -> 0 | B7: =+月次BS!B7 -> 小口現金 | C7: =+月次BS!C7/1000 -> 213.497 | D7: =+月次BS!D7/1000 -> 31.415 | E7: =+月次BS!E7/1000 -> -19.488 | F7: =+月次BS!F7/1000 -> 92.694 | G7: =+月次BS!G7/1000 -> 163.098 | H7: =+月次BS!H7/1000 -> 61.084 | I7: =+月次BS!I7/1000 -> 162.213 | J7: =+月次BS!J7/1000 -> 368.643 | ... O7: =+月次BS!O7/1000 -> 316.465
A8: =+月次BS!A8 -> 現金及び預金合計 | B8: =+月次BS!B8 -> 0 | C8: =+月次BS!C8/1000 -> 40765.643 | D8: =+月次BS!D8/1000 -> 40284.282 | E8: =+月次BS!E8/1000 -> 38434.41 | F8: =+月次BS!F8/1000 -> 37813.923 | G8: =+月次BS!G8/1000 -> 37607.401 | H8: =+月次BS!H8/1000 -> 38498.1 | I8: =+月次BS!I8/1000 -> 39627.611 | J8: =+月次BS!J8/1000 -> 38176.184 | ... O8: =+月次BS!O8/1000 -> 34901.665
A9: =+月次BS!A9 -> 売上債権 | B9: =+月次BS!B9 -> 0 | C9: =+月次BS!C9/1000 -> 0 | D9: =+月次BS!D9/1000 -> 0 | E9: =+月次BS!E9/1000 -> 0 | F9: =+月次BS!F9/1000 -> 0 | G9: =+月次BS!G9/1000 -> 0 | H9: =+月次BS!H9/1000 -> 0 | I9: =+月次BS!I9/1000 -> 0 | J9: =+月次BS!J9/1000 -> 0 | ... O9: =+月次BS!O9/1000 -> 0
A10: =+月次BS!A10 -> 0 | B10: =+月次BS!B10 -> 売掛金 | C10: =+月次BS!C10/1000 -> 8953.308 | D10: =+月次BS!D10/1000 -> 9906.965 | E10: =+月次BS!E10/1000 -> 10752.692 | F10: =+月次BS!F10/1000 -> 10434.641 | G10: =+月次BS!G10/1000 -> 11510.344 | H10: =+月次BS!H10/1000 -> 11809.72 | I10: =+月次BS!I10/1000 -> 13589.176 | J10: =+月次BS!J10/1000 -> 13035.142 | ... O10: =+月次BS!O10/1000 -> 9716.69
A11: =+月次BS!A11 -> 売上債権合計 | B11: =+月次BS!B11 -> 0 | C11: =+月次BS!C11/1000 -> 8953.308 | D11: =+月次BS!D11/1000 -> 9906.965 | E11: =+月次BS!E11/1000 -> 10752.692 | F11: =+月次BS!F11/1000 -> 10434.641 | G11: =+月次BS!G11/1000 -> 11510.344 | H11: =+月次BS!H11/1000 -> 11809.72 | I11: =+月次BS!I11/1000 -> 13589.176 | J11: =+月次BS!J11/1000 -> 13035.142 | ... O11: =+月次BS!O11/1000 -> 9716.69
A12: =+月次BS!A12 -> 有価証券 | B12: =+月次BS!B12 -> 0 | C12: =+月次BS!C12/1000 -> 0 | D12: =+月次BS!D12/1000 -> 0 | E12: =+月次BS!E12/1000 -> 0 | F12: =+月次BS!F12/1000 -> 0 | G12: =+月次BS!G12/1000 -> 0 | H12: =+月次BS!H12/1000 -> 0 | I12: =+月次BS!I12/1000 -> 0 | J12: =+月次BS!J12/1000 -> 0 | ... O12: =+月次BS!O12/1000 -> 0
A13: =+月次BS!A13 -> 有価証券合計 | B13: =+月次BS!B13 -> 0 | C13: =+月次BS!C13/1000 -> 0 | D13: =+月次BS!D13/1000 -> 0 | E13: =+月次BS!E13/1000 -> 0 | F13: =+月次BS!F13/1000 -> 0 | G13: =+月次BS!G13/1000 -> 0 | H13: =+月次BS!H13/1000 -> 0 | I13: =+月次BS!I13/1000 -> 0 | J13: =+月次BS!J13/1000 -> 0 | ... O13: =+月次BS!O13/1000 -> 0
A14: =+月次BS!A14 -> 棚卸資産 | B14: =+月次BS!B14 -> 0 | C14: =+月次BS!C14/1000 -> 0 | D14: =+月次BS!D14/1000 -> 0 | E14: =+月次BS!E14/1000 -> 0 | F14: =+月次BS!F14/1000 -> 0 | G14: =+月次BS!G14/1000 -> 0 | H14: =+月次BS!H14/1000 -> 0 | I14: =+月次BS!I14/1000 -> 0 | J14: =+月次BS!J14/1000 -> 0 | ... O14: =+月次BS!O14/1000 -> 0
A15: =+月次BS!A15 -> 0 | B15: =+月次BS!B15 -> 商品 | C15: =+月次BS!C15/1000 -> 1324.285 | D15: =+月次BS!D15/1000 -> 1460.296 | E15: =+月次BS!E15/1000 -> 1288.67 | F15: =+月次BS!F15/1000 -> 1317.901 | G15: =+月次BS!G15/1000 -> 1280.808 | H15: =+月次BS!H15/1000 -> 1439.855 | I15: =+月次BS!I15/1000 -> 1677.027 | J15: =+月次BS!J15/1000 -> 1505.883 | ... O15: =+月次BS!O15/1000 -> 1319.258
A16: =+月次BS!A16 -> 0 | B16: =+月次BS!B16 -> 貯蔵品 | C16: =+月次BS!C16/1000 -> 288.654 | D16: =+月次BS!D16/1000 -> 288.654 | E16: =+月次BS!E16/1000 -> 288.654 | F16: =+月次BS!F16/1000 -> 288.654 | G16: =+月次BS!G16/1000 -> 288.654 | H16: =+月次BS!H16/1000 -> 288.654 | I16: =+月次BS!I16/1000 -> 288.654 | J16: =+月次BS!J16/1000 -> 288.654 | ... O16: =+月次BS!O16/1000 -> 150.45
... A93: =+月次BS!A93 -> 負債・純資産の部合計 | B93: =+月次BS!B93 -> 0 | C93: =+月次BS!C93/1000 -> 136194.06 | D93: =+月次BS!D93/1000 -> 136864.59 | E93: =+月次BS!E93/1000 -> 135359.8 | F93: =+月次BS!F93/1000 -> 134475.83 | G93: =+月次BS!G93/1000 -> 135116.67 | H93: =+月次BS!H93/1000 -> 136472.52 | I93: =+月次BS!I93/1000 -> 139760.24 | J93: =+月次BS!J93/1000 -> 137119.23 | ... O93: =+月次BS!O93/1000 -> 129887.64
A94: =+月次BS!A95 -> 0 | B94: =+月次BS!B95 -> 0 | C94: =+月次BS!C95/1000 -> 0 | D94: =+月次BS!D95/1000 -> 0 | E94: =+月次BS!E95/1000 -> 0 | F94: =+月次BS!F95/1000 -> 0 | G94: =+月次BS!G95/1000 -> 0 | H94: =+月次BS!H95/1000 -> 0 | I94: =+月次BS!I95/1000 -> 0 | J94: =+月次BS!J95/1000 -> 0 | ... O94: =+月次BS!O95/1000 -> 0
A95: =+月次BS!A96 -> 0 | B95: 買掛未払債務 | C95: =+C52+C55+C56 -> 5404.43 | D95: =+D52+D55+D56 -> 5796.001 | E95: =+E52+E55+E56 -> 5510.974 | F95: =+F52+F55+F56 -> 4660.897 | G95: =+G52+G55+G56 -> 4449.466 | H95: =+H52+H55+H56 -> 5534.735 | I95: =+I52+I55+I56 -> 7107.653 | J95: =+J52+J55+J56 -> 5130.265 | ... O95: =+O52+O55+O56 -> 5081.739
A96: =+月次BS!A97 -> 0 | B96: その他流動負債 | C96: =+C57+C58+C59+C62 -> 794.047 | D96: =+D57+D58+D59+D62 -> 1345.698 | E96: =+E57+E58+E59+E62 -> 2661.018 | F96: =+F57+F58+F59+F62 -> 3584.37 | G96: =+G57+G58+G59+G62 -> 4798.191 | H96: =+H57+H58+H59+H62 -> 5405.819 | I96: =+I57+I58+I59+I62 -> 5942.674 | J96: =+J57+J58+J59+J62 -> 6745.458 | ... O96: =+O57+O58+O59+O62 -> 10735.477
A97: =+月次BS!A98 -> 0 | B97: 有形・無形固定資産 | C97: =+C33+C36 -> 57090.111 | D97: =+D33+D36 -> 56399.522 | E97: =+E33+E36 -> 55708.933 | F97: =+F33+F36 -> 55018.344 | G97: =+G33+G36 -> 54327.755 | H97: =+H33+H36 -> 53637.166 | I97: =+I33+I36 -> 53101.577 | J97: =+J33+J36 -> 52410.988 | ... O97: =+O33+O36 -> 48958.043
A98: =+月次BS!A99 -> 0 | B98: 長期借入金 | C98: =+C63+C67 -> 139240 | D98: =+D63+D67 -> 139005 | E98: =+E63+E67 -> 139005 | F98: =+F63+F67 -> 138535 | G98: =+G63+G67 -> 138300 | H98: =+H63+H67 -> 138300 | I98: =+I63+I67 -> 138065 | J98: =+J63+J67 -> 137830 | ... O98: =+O63+O67 -> 135225
A99: =+月次BS!A100 -> 0 | B99: =+月次BS!B100 -> 0 | C99: =+月次BS!C100/1000 -> 0 | D99: =+月次BS!D100/1000 -> 0 | E99: =+月次BS!E100/1000 -> 0 | F99: =+月次BS!F100/1000 -> 0 | G99: =+月次BS!G100/1000 -> 0 | H99: =+月次BS!H100/1000 -> 0 | I99: =+月次BS!I100/1000 -> 0 | J99: =+月次BS!J100/1000 -> 0 | ... O99: =+月次BS!O100/1000 -> 0
A100: =+月次BS!A101 -> 0 | B100: =+月次BS!B101 -> 0 | C100: =+月次BS!C101/1000 -> 0 | D100: =+月次BS!D101/1000 -> 0 | E100: =+月次BS!E101/1000 -> 0 | F100: =+月次BS!F101/1000 -> 0 | G100: =+月次BS!G101/1000 -> 0 | H100: =+月次BS!H101/1000 -> 0 | I100: =+月次BS!I101/1000 -> 0 | J100: =+月次BS!J101/1000 -> 0 | ... O100: =+月次BS!O101/1000 -> 0
A101: =+月次BS!A102 -> 0 | B101: =+月次BS!B102 -> 0 | C101: =+月次BS!C102/1000 -> 0 | D101: =+月次BS!D102/1000 -> 0 | E101: =+月次BS!E102/1000 -> 0 | F101: =+月次BS!F102/1000 -> 0 | G101: =+月次BS!G102/1000 -> 0 | H101: =+月次BS!H102/1000 -> 0 | I101: =+月次BS!I102/1000 -> 0 | J101: =+月次BS!J102/1000 -> 0 | ... O101: =+月次BS!O102/1000 -> 0
A102: =+月次BS!A103 -> 0 | B102: =+月次BS!B103 -> 0 | C102: =+月次BS!C103/1000 -> 0 | D102: =+月次BS!D103/1000 -> 0 | E102: =+月次BS!E103/1000 -> 0 | F102: =+月次BS!F103/1000 -> 0 | G102: =+月次BS!G103/1000 -> 0 | H102: =+月次BS!H103/1000 -> 0 | I102: =+月次BS!I103/1000 -> 0 | J102: =+月次BS!J103/1000 -> 0 | ... O102: =+月次BS!O103/1000 -> 0
A103: =+月次BS!A104 -> 0 | B103: =+月次BS!B104 -> 0 | C103: =+月次BS!C104/1000 -> 0 | D103: =+月次BS!D104/1000 -> 0 | E103: =+月次BS!E104/1000 -> 0 | F103: =+月次BS!F104/1000 -> 0 | G103: =+月次BS!G104/1000 -> 0 | H103: =+月次BS!H104/1000 -> 0 | I103: =+月次BS!I104/1000 -> 0 | J103: =+月次BS!J104/1000 -> 0 | ... O103: =+月次BS!O104/1000 -> 0

Sheet 月次PL
B1: 勘定科目 | C1: =+月次BS!D1 -> 7月 | D1: =+月次BS!E1 -> 8月 | E1: =+月次BS!F1 -> 9月 | F1: =+月次BS!G1 -> 10月 | G1: =+月次BS!H1 -> 11月 | H1: =+月次BS!I1 -> 12月 | I1: =+月次BS!J1 -> 1月 | J1: =+月次BS!K1 -> 2月 | ... N1: =+月次BS!O1 -> 6月 | O1: 累計
A2: 売上高
B3: レストラン売上 | C3: 7355981 | D3: 7304280 | E3: 6074830 | F3: 6161257 | G3: 6585842 | H3: 9980134 | I3: 6090480 | J3: 6446164 | K3: 6978449 | L3: 5291210 | M3: 5672033 | N3: 5536466 | O3: =SUM(C3:N3) -> 79477126
B4: 売上高 | C4: 1345240 | D4: 2064194 | E4: 1191395 | F4: 1562343 | G4: 1064084 | H4: 1117278 | I4: 1121936 | J4: 1038818 | K4: 1159845 | L4: 1371265 | M4: 1312243 | N4: 1560958 | O4: =SUM(C4:N4) -> 15909599
B5: 村売上 | C5: 573353 | D5: 597444 | E5: 601738 | F5: 580314 | G5: 531055 | H5: 557864 | I5: 589775 | J5: 596428 | K5: 606000 | L5: 541519 | M5: 611604 | N5: 599819 | O5: =SUM(C5:N5) -> 6986913
O6: =SUM(C6:N6) -> 0
B7: その他売上 | O7: =SUM(C7:N7) -> 0
A8: 売上高合計 | C8: =+SUM(C3:C7) -> 9274574 | D8: =+SUM(D3:D7) -> 9965918 | E8: =+SUM(E3:E7) -> 7867963 | F8: =+SUM(F3:F7) -> 8303914 | G8: =+SUM(G3:G7) -> 8180981 | H8: =+SUM(H3:H7) -> 11655276 | I8: =+SUM(I3:I7) -> 7802191 | J8: =+SUM(J3:J7) -> 8081410 | ... N8: =+SUM(N3:N7) -> 7697243 | O8: =SUM(C8:N8) -> 102373638
A9: 売上原価 | O9: =SUM(C9:N9) -> 0
B10: 期首商品棚卸高 | C10: 1324285 | D10: 0 | E10: 0 | F10: 0 | G10: 0 | H10: 0 | I10: 0 | J10: 0 | K10: 0 | L10: 0 | M10: 0 | N10: 0 | O10: =SUM(C10:N10) -> 1324285
B11: 飲料仕入 | C11: 1214302 | D11: 1229321 | E11: 954132 | F11: 932212 | G11: 1169442 | H11: 1618009 | I11: 930283 | J11: 1125121 | K11: 1394928 | L11: 1139680 | M11: 917541 | N11: 962022 | O11: =SUM(C11:N11) -> 13586993
B12: 食材仕入 | C12: 1056629 | D12: 718469 | E12: 681656 | F12: 731299 | G12: 770565 | H12: 1354437 | I12: 629051 | J12: 823087 | K12: 701327 | L12: 850444 | M12: 833116 | N12: 790187 | O12: =SUM(C12:N12) -> 9940267
B13: 仕入値引 | O13: =SUM(C13:N13) -> 0
B14: 期末商品棚卸高 | C14: 1460296 | D14: -171626 | E14: 29231 | F14: -37093 | G14: 159047 | H14: 237172 | I14: -171144 | J14: 78655 | K14: 68920 | L14: 11396 | M14: -231867 | N14: -113729 | O14: =SUM(C14:N14) -> 1319258
A15: 売上原価 | C15: =+C10+C11+C12-C13-C14 -> 2134920 | D15: =+D10+D11+D12-D13-D14 -> 2119416 | E15: =+E10+E11+E12-E13-E14 -> 1606557 | F15: =+F10+F11+F12-F13-F14 -> 1700604 | G15: =+G10+G11+G12-G13-G14 -> 1780960 | H15: =+H10+H11+H12-H13-H14 -> 2735274 | I15: =+I10+I11+I12-I13-I14 -> 1730478 | J15: =+J10+J11+J12-J13-J14 -> 1869553 | ... N15: =+N10+N11+N12-N13-N14 -> 1865938 | O15: =SUM(C15:N15) -> 23532287
A16: 売上総利益 | C16: =+C8-C15 -> 7139654 | D16: =+D8-D15 -> 7846502 | E16: =+E8-E15 -> 6261406 | F16: =+F8-F15 -> 6603310 | G16: =+G8-G15 -> 6400021 | H16: =+H8-H15 -> 8920002 | I16: =+I8-I15 -> 6071713 | J16: =+J8-J15 -> 6211857 | ... N16: =+N8-N15 -> 5831305 | O16: =SUM(C16:N16) -> 78841351
A17: 販売費及び一般管理費 | O17: =SUM(C17:N17) -> 0
B18: 役員報酬 | C18: 500000 | D18: 500000 | E18: 500000 | F18: 500000 | G18: 500000 | H18: 500000 | I18: 500000 | J18: 500000 | K18: 500000 | L18: 500000 | M18: 500000 | N18: 500000 | O18: =SUM(C18:N18) -> 6000000
B19: 給料賃金 | C19: 570000 | D19: 570000 | E19: 586976 | F19: 350000 | G19: 373907 | H19: 365819 | I19: 361841 | J19: 350000 | K19: 350000 | L19: 350000 | M19: 350000 | N19: 350000 | O19: =SUM(C19:N19) -> 4928543
B20: 賞与 | C20: 118179 | D20: 0 | E20: 0 | F20: 0 | G20: 0 | H20: 97731 | I20: 0 | J20: 0 | K20: 522000 | L20: 0 | M20: 0 | N20: 47416 | O20: =SUM(C20:N20) -> 785326
B21: 雑給 | C21: 647091 | D21: 807714 | E21: 675463 | F21: 959800 | G21: 956908 | H21: 1380581 | I21: 1454580 | J21: 1424401 | K21: 1277171 | L21: 1170281 | M21: 1166205 | N21: 1008651 | O21: =SUM(C21:N21) -> 12928846
B22: 法定福利費 | C22: 137656 | D22: 94370 | E22: 233530 | F22: 207842 | G22: 225657 | H22: 167438 | I22: 182465 | J22: 243096 | K22: 184662 | L22: 257785 | M22: 136927 | N22: 249802 | O22: =SUM(C22:N22) -> 2321230
B23: 福利厚生費 | C23: 0 | D23: 0 | E23: 0 | F23: 0 | G23: 50500 | H23: 5000 | I23: 0 | J23: 0 | K23: 0 | L23: 0 | M23: 0 | N23: 0 | O23: =SUM(C23:N23) -> 55500
B24: 業務委託費 | C24: 399020 | D24: 380774 | E24: 270522 | F24: 357924 | G24: 290836 | H24: 300039 | I24: 305298 | J24: 273130 | K24: 355882 | L24: 371731 | M24: 517264 | N24: 366911 | O24: =SUM(C24:N24) -> 4189331
B25: 広告宣伝費 | C25: 186903 | D25: 179400 | E25: 177560 | F25: 176503 | G25: 215303 | H25: 210153 | I25: 112000 | J25: 2162421 | K25: 108000 | L25: 100654 | M25: 134400 | N25: 123402 | O25: =SUM(C25:N25) -> 3886699
B26: 接待交際費 | O26: =SUM(C26:N26) -> 0
B27: 旅費交通費 | C27: 42401 | D27: 43147 | E27: 27646 | F27: 41601 | G27: 47715 | H27: 40511 | I27: 34183 | J27: 42182 | K27: 54459 | L27: 46858 | M27: 52253 | N27: 42731 | O27: =SUM(C27:N27) -> 515687
B28: 通信費 | C28: 45779 | D28: 55395 | E28: 45570 | F28: 44794 | G28: 52175 | H28: 40364 | I28: 54262 | J28: 70983 | K28: 54590 | L28: 122039 | M28: 54629 | N28: 51282 | O28: =SUM(C28:N28) -> 691862
B29: 水道光熱費 | C29: 1055015 | D29: 1104210 | E29: 968209 | F29: 757600 | G29: 878364 | H29: 1110021 | I29: 1144612 | J29: 1235761 | K29: 1093647 | L29: 804331 | M29: 719828 | N29: 852493 | O29: =SUM(C29:N29) -> 11724091
B30: 修繕費 | C30: 13500 | D30: 57300 | E30: 15000 | F30: 0 | G30: 20000 | H30: 19000 | I30: 17000 | J30: 90910 | K30: 0 | L30: 0 | M30: 0 | N30: 15000 | O30: =SUM(C30:N30) -> 247710
B31: 消耗品費 | C31: 332272 | D31: 162804 | E31: 154474 | F31: 229112 | G31: 153400 | H31: 227238 | I31: 157253 | J31: 203697 | K31: 158297 | L31: 160095 | M31: 127598 | N31: 280820 | O31: =SUM(C31:N31) -> 2347060
B32: リース料 | C32: 49700 | D32: 49700 | E32: 49700 | F32: 49700 | G32: 49700 | H32: 49700 | I32: 49700 | J32: 49700 | K32: 49700 | L32: 49700 | M32: 77900 | N32: 49700 | O32: =SUM(C32:N32) -> 624600
B33: 地代家賃 | C33: 1645661 | D33: 1645661 | E33: 1645661 | F33: 1645661 | G33: 1645661 | H33: 1645661 | I33: 1645661 | J33: 1645661 | K33: 1645661 | L33: 1645661 | M33: 1645661 | N33: 1645661 | O33: =SUM(C33:N33) -> 19747932
B34: 賃借料 | C34: 30000 | D34: 30000 | E34: 30000 | F34: 30000 | G34: 30000 | H34: 30000 | I34: 30000 | J34: 30000 | K34: 30000 | L34: 30000 | M34: 30000 | N34: 30000 | O34: =SUM(C34:N34) -> 360000
B35: 保険料 | C35: 22215 | D35: 22215 | E35: 22215 | F35: 22215 | G35: 22215 | H35: 28375 | I35: 28375 | J35: 28375 | K35: 28375 | L35: 28375 | M35: 28375 | N35: 28375 | O35: =SUM(C35:N35) -> 309700
B36: 租税公課 | C36: 146000 | D36: 1000 | E36: 147000 | F36: 0 | G36: 2450 | H36: 148000 | I36: 0 | J36: 0 | K36: 1000 | L36: 125900 | M36: 0 | N36: 1000 | O36: =SUM(C36:N36) -> 572350
B37: 支払手数料 | C37: 238917 | D37: 268309 | E37: 276554 | F37: 224363 | G37: 226852 | H37: 264110 | I37: 245928 | J37: 218075 | K37: 308807 | L37: 185840 | M37: 193092 | N37: 243661 | O37: =SUM(C37:N37) -> 2894508
B38: 会議費 | C38: 0 | D38: 0 | E38: 0 | F38: 0 | G38: 0 | H38: 0 | I38: 0 | J38: 0 | K38: 0 | O38: =SUM(C38:N38) -> 0
B39: 新聞図書費 | C39: 2593 | D39: 0 | E39: 0 | F39: 0 | G39: 0 | H39: 0 | I39: 0 | J39: 0 | K39: 0 | L39: 0 | M39: 0 | O39: =SUM(C39:N39) -> 2593
B40: 減価償却費 | C40: 690589 | D40: 690589 | E40: 690589 | F40: 690589 | G40: 690589 | H40: 690589 | I40: 690589 | J40: 690589 | K40: 690589 | L40: 690589 | M40: 690589 | N40: 690589 | O40: =SUM(C40:N40) -> 8287068
...

Sheet PL推移
B2: CK | C2: 売上高 | D2: =IF(D10<>0,IF(D10=月次PL!C8/1000,"OK",PL推移!D10-月次PL!C8/1000),"nd") -> OK | F2: =IF(F10<>0,IF(月次PL!D8/1000=PL推移!F10,"OK",PL推移!F10-月次PL!D8/1000),"nd") -> OK | H2: =IF(H10<>0,IF(月次PL!E8/1000=PL推移!H10,"OK",PL推移!H10-月次PL!E8/1000),"nd") -> OK | J2: =IF(J10<>0,IF(月次PL!F8/1000=PL推移!J10,"OK",PL推移!J10-月次PL!F8/1000),"nd") -> OK | L2: =IF(L10<>0,IF(月次PL!G8/1000=PL推移!L10,"OK",PL推移!L10-月次PL!G8/1000),"nd") -> OK | N2: =IF(N10<>0,IF(月次PL!H8/1000=PL推移!N10,"OK",PL推移!N10-月次PL!H8/1000),"nd") -> OK | P2: =IF(P10<>0,IF(月次PL!I8/1000=PL推移!P10,"OK",PL推移!P10-月次PL!I8/1000),"nd") -> OK | R2: =IF(R10<>0,IF(月次PL!J8/1000=PL推移!R10,"OK",PL推移!R10-月次PL!J8/1000),"nd") -> OK | T2: =IF(T10<>0,IF(月次PL!K8/1000=PL推移!T10,"OK",PL推移!T10-月次PL!K8/1000),"nd") -> 1.706 | V2: =IF(V10<>0,IF(月次PL!L8/1000=PL推移!V10,"OK",PL推移!V10-月次PL!L8/1000),"nd") -> OK | X2: =IF(X10<>0,IF(月次PL!M8/1000=PL推移!X10,"OK",PL推移!X10-月次PL!M8/1000),"nd") -> OK | Z2: =IF(Z10<>0,IF(月次PL!N8/1000=PL推移!Z10,"OK",PL推移!Z10-月次PL!N8/1000),"nd") -> OK
C3: 粗利益 | D3: =IF(D22<>0,IF(D22=月次PL!C16/1000,"OK",PL推移!D22-月次PL!C16/1000),"nd") -> OK | F3: =IF(F22<>0,IF(F22=月次PL!D16/1000,"OK",PL推移!F22-月次PL!D16/1000),"nd") -> OK | H3: =IF(H22<>0,IF(H22=月次PL!E16/1000,"OK",PL推移!H22-月次PL!E16/1000),"nd") -> OK | J3: =IF(J22<>0,IF(J22=月次PL!F16/1000,"OK",PL推移!J22-月次PL!F16/1000),"nd") -> OK | L3: =IF(L22<>0,IF(L22=月次PL!G16/1000,"OK",PL推移!L22-月次PL!G16/1000),"nd") -> OK | N3: =IF(N22<>0,IF(N22=月次PL!H16/1000,"OK",PL推移!N22-月次PL!H16/1000),"nd") -> OK | P3: =IF(P22<>0,IF(P22=月次PL!I16/1000,"OK",PL推移!P22-月次PL!I16/1000),"nd") -> OK | R3: =IF(R22<>0,IF(R22=月次PL!J16/1000,"OK",PL推移!R22-月次PL!J16/1000),"nd") -> OK | T3: =IF(T22<>0,IF(T22=月次PL!K16/1000,"OK",PL推移!T22-月次PL!K16/1000),"nd") -> 1.706 | V3: =IF(V22<>0,IF(V22=月次PL!L16/1000,"OK",PL推移!V22-月次PL!L16/1000),"nd") -> OK | X3: =IF(X22<>0,IF(X22=月次PL!M16/1000,"OK",PL推移!X22-月次PL!M16/1000),"nd") -> OK | Z3: =IF(Z22<>0,IF(Z22=月次PL!N16/1000,"OK",PL推移!Z22-月次PL!N16/1000),"nd") -> OK
C4: 販管費 | D4: =IF(D28<>0,IF(D28=月次PL!C44/1000,"OK",PL推移!D28-月次PL!C44/1000),"nd") -> OK | F4: =IF(F28<>0,IF(F28=月次PL!D44/1000,"OK",PL推移!F28-月次PL!D44/1000),"nd") -> OK | H4: =IF(H28<>0,IF(H28=月次PL!E44/1000,"OK",PL推移!H28-月次PL!E44/1000),"nd") -> OK | J4: =IF(J28<>0,IF(J28=月次PL!F44/1000,"OK",PL推移!J28-月次PL!F44/1000),"nd") -> OK | L4: =IF(L28<>0,IF(L28=月次PL!G44/1000,"OK",PL推移!L28-月次PL!G44/1000),"nd") -> OK | N4: =IF(N28<>0,IF(N28=月次PL!H44/1000,"OK",PL推移!N28-月次PL!H44/1000),"nd") -> OK | P4: =IF(P28<>0,IF(P28=月次PL!I44/1000,"OK",PL推移!P28-月次PL!I44/1000),"nd") -> OK | R4: =IF(R28<>0,IF(R28=月次PL!J44/1000,"OK",PL推移!R28-月次PL!J44/1000),"nd") -> OK | T4: =IF(T28<>0,IF(T28=月次PL!K44/1000,"OK",PL推移!T28-月次PL!K44/1000),"nd") -> OK | V4: =IF(V28<>0,IF(V28=月次PL!L44/1000,"OK",PL推移!V28-月次PL!L44/1000),"nd") -> OK | X4: =IF(X28<>0,IF(X28=月次PL!M44/1000,"OK",PL推移!X28-月次PL!M44/1000),"nd") -> OK | Z4: =IF(Z28<>0,IF(Z28=月次PL!N44/1000,"OK",PL推移!Z28-月次PL!N44/1000),"nd") -> OK
C5: 営業利益 | D5: =IF(D50<>0,IF(D50=月次PL!C45/1000,"OK",PL推移!D50-月次PL!C45/1000),"nd") -> OK | F5: =IF(F50<>0,IF(F50=月次PL!D45/1000,"OK",PL推移!F50-月次PL!D45/1000),"nd") -> -5.6843419e-13 | H5: =IF(H50<>0,IF(H50=月次PL!E45/1000,"OK",PL推移!H50-月次PL!E45/1000),"nd") -> -1.3642421e-12 | J5: =IF(J50<>0,IF(J50=月次PL!F45/1000,"OK",PL推移!J50-月次PL!F45/1000),"nd") -> -1.7408297e-13 | L5: =IF(L50<>0,IF(L50=月次PL!G45/1000,"OK",PL推移!L50-月次PL!G45/1000),"nd") -> OK | N5: =IF(N50<>0,IF(N50=月次PL!H45/1000,"OK",PL推移!N50-月次PL!H45/1000),"nd") -> OK | P5: =IF(P50<>0,IF(P50=月次PL!I45/1000,"OK",PL推移!P50-月次PL!I45/1000),"nd") -> OK | R5: =IF(R50<>0,IF(R50=月次PL!J45/1000,"OK",PL推移!R50-月次PL!J45/1000),"nd") -> OK | T5: =IF(T50<>0,IF(T50=月次PL!K45/1000,"OK",PL推移!T50-月次PL!K45/1000),"nd") -> 1.706 | V5: =IF(V50<>0,IF(V50=月次PL!L45/1000,"OK",PL推移!V50-月次PL!L45/1000),"nd") -> OK | X5: =IF(X50<>0,IF(X50=月次PL!M45/1000,"OK",PL推移!X50-月次PL!M45/1000),"nd") -> 1.2505552e-12 | Z5: =IF(Z50<>0,IF(Z50=月次PL!N45/1000,"OK",PL推移!Z50-月次PL!N45/1000),"nd") -> OK
C6: 経常利益 | D6: =IF(D54<>0,IF(D54=月次PL!C56/1000,"OK",PL推移!D54-月次PL!C56/1000),"nd") -> -3.5527137e-13 | F6: =IF(F54<>0,IF(F54=月次PL!D56/1000,"OK",PL推移!F54-月次PL!D56/1000),"nd") -> -5.6843419e-13 | H6: =IF(H54<>0,IF(H54=月次PL!E56/1000,"OK",PL推移!H54-月次PL!E56/1000),"nd") -> -1.4210855e-12 | J6: =IF(J54<>0,IF(J54=月次PL!F56/1000,"OK",PL推移!J54-月次PL!F56/1000),"nd") -> OK | L6: =IF(L54<>0,IF(L54=月次PL!G56/1000,"OK",PL推移!L54-月次PL!G56/1000),"nd") -> OK | N6: =IF(N54<>0,IF(N54=月次PL!H56/1000,"OK",PL推移!N54-月次PL!H56/1000),"nd") -> OK | P6: =IF(P54<>0,IF(P54=月次PL!I56/1000,"OK",PL推移!P54-月次PL!I56/1000),"nd") -> OK | R6: =IF(R54<>0,IF(R54=月次PL!J56/1000,"OK",PL推移!R54-月次PL!J56/1000),"nd") -> OK | T6: =IF(T54<>0,IF(T54=月次PL!K56/1000,"OK",PL推移!T54-月次PL!K56/1000),"nd") -> 1.706 | V6: =IF(V54<>0,IF(V54=月次PL!L56/1000,"OK",PL推移!V54-月次PL!L56/1000),"nd") -> OK | X6: =IF(X54<>0,IF(X54=月次PL!M56/1000,"OK",PL推移!X54-月次PL!M56/1000),"nd") -> 1.2505552e-12 | Z6: =IF(Z54<>0,IF(Z54=月次PL!N56/1000,"OK",PL推移!Z54-月次PL!N56/1000),"nd") -> OK
B7: ■月次報告PL | D7: ㈱ｅｓエンターテイメント
B8: 2025 | C8: 年度 | D8: 単位：千円 | F8: 注意事項 | G8: 概算値 | H8: 異常値 | I8: 処理検討 | J8: 予算検討
B9: 項目 | D9: =+月次PL!C1 -> 7月 | F9: =+月次PL!D1 -> 8月 | H9: =+月次PL!E1 -> 9月 | J9: =+月次PL!F1 -> 10月 | L9: =+月次PL!G1 -> 11月 | N9: =+月次PL!H1 -> 12月 | P9: =+月次PL!I1 -> 1月 | R9: =+月次PL!J1 -> 2月 | T9: =+月次PL!K1 -> 3 | V9: =+月次PL!L1 -> 4 | X9: =+月次PL!M1 -> 5月 | Z9: =+月次PL!N1 -> 6月
B10: 売上高 | D10: =+月次PL!C8/1000 -> 9274.574 | E10: =IF(D$10<>0,D10/D$10,0) -> 1 | F10: =+月次PL!D8/1000 -> 9965.918 | G10: =IF(F$10<>0,F10/F$10,0) -> 1 | H10: =+月次PL!E8/1000 -> 7867.963 | I10: =IF(H$10<>0,H10/H$10,0) -> 1 | J10: =+月次PL!F8/1000 -> 8303.914 | K10: =IF(J$10<>0,J10/J$10,0) -> 1 | L10: =+月次PL!G8/1000 -> 8180.981 | M10: =IF(L$10<>0,L10/L$10,0) -> 1 | N10: =+月次PL!H8/1000 -> 11655.276 | O10: =IF(N$10<>0,N10/N$10,0) -> 1 | P10: =+月次PL!I8/1000 -> 7802.191 | Q10: =IF(P$10<>0,P10/P$10,0) -> 1 | R10: =+月次PL!J8/1000 -> 8081.41 | S10: =IF(R$10<>0,R10/R$10,0) -> 1 | T10: =SUM(T11:T15)+350-11 -> 8746 | U10: =IF(T$10<>0,T10/T$10,0) -> 1 | V10: =+月次PL!L8/1000 -> 7203.994 | W10: =IF(V$10<>0,V10/V$10,0) -> 1 | X10: =+月次PL!M8/1000 -> 7595.88 | Y10: =IF(X$10<>0,X10/X$10,0) -> 1 | Z10: =+月次PL!N8/1000 -> 7697.243 | AA10: =IF(Z$10<>0,Z10/Z$10,0) -> 1
C11: 恵愛 | D11: 6973 | E11: =IF(D$10<>0,D11/D$10,0) -> 0.75184046 | F11: 6864 | G11: =IF(F$10<>0,F11/F$10,0) -> 0.68874739 | H11: 5812 | I11: =IF(H$10<>0,H11/H$10,0) -> 0.73869183 | J11: 5700 | K11: =IF(J$10<>0,J11/J$10,0) -> 0.68642329 | L11: 6255 | M11: =IF(L$10<>0,L11/L$10,0) -> 0.76457823 | N11: 9574 | O11: =IF(N$10<>0,N11/N$10,0) -> 0.82143057 | P11: 5703 | Q11: =IF(P$10<>0,P11/P$10,0) -> 0.73094852 | R11: 6142 | S11: =IF(R$10<>0,R11/R$10,0) -> 0.76001589 | T11: 6615 | U11: =IF(T$10<>0,T11/T$10,0) -> 0.75634576 | V11: 4998 | W11: =IF(V$10<>0,V11/V$10,0) -> 0.69378181 | X11: 5401 | Y11: =IF(X$10<>0,X11/X$10,0) -> 0.71104336 | Z11: 5367 | AA11: =IF(Z$10<>0,Z11/Z$10,0) -> 0.69726264
C12: 村 | D12: 573 | E12: =IF(D$10<>0,D12/D$10,0) -> 0.061781813 | F12: 597 | G12: =IF(F$10<>0,F12/F$10,0) -> 0.059904165 | H12: 602 | I12: =IF(H$10<>0,H12/H$10,0) -> 0.076512815 | J12: 580 | K12: =IF(J$10<>0,J12/J$10,0) -> 0.069846581 | L12: 531 | M12: =IF(L$10<>0,L12/L$10,0) -> 0.064906641 | N12: 558 | O12: =IF(N$10<>0,N12/N$10,0) -> 0.047875314 | P12: 590 | Q12: =IF(P$10<>0,P12/P$10,0) -> 0.075619784 | R12: 596 | S12: =IF(R$10<>0,R12/R$10,0) -> 0.073749507 | T12: 606 | U12: =IF(T$10<>0,T12/T$10,0) -> 0.069288818 | V12: 541 | W12: =IF(V$10<>0,V12/V$10,0) -> 0.075097231 | X12: 611 | Y12: =IF(X$10<>0,X12/X$10,0) -> 0.080438343 | Z12: 600 | AA12: =IF(Z$10<>0,Z12/Z$10,0) -> 0.077949988
C13: 弁当 | D13: 464 | E13: =IF(D$10<>0,D13/D$10,0) -> 0.050029252 | F13: 361 | G13: =IF(F$10<>0,F13/F$10,0) -> 0.036223457 | H13: 266 | I13: =IF(H$10<>0,H13/H$10,0) -> 0.033807988 | J13: 209 | K13: =IF(J$10<>0,J13/J$10,0) -> 0.025168854 | L13: 279 | M13: =IF(L$10<>0,L13/L$10,0) -> 0.03410349 | N13: 318 | O13: =IF(N$10<>0,N13/N$10,0) -> 0.027283781 | P13: 337 | Q13: =IF(P$10<>0,P13/P$10,0) -> 0.043192995 | R13: 243 | S13: =IF(R$10<>0,R13/R$10,0) -> 0.03006901 | T13: 371 | U13: =IF(T$10<>0,T13/T$10,0) -> 0.042419392 | V13: 421 | W13: =IF(V$10<>0,V13/V$10,0) -> 0.058439804 | X13: 460 | Y13: =IF(X$10<>0,X13/X$10,0) -> 0.060559145 | Z13: 444 | AA13: =IF(Z$10<>0,Z13/Z$10,0) -> 0.057682991 | AB13: =+D13+F13+H13+J13+L13+N13+P13+R13+T13 -> 2848
C14: シェア | D14: 129 | E14: =IF(D$10<>0,D14/D$10,0) -> 0.013908995 | F14: 180 | G14: =IF(F$10<>0,F14/F$10,0) -> 0.018061557 | H14: 72 | I14: =IF(H$10<>0,H14/H$10,0) -> 0.0091510344 | J14: 283 | K14: =IF(J$10<>0,J14/J$10,0) -> 0.034080314 | L14: 123 | M14: =IF(L$10<>0,L14/L$10,0) -> 0.015034872 | N14: 131 | O14: =IF(N$10<>0,N14/N$10,0) -> 0.011239545 | P14: 106 | Q14: =IF(P$10<>0,P14/P$10,0) -> 0.013585927 | R14: 90 | S14: =IF(R$10<>0,R14/R$10,0) -> 0.01113667 | T14: 125 | U14: =IF(T$10<>0,T14/T$10,0) -> 0.014292248 | V14: 100 | W14: =IF(V$10<>0,V14/V$10,0) -> 0.013881189 | X14: 83 | Y14: =IF(X$10<>0,X14/X$10,0) -> 0.010926976 | Z14: 75 | AA14: =IF(Z$10<>0,Z14/Z$10,0) -> 0.0097437485
C15: サウナ | D15: 786 | E15: =IF(D$10<>0,D15/D$10,0) -> 0.084747828 | F15: 1614 | G15: =IF(F$10<>0,F15/F$10,0) -> 0.16195196 | H15: 765 | I15: =IF(H$10<>0,H15/H$10,0) -> 0.09722974 | J15: 1191 | K15: =IF(J$10<>0,J15/J$10,0) -> 0.14342634 | L15: 643 | M15: =IF(L$10<>0,L15/L$10,0) -> 0.078596931 | N15: 1021 | O15: =IF(N$10<>0,N15/N$10,0) -> 0.087599813 | P15: 716 | Q15: =IF(P$10<>0,P15/P$10,0) -> 0.091769094 | R15: 646 | S15: =IF(R$10<>0,R15/R$10,0) -> 0.079936546 | T15: 690 | U15: =IF(T$10<>0,T15/T$10,0) -> 0.078893208 | V15: 604 | W15: =IF(V$10<>0,V15/V$10,0) -> 0.08384238 | X15: 553 | Y15: =IF(X$10<>0,X15/X$10,0) -> 0.072802625 | Z15: 565 | AA15: =IF(Z$10<>0,Z15/Z$10,0) -> 0.073402905
B16: 売上原価 | D16: =+月次PL!C15/1000 -> 2134.92 | E16: =IF(D$10<>0,D16/D$10,0) -> 0.23019063 | F16: =+月次PL!D15/1000 -> 2119.416 | G16: =IF(F$10<>0,F16/F$10,0) -> 0.21266641 | H16: =+月次PL!E15/1000 -> 1606.557 | I16: =IF(H$10<>0,H16/H$10,0) -> 0.2041897 | J16: =+月次PL!F15/1000 -> 1700.604 | K16: =IF(J$10<>0,J16/J$10,0) -> 0.20479547 | L16: =+月次PL!G15/1000 -> 1780.96 | M16: =IF(L$10<>0,L16/L$10,0) -> 0.21769516 | N16: =+月次PL!H15/1000 -> 2735.274 | O16: =IF(N$10<>0,N16/N$10,0) -> 0.23468119 | P16: =+月次PL!I15/1000 -> 1730.478 | Q16: =IF(P$10<>0,P16/P$10,0) -> 0.22179385 | R16: =+月次PL!J15/1000 -> 1869.553 | S16: =IF(R$10<>0,R16/R$10,0) -> 0.23133995 | T16: =+月次PL!K15/1000 -> 2027.335 | U16: =IF(T$10<>0,T16/T$10,0) -> 0.23180139 | V16: =+月次PL!L15/1000 -> 1978.728 | W16: =IF(V$10<>0,V16/V$10,0) -> 0.27467097 | X16: =+月次PL!M15/1000 -> 1982.524 | Y16: =IF(X$10<>0,X16/X$10,0) -> 0.26099991 | Z16: =+月次PL!N15/1000 -> 1865.938 | AA16: =IF(Z$10<>0,Z16/Z$10,0) -> 0.24241641
C17: =+C11 -> 恵愛 | D17: 1815 | E17: =IF(D11<>0,D17/D11,0) -> 0.26028969 | F17: 1783 | G17: =IF(F11<>0,F17/F11,0) -> 0.25976107 | H17: 1374 | I17: =IF(H11<>0,H17/H11,0) -> 0.23640743 | J17: 1329 | K17: =IF(J11<>0,J17/J11,0) -> 0.23315789 | L17: 1535 | M17: =IF(L11<>0,L17/L11,0) -> 0.24540368 | N17: 2301 | O17: =IF(N11<>0,N17/N11,0) -> 0.24033842 | P17: 1459 | Q17: =IF(P11<>0,P17/P11,0) -> 0.25583026 | R17: 1573 | S17: =IF(R11<>0,R17/R11,0) -> 0.2561055 | T17: 1698 | U17: =IF(T11<>0,T17/T11,0) -> 0.25668934 | V17: 1609 | W17: =IF(V11<>0,V17/V11,0) -> 0.32192877 | X17: 1737 | Y17: =IF(X11<>0,X17/X11,0) -> 0.32160711 | Z17: 1556 | AA17: =IF(Z11<>0,Z17/Z11,0) -> 0.28991988
C18: =+C12 -> 村 | D18: 65 | E18: =IF(D12<>0,D18/D12,0) -> 0.11343805 | F18: 78 | G18: =IF(F12<>0,F18/F12,0) -> 0.13065327 | H18: 59 | I18: =IF(H12<>0,H18/H12,0) -> 0.098006645 | J18: 145 | K18: =IF(J12<>0,J18/J12,0) -> 0.25 | L18: 69 | M18: =IF(L12<>0,L18/L12,0) -> 0.1299435 | N18: 142 | O18: =IF(N12<>0,N18/N12,0) -> 0.25448029 | P18: 87 | Q18: =IF(P12<>0,P18/P12,0) -> 0.14745763 | R18: 100 | S18: =IF(R12<>0,R18/R12,0) -> 0.16778523 | T18: 110 | U18: =IF(T12<>0,T18/T12,0) -> 0.18151815 | V18: 135 | W18: =IF(V12<>0,V18/V12,0) -> 0.24953789 | X18: 102 | Y18: =IF(X12<>0,X18/X12,0) -> 0.16693944 | Z18: 66 | AA18: =IF(Z12<>0,Z18/Z12,0) -> 0.11
C19: =+C13 -> 弁当 | D19: 148 | E19: =IF(D13<>0,D19/D13,0) -> 0.31896552 | F19: 158 | G19: =IF(F13<>0,F19/F13,0) -> 0.43767313 | H19: 135 | I19: =IF(H13<>0,H19/H13,0) -> 0.5075188 | J19: 100 | K19: =IF(J13<>0,J19/J13,0) -> 0.4784689 | L19: 133 | M19: =IF(L13<>0,L19/L13,0) -> 0.47670251 | N19: 129 | O19: =IF(N13<>0,N19/N13,0) -> 0.40566038 | P19: 148 | Q19: =IF(P13<>0,P19/P13,0) -> 0.43916914 | R19: 130 | S19: =IF(R13<>0,R19/R13,0) -> 0.53497942 | T19: 148 | U19: =IF(T13<>0,T19/T13,0) -> 0.39892183 | V19: 163 | W19: =IF(V13<>0,V19/V13,0) -> 0.3871734 | X19: 131 | Y19: =IF(X13<>0,X19/X13,0) -> 0.28478261 | Z19: 197 | AA19: =IF(Z13<>0,Z19/Z13,0) -> 0.44369369 | AB19: =+D19+F19+H19+J19+L19+N19+P19+R19+T19 -> 1229 | AC19: =+AB19/AB13 -> 0.4315309
C20: =+C14 -> シェア | D20: 39 | E20: =IF(D14<>0,D20/D14,0) -> 0.30232558 | F20: 54 | G20: =IF(F14<>0,F20/F14,0) -> 0.3 | H20: 22 | I20: =IF(H14<>0,H20/H14,0) -> 0.30555556 | J20: 84 | K20: =IF(J14<>0,J20/J14,0) -> 0.29681979 | L20: 37 | M20: =IF(L14<>0,L20/L14,0) -> 0.30081301 | N20: 44 | O20: =IF(N14<>0,N20/N14,0) -> 0.33587786 | P20: 32 | Q20: =IF(P14<>0,P20/P14,0) -> 0.30188679 | R20: 27 | S20: =IF(R14<>0,R20/R14,0) -> 0.3 | T20: 38 | U20: =IF(T14<>0,T20/T14,0) -> 0.304 | V20: 30 | W20: =IF(V14<>0,V20/V14,0) -> 0.3 | X20: 25 | Y20: =IF(X14<>0,X20/X14,0) -> 0.30120482 | Z20: 22 | AA20: =IF(Z14<>0,Z20/Z14,0) -> 0.29333333
C21: =+C15 -> サウナ | D21: 67 | E21: =IF(D15<>0,D21/D15,0) -> 0.08524173 | F21: 45 | G21: =IF(F15<>0,F21/F15,0) -> 0.027881041 | H21: 6 | I21: =IF(H15<>0,H21/H15,0) -> 0.0078431373 | J21: 41 | K21: =IF(J15<>0,J21/J15,0) -> 0.034424853 | L21: 6 | M21: =IF(L15<>0,L21/L15,0) -> 0.0093312597 | N21: 28 | O21: =IF(N15<>0,N21/N15,0) -> 0.027424094 | P21: 4 | Q21: =IF(P15<>0,P21/P15,0) -> 0.0055865922 | R21: 39 | S21: =IF(R15<>0,R21/R15,0) -> 0.060371517 | T21: 35 | U21: =IF(T15<>0,T21/T15,0) -> 0.050724638 | V21: 23 | W21: =IF(V15<>0,V21/V15,0) -> 0.03807947 | X21: 21 | Y21: =IF(X15<>0,X21/X15,0) -> 0.037974684 | Z21: 24 | AA21: =IF(Z15<>0,Z21/Z15,0) -> 0.042477876
B22: 粗利益 | D22: =+D10-D16 -> 7139.654 | E22: =IF(D$10<>0,D22/D$10,0) -> 0.76980937 | F22: =+F10-F16 -> 7846.502 | G22: =IF(F$10<>0,F22/F$10,0) -> 0.78733359 | H22: =+H10-H16 -> 6261.406 | I22: =IF(H$10<>0,H22/H$10,0) -> 0.7958103 | J22: =+J10-J16 -> 6603.31 | K22: =IF(J$10<>0,J22/J$10,0) -> 0.79520453 | L22: =+L10-L16 -> 6400.021 | M22: =IF(L$10<>0,L22/L$10,0) -> 0.78230484 | N22: =+N10-N16 -> 8920.002 | O22: =IF(N$10<>0,N22/N$10,0) -> 0.76531881 | P22: =+P10-P16 -> 6071.713 | Q22: =IF(P$10<>0,P22/P$10,0) -> 0.77820615 | R22: =+R10-R16 -> 6211.857 | S22: =IF(R$10<>0,R22/R$10,0) -> 0.76866005 | T22: =+T10-T16 -> 6718.665 | U22: =IF(T$10<>0,T22/T$10,0) -> 0.76819861 | V22: =+V10-V16 -> 5225.266 | W22: =IF(V$10<>0,V22/V$10,0) -> 0.72532903 | X22: =+X10-X16 -> 5613.356 | Y22: =IF(X$10<>0,X22/X$10,0) -> 0.73900009 | Z22: =+Z10-Z16 -> 5831.305 | AA22: =IF(Z$10<>0,Z22/Z$10,0) -> 0.75758359
C23: =+C17 -> 恵愛 | D23: =+D11-D17 -> 5158 | E23: =IF(D11<>0,D23/D11,0) -> 0.73971031 | F23: =+F11-F17 -> 5081 | G23: =IF(F11<>0,F23/F11,0) -> 0.74023893 | H23: =+H11-H17 -> 4438 | I23: =IF(H11<>0,H23/H11,0) -> 0.76359257 | J23: =+J11-J17 -> 4371 | K23: =IF(J11<>0,J23/J11,0) -> 0.76684211 | L23: =+L11-L17 -> 4720 | M23: =IF(L11<>0,L23/L11,0) -> 0.75459632 | N23: =+N11-N17 -> 7273 | O23: =IF(N11<>0,N23/N11,0) -> 0.75966158 | P23: =+P11-P17 -> 4244 | Q23: =IF(P11<>0,P23/P11,0) -> 0.74416974 | R23: =+R11-R17 -> 4569 | S23: =IF(R11<>0,R23/R11,0) -> 0.7438945 | T23: =+T11-T17 -> 4917 | U23: =IF(T11<>0,T23/T11,0) -> 0.74331066 | V23: =+V11-V17 -> 3389 | W23: =IF(V11<>0,V23/V11,0) -> 0.67807123 | X23: =+X11-X17 -> 3664 | Y23: =IF(X11<>0,X23/X11,0) -> 0.67839289 | Z23: =+Z11-Z17 -> 3811 | AA23: =IF(Z11<>0,Z23/Z11,0) -> 0.71008012
C24: =+C18 -> 村 | D24: =+D12-D18 -> 508 | E24: =IF(D12<>0,D24/D12,0) -> 0.88656195 | F24: =+F12-F18 -> 519 | G24: =IF(F12<>0,F24/F12,0) -> 0.86934673 | H24: =+H12-H18 -> 543 | I24: =IF(H12<>0,H24/H12,0) -> 0.90199336 | J24: =+J12-J18 -> 435 | K24: =IF(J12<>0,J24/J12,0) -> 0.75 | L24: =+L12-L18 -> 462 | M24: =IF(L12<>0,L24/L12,0) -> 0.8700565 | N24: =+N12-N18 -> 416 | O24: =IF(N12<>0,N24/N12,0) -> 0.74551971 | P24: =+P12-P18 -> 503 | Q24: =IF(P12<>0,P24/P12,0) -> 0.85254237 | R24: =+R12-R18 -> 496 | S24: =IF(R12<>0,R24/R12,0) -> 0.83221477 | T24: =+T12-T18 -> 496 | U24: =IF(T12<>0,T24/T12,0) -> 0.81848185 | V24: =+V12-V18 -> 406 | W24: =IF(V12<>0,V24/V12,0) -> 0.75046211 | X24: =+X12-X18 -> 509 | Y24: =IF(X12<>0,X24/X12,0) -> 0.83306056 | Z24: =+Z12-Z18 -> 534 | AA24: =IF(Z12<>0,Z24/Z12,0) -> 0.89
C25: =+C19 -> 弁当 | D25: =+D13-D19 -> 316 | E25: =IF(D13<>0,D25/D13,0) -> 0.68103448 | F25: =+F13-F19 -> 203 | G25: =IF(F13<>0,F25/F13,0) -> 0.56232687 | H25: =+H13-H19 -> 131 | I25: =IF(H13<>0,H25/H13,0) -> 0.4924812 | J25: =+J13-J19 -> 109 | K25: =IF(J13<>0,J25/J13,0) -> 0.5215311 | L25: =+L13-L19 -> 146 | M25: =IF(L13<>0,L25/L13,0) -> 0.52329749 | N25: =+N13-N19 -> 189 | O25: =IF(N13<>0,N25/N13,0) -> 0.59433962 | P25: =+P13-P19 -> 189 | Q25: =IF(P13<>0,P25/P13,0) -> 0.56083086 | R25: =+R13-R19 -> 113 | S25: =IF(R13<>0,R25/R13,0) -> 0.46502058 | T25: =+T13-T19 -> 223 | U25: =IF(T13<>0,T25/T13,0) -> 0.60107817 | V25: =+V13-V19 -> 258 | W25: =IF(V13<>0,V25/V13,0) -> 0.6128266 | X25: =+X13-X19 -> 329 | Y25: =IF(X13<>0,X25/X13,0) -> 0.71521739 | Z25: =+Z13-Z19 -> 247 | AA25: =IF(Z13<>0,Z25/Z13,0) -> 0.55630631
C26: =+C20 -> シェア | D26: =+D14-D20 -> 90 | E26: =IF(D14<>0,D26/D14,0) -> 0.69767442 | F26: =+F14-F20 -> 126 | G26: =IF(F14<>0,F26/F14,0) -> 0.7 | H26: =+H14-H20 -> 50 | I26: =IF(H14<>0,H26/H14,0) -> 0.69444444 | J26: =+J14-J20 -> 199 | K26: =IF(J14<>0,J26/J14,0) -> 0.70318021 | L26: =+L14-L20 -> 86 | M26: =IF(L14<>0,L26/L14,0) -> 0.69918699 | N26: =+N14-N20 -> 87 | O26: =IF(N14<>0,N26/N14,0) -> 0.66412214 | P26: =+P14-P20 -> 74 | Q26: =IF(P14<>0,P26/P14,0) -> 0.69811321 | R26: =+R14-R20 -> 63 | S26: =IF(R14<>0,R26/R14,0) -> 0.7 | T26: =+T14-T20 -> 87 | U26: =IF(T14<>0,T26/T14,0) -> 0.696 | V26: =+V14-V20 -> 70 | W26: =IF(V14<>0,V26/V14,0) -> 0.7 | X26: =+X14-X20 -> 58 | Y26: =IF(X14<>0,X26/X14,0) -> 0.69879518 | Z26: =+Z14-Z20 -> 53 | AA26: =IF(Z14<>0,Z26/Z14,0) -> 0.70666667
C27: =+C21 -> サウナ | D27: =+D15-D21 -> 719 | E27: =IF(D15<>0,D27/D15,0) -> 0.91475827 | F27: =+F15-F21 -> 1569 | G27: =IF(F15<>0,F27/F15,0) -> 0.97211896 | H27: =+H15-H21 -> 759 | I27: =IF(H15<>0,H27/H15,0) -> 0.99215686 | J27: =+J15-J21 -> 1150 | K27: =IF(J15<>0,J27/J15,0) -> 0.96557515 | L27: =+L15-L21 -> 637 | M27: =IF(L15<>0,L27/L15,0) -> 0.99066874 | N27: =+N15-N21 -> 993 | O27: =IF(N15<>0,N27/N15,0) -> 0.97257591 | P27: =+P15-P21 -> 712 | Q27: =IF(P15<>0,P27/P15,0) -> 0.99441341 | R27: =+R15-R21 -> 607 | S27: =IF(R15<>0,R27/R15,0) -> 0.93962848 | T27: =+T15-T21 -> 655 | U27: =IF(T15<>0,T27/T15,0) -> 0.94927536 | V27: =+V15-V21 -> 581 | W27: =IF(V15<>0,V27/V15,0) -> 0.96192053 | X27: =+X15-X21 -> 532 | Y27: =IF(X15<>0,X27/X15,0) -> 0.96202532 | Z27: =+Z15-Z21 -> 541 | AA27: =IF(Z15<>0,Z27/Z15,0) -> 0.95752212
B28: 販売管理費 | D28: =SUM(D29:D49) -> 7029.379 | E28: =IF(D$10<>0,D28/D$10,0) -> 0.75791934 | F28: =SUM(F29:F49) -> 6877.286 | G28: =IF(F$10<>0,F28/F$10,0) -> 0.69008053 | H28: =SUM(H29:H49) -> 6946.261 | I28: =IF(H$10<>0,H28/H$10,0) -> 0.8828538 | J28: =SUM(J29:J49) -> 6577.418 | K28: =IF(J$10<>0,J28/J$10,0) -> 0.79208648 | L28: =SUM(L29:L49) -> 6664.637 | M28: =IF(L$10<>0,L28/L$10,0) -> 0.8146501 | N28: =SUM(N29:N49) -> 7432.57 | O28: =IF(N$10<>0,N28/N$10,0) -> 0.63770004 | P28: =SUM(P29:P49) -> 7154.905 | Q28: =IF(P$10<>0,P28/P$10,0) -> 0.91703792 | R28: =SUM(R29:R49) -> 9370.861 | S28: =IF(R$10<>0,R28/R$10,0) -> 1.1595577 | T28: =SUM(T29:T49) -> 7545.12 | U28: =IF(T$10<>0,T28/T$10,0) -> 0.8626938 | V28: =SUM(V29:V49) -> 6818.127 | W28: =IF(V$10<>0,V28/V$10,0) -> 0.94643707 | X28: =SUM(X29:X49) -> 6533.591 | Y28: =IF(X$10<>0,X28/X$10,0) -> 0.86014932 | Z28: =SUM(Z29:Z49) -> 6706.484 | AA28: =IF(Z$10<>0,Z28/Z$10,0) -> 0.87128391
C29: 人件費 | D29: =SUM(月次PL!C18:C24)/1000 -> 2371.946 | E29: =IF(D$10<>0,D29/D$10,0) -> 0.25574716 | F29: =SUM(月次PL!D18:D24)/1000 -> 2352.858 | G29: =IF(F$10<>0,F29/F$10,0) -> 0.23609044 | H29: =SUM(月次PL!E18:E24)/1000 -> 2266.491 | I29: =IF(H$10<>0,H29/H$10,0) -> 0.28806579 | J29: =SUM(月次PL!F18:F24)/1000 -> 2375.566 | K29: =IF(J$10<>0,J29/J$10,0) -> 0.28607787 | L29: =SUM(月次PL!G18:G24)/1000 -> 2397.808 | M29: =IF(L$10<>0,L29/L$10,0) -> 0.29309541 | N29: =SUM(月次PL!H18:H24)/1000 -> 2816.608 | O29: =IF(N$10<>0,N29/N$10,0) -> 0.24165949 | P29: =SUM(月次PL!I18:I24)/1000 -> 2804.184 | Q29: =IF(P$10<>0,P29/P$10,0) -> 0.35940981 | R29: =SUM(月次PL!J18:J24)/1000 -> 2790.627 | S29: =IF(R$10<>0,R29/R$10,0) -> 0.34531437 | T29: =SUM(月次PL!K18:K24)/1000 -> 3189.715 | U29: =IF(T$10<>0,T29/T$10,0) -> 0.36470558 | V29: =SUM(月次PL!L18:L24)/1000 -> 2649.797 | W29: =IF(V$10<>0,V29/V$10,0) -> 0.36782332 | X29: =SUM(月次PL!M18:M24)/1000 -> 2670.396 | Y29: =IF(X$10<>0,X29/X$10,0) -> 0.35155848 | Z29: =SUM(月次PL!N18:N24)/1000 -> 2522.78 | AA29: =IF(Z$10<>0,Z29/Z$10,0) -> 0.32775112
C30: 旅費交通費 | D30: =+月次PL!C27/1000 -> 42.401 | E30: =IF(D$10<>0,D30/D$10,0) -> 0.0045717464 | F30: =+月次PL!D27/1000 -> 43.147 | G30: =IF(F$10<>0,F30/F$10,0) -> 0.0043294557 | H30: =+月次PL!E27/1000 -> 27.646 | I30: =IF(H$10<>0,H30/H$10,0) -> 0.003513743 | J30: =+月次PL!F27/1000 -> 41.601 | K30: =IF(J$10<>0,J30/J$10,0) -> 0.0050098062 | L30: =+月次PL!G27/1000 -> 47.715 | M30: =IF(L$10<>0,L30/L$10,0) -> 0.0058324301 | N30: =+月次PL!H27/1000 -> 40.511 | O30: =IF(N$10<>0,N30/N$10,0) -> 0.003475765 | P30: =+月次PL!I27/1000 -> 34.183 | Q30: =IF(P$10<>0,P30/P$10,0) -> 0.0043812052 | R30: =+月次PL!J27/1000 -> 42.182 | S30: =IF(R$10<>0,R30/R$10,0) -> 0.0052196337 | T30: =+月次PL!K27/1000 -> 54.459 | U30: =IF(T$10<>0,T30/T$10,0) -> 0.0062267322 | V30: =+月次PL!L27/1000 -> 46.858 | W30: =IF(V$10<>0,V30/V$10,0) -> 0.0065044474 | X30: =+月次PL!M27/1000 -> 52.253 | Y30: =IF(X$10<>0,X30/X$10,0) -> 0.0068791239 | Z30: =+月次PL!N27/1000 -> 42.731 | AA30: =IF(Z$10<>0,Z30/Z$10,0) -> 0.0055514682
C31: 通信費 | D31: =+月次PL!C28/1000 -> 45.779 | E31: =IF(D$10<>0,D31/D$10,0) -> 0.0049359679 | F31: =+月次PL!D28/1000 -> 55.395 | G31: =IF(F$10<>0,F31/F$10,0) -> 0.0055584443 | H31: =+月次PL!E28/1000 -> 45.57 | I31: =IF(H$10<>0,H31/H$10,0) -> 0.0057918422 | J31: =+月次PL!F28/1000 -> 44.794 | K31: =IF(J$10<>0,J31/J$10,0) -> 0.0053943237 | L31: =+月次PL!G28/1000 -> 52.175 | M31: =IF(L$10<>0,L31/L$10,0) -> 0.006377597 | N31: =+月次PL!H28/1000 -> 40.364 | O31: =IF(N$10<>0,N31/N$10,0) -> 0.0034631527 | P31: =+月次PL!I28/1000 -> 54.262 | Q31: =IF(P$10<>0,P31/P$10,0) -> 0.0069547131 | R31: =+月次PL!J28/1000 -> 70.983 | S31: =IF(R$10<>0,R31/R$10,0) -> 0.008783492 | T31: =+月次PL!K28/1000 -> 54.59 | U31: =IF(T$10<>0,T31/T$10,0) -> 0.0062417105 | V31: =+月次PL!L28/1000 -> 122.039 | W31: =IF(V$10<>0,V31/V$10,0) -> 0.016940464 | X31: =+月次PL!M28/1000 -> 54.629 | Y31: =IF(X$10<>0,X31/X$10,0) -> 0.0071919251 | Z31: =+月次PL!N28/1000 -> 51.282 | AA31: =IF(Z$10<>0,Z31/Z$10,0) -> 0.0066623855
C32: 開発費 | D32: =+月次PL!C43/1000 -> 21.289 | E32: =IF(D$10<>0,D32/D$10,0) -> 0.0022954154 | F32: =+月次PL!D43/1000 -> 97.177 | G32: =IF(F$10<>0,F32/F$10,0) -> 0.0097509331 | H32: =+月次PL!E43/1000 -> 106.992 | I32: =IF(H$10<>0,H32/H$10,0) -> 0.013598437 | J32: =+月次PL!F43/1000 -> 148.075 | K32: =IF(J$10<>0,J32/J$10,0) -> 0.017831952 | L32: =+月次PL!G43/1000 -> 79.685 | M32: =IF(L$10<>0,L32/L$10,0) -> 0.0097402744 | N32: =+月次PL!H43/1000 -> 0 | O32: =IF(N$10<>0,N32/N$10,0) -> 0 | P32: =+月次PL!I43/1000 -> 0 | Q32: =IF(P$10<>0,P32/P$10,0) -> 0 | R32: =+月次PL!J43/1000 -> 0 | S32: =IF(R$10<>0,R32/R$10,0) -> 0 | T32: =+月次PL!K43/1000 -> 0 | U32: =IF(T$10<>0,T32/T$10,0) -> 0 | V32: =+月次PL!L43/1000 -> 0 | W32: =IF(V$10<>0,V32/V$10,0) -> 0 | X32: =+月次PL!M43/1000 -> 0 | Y32: =IF(X$10<>0,X32/X$10,0) -> 0 | Z32: =+月次PL!N43/1000 -> 0 | AA32: =IF(Z$10<>0,Z32/Z$10,0) -> 0
C33: 交際費 | D33: =+月次PL!C26/1000 -> 0 | E33: =IF(D$10<>0,D33/D$10,0) -> 0 | F33: =+月次PL!D26/1000 -> 0 | G33: =IF(F$10<>0,F33/F$10,0) -> 0 | H33: =+月次PL!E26/1000 -> 0 | I33: =IF(H$10<>0,H33/H$10,0) -> 0 | J33: =+月次PL!F26/1000 -> 0 | K33: =IF(J$10<>0,J33/J$10,0) -> 0 | L33: =+月次PL!G26/1000 -> 0 | M33: =IF(L$10<>0,L33/L$10,0) -> 0 | N33: =+月次PL!H26/1000 -> 0 | O33: =IF(N$10<>0,N33/N$10,0) -> 0 | P33: =+月次PL!I26/1000 -> 0 | Q33: =IF(P$10<>0,P33/P$10,0) -> 0 | R33: =+月次PL!J26/1000 -> 0 | S33: =IF(R$10<>0,R33/R$10,0) -> 0 | T33: =+月次PL!K26/1000 -> 0 | U33: =IF(T$10<>0,T33/T$10,0) -> 0 | V33: =+月次PL!L26/1000 -> 0 | W33: =IF(V$10<>0,V33/V$10,0) -> 0 | X33: =+月次PL!M26/1000 -> 0 | Y33: =IF(X$10<>0,X33/X$10,0) -> 0 | Z33: =+月次PL!N26/1000 -> 0 | AA33: =IF(Z$10<>0,Z33/Z$10,0) -> 0
C34: 会議費 | D34: =+月次PL!C38/1000 -> 0 | E34: =IF(D$10<>0,D34/D$10,0) -> 0 | F34: =+月次PL!D38/1000 -> 0 | G34: =IF(F$10<>0,F34/F$10,0) -> 0 | H34: =+月次PL!E38/1000 -> 0 | I34: =IF(H$10<>0,H34/H$10,0) -> 0 | J34: =+月次PL!F38/1000 -> 0 | K34: =IF(J$10<>0,J34/J$10,0) -> 0 | L34: =+月次PL!G38/1000 -> 0 | M34: =IF(L$10<>0,L34/L$10,0) -> 0 | N34: =+月次PL!H38/1000 -> 0 | O34: =IF(N$10<>0,N34/N$10,0) -> 0 | P34: =+月次PL!I38/1000 -> 0 | Q34: =IF(P$10<>0,P34/P$10,0) -> 0 | R34: =+月次PL!J38/1000 -> 0 | S34: =IF(R$10<>0,R34/R$10,0) -> 0 | T34: =+月次PL!K38/1000 -> 0 | U34: =IF(T$10<>0,T34/T$10,0) -> 0 | V34: =+月次PL!L38/1000 -> 0 | W34: =IF(V$10<>0,V34/V$10,0) -> 0 | X34: =+月次PL!M38/1000 -> 0 | Y34: =IF(X$10<>0,X34/X$10,0) -> 0 | Z34: =+月次PL!N38/1000 -> 0 | AA34: =IF(Z$10<>0,Z34/Z$10,0) -> 0
C35: 減価償却費 | D35: =+月次PL!C40/1000 -> 690.589 | E35: =IF(D$10<>0,D35/D$10,0) -> 0.074460455 | F35: =+月次PL!D40/1000 -> 690.589 | G35: =IF(F$10<>0,F35/F$10,0) -> 0.069295071 | H35: =+月次PL!E40/1000 -> 690.589 | I35: =IF(H$10<>0,H35/H$10,0) -> 0.087772273 | J35: =+月次PL!F40/1000 -> 690.589 | K35: =IF(J$10<>0,J35/J$10,0) -> 0.083164277 | L35: =+月次PL!G40/1000 -> 690.589 | M35: =IF(L$10<>0,L35/L$10,0) -> 0.08441396 | N35: =+月次PL!H40/1000 -> 690.589 | O35: =IF(N$10<>0,N35/N$10,0) -> 0.059251192 | P35: =+月次PL!I40/1000 -> 690.589 | Q35: =IF(P$10<>0,P35/P$10,0) -> 0.088512188 | R35: =+月次PL!J40/1000 -> 690.589 | S35: =IF(R$10<>0,R35/R$10,0) -> 0.085454023 | T35: =+月次PL!K40/1000 -> 690.589 | U35: =IF(T$10<>0,T35/T$10,0) -> 0.078960553 | V35: =+月次PL!L40/1000 -> 690.589 | W35: =IF(V$10<>0,V35/V$10,0) -> 0.095861962 | X35: =+月次PL!M40/1000 -> 690.589 | Y35: =IF(X$10<>0,X35/X$10,0) -> 0.09091626 | Z35: =+月次PL!N40/1000 -> 690.589 | AA35: =IF(Z$10<>0,Z35/Z$10,0) -> 0.089719007
C36: 賃借料 | D36: =+月次PL!C34/1000 -> 30 | E36: =IF(D$10<>0,D36/D$10,0) -> 0.0032346499 | F36: =+月次PL!D34/1000 -> 30 | G36: =IF(F$10<>0,F36/F$10,0) -> 0.0030102596 | H36: =+月次PL!E34/1000 -> 30 | I36: =IF(H$10<>0,H36/H$10,0) -> 0.003812931 | J36: =+月次PL!F34/1000 -> 30 | K36: =IF(J$10<>0,J36/J$10,0) -> 0.0036127542 | L36: =+月次PL!G34/1000 -> 30 | M36: =IF(L$10<>0,L36/L$10,0) -> 0.0036670419 | N36: =+月次PL!H34/1000 -> 30 | O36: =IF(N$10<>0,N36/N$10,0) -> 0.0025739416 | P36: =+月次PL!I34/1000 -> 30 | Q36: =IF(P$10<>0,P36/P$10,0) -> 0.0038450738 | R36: =+月次PL!J34/1000 -> 30 | S36: =IF(R$10<>0,R36/R$10,0) -> 0.0037122235 | T36: =+月次PL!K34/1000 -> 30 | U36: =IF(T$10<>0,T36/T$10,0) -> 0.0034301395 | V36: =+月次PL!L34/1000 -> 30 | W36: =IF(V$10<>0,V36/V$10,0) -> 0.0041643566 | X36: =+月次PL!M34/1000 -> 30 | Y36: =IF(X$10<>0,X36/X$10,0) -> 0.0039495095 | Z36: =+月次PL!N34/1000 -> 30 | AA36: =IF(Z$10<>0,Z36/Z$10,0) -> 0.0038974994
C37: 地代家賃 | D37: =+月次PL!C33/1000 -> 1645.661 | E37: =IF(D$10<>0,D37/D$10,0) -> 0.17743791 | F37: =+月次PL!D33/1000 -> 1645.661 | G37: =IF(F$10<>0,F37/F$10,0) -> 0.16512889 | H37: =+月次PL!E33/1000 -> 1645.661 | I37: =IF(H$10<>0,H37/H$10,0) -> 0.20915973 | J37: =+月次PL!F33/1000 -> 1645.661 | K37: =IF(J$10<>0,J37/J$10,0) -> 0.19817896 | L37: =+月次PL!G33/1000 -> 1645.661 | M37: =IF(L$10<>0,L37/L$10,0) -> 0.20115693 | N37: =+月次PL!H33/1000 -> 1645.661 | O37: =IF(N$10<>0,N37/N$10,0) -> 0.14119451 | P37: =+月次PL!I33/1000 -> 1645.661 | Q37: =IF(P$10<>0,P37/P$10,0) -> 0.21092293 | R37: =+月次PL!J33/1000 -> 1645.661 | S37: =IF(R$10<>0,R37/R$10,0) -> 0.20363538 | T37: =+月次PL!K33/1000 -> 1645.661 | U37: =IF(T$10<>0,T37/T$10,0) -> 0.18816156 | V37: =+月次PL!L33/1000 -> 1645.661 | W37: =IF(V$10<>0,V37/V$10,0) -> 0.22843731 | X37: =+月次PL!M33/1000 -> 1645.661 | Y37: =IF(X$10<>0,X37/X$10,0) -> 0.21665179 | Z37: =+月次PL!N33/1000 -> 1645.661 | AA37: =IF(Z$10<>0,Z37/Z$10,0) -> 0.21379876
C38: リース料 | D38: =+月次PL!C32/1000 -> 49.7 | E38: =IF(D$10<>0,D38/D$10,0) -> 0.0053587367 | F38: =+月次PL!D32/1000 -> 49.7 | G38: =IF(F$10<>0,F38/F$10,0) -> 0.0049869967 | H38: =+月次PL!E32/1000 -> 49.7 | I38: =IF(H$10<>0,H38/H$10,0) -> 0.0063167557 | J38: =+月次PL!F32/1000 -> 49.7 | K38: =IF(J$10<>0,J38/J$10,0) -> 0.0059851294 | L38: =+月次PL!G32/1000 -> 49.7 | M38: =IF(L$10<>0,L38/L$10,0) -> 0.0060750661 | N38: =+月次PL!H32/1000 -> 49.7 | O38: =IF(N$10<>0,N38/N$10,0) -> 0.0042641633 | P38: =+月次PL!I32/1000 -> 49.7 | Q38: =IF(P$10<>0,P38/P$10,0) -> 0.0063700056 | R38: =+月次PL!J32/1000 -> 49.7 | S38: =IF(R$10<>0,R38/R$10,0) -> 0.0061499169 | T38: =+月次PL!K32/1000 -> 49.7 | U38: =IF(T$10<>0,T38/T$10,0) -> 0.0056825978 | V38: =+月次PL!L32/1000 -> 49.7 | W38: =IF(V$10<>0,V38/V$10,0) -> 0.0068989508 | X38: =+月次PL!M32/1000 -> 77.9 | Y38: =IF(X$10<>0,X38/X$10,0) -> 0.01025556 | Z38: =+月次PL!N32/1000 -> 49.7 | AA38: =IF(Z$10<>0,Z38/Z$10,0) -> 0.0064568573
C39: 修繕費 | D39: =+月次PL!C30/1000 -> 13.5 | E39: =IF(D$10<>0,D39/D$10,0) -> 0.0014555925 | F39: =+月次PL!D30/1000 -> 57.3 | G39: =IF(F$10<>0,F39/F$10,0) -> 0.0057495958 | H39: =+月次PL!E30/1000 -> 15 | I39: =IF(H$10<>0,H39/H$10,0) -> 0.0019064655 | J39: =+月次PL!F30/1000 -> 0 | K39: =IF(J$10<>0,J39/J$10,0) -> 0 | L39: =+月次PL!G30/1000 -> 20 | M39: =IF(L$10<>0,L39/L$10,0) -> 0.0024446946 | N39: =+月次PL!H30/1000 -> 19 | O39: =IF(N$10<>0,N39/N$10,0) -> 0.001630163 | P39: =+月次PL!I30/1000 -> 17 | Q39: =IF(P$10<>0,P39/P$10,0) -> 0.0021788751 | R39: =+月次PL!J30/1000 -> 90.91 | S39: =IF(R$10<>0,R39/R$10,0) -> 0.011249275 | T39: =+月次PL!K30/1000 -> 0 | U39: =IF(T$10<>0,T39/T$10,0) -> 0 | V39: =+月次PL!L30/1000 -> 0 | W39: =IF(V$10<>0,V39/V$10,0) -> 0 | X39: =+月次PL!M30/1000 -> 0 | Y39: =IF(X$10<>0,X39/X$10,0) -> 0 | Z39: =+月次PL!N30/1000 -> 15 | AA39: =IF(Z$10<>0,Z39/Z$10,0) -> 0.0019487497
C40: 保険料 | D40: =+月次PL!C35/1000 -> 22.215 | E40: =IF(D$10<>0,D40/D$10,0) -> 0.0023952583 | F40: =+月次PL!D35/1000 -> 22.215 | G40: =IF(F$10<>0,F40/F$10,0) -> 0.0022290972 | H40: =+月次PL!E35/1000 -> 22.215 | I40: =IF(H$10<>0,H40/H$10,0) -> 0.0028234754 | J40: =+月次PL!F35/1000 -> 22.215 | K40: =IF(J$10<>0,J40/J$10,0) -> 0.0026752445 | L40: =+月次PL!G35/1000 -> 22.215 | M40: =IF(L$10<>0,L40/L$10,0) -> 0.0027154445 | N40: =+月次PL!H35/1000 -> 28.375 | O40: =IF(N$10<>0,N40/N$10,0) -> 0.0024345198 | P40: =+月次PL!I35/1000 -> 28.375 | Q40: =IF(P$10<>0,P40/P$10,0) -> 0.0036367989 | R40: =+月次PL!J35/1000 -> 28.375 | S40: =IF(R$10<>0,R40/R$10,0) -> 0.0035111447 | T40: =+月次PL!K35/1000 -> 28.375 | U40: =IF(T$10<>0,T40/T$10,0) -> 0.0032443403 | V40: =+月次PL!L35/1000 -> 28.375 | W40: =IF(V$10<>0,V40/V$10,0) -> 0.0039387873 | X40: =+月次PL!M35/1000 -> 28.375 | Y40: =IF(X$10<>0,X40/X$10,0) -> 0.0037355777 | Z40: =+月次PL!N35/1000 -> 28.375 | AA40: =IF(Z$10<>0,Z40/Z$10,0) -> 0.0036863849
C41: 水道光熱費 | D41: =+月次PL!C29/1000 -> 1055.015 | E41: =IF(D$10<>0,D41/D$10,0) -> 0.11375347 | F41: =+月次PL!D29/1000 -> 1104.21 | G41: =IF(F$10<>0,F41/F$10,0) -> 0.11079862 | H41: =+月次PL!E29/1000 -> 968.209 | I41: =IF(H$10<>0,H41/H$10,0) -> 0.12305714 | J41: =+月次PL!F29/1000 -> 757.6 | K41: =IF(J$10<>0,J41/J$10,0) -> 0.091234086 | L41: =+月次PL!G29/1000 -> 878.364 | M41: =IF(L$10<>0,L41/L$10,0) -> 0.10736659 | N41: =+月次PL!H29/1000 -> 1110.021 | O41: =IF(N$10<>0,N41/N$10,0) -> 0.095237642 | P41: =+月次PL!I29/1000 -> 1144.612 | Q41: =IF(P$10<>0,P41/P$10,0) -> 0.14670392 | R41: =+月次PL!J29/1000 -> 1235.761 | S41: =IF(R$10<>0,R41/R$10,0) -> 0.15291403 | T41: =+月次PL!K29/1000 -> 1093.647 | U41: =IF(T$10<>0,T41/T$10,0) -> 0.12504539 | V41: =+月次PL!L29/1000 -> 804.331 | W41: =IF(V$10<>0,V41/V$10,0) -> 0.1116507 | X41: =+月次PL!M29/1000 -> 719.828 | Y41: =IF(X$10<>0,X41/X$10,0) -> 0.094765583 | Z41: =+月次PL!N29/1000 -> 852.493 | AA41: =IF(Z$10<>0,Z41/Z$10,0) -> 0.11075303
...

Sheet PL予実対比
A7: ■月次PL予実対比 | BB7: =+PL推移!D7 -> ㈱ｅｓエンターテイメント
A8: =+PL推移!B8 -> 2025 | B8: 年度 | BB8: 単位：千円
A9: 項目 | C9: =+PL推移!D9 -> 7月 | G9: =+PL推移!F9 -> 8月 | K9: =+PL推移!H9 -> 9月 | O9: =+PL推移!J9 -> 10月 | S9: =+PL推移!L9 -> 11月 | W9: =+PL推移!N9 -> 12月 | AA9: =+PL推移!P9 -> 1月 | AE9: =+PL推移!R9 -> 2月 | AI9: =+PL推移!T9 -> 3 | AM9: =+PL推移!V9 -> 4 | AQ9: =+PL推移!X9 -> 5月 | AU9: =+PL推移!Z9 -> 6月 | AY9: 累計
C10: 計画 | D10: 実績 | E10: 差異 | F10: 計画比 | G10: 計画 | H10: 実績 | I10: 差異 | J10: 計画比 | K10: 計画 | L10: 実績 | M10: 差異 | N10: 計画比 | O10: 計画 | P10: 実績 | Q10: 差異 | R10: 計画比 | S10: 計画 | T10: 実績 | U10: 差異 | V10: 計画比 | W10: 計画 | X10: 実績 | Y10: 差異 | Z10: 計画比 | AA10: 計画 | AB10: 実績 | AC10: 差異 | AD10: 計画比 | AE10: 計画 | AF10: 実績 | AG10: 差異 | AH10: 計画比 | AI10: 計画 | AJ10: 実績 | AK10: 差異 | AL10: 計画比 | AM10: 計画 | AN10: 実績 | AO10: 差異 | AP10: 計画比 | AQ10: 計画 | AR10: 実績 | AS10: 差異 | AT10: 計画比 | AU10: 計画 | AV10: 実績 | AW10: 差異 | AX10: 計画比 | AY10: 計画 | AZ10: 実績 | BA10: 差異 | BB10: 計画比
A11: 売上高 | C11: =+収支計画!G17/1000 -> 9600 | D11: =+PL推移!D10 -> 9274.574 | E11: =SUM(E12:E16) -> -325 | F11: =IF(C11<>0,D11/C11,"-") -> 0.96610146 | G11: =+収支計画!H17/1000 -> 11220 | H11: =SUM(H12:H16) -> 9616 | I11: =SUM(I12:I16) -> -1254 | J11: =IF(G11<>0,H11/G11,"-") -> 0.857041 | K11: =+収支計画!I17/1000 -> 9600 | L11: =+PL推移!H10 -> 7867.963 | M11: =SUM(M12:M16) -> -1733 | N11: =IF(K11<>0,L11/K11,"-") -> 0.81957948 | O11: =+収支計画!J17/1000 -> 9600 | P11: =+PL推移!J10 -> 8303.914 | Q11: =SUM(Q12:Q16) -> -1287 | R11: =IF(O11<>0,P11/O11,"-") -> 0.86499104 | S11: =+収支計画!K17/1000 -> 9600 | T11: =+PL推移!L10 -> 8180.981 | U11: =SUM(U12:U16) -> -1419 | V11: =IF(S11<>0,T11/S11,"-") -> 0.85218552 | W11: =+収支計画!L17/1000 -> 12100 | X11: =+PL推移!N10 -> 11655.276 | Y11: =SUM(Y12:Y16) -> -148 | Z11: =IF(W11<>0,X11/W11,"-") -> 0.96324595 | AA11: =+収支計画!M17/1000 -> 9600 | AB11: =+PL推移!P10 -> 7802.191 | AC11: =SUM(AC12:AC16) -> -1798 | AD11: =IF(AA11<>0,AB11/AA11,"-") -> 0.81272823 | AE11: =+収支計画!N17/1000 -> 9600 | AF11: =+PL推移!R10 -> 8081.41 | AG11: =SUM(AG12:AG16) -> -1533 | AH11: =IF(AE11<>0,AF11/AE11,"-") -> 0.84181354 | AI11: =+収支計画!O17/1000 -> 11100 | AJ11: =+PL推移!T10 -> 8746 | AK11: =SUM(AK12:AK16) -> -2343 | AL11: =IF(AI11<>0,AJ11/AI11,"-") -> 0.78792793 | AM11: =+収支計画!P17/1000 -> 9600 | AN11: =+PL推移!V10 -> 7203.994 | AO11: =+AN11-AM11 -> -2396.006 | AP11: =IF(AM11<>0,AN11/AM11,"-") -> 0.75041604 | AQ11: =+収支計画!Q17/1000 -> 9600 | AR11: =+PL推移!X10 -> 7595.88 | AS11: =+AR11-AQ11 -> -2004.12 | AT11: =IF(AQ11<>0,AR11/AQ11,"-") -> 0.7912375 | AU11: =+収支計画!R17/1000 -> 9600 | AV11: =+PL推移!Z10 -> 7697.243 | AW11: =+AV11-AU11 -> -1902.757 | AX11: =IF(AU11<>0,AV11/AU11,"-") -> 0.80179615 | AY11: =+C11+G11+K11+O11+S11+W11+AA11+AE11+AI11+AM11+AQ11+AU11 -> 120820 | AZ11: =+D11+H11+L11+P11+T11+X11+AB11+AF11+AJ11+AN11+AR11+AV11 -> 102025.43 | BA11: =+AZ11-AY11 -> -18794.574 | BB11: =IF(AY11<>0,AZ11/AY11,"-") -> 0.84444153
B12: 恵愛 | C12: =+収支計画!G11/1000 -> 7000 | D12: =+PL推移!D11 -> 6973 | E12: =+D12-C12 -> -27 | F12: =IF(C12<>0,D12/C12,"-") -> 0.99614286 | G12: =+収支計画!H11/1000 -> 7000 | H12: =+PL推移!F11 -> 6864 | I12: =+H12-G12 -> -136 | J12: =IF(G12<>0,H12/G12,"-") -> 0.98057143 | K12: =+収支計画!I11/1000 -> 7000 | L12: =+PL推移!H11 -> 5812 | M12: =+L12-K12 -> -1188 | N12: =IF(K12<>0,L12/K12,"-") -> 0.83028571 | O12: =+収支計画!S11/1000 -> 7000 | P12: =+PL推移!J11 -> 5700 | Q12: =+P12-O12 -> -1300 | R12: =IF(O12<>0,P12/O12,"-") -> 0.81428571 | S12: =+収支計画!K11/1000 -> 7000 | T12: =+PL推移!L11 -> 6255 | U12: =+T12-S12 -> -745 | V12: =IF(S12<>0,T12/S12,"-") -> 0.89357143 | W12: =+収支計画!L11/1000 -> 9500 | X12: =+PL推移!N11 -> 9574 | Y12: =+X12-W12 -> 74 | Z12: =IF(W12<>0,X12/W12,"-") -> 1.0077895 | AA12: =+収支計画!M11/1000 -> 7000 | AB12: =+PL推移!P11 -> 5703 | AC12: =+AB12-AA12 -> -1297 | AD12: =IF(AA12<>0,AB12/AA12,"-") -> 0.81471429 | AE12: =+収支計画!N11/1000 -> 7000 | AF12: =+PL推移!R11 -> 6142 | AG12: =+AF12-AE12 -> -858 | AH12: =IF(AE12<>0,AF12/AE12,"-") -> 0.87742857 | AI12: =+収支計画!O11/1000 -> 8500 | AJ12: =+PL推移!T11 -> 6615 | AK12: =+AJ12-AI12 -> -1885 | AL12: =IF(AI12<>0,AJ12/AI12,"-") -> 0.77823529 | AM12: =+収支計画!P11/1000 -> 7000 | AN12: =+PL推移!V11 -> 4998 | AO12: =+AN12-AM12 -> -2002 | AP12: =IF(AM12<>0,AN12/AM12,"-") -> 0.714 | AQ12: =+収支計画!Q11/1000 -> 7000 | AR12: =+PL推移!X11 -> 5401 | AS12: =+AR12-AQ12 -> -1599 | AT12: =IF(AQ12<>0,AR12/AQ12,"-") -> 0.77157143 | AU12: =+収支計画!R11/1000 -> 7000 | AV12: =+PL推移!Z11 -> 5367 | AW12: =+AV12-AU12 -> -1633 | AX12: =IF(AU12<>0,AV12/AU12,"-") -> 0.76671429 | AY12: =+C12+G12+K12+O12+S12+W12+AA12+AE12+AI12+AM12+AQ12+AU12 -> 88000 | AZ12: =+D12+H12+L12+P12+T12+X12+AB12+AF12+AJ12+AN12+AR12+AV12 -> 75404 | BA12: =+AZ12-AY12 -> -12596 | BB12: =IF(AY12<>0,AZ12/AY12,"-") -> 0.85686364
B13: 村 | C13: =+収支計画!G12/1000 -> 750 | D13: =+PL推移!D12 -> 573 | E13: =+D13-C13 -> -177 | F13: =IF(C13<>0,D13/C13,"-") -> 0.764 | G13: =+収支計画!H12/1000 -> 750 | H13: =+PL推移!F12 -> 597 | I13: =+H13-G13 -> -153 | J13: =IF(G13<>0,H13/G13,"-") -> 0.796 | K13: =+収支計画!I12/1000 -> 750 | L13: =+PL推移!H12 -> 602 | M13: =+L13-K13 -> -148 | N13: =IF(K13<>0,L13/K13,"-") -> 0.80266667 | O13: =+収支計画!S12/1000 -> 750 | P13: =+PL推移!J12 -> 580 | Q13: =+P13-O13 -> -170 | R13: =IF(O13<>0,P13/O13,"-") -> 0.77333333 | S13: =+収支計画!K12/1000 -> 750 | T13: =+PL推移!L12 -> 531 | U13: =+T13-S13 -> -219 | V13: =IF(S13<>0,T13/S13,"-") -> 0.708 | W13: =+収支計画!L12/1000 -> 750 | X13: =+PL推移!N12 -> 558 | Y13: =+X13-W13 -> -192 | Z13: =IF(W13<>0,X13/W13,"-") -> 0.744 | AA13: =+収支計画!M12/1000 -> 750 | AB13: =+PL推移!P12 -> 590 | AC13: =+AB13-AA13 -> -160 | AD13: =IF(AA13<>0,AB13/AA13,"-") -> 0.78666667 | AE13: =+収支計画!N12/1000 -> 750 | AF13: =+PL推移!R12 -> 596 | AG13: =+AF13-AE13 -> -154 | AH13: =IF(AE13<>0,AF13/AE13,"-") -> 0.79466667 | AI13: =+収支計画!O12/1000 -> 750 | AJ13: =+PL推移!T12 -> 606 | AK13: =+AJ13-AI13 -> -144 | AL13: =IF(AI13<>0,AJ13/AI13,"-") -> 0.808 | AM13: =+収支計画!P12/1000 -> 750 | AN13: =+PL推移!V12 -> 541 | AO13: =+AN13-AM13 -> -209 | AP13: =IF(AM13<>0,AN13/AM13,"-") -> 0.72133333 | AQ13: =+収支計画!Q12/1000 -> 750 | AR13: =+PL推移!X12 -> 611 | AS13: =+AR13-AQ13 -> -139 | AT13: =IF(AQ13<>0,AR13/AQ13,"-") -> 0.81466667 | AU13: =+収支計画!R12/1000 -> 750 | AV13: =+PL推移!Z12 -> 600 | AW13: =+AV13-AU13 -> -150 | AX13: =IF(AU13<>0,AV13/AU13,"-") -> 0.8 | AY13: =+C13+G13+K13+O13+S13+W13+AA13+AE13+AI13+AM13+AQ13+AU13 -> 9000 | AZ13: =+D13+H13+L13+P13+T13+X13+AB13+AF13+AJ13+AN13+AR13+AV13 -> 6985 | BA13: =+AZ13-AY13 -> -2015 | BB13: =IF(AY13<>0,AZ13/AY13,"-") -> 0.77611111
